Workbook

Sheet Cover
B3: Configuration Parameters
B5: Generated: | C5: December 03, 2025
B6: Solution: | C6: Virtual Desktop
B7: Customer: | C7: [Customer Name]
B8: Version: | C8: 1.0
B9: Status: | C9: Draft
C12: eoframework.org

Sheet All Parameters (Read Only)
A1: Total Parameters | B1: Categories | C1: Required | D1: Confidential/Secret
A2: 72 | B2: 14 | C2: 71 | D2: 6
A4: Parameter Name | B4: Category | C4: Production | D4: Test | E4: DR | F4: Description | G4: Required | H4: Data Type | I4: Validation Rules | J4: Security Level
A5: =IF('Project'!A3="","",'Project'!A3) | B5: Project | C5: =IF('Project'!B3="","",'Project'!B3) | D5: =IF('Project'!C3="","",'Project'!C3) | E5: =IF('Project'!D3="","",'Project'!D3) | F5: =IF('Project'!E3="","",'Project'!E3) | G5: =IF('Project'!F3="","",'Project'!F3) | H5: =IF('Project'!G3="","",'Project'!G3) | I5: =IF('Project'!H3="","",'Project'!H3) | J5: =IF('Project'!I3="","",'Project'!I3)
A6: =IF('Project'!A4="","",'Project'!A4) | B6: Project | C6: =IF('Project'!B4="","",'Project'!B4) | D6: =IF('Project'!C4="","",'Project'!C4) | E6: =IF('Project'!D4="","",'Project'!D4) | F6: =IF('Project'!E4="","",'Project'!E4) | G6: =IF('Project'!F4="","",'Project'!F4) | H6: =IF('Project'!G4="","",'Project'!G4) | I6: =IF('Project'!H4="","",'Project'!H4) | J6: =IF('Project'!I4="","",'Project'!I4)
A7: =IF('Project'!A5="","",'Project'!A5) | B7: Project | C7: =IF('Project'!B5="","",'Project'!B5) | D7: =IF('Project'!C5="","",'Project'!C5) | E7: =IF('Project'!D5="","",'Project'!D5) | F7: =IF('Project'!E5="","",'Project'!E5) | G7: =IF('Project'!F5="","",'Project'!F5) | H7: =IF('Project'!G5="","",'Project'!G5) | I7: =IF('Project'!H5="","",'Project'!H5) | J7: =IF('Project'!I5="","",'Project'!I5)
A8: =IF('Project'!A6="","",'Project'!A6) | B8: Project | C8: =IF('Project'!B6="","",'Project'!B6) | D8: =IF('Project'!C6="","",'Project'!C6) | E8: =IF('Project'!D6="","",'Project'!D6) | F8: =IF('Project'!E6="","",'Project'!E6) | G8: =IF('Project'!F6="","",'Project'!F6) | H8: =IF('Project'!G6="","",'Project'!G6) | I8: =IF('Project'!H6="","",'Project'!H6) | J8: =IF('Project'!I6="","",'Project'!I6)
A9: =IF('Project'!A7="","",'Project'!A7) | B9: Project | C9: =IF('Project'!B7="","",'Project'!B7) | D9: =IF('Project'!C7="","",'Project'!C7) | E9: =IF('Project'!D7="","",'Project'!D7) | F9: =IF('Project'!E7="","",'Project'!E7) | G9: =IF('Project'!F7="","",'Project'!F7) | H9: =IF('Project'!G7="","",'Project'!G7) | I9: =IF('Project'!H7="","",'Project'!H7) | J9: =IF('Project'!I7="","",'Project'!I7)
A10: =IF('Project'!A8="","",'Project'!A8) | B10: Project | C10: =IF('Project'!B8="","",'Project'!B8) | D10: =IF('Project'!C8="","",'Project'!C8) | E10: =IF('Project'!D8="","",'Project'!D8) | F10: =IF('Project'!E8="","",'Project'!E8) | G10: =IF('Project'!F8="","",'Project'!F8) | H10: =IF('Project'!G8="","",'Project'!G8) | I10: =IF('Project'!H8="","",'Project'!H8) | J10: =IF('Project'!I8="","",'Project'!I8)
A11: =IF('Project'!A9="","",'Project'!A9) | B11: Project | C11: =IF('Project'!B9="","",'Project'!B9) | D11: =IF('Project'!C9="","",'Project'!C9) | E11: =IF('Project'!D9="","",'Project'!D9) | F11: =IF('Project'!E9="","",'Project'!E9) | G11: =IF('Project'!F9="","",'Project'!F9) | H11: =IF('Project'!G9="","",'Project'!G9) | I11: =IF('Project'!H9="","",'Project'!H9) | J11: =IF('Project'!I9="","",'Project'!I9)
A12: =IF('Project'!A10="","",'Project'!A10) | B12: Project | C12: =IF('Project'!B10="","",'Project'!B10) | D12: =IF('Project'!C10="","",'Project'!C10) | E12: =IF('Project'!D10="","",'Project'!D10) | F12: =IF('Project'!E10="","",'Project'!E10) | G12: =IF('Project'!F10="","",'Project'!F10) | H12: =IF('Project'!G10="","",'Project'!G10) | I12: =IF('Project'!H10="","",'Project'!H10) | J12: =IF('Project'!I10="","",'Project'!I10)
A13: =IF('Project'!A11="","",'Project'!A11) | B13: Project | C13: =IF('Project'!B11="","",'Project'!B11) | D13: =IF('Project'!C11="","",'Project'!C11) | E13: =IF('Project'!D11="","",'Project'!D11) | F13: =IF('Project'!E11="","",'Project'!E11) | G13: =IF('Project'!F11="","",'Project'!F11) | H13: =IF('Project'!G11="","",'Project'!G11) | I13: =IF('Project'!H11="","",'Project'!H11) | J13: =IF('Project'!I11="","",'Project'!I11)
A14: =IF('Project'!A12="","",'Project'!A12) | B14: Project | C14: =IF('Project'!B12="","",'Project'!B12) | D14: =IF('Project'!C12="","",'Project'!C12) | E14: =IF('Project'!D12="","",'Project'!D12) | F14: =IF('Project'!E12="","",'Project'!E12) | G14: =IF('Project'!F12="","",'Project'!F12) | H14: =IF('Project'!G12="","",'Project'!G12) | I14: =IF('Project'!H12="","",'Project'!H12) | J14: =IF('Project'!I12="","",'Project'!I12)
A15: =IF('Project'!A13="","",'Project'!A13) | B15: Project | C15: =IF('Project'!B13="","",'Project'!B13) | D15: =IF('Project'!C13="","",'Project'!C13) | E15: =IF('Project'!D13="","",'Project'!D13) | F15: =IF('Project'!E13="","",'Project'!E13) | G15: =IF('Project'!F13="","",'Project'!F13) | H15: =IF('Project'!G13="","",'Project'!G13) | I15: =IF('Project'!H13="","",'Project'!H13) | J15: =IF('Project'!I13="","",'Project'!I13)
A16: =IF('Security'!A3="","",'Security'!A3) | B16: Security | C16: =IF('Security'!B3="","",'Security'!B3) | D16: =IF('Security'!C3="","",'Security'!C3) | E16: =IF('Security'!D3="","",'Security'!D3) | F16: =IF('Security'!E3="","",'Security'!E3) | G16: =IF('Security'!F3="","",'Security'!F3) | H16: =IF('Security'!G3="","",'Security'!G3) | I16: =IF('Security'!H3="","",'Security'!H3) | J16: =IF('Security'!I3="","",'Security'!I3)
A17: =IF('Security'!A4="","",'Security'!A4) | B17: Security | C17: =IF('Security'!B4="","",'Security'!B4) | D17: =IF('Security'!C4="","",'Security'!C4) | E17: =IF('Security'!D4="","",'Security'!D4) | F17: =IF('Security'!E4="","",'Security'!E4) | G17: =IF('Security'!F4="","",'Security'!F4) | H17: =IF('Security'!G4="","",'Security'!G4) | I17: =IF('Security'!H4="","",'Security'!H4) | J17: =IF('Security'!I4="","",'Security'!I4)
A18: =IF('Security'!A5="","",'Security'!A5) | B18: Security | C18: =IF('Security'!B5="","",'Security'!B5) | D18: =IF('Security'!C5="","",'Security'!C5) | E18: =IF('Security'!D5="","",'Security'!D5) | F18: =IF('Security'!E5="","",'Security'!E5) | G18: =IF('Security'!F5="","",'Security'!F5) | H18: =IF('Security'!G5="","",'Security'!G5) | I18: =IF('Security'!H5="","",'Security'!H5) | J18: =IF('Security'!I5="","",'Security'!I5)
A19: =IF('Storage'!A3="","",'Storage'!A3) | B19: Storage | C19: =IF('Storage'!B3="","",'Storage'!B3) | D19: =IF('Storage'!C3="","",'Storage'!C3) | E19: =IF('Storage'!D3="","",'Storage'!D3) | F19: =IF('Storage'!E3="","",'Storage'!E3) | G19: =IF('Storage'!F3="","",'Storage'!F3) | H19: =IF('Storage'!G3="","",'Storage'!G3) | I19: =IF('Storage'!H3="","",'Storage'!H3) | J19: =IF('Storage'!I3="","",'Storage'!I3)
A20: =IF('Storage'!A4="","",'Storage'!A4) | B20: Storage | C20: =IF('Storage'!B4="","",'Storage'!B4) | D20: =IF('Storage'!C4="","",'Storage'!C4) | E20: =IF('Storage'!D4="","",'Storage'!D4) | F20: =IF('Storage'!E4="","",'Storage'!E4) | G20: =IF('Storage'!F4="","",'Storage'!F4) | H20: =IF('Storage'!G4="","",'Storage'!G4) | I20: =IF('Storage'!H4="","",'Storage'!H4) | J20: =IF('Storage'!I4="","",'Storage'!I4)
A21: =IF('Storage'!A5="","",'Storage'!A5) | B21: Storage | C21: =IF('Storage'!B5="","",'Storage'!B5) | D21: =IF('Storage'!C5="","",'Storage'!C5) | E21: =IF('Storage'!D5="","",'Storage'!D5) | F21: =IF('Storage'!E5="","",'Storage'!E5) | G21: =IF('Storage'!F5="","",'Storage'!F5) | H21: =IF('Storage'!G5="","",'Storage'!G5) | I21: =IF('Storage'!H5="","",'Storage'!H5) | J21: =IF('Storage'!I5="","",'Storage'!I5)
A22: =IF('Storage'!A6="","",'Storage'!A6) | B22: Storage | C22: =IF('Storage'!B6="","",'Storage'!B6) | D22: =IF('Storage'!C6="","",'Storage'!C6) | E22: =IF('Storage'!D6="","",'Storage'!D6) | F22: =IF('Storage'!E6="","",'Storage'!E6) | G22: =IF('Storage'!F6="","",'Storage'!F6) | H22: =IF('Storage'!G6="","",'Storage'!G6) | I22: =IF('Storage'!H6="","",'Storage'!H6) | J22: =IF('Storage'!I6="","",'Storage'!I6)
A23: =IF('Storage'!A7="","",'Storage'!A7) | B23: Storage | C23: =IF('Storage'!B7="","",'Storage'!B7) | D23: =IF('Storage'!C7="","",'Storage'!C7) | E23: =IF('Storage'!D7="","",'Storage'!D7) | F23: =IF('Storage'!E7="","",'Storage'!E7) | G23: =IF('Storage'!F7="","",'Storage'!F7) | H23: =IF('Storage'!G7="","",'Storage'!G7) | I23: =IF('Storage'!H7="","",'Storage'!H7) | J23: =IF('Storage'!I7="","",'Storage'!I7)
A24: =IF('Application'!A3="","",'Application'!A3) | B24: Application | C24: =IF('Application'!B3="","",'Application'!B3) | D24: =IF('Application'!C3="","",'Application'!C3) | E24: =IF('Application'!D3="","",'Application'!D3) | F24: =IF('Application'!E3="","",'Application'!E3) | G24: =IF('Application'!F3="","",'Application'!F3) | H24: =IF('Application'!G3="","",'Application'!G3) | I24: =IF('Application'!H3="","",'Application'!H3) | J24: =IF('Application'!I3="","",'Application'!I3)
A25: =IF('Application'!A4="","",'Application'!A4) | B25: Application | C25: =IF('Application'!B4="","",'Application'!B4) | D25: =IF('Application'!C4="","",'Application'!C4) | E25: =IF('Application'!D4="","",'Application'!D4) | F25: =IF('Application'!E4="","",'Application'!E4) | G25: =IF('Application'!F4="","",'Application'!F4) | H25: =IF('Application'!G4="","",'Application'!G4) | I25: =IF('Application'!H4="","",'Application'!H4) | J25: =IF('Application'!I4="","",'Application'!I4)
A26: =IF('Monitoring'!A3="","",'Monitoring'!A3) | B26: Monitoring | C26: =IF('Monitoring'!B3="","",'Monitoring'!B3) | D26: =IF('Monitoring'!C3="","",'Monitoring'!C3) | E26: =IF('Monitoring'!D3="","",'Monitoring'!D3) | F26: =IF('Monitoring'!E3="","",'Monitoring'!E3) | G26: =IF('Monitoring'!F3="","",'Monitoring'!F3) | H26: =IF('Monitoring'!G3="","",'Monitoring'!G3) | I26: =IF('Monitoring'!H3="","",'Monitoring'!H3) | J26: =IF('Monitoring'!I3="","",'Monitoring'!I3)
A27: =IF('Monitoring'!A4="","",'Monitoring'!A4) | B27: Monitoring | C27: =IF('Monitoring'!B4="","",'Monitoring'!B4) | D27: =IF('Monitoring'!C4="","",'Monitoring'!C4) | E27: =IF('Monitoring'!D4="","",'Monitoring'!D4) | F27: =IF('Monitoring'!E4="","",'Monitoring'!E4) | G27: =IF('Monitoring'!F4="","",'Monitoring'!F4) | H27: =IF('Monitoring'!G4="","",'Monitoring'!G4) | I27: =IF('Monitoring'!H4="","",'Monitoring'!H4) | J27: =IF('Monitoring'!I4="","",'Monitoring'!I4)
A28: =IF('Monitoring'!A5="","",'Monitoring'!A5) | B28: Monitoring | C28: =IF('Monitoring'!B5="","",'Monitoring'!B5) | D28: =IF('Monitoring'!C5="","",'Monitoring'!C5) | E28: =IF('Monitoring'!D5="","",'Monitoring'!D5) | F28: =IF('Monitoring'!E5="","",'Monitoring'!E5) | G28: =IF('Monitoring'!F5="","",'Monitoring'!F5) | H28: =IF('Monitoring'!G5="","",'Monitoring'!G5) | I28: =IF('Monitoring'!H5="","",'Monitoring'!H5) | J28: =IF('Monitoring'!I5="","",'Monitoring'!I5)
A29: =IF('Monitoring'!A6="","",'Monitoring'!A6) | B29: Monitoring | C29: =IF('Monitoring'!B6="","",'Monitoring'!B6) | D29: =IF('Monitoring'!C6="","",'Monitoring'!C6) | E29: =IF('Monitoring'!D6="","",'Monitoring'!D6) | F29: =IF('Monitoring'!E6="","",'Monitoring'!E6) | G29: =IF('Monitoring'!F6="","",'Monitoring'!F6) | H29: =IF('Monitoring'!G6="","",'Monitoring'!G6) | I29: =IF('Monitoring'!H6="","",'Monitoring'!H6) | J29: =IF('Monitoring'!I6="","",'Monitoring'!I6)
A30: =IF('Monitoring'!A7="","",'Monitoring'!A7) | B30: Monitoring | C30: =IF('Monitoring'!B7="","",'Monitoring'!B7) | D30: =IF('Monitoring'!C7="","",'Monitoring'!C7) | E30: =IF('Monitoring'!D7="","",'Monitoring'!D7) | F30: =IF('Monitoring'!E7="","",'Monitoring'!E7) | G30: =IF('Monitoring'!F7="","",'Monitoring'!F7) | H30: =IF('Monitoring'!G7="","",'Monitoring'!G7) | I30: =IF('Monitoring'!H7="","",'Monitoring'!H7) | J30: =IF('Monitoring'!I7="","",'Monitoring'!I7)
A31: =IF('DR'!A3="","",'DR'!A3) | B31: DR | C31: =IF('DR'!B3="","",'DR'!B3) | D31: =IF('DR'!C3="","",'DR'!C3) | E31: =IF('DR'!D3="","",'DR'!D3) | F31: =IF('DR'!E3="","",'DR'!E3) | G31: =IF('DR'!F3="","",'DR'!F3) | H31: =IF('DR'!G3="","",'DR'!G3) | I31: =IF('DR'!H3="","",'DR'!H3) | J31: =IF('DR'!I3="","",'DR'!I3)
A32: =IF('DR'!A4="","",'DR'!A4) | B32: DR | C32: =IF('DR'!B4="","",'DR'!B4) | D32: =IF('DR'!C4="","",'DR'!C4) | E32: =IF('DR'!D4="","",'DR'!D4) | F32: =IF('DR'!E4="","",'DR'!E4) | G32: =IF('DR'!F4="","",'DR'!F4) | H32: =IF('DR'!G4="","",'DR'!G4) | I32: =IF('DR'!H4="","",'DR'!H4) | J32: =IF('DR'!I4="","",'DR'!I4)
A33: =IF('DR'!A5="","",'DR'!A5) | B33: DR | C33: =IF('DR'!B5="","",'DR'!B5) | D33: =IF('DR'!C5="","",'DR'!C5) | E33: =IF('DR'!D5="","",'DR'!D5) | F33: =IF('DR'!E5="","",'DR'!E5) | G33: =IF('DR'!F5="","",'DR'!F5) | H33: =IF('DR'!G5="","",'DR'!G5) | I33: =IF('DR'!H5="","",'DR'!H5) | J33: =IF('DR'!I5="","",'DR'!I5)
A34: =IF('AVD'!A3="","",'AVD'!A3) | B34: AVD | C34: =IF('AVD'!B3="","",'AVD'!B3) | D34: =IF('AVD'!C3="","",'AVD'!C3) | E34: =IF('AVD'!D3="","",'AVD'!D3) | F34: =IF('AVD'!E3="","",'AVD'!E3) | G34: =IF('AVD'!F3="","",'AVD'!F3) | H34: =IF('AVD'!G3="","",'AVD'!G3) | I34: =IF('AVD'!H3="","",'AVD'!H3) | J34: =IF('AVD'!I3="","",'AVD'!I3)
A35: =IF('AVD'!A4="","",'AVD'!A4) | B35: AVD | C35: =IF('AVD'!B4="","",'AVD'!B4) | D35: =IF('AVD'!C4="","",'AVD'!C4) | E35: =IF('AVD'!D4="","",'AVD'!D4) | F35: =IF('AVD'!E4="","",'AVD'!E4) | G35: =IF('AVD'!F4="","",'AVD'!F4) | H35: =IF('AVD'!G4="","",'AVD'!G4) | I35: =IF('AVD'!H4="","",'AVD'!H4) | J35: =IF('AVD'!I4="","",'AVD'!I4)
A36: =IF('AVD'!A5="","",'AVD'!A5) | B36: AVD | C36: =IF('AVD'!B5="","",'AVD'!B5) | D36: =IF('AVD'!C5="","",'AVD'!C5) | E36: =IF('AVD'!D5="","",'AVD'!D5) | F36: =IF('AVD'!E5="","",'AVD'!E5) | G36: =IF('AVD'!F5="","",'AVD'!F5) | H36: =IF('AVD'!G5="","",'AVD'!G5) | I36: =IF('AVD'!H5="","",'AVD'!H5) | J36: =IF('AVD'!I5="","",'AVD'!I5)
A37: =IF('AVD'!A6="","",'AVD'!A6) | B37: AVD | C37: =IF('AVD'!B6="","",'AVD'!B6) | D37: =IF('AVD'!C6="","",'AVD'!C6) | E37: =IF('AVD'!D6="","",'AVD'!D6) | F37: =IF('AVD'!E6="","",'AVD'!E6) | G37: =IF('AVD'!F6="","",'AVD'!F6) | H37: =IF('AVD'!G6="","",'AVD'!G6) | I37: =IF('AVD'!H6="","",'AVD'!H6) | J37: =IF('AVD'!I6="","",'AVD'!I6)
A38: =IF('AVD'!A7="","",'AVD'!A7) | B38: AVD | C38: =IF('AVD'!B7="","",'AVD'!B7) | D38: =IF('AVD'!C7="","",'AVD'!C7) | E38: =IF('AVD'!D7="","",'AVD'!D7) | F38: =IF('AVD'!E7="","",'AVD'!E7) | G38: =IF('AVD'!F7="","",'AVD'!F7) | H38: =IF('AVD'!G7="","",'AVD'!G7) | I38: =IF('AVD'!H7="","",'AVD'!H7) | J38: =IF('AVD'!I7="","",'AVD'!I7)
A39: =IF('AVD'!A8="","",'AVD'!A8) | B39: AVD | C39: =IF('AVD'!B8="","",'AVD'!B8) | D39: =IF('AVD'!C8="","",'AVD'!C8) | E39: =IF('AVD'!D8="","",'AVD'!D8) | F39: =IF('AVD'!E8="","",'AVD'!E8) | G39: =IF('AVD'!F8="","",'AVD'!F8) | H39: =IF('AVD'!G8="","",'AVD'!G8) | I39: =IF('AVD'!H8="","",'AVD'!H8) | J39: =IF('AVD'!I8="","",'AVD'!I8)
A40: =IF('AppGroup'!A3="","",'AppGroup'!A3) | B40: AppGroup | C40: =IF('AppGroup'!B3="","",'AppGroup'!B3) | D40: =IF('AppGroup'!C3="","",'AppGroup'!C3) | E40: =IF('AppGroup'!D3="","",'AppGroup'!D3) | F40: =IF('AppGroup'!E3="","",'AppGroup'!E3) | G40: =IF('AppGroup'!F3="","",'AppGroup'!F3) | H40: =IF('AppGroup'!G3="","",'AppGroup'!G3) | I40: =IF('AppGroup'!H3="","",'AppGroup'!H3) | J40: =IF('AppGroup'!I3="","",'AppGroup'!I3)
A41: =IF('AppGroup'!A4="","",'AppGroup'!A4) | B41: AppGroup | C41: =IF('AppGroup'!B4="","",'AppGroup'!B4) | D41: =IF('AppGroup'!C4="","",'AppGroup'!C4) | E41: =IF('AppGroup'!D4="","",'AppGroup'!D4) | F41: =IF('AppGroup'!E4="","",'AppGroup'!E4) | G41: =IF('AppGroup'!F4="","",'AppGroup'!F4) | H41: =IF('AppGroup'!G4="","",'AppGroup'!G4) | I41: =IF('AppGroup'!H4="","",'AppGroup'!H4) | J41: =IF('AppGroup'!I4="","",'AppGroup'!I4)
...

Sheet Project
A1: Project Parameters
A2: Parameter Name | B2: Production | C2: Test | D2: DR | E2: Description | F2: Required | G2: Data Type | H2: Validation Rules | I2: Security Level
A3: solution.name | B3: Azure Virtual Desktop | C3: Azure Virtual Desktop | D3: Azure Virtual Desktop | E3: Solution display name | F3: Yes | G3: String | H3: Max 50 characters | I3: Public
A4: solution.abbr | B4: avd | C4: avd | D4: avd | E4: Solution abbreviation for resource naming | F4: Yes | G4: String | H4: Max 10 characters | I4: Public
A5: solution.provider_name | B5: azure | C5: azure | D5: azure | E5: Cloud provider name | F5: Yes | G5: String | H5: aws|azure|gcp | I5: Public
A6: solution.category_name | B6: modern-workspace | C6: modern-workspace | D6: modern-workspace | E6: Solution category | F6: Yes | G6: String | H6: Valid category | I6: Public
A7: azure.subscription_id | B7: [SUBSCRIPTION_ID] | C7: [SUBSCRIPTION_ID] | D7: [SUBSCRIPTION_ID] | E7: Azure subscription identifier | F7: Yes | G7: String | H7: GUID format | I7: Confidential
A8: azure.tenant_id | B8: [TENANT_ID] | C8: [TENANT_ID] | D8: [TENANT_ID] | E8: Azure AD tenant identifier | F8: Yes | G8: String | H8: GUID format | I8: Confidential
A9: azure.region | B9: eastus | C9: eastus | D9: westus2 | E9: Primary Azure region | F9: Yes | G9: String | H9: Valid Azure region | I9: Public
A10: azure.dr_region | B10: westus2 | C10: westus2 | D10: eastus | E10: DR region for failover | F10: Yes | G10: String | H10: Valid Azure region | I10: Public
A11: ownership.cost_center | B11: CC-WS-001 | C11: CC-WS-001 | D11: CC-WS-001 | E11: Cost center for billing | F11: Yes | G11: String | H11: CC format | I11: Public
A12: ownership.owner_email | B12: workspace-team@company.com | C12: dev-team@company.com | D12: workspace-team@company.com | E12: Team email for ownership | F12: Yes | G12: String | H12: Valid email | I12: Public
A13: ownership.project_code | B13: PRJ-AVD-2025 | C13: PRJ-AVD-2025 | D13: PRJ-AVD-2025 | E13: Project tracking code | F13: Yes | G13: String | H13: PRJ format | I13: Public

Sheet Security
A1: Security Parameters
A2: Parameter Name | B2: Production | C2: Test | D2: DR | E2: Description | F2: Required | G2: Data Type | H2: Validation Rules | I2: Security Level
A3: security.enable_customer_managed_key | B3: true | C3: false | D3: true | E3: Use customer-managed key for encryption | F3: Yes | G3: Boolean | H3: true|false | I3: Public
A4: security.admin_group_id | B4: [ADMIN_GROUP_ID] | C4: [ADMIN_GROUP_ID] | D4: [ADMIN_GROUP_ID] | E4: Azure AD group for administrators | F4: Yes | G4: String | H4: GUID format | I4: Confidential
A5: security.user_group_id | B5: [USER_GROUP_ID] | C5: [USER_GROUP_ID] | D5: [USER_GROUP_ID] | E5: Azure AD group for end users | F5: Yes | G5: String | H5: GUID format | I5: Confidential

Sheet Storage
A1: Storage Parameters
A2: Parameter Name | B2: Production | C2: Test | D2: DR | E2: Description | F2: Required | G2: Data Type | H2: Validation Rules | I2: Security Level
A3: storage.account_tier | B3: Premium | C3: Standard | D3: Premium | E3: Storage account tier for FSLogix | F3: Yes | G3: String | H3: Standard|Premium | I3: Public
A4: storage.replication_type | B4: ZRS | C4: LRS | D4: ZRS | E4: Storage replication type | F4: Yes | G4: String | H4: LRS|ZRS|GRS | I4: Public
A5: storage.fslogix_share_quota_gb | B5: 5120 | C5: 1024 | D5: 5120 | E5: File share quota in GB for FSLogix profiles | F5: Yes | G5: Integer | H5: 100-100000 | I5: Public
A6: storage.enable_smb_multichannel | B6: true | C6: false | D6: true | E6: Enable SMB multichannel for performance | F6: Yes | G6: Boolean | H6: true|false | I6: Public
A7: storage.enable_large_file_shares | B7: true | C7: false | D7: true | E7: Enable large file share support | F7: Yes | G7: Boolean | H7: true|false | I7: Public

Sheet Application
A1: Application Parameters
A2: Parameter Name | B2: Production | C2: Test | D2: DR | E2: Description | F2: Required | G2: Data Type | H2: Validation Rules | I2: Security Level
A3: application.environment | B3: production | C3: development | D3: disaster-recovery | E3: Deployment environment identifier | F3: Yes | G3: String | H3: Valid env name | I3: Public
A4: application.log_level | B4: INFO | C4: DEBUG | D4: INFO | E4: Logging verbosity level | F4: Yes | G4: String | H4: DEBUG|INFO|WARN|ERROR | I4: Public

Sheet Monitoring
A1: Monitoring Parameters
A2: Parameter Name | B2: Production | C2: Test | D2: DR | E2: Description | F2: Required | G2: Data Type | H2: Validation Rules | I2: Security Level
A3: monitoring.enable_alerts | B3: true | C3: false | D3: true | E3: Enable monitoring alerts | F3: Yes | G3: Boolean | H3: true|false | I3: Public
A4: monitoring.enable_dashboard | B4: true | C4: false | D4: true | E4: Enable Azure dashboard | F4: Yes | G4: Boolean | H4: true|false | I4: Public
A5: monitoring.log_retention_days | B5: 90 | C5: 30 | D5: 90 | E5: Log retention in days | F5: Yes | G5: Integer | H5: 30-730 | I5: Public
A6: monitoring.alert_email | B6: ops-team@company.com | C6: dev-team@company.com | D6: ops-team@company.com | E6: Email for critical alerts | F6: Yes | G6: String | H6: Valid email | I6: Confidential
A7: monitoring.health_check_interval | B7: 300 | C7: 600 | D7: 300 | E7: Health check frequency in seconds | F7: Yes | G7: Integer | H7: 60-3600 | I7: Public

Sheet DR
A1: DR Parameters
A2: Parameter Name | B2: Production | C2: Test | D2: DR | E2: Description | F2: Required | G2: Data Type | H2: Validation Rules | I2: Security Level
A3: dr.enabled | B3: true | C3: false | D3: false | E3: Enable disaster recovery | F3: Yes | G3: Boolean | H3: true|false | I3: Public
A4: dr.replication_enabled | B4: true | C4: false | D4: false | E4: Enable storage replication | F4: Yes | G4: Boolean | H4: true|false | I4: Public
A5: dr.failover_priority | B5: 1 | C5: 0 | D5: 0 | E5: Failover priority (0=disabled) | F5: Yes | G5: Integer | H5: 0-2 | I5: Public

Sheet AVD
A1: AVD Parameters
A2: Parameter Name | B2: Production | C2: Test | D2: DR | E2: Description | F2: Required | G2: Data Type | H2: Validation Rules | I2: Security Level
A3: avd.host_pool_type | B3: Pooled | C3: Pooled | D3: Pooled | E3: Host pool type (Pooled or Personal) | F3: Yes | G3: String | H3: Pooled|Personal | I3: Public
A4: avd.load_balancer | B4: BreadthFirst | C4: BreadthFirst | D4: BreadthFirst | E4: Load balancing algorithm | F4: Yes | G4: String | H4: BreadthFirst|DepthFirst | I4: Public
A5: avd.max_session_limit | B5: 10 | C5: 5 | D5: 10 | E5: Maximum sessions per host | F5: Yes | G5: Integer | H5: 1-50 | I5: Public
A6: avd.start_vm_on_connect | B6: true | C6: true | D6: true | E6: Start VMs automatically on connect | F6: Yes | G6: Boolean | H6: true|false | I6: Public
A7: avd.personal_assignment | B7: Automatic | C7: Automatic | D7: Automatic | E7: Personal desktop assignment type | F7: No | G7: String | H7: Automatic|Direct | I7: Public
A8: avd.validate_environment | B8: false | C8: true | D8: false | E8: Mark as validation environment | F8: Yes | G8: Boolean | H8: true|false | I8: Public

Sheet AppGroup
A1: AppGroup Parameters
A2: Parameter Name | B2: Production | C2: Test | D2: DR | E2: Description | F2: Required | G2: Data Type | H2: Validation Rules | I2: Security Level
A3: appgroup.desktop_enabled | B3: true | C3: true | D3: true | E3: Enable desktop application group | F3: Yes | G3: Boolean | H3: true|false | I3: Public
A4: appgroup.remoteapp_enabled | B4: true | C4: false | D4: true | E4: Enable RemoteApp application group | F4: Yes | G4: Boolean | H4: true|false | I4: Public
A5: appgroup.desktop_name | B5: Full Desktop | C5: Test Desktop | D5: DR Desktop | E5: Friendly name for desktop app group | F5: Yes | G5: String | H5: Any text | I5: Public

Sheet Autoscale
A1: Autoscale Parameters
A2: Parameter Name | B2: Production | C2: Test | D2: DR | E2: Description | F2: Required | G2: Data Type | H2: Validation Rules | I2: Security Level
A3: autoscale.enabled | B3: true | C3: false | D3: true | E3: Enable auto-scaling for session hosts | F3: Yes | G3: Boolean | H3: true|false | I3: Public
A4: autoscale.min_hosts | B4: 2 | C4: 1 | D4: 1 | E4: Minimum number of session hosts | F4: Yes | G4: Integer | H4: 0-100 | I4: Public
A5: autoscale.max_hosts | B5: 10 | C5: 3 | D5: 5 | E5: Maximum number of session hosts | F5: Yes | G5: Integer | H5: 1-100 | I5: Public
A6: autoscale.scale_up_threshold | B6: 80 | C6: 80 | D6: 80 | E6: Scale up when utilization exceeds percentage | F6: Yes | G6: Integer | H6: 1-100 | I6: Public
A7: autoscale.scale_down_threshold | B7: 20 | C7: 20 | D7: 20 | E7: Scale down when utilization below percentage | F7: Yes | G7: Integer | H7: 1-100 | I7: Public
A8: autoscale.ramp_up_start | B8: 07:00 | C8: 08:00 | D8: 07:00 | E8: Ramp up start time (HH:MM) | F8: Yes | G8: String | H8: Valid time | I8: Public
A9: autoscale.ramp_up_capacity | B9: 60 | C9: 60 | D9: 60 | E9: Ramp up capacity threshold percentage | F9: Yes | G9: Integer | H9: 1-100 | I9: Public
A10: autoscale.peak_start | B10: 09:00 | C10: 09:00 | D10: 09:00 | E10: Peak hours start time (HH:MM) | F10: Yes | G10: String | H10: Valid time | I10: Public
A11: autoscale.ramp_down_start | B11: 17:00 | C11: 17:00 | D11: 17:00 | E11: Ramp down start time (HH:MM) | F11: Yes | G11: String | H11: Valid time | I11: Public
A12: autoscale.ramp_down_capacity | B12: 50 | C12: 50 | D12: 50 | E12: Ramp down capacity threshold percentage | F12: Yes | G12: Integer | H12: 1-100 | I12: Public
A13: autoscale.off_peak_start | B13: 19:00 | C13: 18:00 | D13: 19:00 | E13: Off-peak hours start time (HH:MM) | F13: Yes | G13: String | H13: Valid time | I13: Public
A14: autoscale.timezone | B14: Eastern Standard Time | C14: Eastern Standard Time | D14: Pacific Standard Time | E14: Timezone for scaling schedule | F14: Yes | G14: String | H14: Valid timezone | I14: Public

Sheet Backup
A1: Backup Parameters
A2: Parameter Name | B2: Production | C2: Test | D2: DR | E2: Description | F2: Required | G2: Data Type | H2: Validation Rules | I2: Security Level
A3: backup.enabled | B3: true | C3: false | D3: true | E3: Enable backup services | F3: Yes | G3: Boolean | H3: true|false | I3: Public
A4: backup.retention_days | B4: 30 | C4: 7 | D4: 30 | E4: Backup retention in days | F4: Yes | G4: Integer | H4: 7-365 | I4: Public

Sheet Budget
A1: Budget Parameters
A2: Parameter Name | B2: Production | C2: Test | D2: DR | E2: Description | F2: Required | G2: Data Type | H2: Validation Rules | I2: Security Level
A3: budget.enabled | B3: true | C3: true | D3: true | E3: Enable cost budgets | F3: Yes | G3: Boolean | H3: true|false | I3: Public
A4: budget.monthly_amount | B4: 5000 | C4: 1000 | D4: 3000 | E4: Monthly budget in USD | F4: Yes | G4: Integer | H4: 100-100000 | I4: Public
A5: budget.alert_thresholds | B5: [50,80,100] | C5: [80,100] | D5: [50,80,100] | E5: Alert thresholds as percentages | F5: Yes | G5: List(Number) | H5: Valid percentages | I5: Public
A6: budget.notification_email | B6: finance@company.com | C6: dev-team@company.com | D6: finance@company.com | E6: Email for budget alerts | F6: Yes | G6: String | H6: Valid email | I6: Confidential

Sheet Network
A1: Network Parameters
A2: Parameter Name | B2: Production | C2: Test | D2: DR | E2: Description | F2: Required | G2: Data Type | H2: Validation Rules | I2: Security Level
A3: network.vnet_cidr | B3: 10.10.0.0/16 | C3: 10.11.0.0/16 | D3: 10.12.0.0/16 | E3: Virtual network CIDR block | F3: Yes | G3: String | H3: Valid CIDR | I3: Public
A4: network.subnet_session_hosts | B4: 10.10.1.0/24 | C4: 10.11.1.0/24 | D4: 10.12.1.0/24 | E4: Subnet for session host VMs | F4: Yes | G4: String | H4: Valid CIDR | I4: Public
A5: network.subnet_private_endpoints | B5: 10.10.2.0/24 | C5: 10.11.2.0/24 | D5: 10.12.2.0/24 | E5: Subnet for private endpoints | F5: Yes | G5: String | H5: Valid CIDR | I5: Public
A6: network.enable_private_endpoints | B6: true | C6: false | D6: true | E6: Enable private endpoints for services | F6: Yes | G6: Boolean | H6: true|false | I6: Public

Sheet Policy
A1: Policy Parameters
A2: Parameter Name | B2: Production | C2: Test | D2: DR | E2: Description | F2: Required | G2: Data Type | H2: Validation Rules | I2: Security Level
A3: policy.enable_security_policies | B3: true | C3: false | D3: true | E3: Enable Azure security policies | F3: Yes | G3: Boolean | H3: true|false | I3: Public
A4: policy.enable_cost_policies | B4: true | C4: true | D4: true | E4: Enable cost management policies | F4: Yes | G4: Boolean | H4: true|false | I4: Public
A5: policy.enable_operational_policies | B5: true | C5: false | D5: true | E5: Enable operational policies | F5: Yes | G5: Boolean | H5: true|false | I5: Public

Sheet SessionHost
A1: SessionHost Parameters
A2: Parameter Name | B2: Production | C2: Test | D2: DR | E2: Description | F2: Required | G2: Data Type | H2: Validation Rules | I2: Security Level
A3: sessionhost.vm_size | B3: Standard_D4s_v5 | C3: Standard_D2s_v5 | D3: Standard_D4s_v5 | E3: Azure VM size for session hosts | F3: Yes | G3: String | H3: Valid VM size | I3: Public
A4: sessionhost.vm_count | B4: 3 | C4: 1 | D4: 2 | E4: Number of session host VMs | F4: Yes | G4: Integer | H4: 1-100 | I4: Public
A5: sessionhost.image_publisher | B5: MicrosoftWindowsDesktop | C5: MicrosoftWindowsDesktop | D5: MicrosoftWindowsDesktop | E5: VM image publisher | F5: Yes | G5: String | H5: Valid publisher | I5: Public
A6: sessionhost.image_offer | B6: Windows-11 | C6: Windows-11 | D6: Windows-11 | E6: VM image offer | F6: Yes | G6: String | H6: Valid offer | I6: Public
A7: sessionhost.image_sku | B7: win11-22h2-avd | C7: win11-22h2-avd | D7: win11-22h2-avd | E7: VM image SKU | F7: Yes | G7: String | H7: Valid SKU | I7: Public
A8: sessionhost.image_version | B8: latest | C8: latest | D8: latest | E8: VM image version | F8: Yes | G8: String | H8: latest or version | I8: Public
A9: sessionhost.os_disk_type | B9: Premium_LRS | C9: Standard_LRS | D9: Premium_LRS | E9: OS disk storage type | F9: Yes | G9: String | H9: Standard_LRS|Premium_LRS | I9: Public
A10: sessionhost.os_disk_size_gb | B10: 128 | C10: 128 | D10: 128 | E10: OS disk size in GB | F10: Yes | G10: Integer | H10: 30-4096 | I10: Public
A11: sessionhost.accelerated_networking | B11: true | C11: false | D11: true | E11: Enable accelerated networking | F11: Yes | G11: Boolean | H11: true|false | I11: Public
