Workbook

Sheet Cover
B3: [DOCUMENT TITLE]
B4: Discovery Questionnaire
B5: Presales Document
B6: Generated: | C6: November 16, 2025
B7: Solution: | C7: November 22, 2025
B8: Customer: | C8: Gpu Compute Cluster
B9: Version: | C9: [Customer Name]
B10: Status: | C10: Draft
C12: eoframework.org

Sheet All Categories (Read Only)
A1: Total Questions | B1: Answered | C1: Remaining | D1: % Complete
A2: 70 | B2: =SUMPRODUCT(--(LEN(F5:F74)>0)) | C2: =A2-B2 | D2: =B2/A2
A4: Question ID | B4: Category | C4: Sub-Category | D4: Question | E4: Guidance | F4: Customer Response | G4: Notes
A5: =IF('Business Requirements'!A2="","",'Business Requirements'!A2) | B5: =IF('Business Requirements'!B2="","",'Business Requirements'!B2) | C5: =IF('Business Requirements'!C2="","",'Business Requirements'!C2) | D5: =IF('Business Requirements'!D2="","",'Business Requirements'!D2) | E5: =IF('Business Requirements'!E2="","",'Business Requirements'!E2) | F5: =IF('Business Requirements'!F2="","",'Business Requirements'!F2) | G5: =IF('Business Requirements'!G2="","",'Business Requirements'!G2)
A6: =IF('Business Requirements'!A3="","",'Business Requirements'!A3) | B6: =IF('Business Requirements'!B3="","",'Business Requirements'!B3) | C6: =IF('Business Requirements'!C3="","",'Business Requirements'!C3) | D6: =IF('Business Requirements'!D3="","",'Business Requirements'!D3) | E6: =IF('Business Requirements'!E3="","",'Business Requirements'!E3) | F6: =IF('Business Requirements'!F3="","",'Business Requirements'!F3) | G6: =IF('Business Requirements'!G3="","",'Business Requirements'!G3)
A7: =IF('Business Requirements'!A4="","",'Business Requirements'!A4) | B7: =IF('Business Requirements'!B4="","",'Business Requirements'!B4) | C7: =IF('Business Requirements'!C4="","",'Business Requirements'!C4) | D7: =IF('Business Requirements'!D4="","",'Business Requirements'!D4) | E7: =IF('Business Requirements'!E4="","",'Business Requirements'!E4) | F7: =IF('Business Requirements'!F4="","",'Business Requirements'!F4) | G7: =IF('Business Requirements'!G4="","",'Business Requirements'!G4)
A8: =IF('Business Requirements'!A5="","",'Business Requirements'!A5) | B8: =IF('Business Requirements'!B5="","",'Business Requirements'!B5) | C8: =IF('Business Requirements'!C5="","",'Business Requirements'!C5) | D8: =IF('Business Requirements'!D5="","",'Business Requirements'!D5) | E8: =IF('Business Requirements'!E5="","",'Business Requirements'!E5) | F8: =IF('Business Requirements'!F5="","",'Business Requirements'!F5) | G8: =IF('Business Requirements'!G5="","",'Business Requirements'!G5)
A9: =IF('Business Requirements'!A6="","",'Business Requirements'!A6) | B9: =IF('Business Requirements'!B6="","",'Business Requirements'!B6) | C9: =IF('Business Requirements'!C6="","",'Business Requirements'!C6) | D9: =IF('Business Requirements'!D6="","",'Business Requirements'!D6) | E9: =IF('Business Requirements'!E6="","",'Business Requirements'!E6) | F9: =IF('Business Requirements'!F6="","",'Business Requirements'!F6) | G9: =IF('Business Requirements'!G6="","",'Business Requirements'!G6)
A10: =IF('Business Requirements'!A7="","",'Business Requirements'!A7) | B10: =IF('Business Requirements'!B7="","",'Business Requirements'!B7) | C10: =IF('Business Requirements'!C7="","",'Business Requirements'!C7) | D10: =IF('Business Requirements'!D7="","",'Business Requirements'!D7) | E10: =IF('Business Requirements'!E7="","",'Business Requirements'!E7) | F10: =IF('Business Requirements'!F7="","",'Business Requirements'!F7) | G10: =IF('Business Requirements'!G7="","",'Business Requirements'!G7)
A11: =IF('Business Requirements'!A8="","",'Business Requirements'!A8) | B11: =IF('Business Requirements'!B8="","",'Business Requirements'!B8) | C11: =IF('Business Requirements'!C8="","",'Business Requirements'!C8) | D11: =IF('Business Requirements'!D8="","",'Business Requirements'!D8) | E11: =IF('Business Requirements'!E8="","",'Business Requirements'!E8) | F11: =IF('Business Requirements'!F8="","",'Business Requirements'!F8) | G11: =IF('Business Requirements'!G8="","",'Business Requirements'!G8)
A12: =IF('Business Requirements'!A9="","",'Business Requirements'!A9) | B12: =IF('Business Requirements'!B9="","",'Business Requirements'!B9) | C12: =IF('Business Requirements'!C9="","",'Business Requirements'!C9) | D12: =IF('Business Requirements'!D9="","",'Business Requirements'!D9) | E12: =IF('Business Requirements'!E9="","",'Business Requirements'!E9) | F12: =IF('Business Requirements'!F9="","",'Business Requirements'!F9) | G12: =IF('Business Requirements'!G9="","",'Business Requirements'!G9)
A13: =IF('Business Requirements'!A10="","",'Business Requirements'!A10) | B13: =IF('Business Requirements'!B10="","",'Business Requirements'!B10) | C13: =IF('Business Requirements'!C10="","",'Business Requirements'!C10) | D13: =IF('Business Requirements'!D10="","",'Business Requirements'!D10) | E13: =IF('Business Requirements'!E10="","",'Business Requirements'!E10) | F13: =IF('Business Requirements'!F10="","",'Business Requirements'!F10) | G13: =IF('Business Requirements'!G10="","",'Business Requirements'!G10)
A14: =IF('Business Requirements'!A11="","",'Business Requirements'!A11) | B14: =IF('Business Requirements'!B11="","",'Business Requirements'!B11) | C14: =IF('Business Requirements'!C11="","",'Business Requirements'!C11) | D14: =IF('Business Requirements'!D11="","",'Business Requirements'!D11) | E14: =IF('Business Requirements'!E11="","",'Business Requirements'!E11) | F14: =IF('Business Requirements'!F11="","",'Business Requirements'!F11) | G14: =IF('Business Requirements'!G11="","",'Business Requirements'!G11)
A15: =IF('Business Requirements'!A12="","",'Business Requirements'!A12) | B15: =IF('Business Requirements'!B12="","",'Business Requirements'!B12) | C15: =IF('Business Requirements'!C12="","",'Business Requirements'!C12) | D15: =IF('Business Requirements'!D12="","",'Business Requirements'!D12) | E15: =IF('Business Requirements'!E12="","",'Business Requirements'!E12) | F15: =IF('Business Requirements'!F12="","",'Business Requirements'!F12) | G15: =IF('Business Requirements'!G12="","",'Business Requirements'!G12)
A16: =IF('Business Requirements'!A13="","",'Business Requirements'!A13) | B16: =IF('Business Requirements'!B13="","",'Business Requirements'!B13) | C16: =IF('Business Requirements'!C13="","",'Business Requirements'!C13) | D16: =IF('Business Requirements'!D13="","",'Business Requirements'!D13) | E16: =IF('Business Requirements'!E13="","",'Business Requirements'!E13) | F16: =IF('Business Requirements'!F13="","",'Business Requirements'!F13) | G16: =IF('Business Requirements'!G13="","",'Business Requirements'!G13)
A17: =IF('Technical Requirements'!A2="","",'Technical Requirements'!A2) | B17: =IF('Technical Requirements'!B2="","",'Technical Requirements'!B2) | C17: =IF('Technical Requirements'!C2="","",'Technical Requirements'!C2) | D17: =IF('Technical Requirements'!D2="","",'Technical Requirements'!D2) | E17: =IF('Technical Requirements'!E2="","",'Technical Requirements'!E2) | F17: =IF('Technical Requirements'!F2="","",'Technical Requirements'!F2) | G17: =IF('Technical Requirements'!G2="","",'Technical Requirements'!G2)
A18: =IF('Technical Requirements'!A3="","",'Technical Requirements'!A3) | B18: =IF('Technical Requirements'!B3="","",'Technical Requirements'!B3) | C18: =IF('Technical Requirements'!C3="","",'Technical Requirements'!C3) | D18: =IF('Technical Requirements'!D3="","",'Technical Requirements'!D3) | E18: =IF('Technical Requirements'!E3="","",'Technical Requirements'!E3) | F18: =IF('Technical Requirements'!F3="","",'Technical Requirements'!F3) | G18: =IF('Technical Requirements'!G3="","",'Technical Requirements'!G3)
A19: =IF('Technical Requirements'!A4="","",'Technical Requirements'!A4) | B19: =IF('Technical Requirements'!B4="","",'Technical Requirements'!B4) | C19: =IF('Technical Requirements'!C4="","",'Technical Requirements'!C4) | D19: =IF('Technical Requirements'!D4="","",'Technical Requirements'!D4) | E19: =IF('Technical Requirements'!E4="","",'Technical Requirements'!E4) | F19: =IF('Technical Requirements'!F4="","",'Technical Requirements'!F4) | G19: =IF('Technical Requirements'!G4="","",'Technical Requirements'!G4)
A20: =IF('Technical Requirements'!A5="","",'Technical Requirements'!A5) | B20: =IF('Technical Requirements'!B5="","",'Technical Requirements'!B5) | C20: =IF('Technical Requirements'!C5="","",'Technical Requirements'!C5) | D20: =IF('Technical Requirements'!D5="","",'Technical Requirements'!D5) | E20: =IF('Technical Requirements'!E5="","",'Technical Requirements'!E5) | F20: =IF('Technical Requirements'!F5="","",'Technical Requirements'!F5) | G20: =IF('Technical Requirements'!G5="","",'Technical Requirements'!G5)
A21: =IF('Technical Requirements'!A6="","",'Technical Requirements'!A6) | B21: =IF('Technical Requirements'!B6="","",'Technical Requirements'!B6) | C21: =IF('Technical Requirements'!C6="","",'Technical Requirements'!C6) | D21: =IF('Technical Requirements'!D6="","",'Technical Requirements'!D6) | E21: =IF('Technical Requirements'!E6="","",'Technical Requirements'!E6) | F21: =IF('Technical Requirements'!F6="","",'Technical Requirements'!F6) | G21: =IF('Technical Requirements'!G6="","",'Technical Requirements'!G6)
A22: =IF('Technical Requirements'!A7="","",'Technical Requirements'!A7) | B22: =IF('Technical Requirements'!B7="","",'Technical Requirements'!B7) | C22: =IF('Technical Requirements'!C7="","",'Technical Requirements'!C7) | D22: =IF('Technical Requirements'!D7="","",'Technical Requirements'!D7) | E22: =IF('Technical Requirements'!E7="","",'Technical Requirements'!E7) | F22: =IF('Technical Requirements'!F7="","",'Technical Requirements'!F7) | G22: =IF('Technical Requirements'!G7="","",'Technical Requirements'!G7)
A23: =IF('Technical Requirements'!A8="","",'Technical Requirements'!A8) | B23: =IF('Technical Requirements'!B8="","",'Technical Requirements'!B8) | C23: =IF('Technical Requirements'!C8="","",'Technical Requirements'!C8) | D23: =IF('Technical Requirements'!D8="","",'Technical Requirements'!D8) | E23: =IF('Technical Requirements'!E8="","",'Technical Requirements'!E8) | F23: =IF('Technical Requirements'!F8="","",'Technical Requirements'!F8) | G23: =IF('Technical Requirements'!G8="","",'Technical Requirements'!G8)
A24: =IF('Technical Requirements'!A9="","",'Technical Requirements'!A9) | B24: =IF('Technical Requirements'!B9="","",'Technical Requirements'!B9) | C24: =IF('Technical Requirements'!C9="","",'Technical Requirements'!C9) | D24: =IF('Technical Requirements'!D9="","",'Technical Requirements'!D9) | E24: =IF('Technical Requirements'!E9="","",'Technical Requirements'!E9) | F24: =IF('Technical Requirements'!F9="","",'Technical Requirements'!F9) | G24: =IF('Technical Requirements'!G9="","",'Technical Requirements'!G9)
A25: =IF('Technical Requirements'!A10="","",'Technical Requirements'!A10) | B25: =IF('Technical Requirements'!B10="","",'Technical Requirements'!B10) | C25: =IF('Technical Requirements'!C10="","",'Technical Requirements'!C10) | D25: =IF('Technical Requirements'!D10="","",'Technical Requirements'!D10) | E25: =IF('Technical Requirements'!E10="","",'Technical Requirements'!E10) | F25: =IF('Technical Requirements'!F10="","",'Technical Requirements'!F10) | G25: =IF('Technical Requirements'!G10="","",'Technical Requirements'!G10)
A26: =IF('Technical Requirements'!A11="","",'Technical Requirements'!A11) | B26: =IF('Technical Requirements'!B11="","",'Technical Requirements'!B11) | C26: =IF('Technical Requirements'!C11="","",'Technical Requirements'!C11) | D26: =IF('Technical Requirements'!D11="","",'Technical Requirements'!D11) | E26: =IF('Technical Requirements'!E11="","",'Technical Requirements'!E11) | F26: =IF('Technical Requirements'!F11="","",'Technical Requirements'!F11) | G26: =IF('Technical Requirements'!G11="","",'Technical Requirements'!G11)
A27: =IF('Technical Requirements'!A12="","",'Technical Requirements'!A12) | B27: =IF('Technical Requirements'!B12="","",'Technical Requirements'!B12) | C27: =IF('Technical Requirements'!C12="","",'Technical Requirements'!C12) | D27: =IF('Technical Requirements'!D12="","",'Technical Requirements'!D12) | E27: =IF('Technical Requirements'!E12="","",'Technical Requirements'!E12) | F27: =IF('Technical Requirements'!F12="","",'Technical Requirements'!F12) | G27: =IF('Technical Requirements'!G12="","",'Technical Requirements'!G12)
A28: =IF('Technical Requirements'!A13="","",'Technical Requirements'!A13) | B28: =IF('Technical Requirements'!B13="","",'Technical Requirements'!B13) | C28: =IF('Technical Requirements'!C13="","",'Technical Requirements'!C13) | D28: =IF('Technical Requirements'!D13="","",'Technical Requirements'!D13) | E28: =IF('Technical Requirements'!E13="","",'Technical Requirements'!E13) | F28: =IF('Technical Requirements'!F13="","",'Technical Requirements'!F13) | G28: =IF('Technical Requirements'!G13="","",'Technical Requirements'!G13)
... A36: =IF('Technical Requirements'!A21="","",'Technical Requirements'!A21) | B36: =IF('Technical Requirements'!B21="","",'Technical Requirements'!B21) | C36: =IF('Technical Requirements'!C21="","",'Technical Requirements'!C21) | D36: =IF('Technical Requirements'!D21="","",'Technical Requirements'!D21) | E36: =IF('Technical Requirements'!E21="","",'Technical Requirements'!E21) | F36: =IF('Technical Requirements'!F21="","",'Technical Requirements'!F21) | G36: =IF('Technical Requirements'!G21="","",'Technical Requirements'!G21)
A37: =IF('Security & Compliance'!A2="","",'Security & Compliance'!A2) | B37: =IF('Security & Compliance'!B2="","",'Security & Compliance'!B2) | C37: =IF('Security & Compliance'!C2="","",'Security & Compliance'!C2) | D37: =IF('Security & Compliance'!D2="","",'Security & Compliance'!D2) | E37: =IF('Security & Compliance'!E2="","",'Security & Compliance'!E2) | F37: =IF('Security & Compliance'!F2="","",'Security & Compliance'!F2) | G37: =IF('Security & Compliance'!G2="","",'Security & Compliance'!G2)
A38: =IF('Security & Compliance'!A3="","",'Security & Compliance'!A3) | B38: =IF('Security & Compliance'!B3="","",'Security & Compliance'!B3) | C38: =IF('Security & Compliance'!C3="","",'Security & Compliance'!C3) | D38: =IF('Security & Compliance'!D3="","",'Security & Compliance'!D3) | E38: =IF('Security & Compliance'!E3="","",'Security & Compliance'!E3) | F38: =IF('Security & Compliance'!F3="","",'Security & Compliance'!F3) | G38: =IF('Security & Compliance'!G3="","",'Security & Compliance'!G3)
A39: =IF('Security & Compliance'!A4="","",'Security & Compliance'!A4) | B39: =IF('Security & Compliance'!B4="","",'Security & Compliance'!B4) | C39: =IF('Security & Compliance'!C4="","",'Security & Compliance'!C4) | D39: =IF('Security & Compliance'!D4="","",'Security & Compliance'!D4) | E39: =IF('Security & Compliance'!E4="","",'Security & Compliance'!E4) | F39: =IF('Security & Compliance'!F4="","",'Security & Compliance'!F4) | G39: =IF('Security & Compliance'!G4="","",'Security & Compliance'!G4)
A40: =IF('Security & Compliance'!A5="","",'Security & Compliance'!A5) | B40: =IF('Security & Compliance'!B5="","",'Security & Compliance'!B5) | C40: =IF('Security & Compliance'!C5="","",'Security & Compliance'!C5) | D40: =IF('Security & Compliance'!D5="","",'Security & Compliance'!D5) | E40: =IF('Security & Compliance'!E5="","",'Security & Compliance'!E5) | F40: =IF('Security & Compliance'!F5="","",'Security & Compliance'!F5) | G40: =IF('Security & Compliance'!G5="","",'Security & Compliance'!G5)
A41: =IF('Security & Compliance'!A6="","",'Security & Compliance'!A6) | B41: =IF('Security & Compliance'!B6="","",'Security & Compliance'!B6) | C41: =IF('Security & Compliance'!C6="","",'Security & Compliance'!C6) | D41: =IF('Security & Compliance'!D6="","",'Security & Compliance'!D6) | E41: =IF('Security & Compliance'!E6="","",'Security & Compliance'!E6) | F41: =IF('Security & Compliance'!F6="","",'Security & Compliance'!F6) | G41: =IF('Security & Compliance'!G6="","",'Security & Compliance'!G6)
A42: =IF('Security & Compliance'!A7="","",'Security & Compliance'!A7) | B42: =IF('Security & Compliance'!B7="","",'Security & Compliance'!B7) | C42: =IF('Security & Compliance'!C7="","",'Security & Compliance'!C7) | D42: =IF('Security & Compliance'!D7="","",'Security & Compliance'!D7) | E42: =IF('Security & Compliance'!E7="","",'Security & Compliance'!E7) | F42: =IF('Security & Compliance'!F7="","",'Security & Compliance'!F7) | G42: =IF('Security & Compliance'!G7="","",'Security & Compliance'!G7)
A43: =IF('Security & Compliance'!A8="","",'Security & Compliance'!A8) | B43: =IF('Security & Compliance'!B8="","",'Security & Compliance'!B8) | C43: =IF('Security & Compliance'!C8="","",'Security & Compliance'!C8) | D43: =IF('Security & Compliance'!D8="","",'Security & Compliance'!D8) | E43: =IF('Security & Compliance'!E8="","",'Security & Compliance'!E8) | F43: =IF('Security & Compliance'!F8="","",'Security & Compliance'!F8) | G43: =IF('Security & Compliance'!G8="","",'Security & Compliance'!G8)
A44: =IF('Security & Compliance'!A9="","",'Security & Compliance'!A9) | B44: =IF('Security & Compliance'!B9="","",'Security & Compliance'!B9) | C44: =IF('Security & Compliance'!C9="","",'Security & Compliance'!C9) | D44: =IF('Security & Compliance'!D9="","",'Security & Compliance'!D9) | E44: =IF('Security & Compliance'!E9="","",'Security & Compliance'!E9) | F44: =IF('Security & Compliance'!F9="","",'Security & Compliance'!F9) | G44: =IF('Security & Compliance'!G9="","",'Security & Compliance'!G9)
A45: =IF('Security & Compliance'!A10="","",'Security & Compliance'!A10) | B45: =IF('Security & Compliance'!B10="","",'Security & Compliance'!B10) | C45: =IF('Security & Compliance'!C10="","",'Security & Compliance'!C10) | D45: =IF('Security & Compliance'!D10="","",'Security & Compliance'!D10) | E45: =IF('Security & Compliance'!E10="","",'Security & Compliance'!E10) | F45: =IF('Security & Compliance'!F10="","",'Security & Compliance'!F10) | G45: =IF('Security & Compliance'!G10="","",'Security & Compliance'!G10)
A46: =IF('Operations & Support'!A2="","",'Operations & Support'!A2) | B46: =IF('Operations & Support'!B2="","",'Operations & Support'!B2) | C46: =IF('Operations & Support'!C2="","",'Operations & Support'!C2) | D46: =IF('Operations & Support'!D2="","",'Operations & Support'!D2) | E46: =IF('Operations & Support'!E2="","",'Operations & Support'!E2) | F46: =IF('Operations & Support'!F2="","",'Operations & Support'!F2) | G46: =IF('Operations & Support'!G2="","",'Operations & Support'!G2)
A47: =IF('Operations & Support'!A3="","",'Operations & Support'!A3) | B47: =IF('Operations & Support'!B3="","",'Operations & Support'!B3) | C47: =IF('Operations & Support'!C3="","",'Operations & Support'!C3) | D47: =IF('Operations & Support'!D3="","",'Operations & Support'!D3) | E47: =IF('Operations & Support'!E3="","",'Operations & Support'!E3) | F47: =IF('Operations & Support'!F3="","",'Operations & Support'!F3) | G47: =IF('Operations & Support'!G3="","",'Operations & Support'!G3)
A48: =IF('Operations & Support'!A4="","",'Operations & Support'!A4) | B48: =IF('Operations & Support'!B4="","",'Operations & Support'!B4) | C48: =IF('Operations & Support'!C4="","",'Operations & Support'!C4) | D48: =IF('Operations & Support'!D4="","",'Operations & Support'!D4) | E48: =IF('Operations & Support'!E4="","",'Operations & Support'!E4) | F48: =IF('Operations & Support'!F4="","",'Operations & Support'!F4) | G48: =IF('Operations & Support'!G4="","",'Operations & Support'!G4)
...

Sheet Business Requirements
A1: Question ID | B1: Category | C1: Sub-Category | D1: Question | E1: Guidance | F1: Customer Response | G1: Notes
A2: BUS-001 | B2: Business Requirements | C2: Project Information | D2: What is the name of your GPU compute cluster project? | E2: Provide internal project reference name | G2: Internal project reference for tracking
A3: BUS-002 | B3: Business Requirements | C3: Project Information | D3: Who is the primary stakeholder for this GPU cluster project? | E3: Name, role, and decision-making authority | G3: Main point of contact and decision authority
A4: BUS-003 | B4: Business Requirements | C4: Business Drivers | D4: What AI/ML challenges are you trying to solve with GPU infrastructure? | E4: Common challenges: Long training times, Limited GPU access, High cloud costs, Team collaboration bottlenecks, Model deployment complexity | G4: Primary business driver for GPU investment
A5: BUS-004 | B5: Business Requirements | C5: Current State | D5: What is your current AI/ML infrastructure? | E5: Describe existing GPU systems, cloud resources (AWS p3/p4d, Azure NCv3), and constraints | G5: Current state baseline assessment
A6: BUS-005 | B6: Business Requirements | C6: Research Team | D6: How many data scientists and ML engineers will use the cluster? | E6: Typical ranges: 5-10, 10-25, 25-50, 50+ | G6: User base sizing for capacity planning
A7: BUS-006 | B7: Business Requirements | C7: AI Workloads | D7: What types of AI workloads will you run? | E7: Common types: Deep learning training, Computer vision, NLP models, Recommendation systems, Time series forecasting, Reinforcement learning | G7: Workload classification and requirements
A8: BUS-007 | B8: Business Requirements | C8: Objectives | D8: What are your primary goals for implementing a GPU cluster? | E8: Common goals: Reduce training time, Eliminate cloud costs, Enable team collaboration, Support production inference, Accelerate experimentation, Scale AI capabilities | G8: Business objectives and expected outcomes
A9: BUS-008 | B9: Business Requirements | C9: Success Criteria | D9: How will you measure GPU cluster success? | E9: Define KPIs: training time reduction, cloud cost savings, GPU utilization %, models deployed per month, team productivity | G9: Success metrics for project evaluation
A10: BUS-009 | B10: Business Requirements | C10: Timeline | D10: What is your expected timeline for GPU cluster deployment? | E10: Typical ranges: 0-3 months, 3-6 months, 6-12 months, 12+ months | G10: Project timeline expectations and constraints
A11: BUS-010 | B11: Business Requirements | C11: Budget | D11: What is your approved budget range for GPU cluster infrastructure? | E11: Common ranges: $250K-750K, $750K-1.5M, $1.5M-3M, $3M+. Include hardware, software, facilities | G11: Budget constraints for solution sizing
A12: BUS-011 | B12: Business Requirements | C12: Cloud Spending | D12: What are your current monthly cloud GPU costs? | E12: Specify: AWS p3/p4d, Azure NCv3/NDv4, GCP A100 instance spending | G12: Cloud cost baseline for ROI calculation
A13: BUS-012 | B13: Business Requirements | C13: Growth Projections | D13: How do you expect AI compute demand to change over 3 years? | E13: Provide current team size and projected annual growth rate | G13: Scalability requirements and capacity planning

Sheet Technical Requirements
A1: Question ID | B1: Category | C1: Sub-Category | D1: Question | E1: Guidance | F1: Customer Response | G1: Notes
A2: TECH-001 | B2: Technical Requirements | C2: GPU Sizing | D2: How many GPUs do you estimate you need? | E2: Ranges: 8-16 GPUs, 16-32, 32-64, 64+ GPUs | G2: Initial cluster sizing based on workload analysis
A3: TECH-002 | B3: Technical Requirements | C3: GPU Type | D3: What GPU type best fits your workloads? | E3: Options: A100 40GB (balanced), A100 80GB (large models), H100 (latest performance), L40S (inference-optimized), Mixed configurations | G3: GPU selection affects performance and cost
A4: TECH-003 | B4: Technical Requirements | C4: GPU Memory | D4: What GPU memory capacity do you require? | E4: Options: 40 GB per GPU, 80 GB per GPU, Mixed 40/80 GB | G4: Memory requirements for model sizes
A5: TECH-004 | B5: Technical Requirements | C5: Model Sizes | D5: What is the typical size of models you train? | E5: Model sizes: <1B parameters, 1-10B, 10-50B, 50-100B, >100B parameters | G5: Model size determines GPU memory and count
A6: TECH-005 | B6: Technical Requirements | C6: Training Time | D6: What are your target training times for key models? | E6: Specify: model type (BERT, ResNet, GPT-style), current time, desired time | G6: Performance requirements for sizing
A7: TECH-006 | B7: Technical Requirements | C7: Distributed Training | D7: Will you need multi-GPU or multi-node training? | E7: Options: Single GPU sufficient, Multi-GPU (1 node), Multi-node (2-4 nodes), Large-scale (4+ nodes) | G7: Determines networking and communication requirements
A8: TECH-007 | B8: Technical Requirements | C8: AI Frameworks | D8: What AI/ML frameworks will you use? | E8: Common frameworks: PyTorch, TensorFlow, JAX, Keras, scikit-learn, XGBoost, Hugging Face Transformers | G8: Software stack and NGC container requirements
A9: TECH-008 | B9: Technical Requirements | C9: Dataset Size | D9: What is your typical training dataset size per project? | E9: Sizes: <100 GB, 100 GB-1 TB, 1-10 TB, 10-50 TB, >50 TB | G9: Storage capacity and throughput requirements
A10: TECH-009 | B10: Technical Requirements | C10: Storage Performance | D10: What storage performance do you need? | E10: Options: Standard NFS (1-2 GB/s), High-performance (3-5 GB/s), NVMe (5-10 GB/s) | G10: Storage tier affects training throughput
A11: TECH-010 | B11: Technical Requirements | C11: Networking | D11: What network speed do you need for distributed training? | E11: Options: 10 GbE (single-node), 25 GbE (light multi-node), 100 GbE (standard multi-node), InfiniBand (intensive multi-node) | G11: Network fabric selection for GPU communication
A12: TECH-011 | B12: Technical Requirements | C12: Container Platform | D12: Will you use containers for AI workloads? | E12: Options: Docker only, Kubernetes for orchestration, NGC containers, Custom containers, No containers | G12: Container runtime and orchestration requirements
A13: TECH-012 | B13: Technical Requirements | C13: Orchestration | D13: What job scheduling and orchestration do you need? | E13: Options: Kubernetes with GPU Operator, Slurm HPC scheduler, Run:ai MLOps platform, Custom scheduling, Manual allocation | G13: Workload management and resource allocation
... A21: TECH-020 | B21: Technical Requirements | C21: Model Registry | D21: Do you need a centralized model registry? | E21: Options: MLflow registry, Kubeflow registry, Custom S3-based, Cloud registry (Azure ML AWS SageMaker), No registry needed | G21: Model versioning and artifact management

Sheet Security & Compliance
A1: Question ID | B1: Category | C1: Sub-Category | D1: Question | E1: Guidance | F1: Customer Response | G1: Notes
A2: SEC-001 | B2: Security & Compliance | C2: Data Classification | D2: What is the highest data classification level for training data? | E2: Levels: Public, Internal, Confidential, Restricted/Regulated | G2: Determines security controls and isolation
A3: SEC-002 | B3: Security & Compliance | C3: Sensitive Data | D3: What sensitive data types are in your training datasets? | E3: Sensitive data types: PII, PHI, Financial data, Proprietary IP, Trade secrets, Government classified, No sensitive data | G3: Data protection and encryption requirements
A4: SEC-003 | B4: Security & Compliance | C4: Compliance Standards | D4: What compliance standards must the GPU cluster meet? | E4: Common standards: SOC 2, ISO 27001, HIPAA, PCI DSS, GDPR, FedRAMP, None | G4: Compliance controls and audit requirements
A5: SEC-004 | B5: Security & Compliance | C5: Access Control | D5: What authentication and authorization requirements apply? | E5: Options: LDAP/AD integration, MFA required, RBAC (role-based access), SSH key management, Certificate-based, SSO (SAML/OIDC) | G5: Identity and access management requirements
A6: SEC-005 | B6: Security & Compliance | C6: Network Security | D6: What network security controls are required? | E6: Requirements: VLAN segmentation, Firewall rules, VPN access, Air-gapped environment, DMZ placement, Internet access restrictions | G6: Network security architecture
A7: SEC-006 | B7: Security & Compliance | C7: Encryption | D7: What encryption requirements apply? | E7: Requirements: Encryption at rest (storage), Encryption in transit (TLS/SSH), Key management, Full disk encryption | G7: Data protection and encryption standards
A8: SEC-007 | B8: Security & Compliance | C8: Audit Logging | D8: What audit and logging requirements do you have? | E8: Requirements: User access logs, Job execution logs, Data access trails, Security event logging, Compliance reporting | G8: Audit trail and compliance reporting needs
A9: SEC-008 | B9: Security & Compliance | C9: Multi-Tenancy | D9: Do you need isolation between teams or projects? | E9: Options: No isolation needed, Namespace-level (Kubernetes), Project-level quotas, Complete tenant isolation, Department-level separation | G9: Resource isolation and security boundaries
A10: SEC-009 | B10: Security & Compliance | C10: Data Residency | D10: Do you require data to remain in specific locations? | E10: Specify: geographic regions, on-premises only, compliance-driven restrictions | G10: Data sovereignty and location requirements

Sheet Operations & Support
A1: Question ID | B1: Category | C1: Sub-Category | D1: Question | E1: Guidance | F1: Customer Response | G1: Notes
A2: OPS-001 | B2: Operations & Support | C2: Availability | D2: What uptime requirements do you have for the GPU cluster? | E2: Common targets: 95%, 99%, 99.5%, 99.9% (development vs production) | G2: SLA requirements drive architecture design
A3: OPS-002 | B3: Operations & Support | C3: Deployment Location | D3: Where will the GPU cluster be deployed? | E3: Options: On-premises datacenter, Colocation facility, Cloud (hybrid), Edge location | G3: Deployment location and logistics
A4: OPS-003 | B4: Operations & Support | C4: Rack Space | D4: How much rack space is available for GPU servers? | E4: Specify: number of U available, rack power capacity (kW), existing vs new racks | G4: Physical space and power constraints
A5: OPS-004 | B5: Operations & Support | C5: Power Capacity | D5: What power capacity is available for GPU cluster? | E5: Specify: available kW per rack, voltage (208V/240V), PDU configuration | G5: Power infrastructure and upgrade needs
A6: OPS-005 | B6: Operations & Support | C6: Cooling | D6: What cooling infrastructure is available? | E6: Options: Standard air cooling, Hot/cold aisle, In-row cooling, No existing cooling | G6: Thermal management for GPU heat density
A7: OPS-006 | B7: Operations & Support | C7: Administration | D7: Who will administer the GPU cluster? | E7: Options: In-house IT team, Data science team, Dedicated ML infrastructure team, Outsourced management, Shared responsibility | G7: Operational responsibility and training needs
A8: OPS-007 | B8: Operations & Support | C8: IT Skills | D8: What is your team's experience with GPU infrastructure? | E8: Experience levels: No experience, Basic knowledge, Intermediate (managed cloud GPUs), Advanced (deployed GPU clusters), Expert | G8: Training needs and support requirements
A9: OPS-008 | B9: Operations & Support | C9: Support Coverage | D9: What support coverage do you require? | E9: Options: Business hours (8x5), Extended (12x5), Full (24x7), Standard (next-business-day) | G9: Support SLA and vendor contract planning
A10: OPS-009 | B10: Operations & Support | C10: Backup | D10: What backup requirements do you have for models and data? | E10: Specify: backup frequency (daily, weekly), retention period, off-site replication, disaster recovery RPO/RTO | G10: Backup strategy and data protection
A11: OPS-010 | B11: Operations & Support | C11: Maintenance Windows | D11: What maintenance windows are acceptable? | E11: Options: Weekly off-hours, Monthly scheduled, Quarterly planned, Rolling updates (no downtime), As-needed only | G11: Maintenance planning and user impact
A12: OPS-011 | B12: Operations & Support | C12: User Support | D12: How will users get support for GPU cluster issues? | E12: Options: IT helpdesk, Dedicated ML infrastructure team, Slack/Teams channel, Email ticketing, Self-service documentation | G12: User support model and escalation

Sheet Implementation Planning
A1: Question ID | B1: Category | C1: Sub-Category | D1: Question | E1: Guidance | F1: Customer Response | G1: Notes
A2: IMPL-001 | B2: Implementation Planning | C2: Resources | D2: Who will be the technical lead for this GPU cluster project? | E2: Name, role, contact information | G2: Technical ownership and project management
A3: IMPL-002 | B3: Implementation Planning | C3: Team Availability | D3: What internal resources are available for GPU cluster implementation? | E3: List team members, roles, and time commitment (hours per week) | G3: Resource planning and project timeline feasibility
A4: IMPL-003 | B4: Implementation Planning | C4: GPU Experience | D4: What is your team's experience with GPU computing? | E4: Experience levels: No experience, Basic (used cloud GPUs), Intermediate (deployed small clusters), Advanced (production GPU infrastructure), Expert | G4: Training needs assessment and knowledge transfer requirements
A5: IMPL-004 | B5: Implementation Planning | C5: Kubernetes Experience | D5: What is your team's experience with Kubernetes? | E5: Experience levels: No experience, Basic knowledge, Intermediate (deployed apps), Advanced (cluster admin), Expert (custom operators) | G5: Container orchestration skills assessment
A6: IMPL-005 | B6: Implementation Planning | C6: Infrastructure Readiness | D6: Is your datacenter ready for GPU cluster deployment? | E6: Options: Fully ready (power, cooling, network), Partial readiness, Requires upgrades, New facility needed | G6: Infrastructure preparation timeline and cost
A7: IMPL-006 | B7: Implementation Planning | C7: Deployment Approach | D7: What is your preferred deployment approach? | E7: Options: Phased deployment (start small, expand), Pilot with 1-2 nodes, Full deployment, Rolling implementation | G7: Implementation strategy and risk mitigation
A8: IMPL-007 | B8: Implementation Planning | C8: Migration Strategy | D8: How will you migrate from current AI infrastructure? | E8: Options: Parallel operation, Gradual workload migration, Direct cutover, Greenfield deployment, Hybrid (cloud + on-prem) | G8: Migration approach and transition planning
A9: IMPL-008 | B9: Implementation Planning | C9: Training Needs | D9: What training will be needed for users and administrators? | E9: Types: Admin training (cluster management), User training (job submission), Kubernetes training, Best practices, Certification programs | G9: Knowledge transfer scope and timeline
A10: IMPL-009 | B10: Implementation Planning | C10: Testing Requirements | D10: What testing and validation approach do you prefer? | E10: Options: Benchmark testing, Application validation, Performance tuning, User acceptance testing, Pilot workloads | G10: Testing and validation requirements
A11: IMPL-010 | B11: Implementation Planning | C11: Vendor Preference | D11: Do you have existing vendor relationships for GPU infrastructure? | E11: Options: NVIDIA direct, Dell/HPE/Supermicro, System integrator, Cloud provider partnership, No preference | G11: Procurement and partnership approach

Sheet Risk & Constraints
A1: Question ID | B1: Category | C1: Sub-Category | D1: Question | E1: Guidance | F1: Customer Response | G1: Notes
A2: RISK-001 | B2: Risk & Constraints | C2: Implementation Risks | D2: What are your main concerns about GPU cluster deployment? | E2: Consider: infrastructure readiness, cost overruns, complexity, skills gap, vendor lock-in, underutilization | G2: Primary implementation concerns and risk factors
A3: RISK-002 | B3: Risk & Constraints | C3: Failure Factors | D3: What could cause this GPU cluster project to fail? | E3: Consider: lack of executive support, insufficient budget, infrastructure gaps, skills shortage, poor adoption, unrealistic expectations | G3: Failure mode analysis and mitigation planning
A4: RISK-003 | B4: Risk & Constraints | C4: Infrastructure Risks | D4: What are your concerns about datacenter infrastructure? | E4: Consider: power capacity, cooling capacity, rack space, network bandwidth, lead times for upgrades | G4: Infrastructure risk factors and mitigation strategies
A5: RISK-004 | B5: Risk & Constraints | C5: Technical Risks | D5: What technical risks worry you most about GPU infrastructure? | E5: Consider: integration complexity, Kubernetes learning curve, GPU utilization rates, software compatibility, performance expectations | G5: Technical risk factors and mitigation strategies
A6: RISK-005 | B6: Risk & Constraints | C6: Skills Gap | D6: Do you have concerns about team skills for managing GPU cluster? | E6: Consider: Kubernetes expertise, GPU programming, infrastructure management, MLOps platform knowledge | G6: Skills assessment and training planning
A7: RISK-006 | B7: Risk & Constraints | C7: Utilization Risk | D7: What are your concerns about achieving high GPU utilization? | E7: Consider: workload scheduling, team adoption, job queueing, idle time, fractional GPU sharing | G7: Utilization optimization and ROI protection
A8: RISK-007 | B8: Risk & Constraints | C8: Dependencies | D8: What external dependencies exist for this project? | E8: Examples: Infrastructure upgrades, Budget approvals, Procurement timelines, Network upgrades, Vendor availability, Training schedules | G8: Project dependencies and critical path items
A9: RISK-008 | B9: Risk & Constraints | C9: Constraints | D9: What constraints must the solution work within? | E9: Consider: budget limits, timeline, space, power capacity, network, regulatory, organizational policies, vendor standards | G9: Solution design boundaries and constraints
