Workbook

Sheet Cover
B3: Configuration Parameters
B5: Generated: | C5: November 28, 2025
B6: Solution: | C6: Ci Cd Automation
B7: Customer: | C7: [Customer Name]
B8: Version: | C8: 1.0
B9: Status: | C9: Draft
C12: eoframework.org

Sheet All Parameters (Read Only)
A1: Total Parameters | B1: Categories | C1: Required | D1: Confidential/Secret
A2: 48 | B2: 16 | C2: 48 | D2: 24
A4: Parameter Name | B4: Category | C4: Environment | D4: Default Value | E4: Description | F4: Required | G4: Data Type | H4: Validation Rules | I4: Security Level | J4: Owner Team | K4: Dependencies | L4: Notes | M4: Last Updated
A5: =IF('Cisco DNA Center'!A3="","",'Cisco DNA Center'!A3) | B5: Cisco DNA Center | C5: =IF('Cisco DNA Center'!B3="","",'Cisco DNA Center'!B3) | D5: =IF('Cisco DNA Center'!C3="","",'Cisco DNA Center'!C3) | E5: =IF('Cisco DNA Center'!D3="","",'Cisco DNA Center'!D3) | F5: =IF('Cisco DNA Center'!E3="","",'Cisco DNA Center'!E3) | G5: =IF('Cisco DNA Center'!F3="","",'Cisco DNA Center'!F3) | H5: =IF('Cisco DNA Center'!G3="","",'Cisco DNA Center'!G3) | I5: =IF('Cisco DNA Center'!H3="","",'Cisco DNA Center'!H3) | J5: =IF('Cisco DNA Center'!I3="","",'Cisco DNA Center'!I3) | ... M5: =IF('Cisco DNA Center'!L3="","",'Cisco DNA Center'!L3)
A6: =IF('Cisco DNA Center'!A4="","",'Cisco DNA Center'!A4) | B6: Cisco DNA Center | C6: =IF('Cisco DNA Center'!B4="","",'Cisco DNA Center'!B4) | D6: =IF('Cisco DNA Center'!C4="","",'Cisco DNA Center'!C4) | E6: =IF('Cisco DNA Center'!D4="","",'Cisco DNA Center'!D4) | F6: =IF('Cisco DNA Center'!E4="","",'Cisco DNA Center'!E4) | G6: =IF('Cisco DNA Center'!F4="","",'Cisco DNA Center'!F4) | H6: =IF('Cisco DNA Center'!G4="","",'Cisco DNA Center'!G4) | I6: =IF('Cisco DNA Center'!H4="","",'Cisco DNA Center'!H4) | J6: =IF('Cisco DNA Center'!I4="","",'Cisco DNA Center'!I4) | ... M6: =IF('Cisco DNA Center'!L4="","",'Cisco DNA Center'!L4)
A7: =IF('Cisco DNA Center'!A5="","",'Cisco DNA Center'!A5) | B7: Cisco DNA Center | C7: =IF('Cisco DNA Center'!B5="","",'Cisco DNA Center'!B5) | D7: =IF('Cisco DNA Center'!C5="","",'Cisco DNA Center'!C5) | E7: =IF('Cisco DNA Center'!D5="","",'Cisco DNA Center'!D5) | F7: =IF('Cisco DNA Center'!E5="","",'Cisco DNA Center'!E5) | G7: =IF('Cisco DNA Center'!F5="","",'Cisco DNA Center'!F5) | H7: =IF('Cisco DNA Center'!G5="","",'Cisco DNA Center'!G5) | I7: =IF('Cisco DNA Center'!H5="","",'Cisco DNA Center'!H5) | J7: =IF('Cisco DNA Center'!I5="","",'Cisco DNA Center'!I5) | ... M7: =IF('Cisco DNA Center'!L5="","",'Cisco DNA Center'!L5)
A8: =IF('Cisco DNA Center'!A6="","",'Cisco DNA Center'!A6) | B8: Cisco DNA Center | C8: =IF('Cisco DNA Center'!B6="","",'Cisco DNA Center'!B6) | D8: =IF('Cisco DNA Center'!C6="","",'Cisco DNA Center'!C6) | E8: =IF('Cisco DNA Center'!D6="","",'Cisco DNA Center'!D6) | F8: =IF('Cisco DNA Center'!E6="","",'Cisco DNA Center'!E6) | G8: =IF('Cisco DNA Center'!F6="","",'Cisco DNA Center'!F6) | H8: =IF('Cisco DNA Center'!G6="","",'Cisco DNA Center'!G6) | I8: =IF('Cisco DNA Center'!H6="","",'Cisco DNA Center'!H6) | J8: =IF('Cisco DNA Center'!I6="","",'Cisco DNA Center'!I6) | ... M8: =IF('Cisco DNA Center'!L6="","",'Cisco DNA Center'!L6)
A9: =IF('Cisco DNA Center'!A7="","",'Cisco DNA Center'!A7) | B9: Cisco DNA Center | C9: =IF('Cisco DNA Center'!B7="","",'Cisco DNA Center'!B7) | D9: =IF('Cisco DNA Center'!C7="","",'Cisco DNA Center'!C7) | E9: =IF('Cisco DNA Center'!D7="","",'Cisco DNA Center'!D7) | F9: =IF('Cisco DNA Center'!E7="","",'Cisco DNA Center'!E7) | G9: =IF('Cisco DNA Center'!F7="","",'Cisco DNA Center'!F7) | H9: =IF('Cisco DNA Center'!G7="","",'Cisco DNA Center'!G7) | I9: =IF('Cisco DNA Center'!H7="","",'Cisco DNA Center'!H7) | J9: =IF('Cisco DNA Center'!I7="","",'Cisco DNA Center'!I7) | ... M9: =IF('Cisco DNA Center'!L7="","",'Cisco DNA Center'!L7)
A10: =IF('Cisco NSO'!A3="","",'Cisco NSO'!A3) | B10: Cisco NSO | C10: =IF('Cisco NSO'!B3="","",'Cisco NSO'!B3) | D10: =IF('Cisco NSO'!C3="","",'Cisco NSO'!C3) | E10: =IF('Cisco NSO'!D3="","",'Cisco NSO'!D3) | F10: =IF('Cisco NSO'!E3="","",'Cisco NSO'!E3) | G10: =IF('Cisco NSO'!F3="","",'Cisco NSO'!F3) | H10: =IF('Cisco NSO'!G3="","",'Cisco NSO'!G3) | I10: =IF('Cisco NSO'!H3="","",'Cisco NSO'!H3) | J10: =IF('Cisco NSO'!I3="","",'Cisco NSO'!I3) | ... M10: =IF('Cisco NSO'!L3="","",'Cisco NSO'!L3)
A11: =IF('Cisco NSO'!A4="","",'Cisco NSO'!A4) | B11: Cisco NSO | C11: =IF('Cisco NSO'!B4="","",'Cisco NSO'!B4) | D11: =IF('Cisco NSO'!C4="","",'Cisco NSO'!C4) | E11: =IF('Cisco NSO'!D4="","",'Cisco NSO'!D4) | F11: =IF('Cisco NSO'!E4="","",'Cisco NSO'!E4) | G11: =IF('Cisco NSO'!F4="","",'Cisco NSO'!F4) | H11: =IF('Cisco NSO'!G4="","",'Cisco NSO'!G4) | I11: =IF('Cisco NSO'!H4="","",'Cisco NSO'!H4) | J11: =IF('Cisco NSO'!I4="","",'Cisco NSO'!I4) | ... M11: =IF('Cisco NSO'!L4="","",'Cisco NSO'!L4)
A12: =IF('Cisco NSO'!A5="","",'Cisco NSO'!A5) | B12: Cisco NSO | C12: =IF('Cisco NSO'!B5="","",'Cisco NSO'!B5) | D12: =IF('Cisco NSO'!C5="","",'Cisco NSO'!C5) | E12: =IF('Cisco NSO'!D5="","",'Cisco NSO'!D5) | F12: =IF('Cisco NSO'!E5="","",'Cisco NSO'!E5) | G12: =IF('Cisco NSO'!F5="","",'Cisco NSO'!F5) | H12: =IF('Cisco NSO'!G5="","",'Cisco NSO'!G5) | I12: =IF('Cisco NSO'!H5="","",'Cisco NSO'!H5) | J12: =IF('Cisco NSO'!I5="","",'Cisco NSO'!I5) | ... M12: =IF('Cisco NSO'!L5="","",'Cisco NSO'!L5)
A13: =IF('Cisco NSO'!A6="","",'Cisco NSO'!A6) | B13: Cisco NSO | C13: =IF('Cisco NSO'!B6="","",'Cisco NSO'!B6) | D13: =IF('Cisco NSO'!C6="","",'Cisco NSO'!C6) | E13: =IF('Cisco NSO'!D6="","",'Cisco NSO'!D6) | F13: =IF('Cisco NSO'!E6="","",'Cisco NSO'!E6) | G13: =IF('Cisco NSO'!F6="","",'Cisco NSO'!F6) | H13: =IF('Cisco NSO'!G6="","",'Cisco NSO'!G6) | I13: =IF('Cisco NSO'!H6="","",'Cisco NSO'!H6) | J13: =IF('Cisco NSO'!I6="","",'Cisco NSO'!I6) | ... M13: =IF('Cisco NSO'!L6="","",'Cisco NSO'!L6)
A14: =IF('Cisco NSO'!A7="","",'Cisco NSO'!A7) | B14: Cisco NSO | C14: =IF('Cisco NSO'!B7="","",'Cisco NSO'!B7) | D14: =IF('Cisco NSO'!C7="","",'Cisco NSO'!C7) | E14: =IF('Cisco NSO'!D7="","",'Cisco NSO'!D7) | F14: =IF('Cisco NSO'!E7="","",'Cisco NSO'!E7) | G14: =IF('Cisco NSO'!F7="","",'Cisco NSO'!F7) | H14: =IF('Cisco NSO'!G7="","",'Cisco NSO'!G7) | I14: =IF('Cisco NSO'!H7="","",'Cisco NSO'!H7) | J14: =IF('Cisco NSO'!I7="","",'Cisco NSO'!I7) | ... M14: =IF('Cisco NSO'!L7="","",'Cisco NSO'!L7)
A15: =IF('GitLab'!A3="","",'GitLab'!A3) | B15: GitLab | C15: =IF('GitLab'!B3="","",'GitLab'!B3) | D15: =IF('GitLab'!C3="","",'GitLab'!C3) | E15: =IF('GitLab'!D3="","",'GitLab'!D3) | F15: =IF('GitLab'!E3="","",'GitLab'!E3) | G15: =IF('GitLab'!F3="","",'GitLab'!F3) | H15: =IF('GitLab'!G3="","",'GitLab'!G3) | I15: =IF('GitLab'!H3="","",'GitLab'!H3) | J15: =IF('GitLab'!I3="","",'GitLab'!I3) | ... M15: =IF('GitLab'!L3="","",'GitLab'!L3)
A16: =IF('GitLab'!A4="","",'GitLab'!A4) | B16: GitLab | C16: =IF('GitLab'!B4="","",'GitLab'!B4) | D16: =IF('GitLab'!C4="","",'GitLab'!C4) | E16: =IF('GitLab'!D4="","",'GitLab'!D4) | F16: =IF('GitLab'!E4="","",'GitLab'!E4) | G16: =IF('GitLab'!F4="","",'GitLab'!F4) | H16: =IF('GitLab'!G4="","",'GitLab'!G4) | I16: =IF('GitLab'!H4="","",'GitLab'!H4) | J16: =IF('GitLab'!I4="","",'GitLab'!I4) | ... M16: =IF('GitLab'!L4="","",'GitLab'!L4)
A17: =IF('GitLab'!A5="","",'GitLab'!A5) | B17: GitLab | C17: =IF('GitLab'!B5="","",'GitLab'!B5) | D17: =IF('GitLab'!C5="","",'GitLab'!C5) | E17: =IF('GitLab'!D5="","",'GitLab'!D5) | F17: =IF('GitLab'!E5="","",'GitLab'!E5) | G17: =IF('GitLab'!F5="","",'GitLab'!F5) | H17: =IF('GitLab'!G5="","",'GitLab'!G5) | I17: =IF('GitLab'!H5="","",'GitLab'!H5) | J17: =IF('GitLab'!I5="","",'GitLab'!I5) | ... M17: =IF('GitLab'!L5="","",'GitLab'!L5)
A18: =IF('GitLab'!A6="","",'GitLab'!A6) | B18: GitLab | C18: =IF('GitLab'!B6="","",'GitLab'!B6) | D18: =IF('GitLab'!C6="","",'GitLab'!C6) | E18: =IF('GitLab'!D6="","",'GitLab'!D6) | F18: =IF('GitLab'!E6="","",'GitLab'!E6) | G18: =IF('GitLab'!F6="","",'GitLab'!F6) | H18: =IF('GitLab'!G6="","",'GitLab'!G6) | I18: =IF('GitLab'!H6="","",'GitLab'!H6) | J18: =IF('GitLab'!I6="","",'GitLab'!I6) | ... M18: =IF('GitLab'!L6="","",'GitLab'!L6)
A19: =IF('Jenkins'!A3="","",'Jenkins'!A3) | B19: Jenkins | C19: =IF('Jenkins'!B3="","",'Jenkins'!B3) | D19: =IF('Jenkins'!C3="","",'Jenkins'!C3) | E19: =IF('Jenkins'!D3="","",'Jenkins'!D3) | F19: =IF('Jenkins'!E3="","",'Jenkins'!E3) | G19: =IF('Jenkins'!F3="","",'Jenkins'!F3) | H19: =IF('Jenkins'!G3="","",'Jenkins'!G3) | I19: =IF('Jenkins'!H3="","",'Jenkins'!H3) | J19: =IF('Jenkins'!I3="","",'Jenkins'!I3) | ... M19: =IF('Jenkins'!L3="","",'Jenkins'!L3)
A20: =IF('Jenkins'!A4="","",'Jenkins'!A4) | B20: Jenkins | C20: =IF('Jenkins'!B4="","",'Jenkins'!B4) | D20: =IF('Jenkins'!C4="","",'Jenkins'!C4) | E20: =IF('Jenkins'!D4="","",'Jenkins'!D4) | F20: =IF('Jenkins'!E4="","",'Jenkins'!E4) | G20: =IF('Jenkins'!F4="","",'Jenkins'!F4) | H20: =IF('Jenkins'!G4="","",'Jenkins'!G4) | I20: =IF('Jenkins'!H4="","",'Jenkins'!H4) | J20: =IF('Jenkins'!I4="","",'Jenkins'!I4) | ... M20: =IF('Jenkins'!L4="","",'Jenkins'!L4)
A21: =IF('Jenkins'!A5="","",'Jenkins'!A5) | B21: Jenkins | C21: =IF('Jenkins'!B5="","",'Jenkins'!B5) | D21: =IF('Jenkins'!C5="","",'Jenkins'!C5) | E21: =IF('Jenkins'!D5="","",'Jenkins'!D5) | F21: =IF('Jenkins'!E5="","",'Jenkins'!E5) | G21: =IF('Jenkins'!F5="","",'Jenkins'!F5) | H21: =IF('Jenkins'!G5="","",'Jenkins'!G5) | I21: =IF('Jenkins'!H5="","",'Jenkins'!H5) | J21: =IF('Jenkins'!I5="","",'Jenkins'!I5) | ... M21: =IF('Jenkins'!L5="","",'Jenkins'!L5)
A22: =IF('Ansible'!A3="","",'Ansible'!A3) | B22: Ansible | C22: =IF('Ansible'!B3="","",'Ansible'!B3) | D22: =IF('Ansible'!C3="","",'Ansible'!C3) | E22: =IF('Ansible'!D3="","",'Ansible'!D3) | F22: =IF('Ansible'!E3="","",'Ansible'!E3) | G22: =IF('Ansible'!F3="","",'Ansible'!F3) | H22: =IF('Ansible'!G3="","",'Ansible'!G3) | I22: =IF('Ansible'!H3="","",'Ansible'!H3) | J22: =IF('Ansible'!I3="","",'Ansible'!I3) | ... M22: =IF('Ansible'!L3="","",'Ansible'!L3)
A23: =IF('Ansible'!A4="","",'Ansible'!A4) | B23: Ansible | C23: =IF('Ansible'!B4="","",'Ansible'!B4) | D23: =IF('Ansible'!C4="","",'Ansible'!C4) | E23: =IF('Ansible'!D4="","",'Ansible'!D4) | F23: =IF('Ansible'!E4="","",'Ansible'!E4) | G23: =IF('Ansible'!F4="","",'Ansible'!F4) | H23: =IF('Ansible'!G4="","",'Ansible'!G4) | I23: =IF('Ansible'!H4="","",'Ansible'!H4) | J23: =IF('Ansible'!I4="","",'Ansible'!I4) | ... M23: =IF('Ansible'!L4="","",'Ansible'!L4)
A24: =IF('Ansible'!A5="","",'Ansible'!A5) | B24: Ansible | C24: =IF('Ansible'!B5="","",'Ansible'!B5) | D24: =IF('Ansible'!C5="","",'Ansible'!C5) | E24: =IF('Ansible'!D5="","",'Ansible'!D5) | F24: =IF('Ansible'!E5="","",'Ansible'!E5) | G24: =IF('Ansible'!F5="","",'Ansible'!F5) | H24: =IF('Ansible'!G5="","",'Ansible'!G5) | I24: =IF('Ansible'!H5="","",'Ansible'!H5) | J24: =IF('Ansible'!I5="","",'Ansible'!I5) | ... M24: =IF('Ansible'!L5="","",'Ansible'!L5)
A25: =IF('Ansible'!A6="","",'Ansible'!A6) | B25: Ansible | C25: =IF('Ansible'!B6="","",'Ansible'!B6) | D25: =IF('Ansible'!C6="","",'Ansible'!C6) | E25: =IF('Ansible'!D6="","",'Ansible'!D6) | F25: =IF('Ansible'!E6="","",'Ansible'!E6) | G25: =IF('Ansible'!F6="","",'Ansible'!F6) | H25: =IF('Ansible'!G6="","",'Ansible'!G6) | I25: =IF('Ansible'!H6="","",'Ansible'!H6) | J25: =IF('Ansible'!I6="","",'Ansible'!I6) | ... M25: =IF('Ansible'!L6="","",'Ansible'!L6)
A26: =IF('Terraform'!A3="","",'Terraform'!A3) | B26: Terraform | C26: =IF('Terraform'!B3="","",'Terraform'!B3) | D26: =IF('Terraform'!C3="","",'Terraform'!C3) | E26: =IF('Terraform'!D3="","",'Terraform'!D3) | F26: =IF('Terraform'!E3="","",'Terraform'!E3) | G26: =IF('Terraform'!F3="","",'Terraform'!F3) | H26: =IF('Terraform'!G3="","",'Terraform'!G3) | I26: =IF('Terraform'!H3="","",'Terraform'!H3) | J26: =IF('Terraform'!I3="","",'Terraform'!I3) | ... M26: =IF('Terraform'!L3="","",'Terraform'!L3)
A27: =IF('Terraform'!A4="","",'Terraform'!A4) | B27: Terraform | C27: =IF('Terraform'!B4="","",'Terraform'!B4) | D27: =IF('Terraform'!C4="","",'Terraform'!C4) | E27: =IF('Terraform'!D4="","",'Terraform'!D4) | F27: =IF('Terraform'!E4="","",'Terraform'!E4) | G27: =IF('Terraform'!F4="","",'Terraform'!F4) | H27: =IF('Terraform'!G4="","",'Terraform'!G4) | I27: =IF('Terraform'!H4="","",'Terraform'!H4) | J27: =IF('Terraform'!I4="","",'Terraform'!I4) | ... M27: =IF('Terraform'!L4="","",'Terraform'!L4)
A28: =IF('Terraform'!A5="","",'Terraform'!A5) | B28: Terraform | C28: =IF('Terraform'!B5="","",'Terraform'!B5) | D28: =IF('Terraform'!C5="","",'Terraform'!C5) | E28: =IF('Terraform'!D5="","",'Terraform'!D5) | F28: =IF('Terraform'!E5="","",'Terraform'!E5) | G28: =IF('Terraform'!F5="","",'Terraform'!F5) | H28: =IF('Terraform'!G5="","",'Terraform'!G5) | I28: =IF('Terraform'!H5="","",'Terraform'!H5) | J28: =IF('Terraform'!I5="","",'Terraform'!I5) | ... M28: =IF('Terraform'!L5="","",'Terraform'!L5)
A29: =IF('Terraform'!A6="","",'Terraform'!A6) | B29: Terraform | C29: =IF('Terraform'!B6="","",'Terraform'!B6) | D29: =IF('Terraform'!C6="","",'Terraform'!C6) | E29: =IF('Terraform'!D6="","",'Terraform'!D6) | F29: =IF('Terraform'!E6="","",'Terraform'!E6) | G29: =IF('Terraform'!F6="","",'Terraform'!F6) | H29: =IF('Terraform'!G6="","",'Terraform'!G6) | I29: =IF('Terraform'!H6="","",'Terraform'!H6) | J29: =IF('Terraform'!I6="","",'Terraform'!I6) | ... M29: =IF('Terraform'!L6="","",'Terraform'!L6)
A30: =IF('HashiCorp Vault'!A3="","",'HashiCorp Vault'!A3) | B30: HashiCorp Vault | C30: =IF('HashiCorp Vault'!B3="","",'HashiCorp Vault'!B3) | D30: =IF('HashiCorp Vault'!C3="","",'HashiCorp Vault'!C3) | E30: =IF('HashiCorp Vault'!D3="","",'HashiCorp Vault'!D3) | F30: =IF('HashiCorp Vault'!E3="","",'HashiCorp Vault'!E3) | G30: =IF('HashiCorp Vault'!F3="","",'HashiCorp Vault'!F3) | H30: =IF('HashiCorp Vault'!G3="","",'HashiCorp Vault'!G3) | I30: =IF('HashiCorp Vault'!H3="","",'HashiCorp Vault'!H3) | J30: =IF('HashiCorp Vault'!I3="","",'HashiCorp Vault'!I3) | ... M30: =IF('HashiCorp Vault'!L3="","",'HashiCorp Vault'!L3)
A31: =IF('HashiCorp Vault'!A4="","",'HashiCorp Vault'!A4) | B31: HashiCorp Vault | C31: =IF('HashiCorp Vault'!B4="","",'HashiCorp Vault'!B4) | D31: =IF('HashiCorp Vault'!C4="","",'HashiCorp Vault'!C4) | E31: =IF('HashiCorp Vault'!D4="","",'HashiCorp Vault'!D4) | F31: =IF('HashiCorp Vault'!E4="","",'HashiCorp Vault'!E4) | G31: =IF('HashiCorp Vault'!F4="","",'HashiCorp Vault'!F4) | H31: =IF('HashiCorp Vault'!G4="","",'HashiCorp Vault'!G4) | I31: =IF('HashiCorp Vault'!H4="","",'HashiCorp Vault'!H4) | J31: =IF('HashiCorp Vault'!I4="","",'HashiCorp Vault'!I4) | ... M31: =IF('HashiCorp Vault'!L4="","",'HashiCorp Vault'!L4)
A32: =IF('HashiCorp Vault'!A5="","",'HashiCorp Vault'!A5) | B32: HashiCorp Vault | C32: =IF('HashiCorp Vault'!B5="","",'HashiCorp Vault'!B5) | D32: =IF('HashiCorp Vault'!C5="","",'HashiCorp Vault'!C5) | E32: =IF('HashiCorp Vault'!D5="","",'HashiCorp Vault'!D5) | F32: =IF('HashiCorp Vault'!E5="","",'HashiCorp Vault'!E5) | G32: =IF('HashiCorp Vault'!F5="","",'HashiCorp Vault'!F5) | H32: =IF('HashiCorp Vault'!G5="","",'HashiCorp Vault'!G5) | I32: =IF('HashiCorp Vault'!H5="","",'HashiCorp Vault'!H5) | J32: =IF('HashiCorp Vault'!I5="","",'HashiCorp Vault'!I5) | ... M32: =IF('HashiCorp Vault'!L5="","",'HashiCorp Vault'!L5)
A33: =IF('NetBox'!A3="","",'NetBox'!A3) | B33: NetBox | C33: =IF('NetBox'!B3="","",'NetBox'!B3) | D33: =IF('NetBox'!C3="","",'NetBox'!C3) | E33: =IF('NetBox'!D3="","",'NetBox'!D3) | F33: =IF('NetBox'!E3="","",'NetBox'!E3) | G33: =IF('NetBox'!F3="","",'NetBox'!F3) | H33: =IF('NetBox'!G3="","",'NetBox'!G3) | I33: =IF('NetBox'!H3="","",'NetBox'!H3) | J33: =IF('NetBox'!I3="","",'NetBox'!I3) | ... M33: =IF('NetBox'!L3="","",'NetBox'!L3)
A34: =IF('NetBox'!A4="","",'NetBox'!A4) | B34: NetBox | C34: =IF('NetBox'!B4="","",'NetBox'!B4) | D34: =IF('NetBox'!C4="","",'NetBox'!C4) | E34: =IF('NetBox'!D4="","",'NetBox'!D4) | F34: =IF('NetBox'!E4="","",'NetBox'!E4) | G34: =IF('NetBox'!F4="","",'NetBox'!F4) | H34: =IF('NetBox'!G4="","",'NetBox'!G4) | I34: =IF('NetBox'!H4="","",'NetBox'!H4) | J34: =IF('NetBox'!I4="","",'NetBox'!I4) | ... M34: =IF('NetBox'!L4="","",'NetBox'!L4)
A35: =IF('Monitoring'!A3="","",'Monitoring'!A3) | B35: Monitoring | C35: =IF('Monitoring'!B3="","",'Monitoring'!B3) | D35: =IF('Monitoring'!C3="","",'Monitoring'!C3) | E35: =IF('Monitoring'!D3="","",'Monitoring'!D3) | F35: =IF('Monitoring'!E3="","",'Monitoring'!E3) | G35: =IF('Monitoring'!F3="","",'Monitoring'!F3) | H35: =IF('Monitoring'!G3="","",'Monitoring'!G3) | I35: =IF('Monitoring'!H3="","",'Monitoring'!H3) | J35: =IF('Monitoring'!I3="","",'Monitoring'!I3) | ... M35: =IF('Monitoring'!L3="","",'Monitoring'!L3)
A36: =IF('Monitoring'!A4="","",'Monitoring'!A4) | B36: Monitoring | C36: =IF('Monitoring'!B4="","",'Monitoring'!B4) | D36: =IF('Monitoring'!C4="","",'Monitoring'!C4) | E36: =IF('Monitoring'!D4="","",'Monitoring'!D4) | F36: =IF('Monitoring'!E4="","",'Monitoring'!E4) | G36: =IF('Monitoring'!F4="","",'Monitoring'!F4) | H36: =IF('Monitoring'!G4="","",'Monitoring'!G4) | I36: =IF('Monitoring'!H4="","",'Monitoring'!H4) | J36: =IF('Monitoring'!I4="","",'Monitoring'!I4) | ... M36: =IF('Monitoring'!L4="","",'Monitoring'!L4)
A37: =IF('Monitoring'!A5="","",'Monitoring'!A5) | B37: Monitoring | C37: =IF('Monitoring'!B5="","",'Monitoring'!B5) | D37: =IF('Monitoring'!C5="","",'Monitoring'!C5) | E37: =IF('Monitoring'!D5="","",'Monitoring'!D5) | F37: =IF('Monitoring'!E5="","",'Monitoring'!E5) | G37: =IF('Monitoring'!F5="","",'Monitoring'!F5) | H37: =IF('Monitoring'!G5="","",'Monitoring'!G5) | I37: =IF('Monitoring'!H5="","",'Monitoring'!H5) | J37: =IF('Monitoring'!I5="","",'Monitoring'!I5) | ... M37: =IF('Monitoring'!L5="","",'Monitoring'!L5)
A38: =IF('Logging'!A3="","",'Logging'!A3) | B38: Logging | C38: =IF('Logging'!B3="","",'Logging'!B3) | D38: =IF('Logging'!C3="","",'Logging'!C3) | E38: =IF('Logging'!D3="","",'Logging'!D3) | F38: =IF('Logging'!E3="","",'Logging'!E3) | G38: =IF('Logging'!F3="","",'Logging'!F3) | H38: =IF('Logging'!G3="","",'Logging'!G3) | I38: =IF('Logging'!H3="","",'Logging'!H3) | J38: =IF('Logging'!I3="","",'Logging'!I3) | ... M38: =IF('Logging'!L3="","",'Logging'!L3)
A39: =IF('Logging'!A4="","",'Logging'!A4) | B39: Logging | C39: =IF('Logging'!B4="","",'Logging'!B4) | D39: =IF('Logging'!C4="","",'Logging'!C4) | E39: =IF('Logging'!D4="","",'Logging'!D4) | F39: =IF('Logging'!E4="","",'Logging'!E4) | G39: =IF('Logging'!F4="","",'Logging'!F4) | H39: =IF('Logging'!G4="","",'Logging'!G4) | I39: =IF('Logging'!H4="","",'Logging'!H4) | J39: =IF('Logging'!I4="","",'Logging'!I4) | ... M39: =IF('Logging'!L4="","",'Logging'!L4)
A40: =IF('Container'!A3="","",'Container'!A3) | B40: Container | C40: =IF('Container'!B3="","",'Container'!B3) | D40: =IF('Container'!C3="","",'Container'!C3) | E40: =IF('Container'!D3="","",'Container'!D3) | F40: =IF('Container'!E3="","",'Container'!E3) | G40: =IF('Container'!F3="","",'Container'!F3) | H40: =IF('Container'!G3="","",'Container'!G3) | I40: =IF('Container'!H3="","",'Container'!H3) | J40: =IF('Container'!I3="","",'Container'!I3) | ... M40: =IF('Container'!L3="","",'Container'!L3)
A41: =IF('Container'!A4="","",'Container'!A4) | B41: Container | C41: =IF('Container'!B4="","",'Container'!B4) | D41: =IF('Container'!C4="","",'Container'!C4) | E41: =IF('Container'!D4="","",'Container'!D4) | F41: =IF('Container'!E4="","",'Container'!E4) | G41: =IF('Container'!F4="","",'Container'!F4) | H41: =IF('Container'!G4="","",'Container'!G4) | I41: =IF('Container'!H4="","",'Container'!H4) | J41: =IF('Container'!I4="","",'Container'!I4) | ... M41: =IF('Container'!L4="","",'Container'!L4)
...

Sheet Cisco DNA Center
A1: Cisco DNA Center Parameters
A2: Parameter Name | B2: Environment | C2: Default Value | D2: Description | E2: Required | F2: Data Type | G2: Validation Rules | H2: Security Level | I2: Owner Team | J2: Dependencies | K2: Notes | L2: Last Updated
A3: DNAC_HOSTNAME | B3: All | C3: [********] | D3: DNA Center appliance hostname | E3: Yes | F3: String | G3: Valid FQDN | H3: Confidential | I3: Network Team | J3: Network connectivity | K3: Management interface | L3: [DATE]
A4: DNAC_API_VERSION | B4: All | C4: v2 | D4: DNA Center API version | E4: Yes | F4: String | G4: v1|v2 | H4: Public | I4: Network Team | J4: DNAC_HOSTNAME | K4: Use v2 for latest features | L4: [DATE]
A5: DNAC_ADMIN_USER | B5: All | C5: [********] | D5: DNA Center administrative username | E5: Yes | F5: String | G5: Valid username | H5: Confidential | I5: Network Team | J5: DNAC deployment | K5: Initial admin account | L5: [DATE]
A6: DNAC_SSL_VERIFY | B6: All | C6: true | D6: Verify SSL certificates for API calls | E6: Yes | F6: Boolean | G6: true|false | H6: Public | I6: Network Team | J6: Valid certificates | K6: Disable only for testing | L6: [DATE]
A7: DNAC_TIMEOUT | B7: All | C7: 30 | D7: API request timeout in seconds | E7: Yes | F7: Integer | G7: 10-300 | H7: Public | I7: Network Team | J7: None | K7: Increase for large operations | L7: [DATE]

Sheet Cisco NSO
A1: Cisco NSO Parameters
A2: Parameter Name | B2: Environment | C2: Default Value | D2: Description | E2: Required | F2: Data Type | G2: Validation Rules | H2: Security Level | I2: Owner Team | J2: Dependencies | K2: Notes | L2: Last Updated
A3: NSO_HOSTNAME | B3: All | C3: [********] | D3: Network Services Orchestrator hostname | E3: Yes | F3: String | G3: Valid FQDN | H3: Confidential | I3: Network Team | J3: Network connectivity | K3: REST/RESTCONF interface | L3: [DATE]
A4: NSO_PORT | B4: All | C4: 8443 | D4: NSO RESTCONF API port | E4: Yes | F4: Integer | G4: Valid port number | H4: Public | I4: Network Team | J4: Firewall rules | K4: HTTPS port | L4: [DATE]
A5: NSO_ADMIN_USER | B5: All | C5: [********] | D5: NSO administrative username | E5: Yes | F5: String | G5: Valid username | H5: Confidential | I5: Network Team | J5: NSO deployment | K5: Admin access | L5: [DATE]
A6: NSO_NED_PACKAGES | B6: All | C6: cisco-ios cisco-nxos cisco-asa | D6: Network Element Drivers installed | E6: Yes | F6: String | G6: Space-separated NED names | H6: Public | I6: Network Team | J6: NED licensing | K6: Per device type | L6: [DATE]
A7: NSO_COMMIT_MODE | B7: All | C7: commit-queue | D7: Transaction commit mode | E7: Yes | F7: String | G7: sync|commit-queue | H7: Public | I7: Network Team | J7: None | K7: Async recommended | L7: [DATE]

Sheet GitLab
A1: GitLab Parameters
A2: Parameter Name | B2: Environment | C2: Default Value | D2: Description | E2: Required | F2: Data Type | G2: Validation Rules | H2: Security Level | I2: Owner Team | J2: Dependencies | K2: Notes | L2: Last Updated
A3: GITLAB_URL | B3: All | C3: [********] | D3: GitLab Enterprise server URL | E3: Yes | F3: String | G3: Valid HTTPS URL | H3: Confidential | I3: DevOps Team | J3: Network connectivity | K3: Self-hosted instance | L3: [DATE]
A4: GITLAB_API_VERSION | B4: All | C4: v4 | D4: GitLab API version | E4: Yes | F4: String | G4: v4 | H4: Public | I4: DevOps Team | J4: GITLAB_URL | K4: Current stable API | L4: [DATE]
A5: GITLAB_RUNNER_TAG | B5: All | C5: cisco-automation | D5: Runner tag for automation jobs | E5: Yes | F5: String | G5: Valid runner tag | H5: Public | I5: DevOps Team | J5: Runner configuration | K5: Dedicated runners | L5: [DATE]
A6: GITLAB_ARTIFACT_EXPIRY | B6: All | C6: 30 days | D6: Pipeline artifact retention period | E6: Yes | F6: String | G6: Valid duration | H6: Public | I6: DevOps Team | J6: Storage capacity | K6: Adjust per storage | L6: [DATE]

Sheet Jenkins
A1: Jenkins Parameters
A2: Parameter Name | B2: Environment | C2: Default Value | D2: Description | E2: Required | F2: Data Type | G2: Validation Rules | H2: Security Level | I2: Owner Team | J2: Dependencies | K2: Notes | L2: Last Updated
A3: JENKINS_URL | B3: All | C3: [********] | D3: Jenkins automation server URL | E3: Yes | F3: String | G3: Valid HTTPS URL | H3: Confidential | I3: DevOps Team | J3: Network connectivity | K3: Blue Ocean enabled | L3: [DATE]
A4: JENKINS_ADMIN_USER | B4: All | C4: [********] | D4: Jenkins administrative username | E4: Yes | F4: String | G4: Valid username | H4: Confidential | I4: DevOps Team | J4: Jenkins deployment | K4: Pipeline admin | L4: [DATE]
A5: JENKINS_SHARED_LIB | B5: All | C5: cisco-pipeline-lib | D5: Shared library for Cisco pipelines | E5: Yes | F5: String | G5: Valid library name | H5: Public | I5: DevOps Team | J5: Library repo | K5: Common functions | L5: [DATE]

Sheet Ansible
A1: Ansible Parameters
A2: Parameter Name | B2: Environment | C2: Default Value | D2: Description | E2: Required | F2: Data Type | G2: Validation Rules | H2: Security Level | I2: Owner Team | J2: Dependencies | K2: Notes | L2: Last Updated
A3: ANSIBLE_INVENTORY | B3: All | C3: [********] | D3: Ansible inventory file path | E3: Yes | F3: String | G3: Valid file path | H3: Confidential | I3: DevOps Team | J3: File system access | K3: Dynamic inventory | L3: [DATE]
A4: ANSIBLE_COLLECTIONS | B4: All | C4: cisco.ios cisco.nxos cisco.asa | D4: Required Ansible collections | E4: Yes | F4: String | G4: Space-separated collection names | H4: Public | I4: DevOps Team | J4: Ansible Galaxy | K4: Latest versions | L4: [DATE]
A5: ANSIBLE_VAULT_ID | B5: All | C5: [********] | D5: Ansible Vault identity for secrets | E5: Yes | F5: String | G5: Valid vault ID | H5: Secret | I5: DevOps Team | J5: Vault password file | K5: Encrypted credentials | L5: [DATE]
A6: ANSIBLE_CALLBACK | B6: All | C6: json | D6: Ansible output callback plugin | E6: Yes | F6: String | G6: json|yaml|minimal | H6: Public | I6: DevOps Team | J6: None | K6: JSON for parsing | L6: [DATE]

Sheet Terraform
A1: Terraform Parameters
A2: Parameter Name | B2: Environment | C2: Default Value | D2: Description | E2: Required | F2: Data Type | G2: Validation Rules | H2: Security Level | I2: Owner Team | J2: Dependencies | K2: Notes | L2: Last Updated
A3: TERRAFORM_BACKEND | B3: All | C3: gitlab | D3: Terraform state backend type | E3: Yes | F3: String | G3: local|s3|gitlab|consul | H3: Public | I3: DevOps Team | J3: Backend access | K3: GitLab recommended | L3: [DATE]
A4: TERRAFORM_WORKSPACE | B4: All | C4: default | D4: Default Terraform workspace | E4: Yes | F4: String | G4: Valid workspace name | H4: Public | I4: DevOps Team | J4: Backend configured | K4: Per environment | L4: [DATE]
A5: TF_CISCO_PROVIDER | B5: All | C5: CiscoDevNet/aci | D5: Cisco ACI Terraform provider | E5: Yes | F5: String | G5: Valid provider name | H5: Public | I5: DevOps Team | J5: Provider registry | K5: Latest version | L5: [DATE]
A6: TF_VAR_PARALLELISM | B6: All | C6: 10 | D6: Terraform parallelism limit | E6: Yes | F6: Integer | G6: 1-50 | H6: Public | I6: DevOps Team | J6: None | K6: Adjust per resources | L6: [DATE]

Sheet HashiCorp Vault
A1: HashiCorp Vault Parameters
A2: Parameter Name | B2: Environment | C2: Default Value | D2: Description | E2: Required | F2: Data Type | G2: Validation Rules | H2: Security Level | I2: Owner Team | J2: Dependencies | K2: Notes | L2: Last Updated
A3: VAULT_ADDR | B3: All | C3: [********] | D3: HashiCorp Vault server address | E3: Yes | F3: String | G3: Valid HTTPS URL | H3: Confidential | I3: Security Team | J3: Network connectivity | K3: Secrets management | L3: [DATE]
A4: VAULT_AUTH_METHOD | B4: All | C4: approle | D4: Vault authentication method | E4: Yes | F4: String | G4: token|approle|ldap | H4: Public | I4: Security Team | J4: Auth backend | K4: AppRole for automation | L4: [DATE]
A5: VAULT_SECRET_PATH | B5: All | C5: [********] | D5: Vault secret path for Cisco creds | E5: Yes | F5: String | G5: Valid path | H5: Confidential | I5: Security Team | J5: Secret engine | K5: KV v2 engine | L5: [DATE]

Sheet NetBox
A1: NetBox Parameters
A2: Parameter Name | B2: Environment | C2: Default Value | D2: Description | E2: Required | F2: Data Type | G2: Validation Rules | H2: Security Level | I2: Owner Team | J2: Dependencies | K2: Notes | L2: Last Updated
A3: NETBOX_URL | B3: All | C3: [********] | D3: NetBox DCIM/IPAM server URL | E3: Yes | F3: String | G3: Valid HTTPS URL | H3: Confidential | I3: Network Team | J3: Network connectivity | K3: Source of truth | L3: [DATE]
A4: NETBOX_API_TOKEN | B4: All | C4: [********] | D4: NetBox API authentication token | E4: Yes | F4: String | G4: Valid API token | H4: Secret | I4: Network Team | J4: User account | K4: Read/write access | L4: [DATE]

Sheet Monitoring
A1: Monitoring Parameters
A2: Parameter Name | B2: Environment | C2: Default Value | D2: Description | E2: Required | F2: Data Type | G2: Validation Rules | H2: Security Level | I2: Owner Team | J2: Dependencies | K2: Notes | L2: Last Updated
A3: PROMETHEUS_URL | B3: All | C3: [********] | D3: Prometheus metrics server URL | E3: Yes | F3: String | G3: Valid HTTPS URL | H3: Confidential | I3: Operations Team | J3: Network connectivity | K3: Metrics collection | L3: [DATE]
A4: GRAFANA_URL | B4: All | C4: [********] | D4: Grafana visualization URL | E4: Yes | F4: String | G4: Valid HTTPS URL | H4: Confidential | I4: Operations Team | J4: Prometheus data | K4: Dashboards | L4: [DATE]
A5: ALERTMANAGER_URL | B5: All | C5: [********] | D5: Alertmanager notification URL | E5: Yes | F5: String | G5: Valid HTTPS URL | H5: Confidential | I5: Operations Team | J5: Alert rules | K5: PagerDuty integration | L5: [DATE]

Sheet Logging
A1: Logging Parameters
A2: Parameter Name | B2: Environment | C2: Default Value | D2: Description | E2: Required | F2: Data Type | G2: Validation Rules | H2: Security Level | I2: Owner Team | J2: Dependencies | K2: Notes | L2: Last Updated
A3: SPLUNK_HEC_URL | B3: All | C3: [********] | D3: Splunk HTTP Event Collector URL | E3: Yes | F3: String | G3: Valid HTTPS URL | H3: Confidential | I3: Security Team | J3: Network connectivity | K3: Log aggregation | L3: [DATE]
A4: SPLUNK_HEC_TOKEN | B4: All | C4: [********] | D4: Splunk HEC authentication token | E4: Yes | F4: String | G4: Valid HEC token | H4: Secret | I4: Security Team | J4: HEC input | K4: Pipeline logs | L4: [DATE]

Sheet Container
A1: Container Parameters
A2: Parameter Name | B2: Environment | C2: Default Value | D2: Description | E2: Required | F2: Data Type | G2: Validation Rules | H2: Security Level | I2: Owner Team | J2: Dependencies | K2: Notes | L2: Last Updated
A3: DOCKER_REGISTRY | B3: All | C3: [********] | D3: Private Docker registry hostname | E3: Yes | F3: String | G3: Valid hostname | H3: Confidential | I3: DevOps Team | J3: Registry deployed | K3: Harbor registry | L3: [DATE]
A4: DOCKER_NAMESPACE | B4: All | C4: cisco-automation | D4: Docker image namespace | E4: Yes | F4: String | G4: Valid namespace | H4: Public | I4: DevOps Team | J4: DOCKER_REGISTRY | K4: Organization prefix | L4: [DATE]

Sheet Kubernetes
A1: Kubernetes Parameters
A2: Parameter Name | B2: Environment | C2: Default Value | D2: Description | E2: Required | F2: Data Type | G2: Validation Rules | H2: Security Level | I2: Owner Team | J2: Dependencies | K2: Notes | L2: Last Updated
A3: K8S_CLUSTER_NAME | B3: All | C3: [********] | D3: Kubernetes cluster name | E3: Yes | F3: String | G3: Valid cluster name | H3: Confidential | I3: DevOps Team | J3: K8s deployed | K3: Runner cluster | L3: [DATE]
A4: K8S_NAMESPACE | B4: All | C4: ci-cd-automation | D4: Default Kubernetes namespace | E4: Yes | F4: String | G4: Valid namespace | H4: Public | I4: DevOps Team | J4: K8S_CLUSTER_NAME | K4: Pipeline namespace | L4: [DATE]

Sheet ITSM
A1: ITSM Parameters
A2: Parameter Name | B2: Environment | C2: Default Value | D2: Description | E2: Required | F2: Data Type | G2: Validation Rules | H2: Security Level | I2: Owner Team | J2: Dependencies | K2: Notes | L2: Last Updated
A3: SERVICENOW_URL | B3: All | C3: [********] | D3: ServiceNow instance URL | E3: Yes | F3: String | G3: Valid HTTPS URL | H3: Confidential | I3: Operations Team | J3: ServiceNow license | K3: ITSM integration | L3: [DATE]
A4: SERVICENOW_USER | B4: All | C4: [********] | D4: ServiceNow integration account | E4: Yes | F4: String | G4: Valid username | H4: Confidential | I4: Operations Team | J4: User created | K4: API access | L4: [DATE]

Sheet Pipeline
A1: Pipeline Parameters
A2: Parameter Name | B2: Environment | C2: Default Value | D2: Description | E2: Required | F2: Data Type | G2: Validation Rules | H2: Security Level | I2: Owner Team | J2: Dependencies | K2: Notes | L2: Last Updated
A3: PIPELINE_TIMEOUT | B3: All | C3: 3600 | D3: Default pipeline timeout in seconds | E3: Yes | F3: Integer | G3: 300-7200 | H3: Public | I3: DevOps Team | J3: None | K3: 1 hour default | L3: [DATE]
A4: PIPELINE_RETRY_COUNT | B4: All | C4: 3 | D4: Number of retries on failure | E4: Yes | F4: Integer | G4: 0-5 | H4: Public | I4: DevOps Team | J4: None | K4: Exponential backoff | L4: [DATE]
A5: APPROVAL_REQUIRED | B5: All | C5: true | D5: Require approval for production | E5: Yes | F5: Boolean | G5: true|false | H5: Public | I5: DevOps Team | J5: Approver groups | K5: Change control | L5: [DATE]

Sheet Alerts
A1: Notifications Parameters
A2: Parameter Name | B2: Environment | C2: Default Value | D2: Description | E2: Required | F2: Data Type | G2: Validation Rules | H2: Security Level | I2: Owner Team | J2: Dependencies | K2: Notes | L2: Last Updated
A3: NOTIFICATION_CHANNEL | B3: All | C3: [********] | D3: Slack channel for notifications | E3: Yes | F3: String | G3: Valid channel name | H3: Confidential | I3: DevOps Team | J3: Slack integration | K3: Pipeline alerts | L3: [DATE]
A4: SMTP_SERVER | B4: All | C4: [********] | D4: SMTP server for email notifications | E4: Yes | F4: String | G4: Valid hostname | H4: Confidential | I4: Operations Team | J4: Mail relay | K4: Report delivery | L4: [DATE]

Sheet Operations
A1: Operations Parameters
A2: Parameter Name | B2: Environment | C2: Default Value | D2: Description | E2: Required | F2: Data Type | G2: Validation Rules | H2: Security Level | I2: Owner Team | J2: Dependencies | K2: Notes | L2: Last Updated
A3: LOG_RETENTION_DAYS | B3: All | C3: 90 | D3: Pipeline log retention in days | E3: Yes | F3: Integer | G3: 30-365 | H3: Public | I3: Operations Team | J3: Storage capacity | K3: Compliance requirement | L3: [DATE]
A4: BACKUP_SCHEDULE | B4: All | C4: 0 2 * * * | D4: Configuration backup cron schedule | E4: Yes | F4: String | G4: Valid cron expression | H4: Public | I4: Operations Team | J4: Backup storage | K4: Daily at 2 AM | L4: [DATE]
