Workbook

Sheet Cover
B4: Discovery Questionnaire
B5: Presales Document
B7: Generated: | C7: November 15, 2025
B8: Solution: | C8: Virtual Desktop
B9: Customer Name: | C9: [Customer Name]
B10: Version: | C10: 1.0

Sheet All Categories (Read Only)
A1: Total Questions | B1: Answered | C1: Remaining | D1: % Complete
A2: 60 | B2: =SUMPRODUCT(--(LEN(F5:F64)>0)) | C2: =A2-B2 | D2: =B2/A2
A4: Question ID | B4: Category | C4: Sub-Category | D4: Question | E4: Guidance | F4: Customer Response | G4: Notes
A5: =IF('Project Information'!A2="","",'Project Information'!A2) | B5: =IF('Project Information'!B2="","",'Project Information'!B2) | C5: =IF('Project Information'!C2="","",'Project Information'!C2) | D5: =IF('Project Information'!D2="","",'Project Information'!D2) | E5: =IF('Project Information'!E2="","",'Project Information'!E2) | F5: =IF('Project Information'!F2="","",'Project Information'!F2) | G5: =IF('Project Information'!G2="","",'Project Information'!G2)
A6: =IF('Project Information'!A3="","",'Project Information'!A3) | B6: =IF('Project Information'!B3="","",'Project Information'!B3) | C6: =IF('Project Information'!C3="","",'Project Information'!C3) | D6: =IF('Project Information'!D3="","",'Project Information'!D3) | E6: =IF('Project Information'!E3="","",'Project Information'!E3) | F6: =IF('Project Information'!F3="","",'Project Information'!F3) | G6: =IF('Project Information'!G3="","",'Project Information'!G3)
A7: =IF('Project Information'!A4="","",'Project Information'!A4) | B7: =IF('Project Information'!B4="","",'Project Information'!B4) | C7: =IF('Project Information'!C4="","",'Project Information'!C4) | D7: =IF('Project Information'!D4="","",'Project Information'!D4) | E7: =IF('Project Information'!E4="","",'Project Information'!E4) | F7: =IF('Project Information'!F4="","",'Project Information'!F4) | G7: =IF('Project Information'!G4="","",'Project Information'!G4)
A8: =IF('Project Information'!A5="","",'Project Information'!A5) | B8: =IF('Project Information'!B5="","",'Project Information'!B5) | C8: =IF('Project Information'!C5="","",'Project Information'!C5) | D8: =IF('Project Information'!D5="","",'Project Information'!D5) | E8: =IF('Project Information'!E5="","",'Project Information'!E5) | F8: =IF('Project Information'!F5="","",'Project Information'!F5) | G8: =IF('Project Information'!G5="","",'Project Information'!G5)
A9: =IF('Project Information'!A6="","",'Project Information'!A6) | B9: =IF('Project Information'!B6="","",'Project Information'!B6) | C9: =IF('Project Information'!C6="","",'Project Information'!C6) | D9: =IF('Project Information'!D6="","",'Project Information'!D6) | E9: =IF('Project Information'!E6="","",'Project Information'!E6) | F9: =IF('Project Information'!F6="","",'Project Information'!F6) | G9: =IF('Project Information'!G6="","",'Project Information'!G6)
A10: =IF('Business Requirements'!A2="","",'Business Requirements'!A2) | B10: =IF('Business Requirements'!B2="","",'Business Requirements'!B2) | C10: =IF('Business Requirements'!C2="","",'Business Requirements'!C2) | D10: =IF('Business Requirements'!D2="","",'Business Requirements'!D2) | E10: =IF('Business Requirements'!E2="","",'Business Requirements'!E2) | F10: =IF('Business Requirements'!F2="","",'Business Requirements'!F2) | G10: =IF('Business Requirements'!G2="","",'Business Requirements'!G2)
A11: =IF('Business Requirements'!A3="","",'Business Requirements'!A3) | B11: =IF('Business Requirements'!B3="","",'Business Requirements'!B3) | C11: =IF('Business Requirements'!C3="","",'Business Requirements'!C3) | D11: =IF('Business Requirements'!D3="","",'Business Requirements'!D3) | E11: =IF('Business Requirements'!E3="","",'Business Requirements'!E3) | F11: =IF('Business Requirements'!F3="","",'Business Requirements'!F3) | G11: =IF('Business Requirements'!G3="","",'Business Requirements'!G3)
A12: =IF('Business Requirements'!A4="","",'Business Requirements'!A4) | B12: =IF('Business Requirements'!B4="","",'Business Requirements'!B4) | C12: =IF('Business Requirements'!C4="","",'Business Requirements'!C4) | D12: =IF('Business Requirements'!D4="","",'Business Requirements'!D4) | E12: =IF('Business Requirements'!E4="","",'Business Requirements'!E4) | F12: =IF('Business Requirements'!F4="","",'Business Requirements'!F4) | G12: =IF('Business Requirements'!G4="","",'Business Requirements'!G4)
A13: =IF('Business Requirements'!A5="","",'Business Requirements'!A5) | B13: =IF('Business Requirements'!B5="","",'Business Requirements'!B5) | C13: =IF('Business Requirements'!C5="","",'Business Requirements'!C5) | D13: =IF('Business Requirements'!D5="","",'Business Requirements'!D5) | E13: =IF('Business Requirements'!E5="","",'Business Requirements'!E5) | F13: =IF('Business Requirements'!F5="","",'Business Requirements'!F5) | G13: =IF('Business Requirements'!G5="","",'Business Requirements'!G5)
A14: =IF('Business Requirements'!A6="","",'Business Requirements'!A6) | B14: =IF('Business Requirements'!B6="","",'Business Requirements'!B6) | C14: =IF('Business Requirements'!C6="","",'Business Requirements'!C6) | D14: =IF('Business Requirements'!D6="","",'Business Requirements'!D6) | E14: =IF('Business Requirements'!E6="","",'Business Requirements'!E6) | F14: =IF('Business Requirements'!F6="","",'Business Requirements'!F6) | G14: =IF('Business Requirements'!G6="","",'Business Requirements'!G6)
A15: =IF('Business Requirements'!A7="","",'Business Requirements'!A7) | B15: =IF('Business Requirements'!B7="","",'Business Requirements'!B7) | C15: =IF('Business Requirements'!C7="","",'Business Requirements'!C7) | D15: =IF('Business Requirements'!D7="","",'Business Requirements'!D7) | E15: =IF('Business Requirements'!E7="","",'Business Requirements'!E7) | F15: =IF('Business Requirements'!F7="","",'Business Requirements'!F7) | G15: =IF('Business Requirements'!G7="","",'Business Requirements'!G7)
A16: =IF('Business Requirements'!A8="","",'Business Requirements'!A8) | B16: =IF('Business Requirements'!B8="","",'Business Requirements'!B8) | C16: =IF('Business Requirements'!C8="","",'Business Requirements'!C8) | D16: =IF('Business Requirements'!D8="","",'Business Requirements'!D8) | E16: =IF('Business Requirements'!E8="","",'Business Requirements'!E8) | F16: =IF('Business Requirements'!F8="","",'Business Requirements'!F8) | G16: =IF('Business Requirements'!G8="","",'Business Requirements'!G8)
A17: =IF('Business Requirements'!A9="","",'Business Requirements'!A9) | B17: =IF('Business Requirements'!B9="","",'Business Requirements'!B9) | C17: =IF('Business Requirements'!C9="","",'Business Requirements'!C9) | D17: =IF('Business Requirements'!D9="","",'Business Requirements'!D9) | E17: =IF('Business Requirements'!E9="","",'Business Requirements'!E9) | F17: =IF('Business Requirements'!F9="","",'Business Requirements'!F9) | G17: =IF('Business Requirements'!G9="","",'Business Requirements'!G9)
A18: =IF('Business Requirements'!A10="","",'Business Requirements'!A10) | B18: =IF('Business Requirements'!B10="","",'Business Requirements'!B10) | C18: =IF('Business Requirements'!C10="","",'Business Requirements'!C10) | D18: =IF('Business Requirements'!D10="","",'Business Requirements'!D10) | E18: =IF('Business Requirements'!E10="","",'Business Requirements'!E10) | F18: =IF('Business Requirements'!F10="","",'Business Requirements'!F10) | G18: =IF('Business Requirements'!G10="","",'Business Requirements'!G10)
A19: =IF('Business Requirements'!A11="","",'Business Requirements'!A11) | B19: =IF('Business Requirements'!B11="","",'Business Requirements'!B11) | C19: =IF('Business Requirements'!C11="","",'Business Requirements'!C11) | D19: =IF('Business Requirements'!D11="","",'Business Requirements'!D11) | E19: =IF('Business Requirements'!E11="","",'Business Requirements'!E11) | F19: =IF('Business Requirements'!F11="","",'Business Requirements'!F11) | G19: =IF('Business Requirements'!G11="","",'Business Requirements'!G11)
A20: =IF('User Requirements'!A2="","",'User Requirements'!A2) | B20: =IF('User Requirements'!B2="","",'User Requirements'!B2) | C20: =IF('User Requirements'!C2="","",'User Requirements'!C2) | D20: =IF('User Requirements'!D2="","",'User Requirements'!D2) | E20: =IF('User Requirements'!E2="","",'User Requirements'!E2) | F20: =IF('User Requirements'!F2="","",'User Requirements'!F2) | G20: =IF('User Requirements'!G2="","",'User Requirements'!G2)
A21: =IF('User Requirements'!A3="","",'User Requirements'!A3) | B21: =IF('User Requirements'!B3="","",'User Requirements'!B3) | C21: =IF('User Requirements'!C3="","",'User Requirements'!C3) | D21: =IF('User Requirements'!D3="","",'User Requirements'!D3) | E21: =IF('User Requirements'!E3="","",'User Requirements'!E3) | F21: =IF('User Requirements'!F3="","",'User Requirements'!F3) | G21: =IF('User Requirements'!G3="","",'User Requirements'!G3)
A22: =IF('User Requirements'!A4="","",'User Requirements'!A4) | B22: =IF('User Requirements'!B4="","",'User Requirements'!B4) | C22: =IF('User Requirements'!C4="","",'User Requirements'!C4) | D22: =IF('User Requirements'!D4="","",'User Requirements'!D4) | E22: =IF('User Requirements'!E4="","",'User Requirements'!E4) | F22: =IF('User Requirements'!F4="","",'User Requirements'!F4) | G22: =IF('User Requirements'!G4="","",'User Requirements'!G4)
A23: =IF('User Requirements'!A5="","",'User Requirements'!A5) | B23: =IF('User Requirements'!B5="","",'User Requirements'!B5) | C23: =IF('User Requirements'!C5="","",'User Requirements'!C5) | D23: =IF('User Requirements'!D5="","",'User Requirements'!D5) | E23: =IF('User Requirements'!E5="","",'User Requirements'!E5) | F23: =IF('User Requirements'!F5="","",'User Requirements'!F5) | G23: =IF('User Requirements'!G5="","",'User Requirements'!G5)
A24: =IF('User Requirements'!A6="","",'User Requirements'!A6) | B24: =IF('User Requirements'!B6="","",'User Requirements'!B6) | C24: =IF('User Requirements'!C6="","",'User Requirements'!C6) | D24: =IF('User Requirements'!D6="","",'User Requirements'!D6) | E24: =IF('User Requirements'!E6="","",'User Requirements'!E6) | F24: =IF('User Requirements'!F6="","",'User Requirements'!F6) | G24: =IF('User Requirements'!G6="","",'User Requirements'!G6)
A25: =IF('Application Requirements'!A2="","",'Application Requirements'!A2) | B25: =IF('Application Requirements'!B2="","",'Application Requirements'!B2) | C25: =IF('Application Requirements'!C2="","",'Application Requirements'!C2) | D25: =IF('Application Requirements'!D2="","",'Application Requirements'!D2) | E25: =IF('Application Requirements'!E2="","",'Application Requirements'!E2) | F25: =IF('Application Requirements'!F2="","",'Application Requirements'!F2) | G25: =IF('Application Requirements'!G2="","",'Application Requirements'!G2)
A26: =IF('Application Requirements'!A3="","",'Application Requirements'!A3) | B26: =IF('Application Requirements'!B3="","",'Application Requirements'!B3) | C26: =IF('Application Requirements'!C3="","",'Application Requirements'!C3) | D26: =IF('Application Requirements'!D3="","",'Application Requirements'!D3) | E26: =IF('Application Requirements'!E3="","",'Application Requirements'!E3) | F26: =IF('Application Requirements'!F3="","",'Application Requirements'!F3) | G26: =IF('Application Requirements'!G3="","",'Application Requirements'!G3)
A27: =IF('Application Requirements'!A4="","",'Application Requirements'!A4) | B27: =IF('Application Requirements'!B4="","",'Application Requirements'!B4) | C27: =IF('Application Requirements'!C4="","",'Application Requirements'!C4) | D27: =IF('Application Requirements'!D4="","",'Application Requirements'!D4) | E27: =IF('Application Requirements'!E4="","",'Application Requirements'!E4) | F27: =IF('Application Requirements'!F4="","",'Application Requirements'!F4) | G27: =IF('Application Requirements'!G4="","",'Application Requirements'!G4)
A28: =IF('Application Requirements'!A5="","",'Application Requirements'!A5) | B28: =IF('Application Requirements'!B5="","",'Application Requirements'!B5) | C28: =IF('Application Requirements'!C5="","",'Application Requirements'!C5) | D28: =IF('Application Requirements'!D5="","",'Application Requirements'!D5) | E28: =IF('Application Requirements'!E5="","",'Application Requirements'!E5) | F28: =IF('Application Requirements'!F5="","",'Application Requirements'!F5) | G28: =IF('Application Requirements'!G5="","",'Application Requirements'!G5)
A29: =IF('Application Requirements'!A6="","",'Application Requirements'!A6) | B29: =IF('Application Requirements'!B6="","",'Application Requirements'!B6) | C29: =IF('Application Requirements'!C6="","",'Application Requirements'!C6) | D29: =IF('Application Requirements'!D6="","",'Application Requirements'!D6) | E29: =IF('Application Requirements'!E6="","",'Application Requirements'!E6) | F29: =IF('Application Requirements'!F6="","",'Application Requirements'!F6) | G29: =IF('Application Requirements'!G6="","",'Application Requirements'!G6)
A30: =IF('Infrastructure Requirements'!A2="","",'Infrastructure Requirements'!A2) | B30: =IF('Infrastructure Requirements'!B2="","",'Infrastructure Requirements'!B2) | C30: =IF('Infrastructure Requirements'!C2="","",'Infrastructure Requirements'!C2) | D30: =IF('Infrastructure Requirements'!D2="","",'Infrastructure Requirements'!D2) | E30: =IF('Infrastructure Requirements'!E2="","",'Infrastructure Requirements'!E2) | F30: =IF('Infrastructure Requirements'!F2="","",'Infrastructure Requirements'!F2) | G30: =IF('Infrastructure Requirements'!G2="","",'Infrastructure Requirements'!G2)
A31: =IF('Infrastructure Requirements'!A3="","",'Infrastructure Requirements'!A3) | B31: =IF('Infrastructure Requirements'!B3="","",'Infrastructure Requirements'!B3) | C31: =IF('Infrastructure Requirements'!C3="","",'Infrastructure Requirements'!C3) | D31: =IF('Infrastructure Requirements'!D3="","",'Infrastructure Requirements'!D3) | E31: =IF('Infrastructure Requirements'!E3="","",'Infrastructure Requirements'!E3) | F31: =IF('Infrastructure Requirements'!F3="","",'Infrastructure Requirements'!F3) | G31: =IF('Infrastructure Requirements'!G3="","",'Infrastructure Requirements'!G3)
A32: =IF('Infrastructure Requirements'!A4="","",'Infrastructure Requirements'!A4) | B32: =IF('Infrastructure Requirements'!B4="","",'Infrastructure Requirements'!B4) | C32: =IF('Infrastructure Requirements'!C4="","",'Infrastructure Requirements'!C4) | D32: =IF('Infrastructure Requirements'!D4="","",'Infrastructure Requirements'!D4) | E32: =IF('Infrastructure Requirements'!E4="","",'Infrastructure Requirements'!E4) | F32: =IF('Infrastructure Requirements'!F4="","",'Infrastructure Requirements'!F4) | G32: =IF('Infrastructure Requirements'!G4="","",'Infrastructure Requirements'!G4)
A33: =IF('Infrastructure Requirements'!A5="","",'Infrastructure Requirements'!A5) | B33: =IF('Infrastructure Requirements'!B5="","",'Infrastructure Requirements'!B5) | C33: =IF('Infrastructure Requirements'!C5="","",'Infrastructure Requirements'!C5) | D33: =IF('Infrastructure Requirements'!D5="","",'Infrastructure Requirements'!D5) | E33: =IF('Infrastructure Requirements'!E5="","",'Infrastructure Requirements'!E5) | F33: =IF('Infrastructure Requirements'!F5="","",'Infrastructure Requirements'!F5) | G33: =IF('Infrastructure Requirements'!G5="","",'Infrastructure Requirements'!G5)
A34: =IF('Infrastructure Requirements'!A6="","",'Infrastructure Requirements'!A6) | B34: =IF('Infrastructure Requirements'!B6="","",'Infrastructure Requirements'!B6) | C34: =IF('Infrastructure Requirements'!C6="","",'Infrastructure Requirements'!C6) | D34: =IF('Infrastructure Requirements'!D6="","",'Infrastructure Requirements'!D6) | E34: =IF('Infrastructure Requirements'!E6="","",'Infrastructure Requirements'!E6) | F34: =IF('Infrastructure Requirements'!F6="","",'Infrastructure Requirements'!F6) | G34: =IF('Infrastructure Requirements'!G6="","",'Infrastructure Requirements'!G6)
A35: =IF('Infrastructure Requirements'!A7="","",'Infrastructure Requirements'!A7) | B35: =IF('Infrastructure Requirements'!B7="","",'Infrastructure Requirements'!B7) | C35: =IF('Infrastructure Requirements'!C7="","",'Infrastructure Requirements'!C7) | D35: =IF('Infrastructure Requirements'!D7="","",'Infrastructure Requirements'!D7) | E35: =IF('Infrastructure Requirements'!E7="","",'Infrastructure Requirements'!E7) | F35: =IF('Infrastructure Requirements'!F7="","",'Infrastructure Requirements'!F7) | G35: =IF('Infrastructure Requirements'!G7="","",'Infrastructure Requirements'!G7)
A36: =IF('Security Requirements'!A2="","",'Security Requirements'!A2) | B36: =IF('Security Requirements'!B2="","",'Security Requirements'!B2) | C36: =IF('Security Requirements'!C2="","",'Security Requirements'!C2) | D36: =IF('Security Requirements'!D2="","",'Security Requirements'!D2) | E36: =IF('Security Requirements'!E2="","",'Security Requirements'!E2) | F36: =IF('Security Requirements'!F2="","",'Security Requirements'!F2) | G36: =IF('Security Requirements'!G2="","",'Security Requirements'!G2)
A37: =IF('Security Requirements'!A3="","",'Security Requirements'!A3) | B37: =IF('Security Requirements'!B3="","",'Security Requirements'!B3) | C37: =IF('Security Requirements'!C3="","",'Security Requirements'!C3) | D37: =IF('Security Requirements'!D3="","",'Security Requirements'!D3) | E37: =IF('Security Requirements'!E3="","",'Security Requirements'!E3) | F37: =IF('Security Requirements'!F3="","",'Security Requirements'!F3) | G37: =IF('Security Requirements'!G3="","",'Security Requirements'!G3)
A38: =IF('Security Requirements'!A4="","",'Security Requirements'!A4) | B38: =IF('Security Requirements'!B4="","",'Security Requirements'!B4) | C38: =IF('Security Requirements'!C4="","",'Security Requirements'!C4) | D38: =IF('Security Requirements'!D4="","",'Security Requirements'!D4) | E38: =IF('Security Requirements'!E4="","",'Security Requirements'!E4) | F38: =IF('Security Requirements'!F4="","",'Security Requirements'!F4) | G38: =IF('Security Requirements'!G4="","",'Security Requirements'!G4)
A39: =IF('Security Requirements'!A5="","",'Security Requirements'!A5) | B39: =IF('Security Requirements'!B5="","",'Security Requirements'!B5) | C39: =IF('Security Requirements'!C5="","",'Security Requirements'!C5) | D39: =IF('Security Requirements'!D5="","",'Security Requirements'!D5) | E39: =IF('Security Requirements'!E5="","",'Security Requirements'!E5) | F39: =IF('Security Requirements'!F5="","",'Security Requirements'!F5) | G39: =IF('Security Requirements'!G5="","",'Security Requirements'!G5)
A40: =IF('Security Requirements'!A6="","",'Security Requirements'!A6) | B40: =IF('Security Requirements'!B6="","",'Security Requirements'!B6) | C40: =IF('Security Requirements'!C6="","",'Security Requirements'!C6) | D40: =IF('Security Requirements'!D6="","",'Security Requirements'!D6) | E40: =IF('Security Requirements'!E6="","",'Security Requirements'!E6) | F40: =IF('Security Requirements'!F6="","",'Security Requirements'!F6) | G40: =IF('Security Requirements'!G6="","",'Security Requirements'!G6)
A41: =IF('Architecture'!A2="","",'Architecture'!A2) | B41: =IF('Architecture'!B2="","",'Architecture'!B2) | C41: =IF('Architecture'!C2="","",'Architecture'!C2) | D41: =IF('Architecture'!D2="","",'Architecture'!D2) | E41: =IF('Architecture'!E2="","",'Architecture'!E2) | F41: =IF('Architecture'!F2="","",'Architecture'!F2) | G41: =IF('Architecture'!G2="","",'Architecture'!G2)
...

Sheet Project Information
A1: Question ID | B1: Category | C1: Sub-Category | D1: Question | E1: Guidance | F1: Customer Response | G1: Notes
A2: PROJ-001 | B2: Project Information | C2: Basic Details | D2: What is the name of your Azure Virtual Desktop solution? | G2: Internal project reference
A3: PROJ-002 | B3: Project Information | C3: Basic Details | D3: What is your company name? | G3: Client identification
A4: PROJ-003 | B4: Project Information | C4: Basic Details | D4: Who is the primary stakeholder for this AVD project? | G4: Main point of contact
A5: PROJ-004 | B5: Project Information | C5: Basic Details | D5: What is the stakeholder's role and decision-making authority? | G5: Decision-making authority
A6: PROJ-005 | B6: Project Information | C6: Basic Details | D6: What is today's date? | G6: Questionnaire completion date

Sheet Business Requirements
A1: Question ID | B1: Category | C1: Sub-Category | D1: Question | E1: Guidance | F1: Customer Response | G1: Notes
A2: BUS-001 | B2: Business Requirements | C2: Current State | D2: What are your primary drivers for implementing Azure Virtual Desktop? | E2: Common drivers: Hybrid workforce support, Desktop modernization, Cost optimization, Enhanced security, BYOD enablement, Disaster recovery | G2: Primary business driver for AVD
A3: BUS-002 | B3: Business Requirements | C3: Current State | D3: What is your current desktop and application delivery model? | G3: Current state assessment
A4: BUS-003 | B4: Business Requirements | C4: Current State | D4: What user profiles do you need to support? | E4: Common types: Office workers, Knowledge workers, Call center agents, Medical professionals, Developers, Executive users, Contractors | G4: User classification
A5: BUS-004 | B5: Business Requirements | C5: Current State | D5: How many users need to be migrated to AVD? | E5: Typical ranges: 50-100, 100-500, 500-1000, 1000+ | G5: User count and scale
A6: BUS-005 | B6: Business Requirements | C6: Current State | D6: What applications and workloads must run on AVD? | E6: Common applications: Microsoft 365, Line-of-business apps, Industry-specific software, Web applications, Development tools | G6: Application portfolio
A7: BUS-006 | B7: Business Requirements | C7: Objectives | D7: What are your primary goals for implementing AVD? | E7: Common goals: Enable hybrid workforce, Reduce IT costs, Improve security posture, Modernize infrastructure, Simplify management, Enable remote access | G7: Business objectives
A8: BUS-007 | B8: Business Requirements | C8: Objectives | D8: What specific security and compliance requirements must AVD meet? | G8: Security and regulatory requirements
A9: BUS-008 | B9: Business Requirements | C9: Timeline | D9: What is your expected timeline for AVD implementation? | E9: Typical ranges: 0-3 months, 3-6 months, 6-12 months, 12+ months | G9: Project timeline expectations
A10: BUS-009 | B10: Business Requirements | C10: Budget | D10: What is your approved budget range for this AVD solution? | E10: Common ranges: $100K-300K, $300K-750K, $750K-2M, $2M+ | G10: Budget constraints
A11: BUS-010 | B11: Business Requirements | C11: Success Metrics | D11: How will you measure AVD success? (user adoption remote access quality cost reduction) | G11: KPI definition

Sheet User Requirements
A1: Question ID | B1: Category | C1: Sub-Category | D1: Question | E1: Guidance | F1: Customer Response | G1: Notes
A2: USER-001 | B2: User Requirements | C2: Profiles | D2: What user groups will be using AVD? | E2: User groups: Corporate workforce, Remote workers, Branch office users, Third-party contractors, Mobile users | G2: User segmentation
A3: USER-002 | B3: User Requirements | C3: Profiles | D3: What are the performance requirements for each user group? | E3: Performance needs: Basic (email and web), Standard (Office and LOB apps), High-performance (graphics rendering), Real-time (trading or design) | G3: Performance expectations
A4: USER-003 | B4: User Requirements | C4: Device Access | D4: What devices will users use to access AVD? | E4: Device types: Windows PCs, Mac computers, iOS devices, Android devices, Chromebooks, Thin clients, Browser-only | G4: Client device diversity
A5: USER-004 | B5: User Requirements | C5: Bandwidth | D5: What is the typical user bandwidth availability? | E5: Bandwidth availability: High speed (corporate LAN), Good (home broadband 100+ Mbps), Limited (4G/5G mobile), Variable (branch offices) | G5: Network capacity
A6: USER-005 | B6: User Requirements | C6: Printing | D6: What printing and peripheral requirements must AVD support? | E6: Printing needs: No printing required, Local printers only, Network printers, Specialized printing, Peripheral redirection | G6: Printing and device redirection

Sheet Application Requirements
A1: Question ID | B1: Category | C1: Sub-Category | D1: Question | E1: Guidance | F1: Customer Response | G1: Notes
A2: APP-001 | B2: Application Requirements | C2: Portfolio | D2: What is your total application portfolio size? | E2: Application count: 20-50 apps, 50-100 apps, 100-250 apps, 250+ apps | G2: Scope of application support
A3: APP-002 | B3: Application Requirements | C3: Compatibility | D3: What percentage of applications are natively compatible with multi-session OS? | E3: Compatibility levels: 90%+, 70-90%, 50-70%, Less than 50% | G3: Application modernization assessment
A4: APP-003 | B4: Application Requirements | C4: Critical Apps | D4: What are your mission-critical applications that must run on AVD? | G4: Critical application identification
A5: APP-004 | B5: Application Requirements | C5: Dependencies | D5: Do you have complex application dependencies or integration needs? | E5: Complexity: Simple standalone apps, Dependent applications, Complex LOB systems, Legacy mainframe integration | G5: Integration complexity
A6: APP-005 | B6: Application Requirements | C6: Deployment | D6: How do you currently deploy and manage applications? | E6: Deployment methods: Manual installation, SCCM/Intune, Image-based, Cloud-native, Mix of methods | G6: Application delivery method

Sheet Infrastructure Requirements
A1: Question ID | B1: Category | C1: Sub-Category | D1: Question | E1: Guidance | F1: Customer Response | G1: Notes
A2: INFRA-001 | B2: Infrastructure Requirements | C2: Network | D2: What is your current network architecture? | G2: Network topology
A3: INFRA-002 | B3: Infrastructure Requirements | C3: Network | D3: What network connectivity exists between locations? | E3: Connectivity: All sites on same LAN, Connected via VPN, Hybrid cloud connected, Multiple regions | G3: Network connectivity
A4: INFRA-003 | B4: Infrastructure Requirements | C4: Azure Environment | D4: What Azure services are you currently using? | E4: Azure services: Nothing, Azure AD only, Compute services, Multiple services, Enterprise-scale | G4: Current Azure footprint
A5: INFRA-004 | B5: Infrastructure Requirements | C5: Azure Environment | D5: What Azure regions would you prefer for AVD deployment? | G5: Data residency requirements
A6: INFRA-005 | B6: Infrastructure Requirements | C6: Hybrid Cloud | D6: Do you need to integrate with on-premises infrastructure? | E6: Integration: Cloud-only, Minimal on-premises connectivity, Hybrid connectivity required, Strong on-premises tie-in | G6: Hybrid connectivity needs
A7: INFRA-006 | B7: Infrastructure Requirements | C7: Infrastructure | D7: What current desktop infrastructure (physical or virtual) will be replaced? | E7: Infrastructure: Physical desktops, VDI environment, Hybrid setup, Multiple legacy systems | G7: Infrastructure replacement scope

Sheet Security Requirements
A1: Question ID | B1: Category | C1: Sub-Category | D1: Question | E1: Guidance | F1: Customer Response | G1: Notes
A2: SEC-001 | B2: Security Requirements | C2: Authentication | D2: What authentication methods must AVD support? | E2: Authentication methods: Password only, Multi-factor authentication, Windows Hello, FIDO2, Smart cards, Single Sign-On | G2: Authentication requirements
A3: SEC-002 | B3: Security Requirements | C3: Access Control | D3: What conditional access policies must be enforced? | E3: Access policies: Location-based, Device compliance-based, Risk-based, Time-based, Application-specific | G3: Access control complexity
A4: SEC-003 | B4: Security Requirements | C4: Data Protection | D4: What data classification and protection must be applied? | E4: Data classification: Public only, Internal data, Confidential data, Highly sensitive (PII/PHI), Regulated data | G4: Data sensitivity
A5: SEC-004 | B5: Security Requirements | C5: Encryption | D5: What encryption standards must be applied? | E5: Encryption needs: Standard encryption, Enhanced encryption, FIPS 140-2, HIPAA compliance, PCI-DSS compliance | G5: Encryption requirements
A6: SEC-005 | B6: Security Requirements | C6: Logging | D6: What audit logging and compliance requirements apply? | E6: Logging needs: Basic activity logs, Detailed audit logs, Real-time threat detection, 24/7 monitoring, Regulatory compliance reporting | G6: Logging and compliance

Sheet Architecture
A1: Question ID | B1: Category | C1: Sub-Category | D1: Question | E1: Guidance | F1: Customer Response | G1: Notes
A2: ARCH-001 | B2: Architecture | C2: Session Hosts | D2: What VM SKU and sizing requirements do you have? | E2: VM sizes: D2s, D4s (4vCPU 16GB), D8s (8vCPU 32GB), High-memory (Ev5 series), GPU-enabled (NV series) | G2: VM sizing requirements
A3: ARCH-002 | B3: Architecture | C3: Session Hosts | D3: What is your preferred deployment model for session hosts? | E3: Deployment: Shared multi-session (D4s), Personal dedicated (D2s-D4s), Pooled with auto-scaling, Fixed session count | G3: Session host strategy
A4: ARCH-003 | B4: Architecture | C4: Scaling | D4: What are your peak and average concurrent user requirements? | E4: User scenarios: 25 peak concurrent, 50-100 peak, 100-500 peak, 500+ peak simultaneous users | G4: Scaling requirements
A5: ARCH-004 | B5: Architecture | C5: Profile Management | D5: What profile and data persistence strategy do you need? | E5: Strategy: Stateless (no persistent profiles), FSLogix containers, User profiles on network storage, Hybrid approach | G5: Profile management approach
A6: ARCH-005 | B6: Architecture | C6: Disaster Recovery | D6: What disaster recovery and business continuity requirements exist? | E6: DR needs: No specific requirements, RPO 24 hours, RPO < 4 hours, Near real-time replication | G6: DR/BC requirements

Sheet Management
A1: Question ID | B1: Category | C1: Sub-Category | D1: Question | E1: Guidance | F1: Customer Response | G1: Notes
A2: MGT-001 | B2: Management | C2: Monitoring | D2: What monitoring and alerting capabilities do you require? | E2: Monitoring: Basic availability, Performance metrics, User experience metrics, Proactive anomaly detection | G2: Monitoring requirements
A3: MGT-002 | B3: Management | C3: Support | D3: What operational support model do you prefer? | E3: Support models: Self-service, 24/5 support, 24/7 support, Dedicated support team | G3: Support model preference
A4: MGT-003 | B4: Management | C4: Licensing | D4: Do you have existing Microsoft licensing agreements? | E4: Licensing: Volume license agreement, Enterprise agreement, No Microsoft licensing, Mixed licensing | G4: Licensing situation
A5: MGT-004 | B5: Management | C5: Training | D5: What training and change management support do you need? | E5: Training needs: Online self-service, Instructor-led training, Ongoing coaching, Change management support | G5: Training requirements

Sheet Organizational
A1: Question ID | B1: Category | C1: Sub-Category | D1: Question | E1: Guidance | F1: Customer Response | G1: Notes
A2: ORG-001 | B2: Organizational | C2: Resources | D2: Who will be the technical lead for this AVD project? | G2: Technical ownership
A3: ORG-002 | B3: Organizational | C3: Resources | D3: What internal resources are available for AVD implementation? | G3: Team availability
A4: ORG-003 | B4: Organizational | C4: Resources | D4: What is your team's experience with Azure and AVD? | E4: Experience levels: No experience, Basic knowledge, Intermediate, Advanced, Expert | G4: Training needs assessment
A5: ORG-004 | B5: Organizational | C5: Change Management | D5: How will you handle the transition from existing desktops to AVD? | G5: Change management approach
A6: ORG-005 | B6: Organizational | C6: Change Management | D6: What change management and user communication plan exists? | G6: Stakeholder management
A7: ORG-006 | B7: Organizational | C7: Governance | D7: What approval processes are required for infrastructure changes? | G7: Change approval process

Sheet Risk Assessment
A1: Question ID | B1: Category | C1: Sub-Category | D1: Question | E1: Guidance | F1: Customer Response | G1: Notes
A2: RISK-001 | B2: Risk Assessment | C2: Implementation | D2: What are your main concerns about implementing AVD? | G2: Primary implementation concerns
A3: RISK-002 | B3: Risk Assessment | C3: Implementation | D3: What could cause this AVD project to fail? | G3: Failure mode analysis
A4: RISK-003 | B4: Risk Assessment | C4: User Experience | D4: What concerns do you have about user experience and performance? | G4: UX/performance risks
A5: RISK-004 | B5: Risk Assessment | C5: Migration | D5: What migration risks worry you most? | G5: Migration risk factors

Sheet Future State
A1: Question ID | B1: Category | C1: Sub-Category | D1: Question | E1: Guidance | F1: Customer Response | G1: Notes
A2: FUTURE-001 | B2: Future State | C2: Vision | D2: What is your long-term vision for virtual desktops? | G2: Future roadmap
A3: FUTURE-002 | B3: Future State | C3: Growth | D3: How do you expect user base and application needs to evolve? | G3: Scalability planning
A4: FUTURE-003 | B4: Future State | C4: Expansion | D4: What future geographies or user groups might need AVD? | G4: Future expansion needs

Sheet Vendor Selection
A1: Question ID | B1: Category | C1: Sub-Category | D1: Question | E1: Guidance | F1: Customer Response | G1: Notes
A2: VENDOR-001 | B2: Vendor Selection | C2: Experience | D2: What AVD and Azure implementation experience do you expect from partners? | G2: Partner requirements
A3: VENDOR-002 | B3: Vendor Selection | C3: Support | D3: What ongoing support do you expect for the AVD solution? | G3: Support expectations
