Workbook

Sheet Cover
B3: Configuration Parameters
B5: Generated: | C5: December 03, 2025
B6: Solution: | C6: Sentinel Siem
B7: Customer: | C7: [Customer Name]
B8: Version: | C8: 1.0
B9: Status: | C9: Draft
C12: eoframework.org

Sheet All Parameters (Read Only)
A1: Total Parameters | B1: Categories | C1: Required | D1: Confidential/Secret
A2: 43 | B2: 8 | C2: 43 | D2: 5
A4: Parameter Name | B4: Category | C4: Production | D4: Test | E4: DR | F4: Description | G4: Required | H4: Data Type | I4: Validation Rules | J4: Security Level
A5: =IF('Project'!A3="","",'Project'!A3) | B5: Project | C5: =IF('Project'!B3="","",'Project'!B3) | D5: =IF('Project'!C3="","",'Project'!C3) | E5: =IF('Project'!D3="","",'Project'!D3) | F5: =IF('Project'!E3="","",'Project'!E3) | G5: =IF('Project'!F3="","",'Project'!F3) | H5: =IF('Project'!G3="","",'Project'!G3) | I5: =IF('Project'!H3="","",'Project'!H3) | J5: =IF('Project'!I3="","",'Project'!I3)
A6: =IF('Project'!A4="","",'Project'!A4) | B6: Project | C6: =IF('Project'!B4="","",'Project'!B4) | D6: =IF('Project'!C4="","",'Project'!C4) | E6: =IF('Project'!D4="","",'Project'!D4) | F6: =IF('Project'!E4="","",'Project'!E4) | G6: =IF('Project'!F4="","",'Project'!F4) | H6: =IF('Project'!G4="","",'Project'!G4) | I6: =IF('Project'!H4="","",'Project'!H4) | J6: =IF('Project'!I4="","",'Project'!I4)
A7: =IF('Project'!A5="","",'Project'!A5) | B7: Project | C7: =IF('Project'!B5="","",'Project'!B5) | D7: =IF('Project'!C5="","",'Project'!C5) | E7: =IF('Project'!D5="","",'Project'!D5) | F7: =IF('Project'!E5="","",'Project'!E5) | G7: =IF('Project'!F5="","",'Project'!F5) | H7: =IF('Project'!G5="","",'Project'!G5) | I7: =IF('Project'!H5="","",'Project'!H5) | J7: =IF('Project'!I5="","",'Project'!I5)
A8: =IF('Project'!A6="","",'Project'!A6) | B8: Project | C8: =IF('Project'!B6="","",'Project'!B6) | D8: =IF('Project'!C6="","",'Project'!C6) | E8: =IF('Project'!D6="","",'Project'!D6) | F8: =IF('Project'!E6="","",'Project'!E6) | G8: =IF('Project'!F6="","",'Project'!F6) | H8: =IF('Project'!G6="","",'Project'!G6) | I8: =IF('Project'!H6="","",'Project'!H6) | J8: =IF('Project'!I6="","",'Project'!I6)
A9: =IF('Project'!A7="","",'Project'!A7) | B9: Project | C9: =IF('Project'!B7="","",'Project'!B7) | D9: =IF('Project'!C7="","",'Project'!C7) | E9: =IF('Project'!D7="","",'Project'!D7) | F9: =IF('Project'!E7="","",'Project'!E7) | G9: =IF('Project'!F7="","",'Project'!F7) | H9: =IF('Project'!G7="","",'Project'!G7) | I9: =IF('Project'!H7="","",'Project'!H7) | J9: =IF('Project'!I7="","",'Project'!I7)
A10: =IF('Project'!A8="","",'Project'!A8) | B10: Project | C10: =IF('Project'!B8="","",'Project'!B8) | D10: =IF('Project'!C8="","",'Project'!C8) | E10: =IF('Project'!D8="","",'Project'!D8) | F10: =IF('Project'!E8="","",'Project'!E8) | G10: =IF('Project'!F8="","",'Project'!F8) | H10: =IF('Project'!G8="","",'Project'!G8) | I10: =IF('Project'!H8="","",'Project'!H8) | J10: =IF('Project'!I8="","",'Project'!I8)
A11: =IF('Project'!A9="","",'Project'!A9) | B11: Project | C11: =IF('Project'!B9="","",'Project'!B9) | D11: =IF('Project'!C9="","",'Project'!C9) | E11: =IF('Project'!D9="","",'Project'!D9) | F11: =IF('Project'!E9="","",'Project'!E9) | G11: =IF('Project'!F9="","",'Project'!F9) | H11: =IF('Project'!G9="","",'Project'!G9) | I11: =IF('Project'!H9="","",'Project'!H9) | J11: =IF('Project'!I9="","",'Project'!I9)
A12: =IF('Project'!A10="","",'Project'!A10) | B12: Project | C12: =IF('Project'!B10="","",'Project'!B10) | D12: =IF('Project'!C10="","",'Project'!C10) | E12: =IF('Project'!D10="","",'Project'!D10) | F12: =IF('Project'!E10="","",'Project'!E10) | G12: =IF('Project'!F10="","",'Project'!F10) | H12: =IF('Project'!G10="","",'Project'!G10) | I12: =IF('Project'!H10="","",'Project'!H10) | J12: =IF('Project'!I10="","",'Project'!I10)
A13: =IF('Project'!A11="","",'Project'!A11) | B13: Project | C13: =IF('Project'!B11="","",'Project'!B11) | D13: =IF('Project'!C11="","",'Project'!C11) | E13: =IF('Project'!D11="","",'Project'!D11) | F13: =IF('Project'!E11="","",'Project'!E11) | G13: =IF('Project'!F11="","",'Project'!F11) | H13: =IF('Project'!G11="","",'Project'!G11) | I13: =IF('Project'!H11="","",'Project'!H11) | J13: =IF('Project'!I11="","",'Project'!I11)
A14: =IF('Project'!A12="","",'Project'!A12) | B14: Project | C14: =IF('Project'!B12="","",'Project'!B12) | D14: =IF('Project'!C12="","",'Project'!C12) | E14: =IF('Project'!D12="","",'Project'!D12) | F14: =IF('Project'!E12="","",'Project'!E12) | G14: =IF('Project'!F12="","",'Project'!F12) | H14: =IF('Project'!G12="","",'Project'!G12) | I14: =IF('Project'!H12="","",'Project'!H12) | J14: =IF('Project'!I12="","",'Project'!I12)
A15: =IF('Project'!A13="","",'Project'!A13) | B15: Project | C15: =IF('Project'!B13="","",'Project'!B13) | D15: =IF('Project'!C13="","",'Project'!C13) | E15: =IF('Project'!D13="","",'Project'!D13) | F15: =IF('Project'!E13="","",'Project'!E13) | G15: =IF('Project'!F13="","",'Project'!F13) | H15: =IF('Project'!G13="","",'Project'!G13) | I15: =IF('Project'!H13="","",'Project'!H13) | J15: =IF('Project'!I13="","",'Project'!I13)
A16: =IF('Security'!A3="","",'Security'!A3) | B16: Security | C16: =IF('Security'!B3="","",'Security'!B3) | D16: =IF('Security'!C3="","",'Security'!C3) | E16: =IF('Security'!D3="","",'Security'!D3) | F16: =IF('Security'!E3="","",'Security'!E3) | G16: =IF('Security'!F3="","",'Security'!F3) | H16: =IF('Security'!G3="","",'Security'!G3) | I16: =IF('Security'!H3="","",'Security'!H3) | J16: =IF('Security'!I3="","",'Security'!I3)
A17: =IF('Security'!A4="","",'Security'!A4) | B17: Security | C17: =IF('Security'!B4="","",'Security'!B4) | D17: =IF('Security'!C4="","",'Security'!C4) | E17: =IF('Security'!D4="","",'Security'!D4) | F17: =IF('Security'!E4="","",'Security'!E4) | G17: =IF('Security'!F4="","",'Security'!F4) | H17: =IF('Security'!G4="","",'Security'!G4) | I17: =IF('Security'!H4="","",'Security'!H4) | J17: =IF('Security'!I4="","",'Security'!I4)
A18: =IF('Security'!A5="","",'Security'!A5) | B18: Security | C18: =IF('Security'!B5="","",'Security'!B5) | D18: =IF('Security'!C5="","",'Security'!C5) | E18: =IF('Security'!D5="","",'Security'!D5) | F18: =IF('Security'!E5="","",'Security'!E5) | G18: =IF('Security'!F5="","",'Security'!F5) | H18: =IF('Security'!G5="","",'Security'!G5) | I18: =IF('Security'!H5="","",'Security'!H5) | J18: =IF('Security'!I5="","",'Security'!I5)
A19: =IF('Monitoring'!A3="","",'Monitoring'!A3) | B19: Monitoring | C19: =IF('Monitoring'!B3="","",'Monitoring'!B3) | D19: =IF('Monitoring'!C3="","",'Monitoring'!C3) | E19: =IF('Monitoring'!D3="","",'Monitoring'!D3) | F19: =IF('Monitoring'!E3="","",'Monitoring'!E3) | G19: =IF('Monitoring'!F3="","",'Monitoring'!F3) | H19: =IF('Monitoring'!G3="","",'Monitoring'!G3) | I19: =IF('Monitoring'!H3="","",'Monitoring'!H3) | J19: =IF('Monitoring'!I3="","",'Monitoring'!I3)
A20: =IF('Monitoring'!A4="","",'Monitoring'!A4) | B20: Monitoring | C20: =IF('Monitoring'!B4="","",'Monitoring'!B4) | D20: =IF('Monitoring'!C4="","",'Monitoring'!C4) | E20: =IF('Monitoring'!D4="","",'Monitoring'!D4) | F20: =IF('Monitoring'!E4="","",'Monitoring'!E4) | G20: =IF('Monitoring'!F4="","",'Monitoring'!F4) | H20: =IF('Monitoring'!G4="","",'Monitoring'!G4) | I20: =IF('Monitoring'!H4="","",'Monitoring'!H4) | J20: =IF('Monitoring'!I4="","",'Monitoring'!I4)
A21: =IF('Monitoring'!A5="","",'Monitoring'!A5) | B21: Monitoring | C21: =IF('Monitoring'!B5="","",'Monitoring'!B5) | D21: =IF('Monitoring'!C5="","",'Monitoring'!C5) | E21: =IF('Monitoring'!D5="","",'Monitoring'!D5) | F21: =IF('Monitoring'!E5="","",'Monitoring'!E5) | G21: =IF('Monitoring'!F5="","",'Monitoring'!F5) | H21: =IF('Monitoring'!G5="","",'Monitoring'!G5) | I21: =IF('Monitoring'!H5="","",'Monitoring'!H5) | J21: =IF('Monitoring'!I5="","",'Monitoring'!I5)
A22: =IF('Monitoring'!A6="","",'Monitoring'!A6) | B22: Monitoring | C22: =IF('Monitoring'!B6="","",'Monitoring'!B6) | D22: =IF('Monitoring'!C6="","",'Monitoring'!C6) | E22: =IF('Monitoring'!D6="","",'Monitoring'!D6) | F22: =IF('Monitoring'!E6="","",'Monitoring'!E6) | G22: =IF('Monitoring'!F6="","",'Monitoring'!F6) | H22: =IF('Monitoring'!G6="","",'Monitoring'!G6) | I22: =IF('Monitoring'!H6="","",'Monitoring'!H6) | J22: =IF('Monitoring'!I6="","",'Monitoring'!I6)
A23: =IF('Analytics'!A3="","",'Analytics'!A3) | B23: Analytics | C23: =IF('Analytics'!B3="","",'Analytics'!B3) | D23: =IF('Analytics'!C3="","",'Analytics'!C3) | E23: =IF('Analytics'!D3="","",'Analytics'!D3) | F23: =IF('Analytics'!E3="","",'Analytics'!E3) | G23: =IF('Analytics'!F3="","",'Analytics'!F3) | H23: =IF('Analytics'!G3="","",'Analytics'!G3) | I23: =IF('Analytics'!H3="","",'Analytics'!H3) | J23: =IF('Analytics'!I3="","",'Analytics'!I3)
A24: =IF('Analytics'!A4="","",'Analytics'!A4) | B24: Analytics | C24: =IF('Analytics'!B4="","",'Analytics'!B4) | D24: =IF('Analytics'!C4="","",'Analytics'!C4) | E24: =IF('Analytics'!D4="","",'Analytics'!D4) | F24: =IF('Analytics'!E4="","",'Analytics'!E4) | G24: =IF('Analytics'!F4="","",'Analytics'!F4) | H24: =IF('Analytics'!G4="","",'Analytics'!G4) | I24: =IF('Analytics'!H4="","",'Analytics'!H4) | J24: =IF('Analytics'!I4="","",'Analytics'!I4)
A25: =IF('Analytics'!A5="","",'Analytics'!A5) | B25: Analytics | C25: =IF('Analytics'!B5="","",'Analytics'!B5) | D25: =IF('Analytics'!C5="","",'Analytics'!C5) | E25: =IF('Analytics'!D5="","",'Analytics'!D5) | F25: =IF('Analytics'!E5="","",'Analytics'!E5) | G25: =IF('Analytics'!F5="","",'Analytics'!F5) | H25: =IF('Analytics'!G5="","",'Analytics'!G5) | I25: =IF('Analytics'!H5="","",'Analytics'!H5) | J25: =IF('Analytics'!I5="","",'Analytics'!I5)
A26: =IF('Analytics'!A6="","",'Analytics'!A6) | B26: Analytics | C26: =IF('Analytics'!B6="","",'Analytics'!B6) | D26: =IF('Analytics'!C6="","",'Analytics'!C6) | E26: =IF('Analytics'!D6="","",'Analytics'!D6) | F26: =IF('Analytics'!E6="","",'Analytics'!E6) | G26: =IF('Analytics'!F6="","",'Analytics'!F6) | H26: =IF('Analytics'!G6="","",'Analytics'!G6) | I26: =IF('Analytics'!H6="","",'Analytics'!H6) | J26: =IF('Analytics'!I6="","",'Analytics'!I6)
A27: =IF('Analytics'!A7="","",'Analytics'!A7) | B27: Analytics | C27: =IF('Analytics'!B7="","",'Analytics'!B7) | D27: =IF('Analytics'!C7="","",'Analytics'!C7) | E27: =IF('Analytics'!D7="","",'Analytics'!D7) | F27: =IF('Analytics'!E7="","",'Analytics'!E7) | G27: =IF('Analytics'!F7="","",'Analytics'!F7) | H27: =IF('Analytics'!G7="","",'Analytics'!G7) | I27: =IF('Analytics'!H7="","",'Analytics'!H7) | J27: =IF('Analytics'!I7="","",'Analytics'!I7)
A28: =IF('Automation'!A3="","",'Automation'!A3) | B28: Automation | C28: =IF('Automation'!B3="","",'Automation'!B3) | D28: =IF('Automation'!C3="","",'Automation'!C3) | E28: =IF('Automation'!D3="","",'Automation'!D3) | F28: =IF('Automation'!E3="","",'Automation'!E3) | G28: =IF('Automation'!F3="","",'Automation'!F3) | H28: =IF('Automation'!G3="","",'Automation'!G3) | I28: =IF('Automation'!H3="","",'Automation'!H3) | J28: =IF('Automation'!I3="","",'Automation'!I3)
A29: =IF('Automation'!A4="","",'Automation'!A4) | B29: Automation | C29: =IF('Automation'!B4="","",'Automation'!B4) | D29: =IF('Automation'!C4="","",'Automation'!C4) | E29: =IF('Automation'!D4="","",'Automation'!D4) | F29: =IF('Automation'!E4="","",'Automation'!E4) | G29: =IF('Automation'!F4="","",'Automation'!F4) | H29: =IF('Automation'!G4="","",'Automation'!G4) | I29: =IF('Automation'!H4="","",'Automation'!H4) | J29: =IF('Automation'!I4="","",'Automation'!I4)
A30: =IF('Automation'!A5="","",'Automation'!A5) | B30: Automation | C30: =IF('Automation'!B5="","",'Automation'!B5) | D30: =IF('Automation'!C5="","",'Automation'!C5) | E30: =IF('Automation'!D5="","",'Automation'!D5) | F30: =IF('Automation'!E5="","",'Automation'!E5) | G30: =IF('Automation'!F5="","",'Automation'!F5) | H30: =IF('Automation'!G5="","",'Automation'!G5) | I30: =IF('Automation'!H5="","",'Automation'!H5) | J30: =IF('Automation'!I5="","",'Automation'!I5)
A31: =IF('Automation'!A6="","",'Automation'!A6) | B31: Automation | C31: =IF('Automation'!B6="","",'Automation'!B6) | D31: =IF('Automation'!C6="","",'Automation'!C6) | E31: =IF('Automation'!D6="","",'Automation'!D6) | F31: =IF('Automation'!E6="","",'Automation'!E6) | G31: =IF('Automation'!F6="","",'Automation'!F6) | H31: =IF('Automation'!G6="","",'Automation'!G6) | I31: =IF('Automation'!H6="","",'Automation'!H6) | J31: =IF('Automation'!I6="","",'Automation'!I6)
A32: =IF('Integration'!A3="","",'Integration'!A3) | B32: Integration | C32: =IF('Integration'!B3="","",'Integration'!B3) | D32: =IF('Integration'!C3="","",'Integration'!C3) | E32: =IF('Integration'!D3="","",'Integration'!D3) | F32: =IF('Integration'!E3="","",'Integration'!E3) | G32: =IF('Integration'!F3="","",'Integration'!F3) | H32: =IF('Integration'!G3="","",'Integration'!G3) | I32: =IF('Integration'!H3="","",'Integration'!H3) | J32: =IF('Integration'!I3="","",'Integration'!I3)
A33: =IF('Integration'!A4="","",'Integration'!A4) | B33: Integration | C33: =IF('Integration'!B4="","",'Integration'!B4) | D33: =IF('Integration'!C4="","",'Integration'!C4) | E33: =IF('Integration'!D4="","",'Integration'!D4) | F33: =IF('Integration'!E4="","",'Integration'!E4) | G33: =IF('Integration'!F4="","",'Integration'!F4) | H33: =IF('Integration'!G4="","",'Integration'!G4) | I33: =IF('Integration'!H4="","",'Integration'!H4) | J33: =IF('Integration'!I4="","",'Integration'!I4)
A34: =IF('Operations'!A3="","",'Operations'!A3) | B34: Operations | C34: =IF('Operations'!B3="","",'Operations'!B3) | D34: =IF('Operations'!C3="","",'Operations'!C3) | E34: =IF('Operations'!D3="","",'Operations'!D3) | F34: =IF('Operations'!E3="","",'Operations'!E3) | G34: =IF('Operations'!F3="","",'Operations'!F3) | H34: =IF('Operations'!G3="","",'Operations'!G3) | I34: =IF('Operations'!H3="","",'Operations'!H3) | J34: =IF('Operations'!I3="","",'Operations'!I3)
A35: =IF('Operations'!A4="","",'Operations'!A4) | B35: Operations | C35: =IF('Operations'!B4="","",'Operations'!B4) | D35: =IF('Operations'!C4="","",'Operations'!C4) | E35: =IF('Operations'!D4="","",'Operations'!D4) | F35: =IF('Operations'!E4="","",'Operations'!E4) | G35: =IF('Operations'!F4="","",'Operations'!F4) | H35: =IF('Operations'!G4="","",'Operations'!G4) | I35: =IF('Operations'!H4="","",'Operations'!H4) | J35: =IF('Operations'!I4="","",'Operations'!I4)
A36: =IF('Operations'!A5="","",'Operations'!A5) | B36: Operations | C36: =IF('Operations'!B5="","",'Operations'!B5) | D36: =IF('Operations'!C5="","",'Operations'!C5) | E36: =IF('Operations'!D5="","",'Operations'!D5) | F36: =IF('Operations'!E5="","",'Operations'!E5) | G36: =IF('Operations'!F5="","",'Operations'!F5) | H36: =IF('Operations'!G5="","",'Operations'!G5) | I36: =IF('Operations'!H5="","",'Operations'!H5) | J36: =IF('Operations'!I5="","",'Operations'!I5)
A37: =IF('Operations'!A6="","",'Operations'!A6) | B37: Operations | C37: =IF('Operations'!B6="","",'Operations'!B6) | D37: =IF('Operations'!C6="","",'Operations'!C6) | E37: =IF('Operations'!D6="","",'Operations'!D6) | F37: =IF('Operations'!E6="","",'Operations'!E6) | G37: =IF('Operations'!F6="","",'Operations'!F6) | H37: =IF('Operations'!G6="","",'Operations'!G6) | I37: =IF('Operations'!H6="","",'Operations'!H6) | J37: =IF('Operations'!I6="","",'Operations'!I6)
A38: =IF('Sentinel'!A3="","",'Sentinel'!A3) | B38: Sentinel | C38: =IF('Sentinel'!B3="","",'Sentinel'!B3) | D38: =IF('Sentinel'!C3="","",'Sentinel'!C3) | E38: =IF('Sentinel'!D3="","",'Sentinel'!D3) | F38: =IF('Sentinel'!E3="","",'Sentinel'!E3) | G38: =IF('Sentinel'!F3="","",'Sentinel'!F3) | H38: =IF('Sentinel'!G3="","",'Sentinel'!G3) | I38: =IF('Sentinel'!H3="","",'Sentinel'!H3) | J38: =IF('Sentinel'!I3="","",'Sentinel'!I3)
A39: =IF('Sentinel'!A4="","",'Sentinel'!A4) | B39: Sentinel | C39: =IF('Sentinel'!B4="","",'Sentinel'!B4) | D39: =IF('Sentinel'!C4="","",'Sentinel'!C4) | E39: =IF('Sentinel'!D4="","",'Sentinel'!D4) | F39: =IF('Sentinel'!E4="","",'Sentinel'!E4) | G39: =IF('Sentinel'!F4="","",'Sentinel'!F4) | H39: =IF('Sentinel'!G4="","",'Sentinel'!G4) | I39: =IF('Sentinel'!H4="","",'Sentinel'!H4) | J39: =IF('Sentinel'!I4="","",'Sentinel'!I4)
A40: =IF('Sentinel'!A5="","",'Sentinel'!A5) | B40: Sentinel | C40: =IF('Sentinel'!B5="","",'Sentinel'!B5) | D40: =IF('Sentinel'!C5="","",'Sentinel'!C5) | E40: =IF('Sentinel'!D5="","",'Sentinel'!D5) | F40: =IF('Sentinel'!E5="","",'Sentinel'!E5) | G40: =IF('Sentinel'!F5="","",'Sentinel'!F5) | H40: =IF('Sentinel'!G5="","",'Sentinel'!G5) | I40: =IF('Sentinel'!H5="","",'Sentinel'!H5) | J40: =IF('Sentinel'!I5="","",'Sentinel'!I5)
A41: =IF('Sentinel'!A6="","",'Sentinel'!A6) | B41: Sentinel | C41: =IF('Sentinel'!B6="","",'Sentinel'!B6) | D41: =IF('Sentinel'!C6="","",'Sentinel'!C6) | E41: =IF('Sentinel'!D6="","",'Sentinel'!D6) | F41: =IF('Sentinel'!E6="","",'Sentinel'!E6) | G41: =IF('Sentinel'!F6="","",'Sentinel'!F6) | H41: =IF('Sentinel'!G6="","",'Sentinel'!G6) | I41: =IF('Sentinel'!H6="","",'Sentinel'!H6) | J41: =IF('Sentinel'!I6="","",'Sentinel'!I6)
...

Sheet Project
A1: Project Parameters
A2: Parameter Name | B2: Production | C2: Test | D2: DR | E2: Description | F2: Required | G2: Data Type | H2: Validation Rules | I2: Security Level
A3: solution.name | B3: Azure Sentinel SIEM | C3: Azure Sentinel SIEM | D3: Azure Sentinel SIEM | E3: Solution display name | F3: Yes | G3: String | H3: Max 50 characters | I3: Public
A4: solution.abbr | B4: sentinel | C4: sentinel | D4: sentinel | E4: Solution abbreviation for resource naming | F4: Yes | G4: String | H4: Max 10 characters | I4: Public
A5: solution.provider_name | B5: azure | C5: azure | D5: azure | E5: Cloud provider name | F5: Yes | G5: String | H5: aws|azure|gcp | I5: Public
A6: solution.category_name | B6: cyber-security | C6: cyber-security | D6: cyber-security | E6: Solution category | F6: Yes | G6: String | H6: Valid category | I6: Public
A7: azure.subscription_id | B7: [SUBSCRIPTION_ID] | C7: [SUBSCRIPTION_ID] | D7: [SUBSCRIPTION_ID] | E7: Azure subscription identifier | F7: Yes | G7: String | H7: GUID format | I7: Confidential
A8: azure.tenant_id | B8: [TENANT_ID] | C8: [TENANT_ID] | D8: [TENANT_ID] | E8: Azure AD tenant identifier | F8: Yes | G8: String | H8: GUID format | I8: Confidential
A9: azure.region | B9: eastus | C9: eastus | D9: westus2 | E9: Primary Azure region | F9: Yes | G9: String | H9: Valid Azure region | I9: Public
A10: azure.dr_region | B10: westus2 | C10: westus2 | D10: eastus | E10: DR region for failover | F10: Yes | G10: String | H10: Valid Azure region | I10: Public
A11: ownership.cost_center | B11: CC-SEC-001 | C11: CC-SEC-001 | D11: CC-SEC-001 | E11: Cost center for billing | F11: Yes | G11: String | H11: CC format | I11: Public
A12: ownership.owner_email | B12: security-team@company.com | C12: dev-team@company.com | D12: security-team@company.com | E12: Team email for ownership | F12: Yes | G12: String | H12: Valid email | I12: Public
A13: ownership.project_code | B13: PRJ-SIEM-2025 | C13: PRJ-SIEM-2025 | D13: PRJ-SIEM-2025 | E13: Project tracking code | F13: Yes | G13: String | H13: PRJ format | I13: Public

Sheet Security
A1: Security Parameters
A2: Parameter Name | B2: Production | C2: Test | D2: DR | E2: Description | F2: Required | G2: Data Type | H2: Validation Rules | I2: Security Level
A3: security.keyvault_sku | B3: standard | C3: standard | D3: standard | E3: Key Vault pricing tier | F3: Yes | G3: String | H3: standard|premium | I3: Public
A4: security.soc_group_id | B4: [SOC_GROUP_ID] | C4: [SOC_GROUP_ID] | D4: [SOC_GROUP_ID] | E4: Azure AD group for SOC analysts | F4: Yes | G4: String | H4: GUID format | I4: Confidential
A5: security.admin_group_id | B5: [ADMIN_GROUP_ID] | C5: [ADMIN_GROUP_ID] | D5: [ADMIN_GROUP_ID] | E5: Azure AD group for SOC admins | F5: Yes | G5: String | H5: GUID format | I5: Confidential

Sheet Monitoring
A1: Monitoring Parameters
A2: Parameter Name | B2: Production | C2: Test | D2: DR | E2: Description | F2: Required | G2: Data Type | H2: Validation Rules | I2: Security Level
A3: monitoring.log_analytics_sku | B3: PerGB2018 | C3: PerGB2018 | D3: PerGB2018 | E3: Log Analytics pricing tier | F3: Yes | G3: String | H3: PerGB2018 | I3: Public
A4: monitoring.log_retention_days | B4: 90 | C4: 30 | D4: 90 | E4: Log retention in days | F4: Yes | G4: Integer | H4: 30-730 | I4: Public
A5: monitoring.archive_retention_days | B5: 730 | C5: 365 | D5: 730 | E5: Archive retention in days (compliance) | F5: Yes | G5: Integer | H5: 365-2555 | I5: Public
A6: monitoring.daily_ingestion_cap_gb | B6: 500 | C6: 5 | D6: 500 | E6: Daily ingestion cap in GB | F6: Yes | G6: Integer | H6: 1-5000 | I6: Public

Sheet Analytics
A1: Analytics Parameters
A2: Parameter Name | B2: Production | C2: Test | D2: DR | E2: Description | F2: Required | G2: Data Type | H2: Validation Rules | I2: Security Level
A3: analytics.rules_total_count | B3: 50 | C3: 15 | D3: 50 | E3: Total number of analytics rules | F3: Yes | G3: Integer | H3: 10-200 | I3: Public
A4: analytics.rules_builtin_count | B4: 30 | C4: 10 | D4: 30 | E4: Microsoft built-in rules to enable | F4: Yes | G4: Integer | H4: 10-100 | I4: Public
A5: analytics.rules_custom_count | B5: 20 | C5: 5 | D5: 20 | E5: Custom organization rules | F5: Yes | G5: Integer | H5: 5-50 | I5: Public
A6: analytics.ueba_enabled | B6: true | C6: false | D6: true | E6: Enable User Entity Behavior Analytics | F6: Yes | G6: Boolean | H6: true|false | I6: Public
A7: analytics.threat_intel_feeds | B7: 10 | C7: 3 | D7: 10 | E7: Number of threat intelligence feeds | F7: Yes | G7: Integer | H7: 1-20 | I7: Public

Sheet Automation
A1: Automation Parameters
A2: Parameter Name | B2: Production | C2: Test | D2: DR | E2: Description | F2: Required | G2: Data Type | H2: Validation Rules | I2: Security Level
A3: automation.playbook_count | B3: 12 | C3: 5 | D3: 12 | E3: Number of SOAR playbooks | F3: Yes | G3: Integer | H3: 5-50 | I3: Public
A4: automation.playbook_auto_enrichment | B4: true | C4: true | D4: true | E4: Enable auto-enrichment playbooks | F4: Yes | G4: Boolean | H4: true|false | I4: Public
A5: automation.playbook_auto_containment | B5: true | C5: false | D5: true | E5: Enable auto-containment playbooks | F5: Yes | G5: Boolean | H5: true|false | I5: Public
A6: automation.playbook_auto_ticketing | B6: true | C6: false | D6: true | E6: Enable auto-ticketing playbooks | F6: Yes | G6: Boolean | H6: true|false | I6: Public

Sheet Integration
A1: Integration Parameters
A2: Parameter Name | B2: Production | C2: Test | D2: DR | E2: Description | F2: Required | G2: Data Type | H2: Validation Rules | I2: Security Level
A3: integration.servicenow_enabled | B3: true | C3: false | D3: true | E3: Enable ServiceNow integration | F3: Yes | G3: Boolean | H3: true|false | I3: Public
A4: integration.teams_webhook_enabled | B4: true | C4: true | D4: true | E4: Enable Microsoft Teams notifications | F4: Yes | G4: Boolean | H4: true|false | I4: Public

Sheet Operations
A1: Operations Parameters
A2: Parameter Name | B2: Production | C2: Test | D2: DR | E2: Description | F2: Required | G2: Data Type | H2: Validation Rules | I2: Security Level
A3: operations.alert_email | B3: soc-alerts@company.com | C3: dev-alerts@company.com | D3: dr-alerts@company.com | E3: Email for critical security alerts | F3: Yes | G3: String | H3: Valid email | I3: Confidential
A4: operations.mttd_target_minutes | B4: 15 | C4: 15 | D4: 15 | E4: Target mean time to detect in minutes | F4: Yes | G4: Integer | H4: 1-60 | I4: Public
A5: operations.mttr_target_minutes | B5: 60 | C5: 60 | D5: 60 | E5: Target mean time to respond in minutes | F5: Yes | G5: Integer | H5: 15-240 | I5: Public
A6: operations.false_positive_target_pct | B6: 50 | C6: 50 | D6: 50 | E6: Target false positive rate percentage | F6: Yes | G6: Integer | H6: 10-75 | I6: Public

Sheet Sentinel
A1: Sentinel Parameters
A2: Parameter Name | B2: Production | C2: Test | D2: DR | E2: Description | F2: Required | G2: Data Type | H2: Validation Rules | I2: Security Level
A3: sentinel.tier | B3: Standard | C3: Standard | D3: Standard | E3: Azure Sentinel pricing tier | F3: Yes | G3: String | H3: Free|Standard | I3: Public
A4: sentinel.connector_office365 | B4: true | C4: true | D4: true | E4: Enable Office 365 data connector | F4: Yes | G4: Boolean | H4: true|false | I4: Public
A5: sentinel.connector_azure_ad | B5: true | C5: true | D5: true | E5: Enable Azure AD data connector | F5: Yes | G5: Boolean | H5: true|false | I5: Public
A6: sentinel.connector_azure_activity | B6: true | C6: true | D6: true | E6: Enable Azure Activity data connector | F6: Yes | G6: Boolean | H6: true|false | I6: Public
A7: sentinel.connector_defender_cloud | B7: true | C7: false | D7: true | E7: Enable Defender for Cloud connector | F7: Yes | G7: Boolean | H7: true|false | I7: Public
A8: sentinel.connector_defender_endpoint | B8: true | C8: false | D8: true | E8: Enable Defender for Endpoint connector | F8: Yes | G8: Boolean | H8: true|false | I8: Public
A9: sentinel.connector_defender_identity | B9: true | C9: false | D9: true | E9: Enable Defender for Identity connector | F9: Yes | G9: Boolean | H9: true|false | I9: Public
A10: sentinel.connector_defender_o365 | B10: true | C10: false | D10: true | E10: Enable Defender for Office 365 connector | F10: Yes | G10: Boolean | H10: true|false | I10: Public
A11: sentinel.connector_cef | B11: true | C11: false | D11: true | E11: Enable CEF/Syslog connector | F11: Yes | G11: Boolean | H11: true|false | I11: Public
A12: sentinel.connector_dns | B12: true | C12: false | D12: true | E12: Enable DNS logs connector | F12: Yes | G12: Boolean | H12: true|false | I12: Public
