Workbook

Sheet Cover
B3: Configuration Parameters
B5: Generated: | C5: November 27, 2025
B6: Solution: | C6: Secure Access
B7: Customer: | C7: [Customer Name]
B8: Version: | C8: 1.0
B9: Status: | C9: Draft
C12: eoframework.org

Sheet All Parameters (Read Only)
A1: Total Parameters | B1: Categories | C1: Required | D1: Confidential/Secret
A2: 47 | B2: 11 | C2: 45 | D2: 31
A4: Parameter Name | B4: Category | C4: Environment | D4: Default Value | E4: Description | F4: Required | G4: Data Type | H4: Validation Rules | I4: Security Level | J4: Owner Team | K4: Dependencies | L4: Notes | M4: Last Updated
A5: =IF('Cisco Duo'!A3="","",'Cisco Duo'!A3) | B5: Cisco Duo | C5: =IF('Cisco Duo'!B3="","",'Cisco Duo'!B3) | D5: =IF('Cisco Duo'!C3="","",'Cisco Duo'!C3) | E5: =IF('Cisco Duo'!D3="","",'Cisco Duo'!D3) | F5: =IF('Cisco Duo'!E3="","",'Cisco Duo'!E3) | G5: =IF('Cisco Duo'!F3="","",'Cisco Duo'!F3) | H5: =IF('Cisco Duo'!G3="","",'Cisco Duo'!G3) | I5: =IF('Cisco Duo'!H3="","",'Cisco Duo'!H3) | J5: =IF('Cisco Duo'!I3="","",'Cisco Duo'!I3) | ... M5: =IF('Cisco Duo'!L3="","",'Cisco Duo'!L3)
A6: =IF('Cisco Duo'!A4="","",'Cisco Duo'!A4) | B6: Cisco Duo | C6: =IF('Cisco Duo'!B4="","",'Cisco Duo'!B4) | D6: =IF('Cisco Duo'!C4="","",'Cisco Duo'!C4) | E6: =IF('Cisco Duo'!D4="","",'Cisco Duo'!D4) | F6: =IF('Cisco Duo'!E4="","",'Cisco Duo'!E4) | G6: =IF('Cisco Duo'!F4="","",'Cisco Duo'!F4) | H6: =IF('Cisco Duo'!G4="","",'Cisco Duo'!G4) | I6: =IF('Cisco Duo'!H4="","",'Cisco Duo'!H4) | J6: =IF('Cisco Duo'!I4="","",'Cisco Duo'!I4) | ... M6: =IF('Cisco Duo'!L4="","",'Cisco Duo'!L4)
A7: =IF('Cisco Duo'!A5="","",'Cisco Duo'!A5) | B7: Cisco Duo | C7: =IF('Cisco Duo'!B5="","",'Cisco Duo'!B5) | D7: =IF('Cisco Duo'!C5="","",'Cisco Duo'!C5) | E7: =IF('Cisco Duo'!D5="","",'Cisco Duo'!D5) | F7: =IF('Cisco Duo'!E5="","",'Cisco Duo'!E5) | G7: =IF('Cisco Duo'!F5="","",'Cisco Duo'!F5) | H7: =IF('Cisco Duo'!G5="","",'Cisco Duo'!G5) | I7: =IF('Cisco Duo'!H5="","",'Cisco Duo'!H5) | J7: =IF('Cisco Duo'!I5="","",'Cisco Duo'!I5) | ... M7: =IF('Cisco Duo'!L5="","",'Cisco Duo'!L5)
A8: =IF('Cisco Duo'!A6="","",'Cisco Duo'!A6) | B8: Cisco Duo | C8: =IF('Cisco Duo'!B6="","",'Cisco Duo'!B6) | D8: =IF('Cisco Duo'!C6="","",'Cisco Duo'!C6) | E8: =IF('Cisco Duo'!D6="","",'Cisco Duo'!D6) | F8: =IF('Cisco Duo'!E6="","",'Cisco Duo'!E6) | G8: =IF('Cisco Duo'!F6="","",'Cisco Duo'!F6) | H8: =IF('Cisco Duo'!G6="","",'Cisco Duo'!G6) | I8: =IF('Cisco Duo'!H6="","",'Cisco Duo'!H6) | J8: =IF('Cisco Duo'!I6="","",'Cisco Duo'!I6) | ... M8: =IF('Cisco Duo'!L6="","",'Cisco Duo'!L6)
A9: =IF('Cisco Duo'!A7="","",'Cisco Duo'!A7) | B9: Cisco Duo | C9: =IF('Cisco Duo'!B7="","",'Cisco Duo'!B7) | D9: =IF('Cisco Duo'!C7="","",'Cisco Duo'!C7) | E9: =IF('Cisco Duo'!D7="","",'Cisco Duo'!D7) | F9: =IF('Cisco Duo'!E7="","",'Cisco Duo'!E7) | G9: =IF('Cisco Duo'!F7="","",'Cisco Duo'!F7) | H9: =IF('Cisco Duo'!G7="","",'Cisco Duo'!G7) | I9: =IF('Cisco Duo'!H7="","",'Cisco Duo'!H7) | J9: =IF('Cisco Duo'!I7="","",'Cisco Duo'!I7) | ... M9: =IF('Cisco Duo'!L7="","",'Cisco Duo'!L7)
A10: =IF('Cisco Duo'!A8="","",'Cisco Duo'!A8) | B10: Cisco Duo | C10: =IF('Cisco Duo'!B8="","",'Cisco Duo'!B8) | D10: =IF('Cisco Duo'!C8="","",'Cisco Duo'!C8) | E10: =IF('Cisco Duo'!D8="","",'Cisco Duo'!D8) | F10: =IF('Cisco Duo'!E8="","",'Cisco Duo'!E8) | G10: =IF('Cisco Duo'!F8="","",'Cisco Duo'!F8) | H10: =IF('Cisco Duo'!G8="","",'Cisco Duo'!G8) | I10: =IF('Cisco Duo'!H8="","",'Cisco Duo'!H8) | J10: =IF('Cisco Duo'!I8="","",'Cisco Duo'!I8) | ... M10: =IF('Cisco Duo'!L8="","",'Cisco Duo'!L8)
A11: =IF('Cisco Duo'!A9="","",'Cisco Duo'!A9) | B11: Cisco Duo | C11: =IF('Cisco Duo'!B9="","",'Cisco Duo'!B9) | D11: =IF('Cisco Duo'!C9="","",'Cisco Duo'!C9) | E11: =IF('Cisco Duo'!D9="","",'Cisco Duo'!D9) | F11: =IF('Cisco Duo'!E9="","",'Cisco Duo'!E9) | G11: =IF('Cisco Duo'!F9="","",'Cisco Duo'!F9) | H11: =IF('Cisco Duo'!G9="","",'Cisco Duo'!G9) | I11: =IF('Cisco Duo'!H9="","",'Cisco Duo'!H9) | J11: =IF('Cisco Duo'!I9="","",'Cisco Duo'!I9) | ... M11: =IF('Cisco Duo'!L9="","",'Cisco Duo'!L9)
A12: =IF('Cisco Umbrella'!A3="","",'Cisco Umbrella'!A3) | B12: Cisco Umbrella | C12: =IF('Cisco Umbrella'!B3="","",'Cisco Umbrella'!B3) | D12: =IF('Cisco Umbrella'!C3="","",'Cisco Umbrella'!C3) | E12: =IF('Cisco Umbrella'!D3="","",'Cisco Umbrella'!D3) | F12: =IF('Cisco Umbrella'!E3="","",'Cisco Umbrella'!E3) | G12: =IF('Cisco Umbrella'!F3="","",'Cisco Umbrella'!F3) | H12: =IF('Cisco Umbrella'!G3="","",'Cisco Umbrella'!G3) | I12: =IF('Cisco Umbrella'!H3="","",'Cisco Umbrella'!H3) | J12: =IF('Cisco Umbrella'!I3="","",'Cisco Umbrella'!I3) | ... M12: =IF('Cisco Umbrella'!L3="","",'Cisco Umbrella'!L3)
A13: =IF('Cisco Umbrella'!A4="","",'Cisco Umbrella'!A4) | B13: Cisco Umbrella | C13: =IF('Cisco Umbrella'!B4="","",'Cisco Umbrella'!B4) | D13: =IF('Cisco Umbrella'!C4="","",'Cisco Umbrella'!C4) | E13: =IF('Cisco Umbrella'!D4="","",'Cisco Umbrella'!D4) | F13: =IF('Cisco Umbrella'!E4="","",'Cisco Umbrella'!E4) | G13: =IF('Cisco Umbrella'!F4="","",'Cisco Umbrella'!F4) | H13: =IF('Cisco Umbrella'!G4="","",'Cisco Umbrella'!G4) | I13: =IF('Cisco Umbrella'!H4="","",'Cisco Umbrella'!H4) | J13: =IF('Cisco Umbrella'!I4="","",'Cisco Umbrella'!I4) | ... M13: =IF('Cisco Umbrella'!L4="","",'Cisco Umbrella'!L4)
A14: =IF('Cisco Umbrella'!A5="","",'Cisco Umbrella'!A5) | B14: Cisco Umbrella | C14: =IF('Cisco Umbrella'!B5="","",'Cisco Umbrella'!B5) | D14: =IF('Cisco Umbrella'!C5="","",'Cisco Umbrella'!C5) | E14: =IF('Cisco Umbrella'!D5="","",'Cisco Umbrella'!D5) | F14: =IF('Cisco Umbrella'!E5="","",'Cisco Umbrella'!E5) | G14: =IF('Cisco Umbrella'!F5="","",'Cisco Umbrella'!F5) | H14: =IF('Cisco Umbrella'!G5="","",'Cisco Umbrella'!G5) | I14: =IF('Cisco Umbrella'!H5="","",'Cisco Umbrella'!H5) | J14: =IF('Cisco Umbrella'!I5="","",'Cisco Umbrella'!I5) | ... M14: =IF('Cisco Umbrella'!L5="","",'Cisco Umbrella'!L5)
A15: =IF('Cisco Umbrella'!A6="","",'Cisco Umbrella'!A6) | B15: Cisco Umbrella | C15: =IF('Cisco Umbrella'!B6="","",'Cisco Umbrella'!B6) | D15: =IF('Cisco Umbrella'!C6="","",'Cisco Umbrella'!C6) | E15: =IF('Cisco Umbrella'!D6="","",'Cisco Umbrella'!D6) | F15: =IF('Cisco Umbrella'!E6="","",'Cisco Umbrella'!E6) | G15: =IF('Cisco Umbrella'!F6="","",'Cisco Umbrella'!F6) | H15: =IF('Cisco Umbrella'!G6="","",'Cisco Umbrella'!G6) | I15: =IF('Cisco Umbrella'!H6="","",'Cisco Umbrella'!H6) | J15: =IF('Cisco Umbrella'!I6="","",'Cisco Umbrella'!I6) | ... M15: =IF('Cisco Umbrella'!L6="","",'Cisco Umbrella'!L6)
A16: =IF('Cisco Umbrella'!A7="","",'Cisco Umbrella'!A7) | B16: Cisco Umbrella | C16: =IF('Cisco Umbrella'!B7="","",'Cisco Umbrella'!B7) | D16: =IF('Cisco Umbrella'!C7="","",'Cisco Umbrella'!C7) | E16: =IF('Cisco Umbrella'!D7="","",'Cisco Umbrella'!D7) | F16: =IF('Cisco Umbrella'!E7="","",'Cisco Umbrella'!E7) | G16: =IF('Cisco Umbrella'!F7="","",'Cisco Umbrella'!F7) | H16: =IF('Cisco Umbrella'!G7="","",'Cisco Umbrella'!G7) | I16: =IF('Cisco Umbrella'!H7="","",'Cisco Umbrella'!H7) | J16: =IF('Cisco Umbrella'!I7="","",'Cisco Umbrella'!I7) | ... M16: =IF('Cisco Umbrella'!L7="","",'Cisco Umbrella'!L7)
A17: =IF('Cisco Umbrella'!A8="","",'Cisco Umbrella'!A8) | B17: Cisco Umbrella | C17: =IF('Cisco Umbrella'!B8="","",'Cisco Umbrella'!B8) | D17: =IF('Cisco Umbrella'!C8="","",'Cisco Umbrella'!C8) | E17: =IF('Cisco Umbrella'!D8="","",'Cisco Umbrella'!D8) | F17: =IF('Cisco Umbrella'!E8="","",'Cisco Umbrella'!E8) | G17: =IF('Cisco Umbrella'!F8="","",'Cisco Umbrella'!F8) | H17: =IF('Cisco Umbrella'!G8="","",'Cisco Umbrella'!G8) | I17: =IF('Cisco Umbrella'!H8="","",'Cisco Umbrella'!H8) | J17: =IF('Cisco Umbrella'!I8="","",'Cisco Umbrella'!I8) | ... M17: =IF('Cisco Umbrella'!L8="","",'Cisco Umbrella'!L8)
A18: =IF('Cisco ISE'!A3="","",'Cisco ISE'!A3) | B18: Cisco ISE | C18: =IF('Cisco ISE'!B3="","",'Cisco ISE'!B3) | D18: =IF('Cisco ISE'!C3="","",'Cisco ISE'!C3) | E18: =IF('Cisco ISE'!D3="","",'Cisco ISE'!D3) | F18: =IF('Cisco ISE'!E3="","",'Cisco ISE'!E3) | G18: =IF('Cisco ISE'!F3="","",'Cisco ISE'!F3) | H18: =IF('Cisco ISE'!G3="","",'Cisco ISE'!G3) | I18: =IF('Cisco ISE'!H3="","",'Cisco ISE'!H3) | J18: =IF('Cisco ISE'!I3="","",'Cisco ISE'!I3) | ... M18: =IF('Cisco ISE'!L3="","",'Cisco ISE'!L3)
A19: =IF('Cisco ISE'!A4="","",'Cisco ISE'!A4) | B19: Cisco ISE | C19: =IF('Cisco ISE'!B4="","",'Cisco ISE'!B4) | D19: =IF('Cisco ISE'!C4="","",'Cisco ISE'!C4) | E19: =IF('Cisco ISE'!D4="","",'Cisco ISE'!D4) | F19: =IF('Cisco ISE'!E4="","",'Cisco ISE'!E4) | G19: =IF('Cisco ISE'!F4="","",'Cisco ISE'!F4) | H19: =IF('Cisco ISE'!G4="","",'Cisco ISE'!G4) | I19: =IF('Cisco ISE'!H4="","",'Cisco ISE'!H4) | J19: =IF('Cisco ISE'!I4="","",'Cisco ISE'!I4) | ... M19: =IF('Cisco ISE'!L4="","",'Cisco ISE'!L4)
A20: =IF('Cisco ISE'!A5="","",'Cisco ISE'!A5) | B20: Cisco ISE | C20: =IF('Cisco ISE'!B5="","",'Cisco ISE'!B5) | D20: =IF('Cisco ISE'!C5="","",'Cisco ISE'!C5) | E20: =IF('Cisco ISE'!D5="","",'Cisco ISE'!D5) | F20: =IF('Cisco ISE'!E5="","",'Cisco ISE'!E5) | G20: =IF('Cisco ISE'!F5="","",'Cisco ISE'!F5) | H20: =IF('Cisco ISE'!G5="","",'Cisco ISE'!G5) | I20: =IF('Cisco ISE'!H5="","",'Cisco ISE'!H5) | J20: =IF('Cisco ISE'!I5="","",'Cisco ISE'!I5) | ... M20: =IF('Cisco ISE'!L5="","",'Cisco ISE'!L5)
A21: =IF('Cisco ISE'!A6="","",'Cisco ISE'!A6) | B21: Cisco ISE | C21: =IF('Cisco ISE'!B6="","",'Cisco ISE'!B6) | D21: =IF('Cisco ISE'!C6="","",'Cisco ISE'!C6) | E21: =IF('Cisco ISE'!D6="","",'Cisco ISE'!D6) | F21: =IF('Cisco ISE'!E6="","",'Cisco ISE'!E6) | G21: =IF('Cisco ISE'!F6="","",'Cisco ISE'!F6) | H21: =IF('Cisco ISE'!G6="","",'Cisco ISE'!G6) | I21: =IF('Cisco ISE'!H6="","",'Cisco ISE'!H6) | J21: =IF('Cisco ISE'!I6="","",'Cisco ISE'!I6) | ... M21: =IF('Cisco ISE'!L6="","",'Cisco ISE'!L6)
A22: =IF('Cisco ISE'!A7="","",'Cisco ISE'!A7) | B22: Cisco ISE | C22: =IF('Cisco ISE'!B7="","",'Cisco ISE'!B7) | D22: =IF('Cisco ISE'!C7="","",'Cisco ISE'!C7) | E22: =IF('Cisco ISE'!D7="","",'Cisco ISE'!D7) | F22: =IF('Cisco ISE'!E7="","",'Cisco ISE'!E7) | G22: =IF('Cisco ISE'!F7="","",'Cisco ISE'!F7) | H22: =IF('Cisco ISE'!G7="","",'Cisco ISE'!G7) | I22: =IF('Cisco ISE'!H7="","",'Cisco ISE'!H7) | J22: =IF('Cisco ISE'!I7="","",'Cisco ISE'!I7) | ... M22: =IF('Cisco ISE'!L7="","",'Cisco ISE'!L7)
A23: =IF('Cisco ISE'!A8="","",'Cisco ISE'!A8) | B23: Cisco ISE | C23: =IF('Cisco ISE'!B8="","",'Cisco ISE'!B8) | D23: =IF('Cisco ISE'!C8="","",'Cisco ISE'!C8) | E23: =IF('Cisco ISE'!D8="","",'Cisco ISE'!D8) | F23: =IF('Cisco ISE'!E8="","",'Cisco ISE'!E8) | G23: =IF('Cisco ISE'!F8="","",'Cisco ISE'!F8) | H23: =IF('Cisco ISE'!G8="","",'Cisco ISE'!G8) | I23: =IF('Cisco ISE'!H8="","",'Cisco ISE'!H8) | J23: =IF('Cisco ISE'!I8="","",'Cisco ISE'!I8) | ... M23: =IF('Cisco ISE'!L8="","",'Cisco ISE'!L8)
A24: =IF('Cisco ISE'!A9="","",'Cisco ISE'!A9) | B24: Cisco ISE | C24: =IF('Cisco ISE'!B9="","",'Cisco ISE'!B9) | D24: =IF('Cisco ISE'!C9="","",'Cisco ISE'!C9) | E24: =IF('Cisco ISE'!D9="","",'Cisco ISE'!D9) | F24: =IF('Cisco ISE'!E9="","",'Cisco ISE'!E9) | G24: =IF('Cisco ISE'!F9="","",'Cisco ISE'!F9) | H24: =IF('Cisco ISE'!G9="","",'Cisco ISE'!G9) | I24: =IF('Cisco ISE'!H9="","",'Cisco ISE'!H9) | J24: =IF('Cisco ISE'!I9="","",'Cisco ISE'!I9) | ... M24: =IF('Cisco ISE'!L9="","",'Cisco ISE'!L9)
A25: =IF('Cisco ISE'!A10="","",'Cisco ISE'!A10) | B25: Cisco ISE | C25: =IF('Cisco ISE'!B10="","",'Cisco ISE'!B10) | D25: =IF('Cisco ISE'!C10="","",'Cisco ISE'!C10) | E25: =IF('Cisco ISE'!D10="","",'Cisco ISE'!D10) | F25: =IF('Cisco ISE'!E10="","",'Cisco ISE'!E10) | G25: =IF('Cisco ISE'!F10="","",'Cisco ISE'!F10) | H25: =IF('Cisco ISE'!G10="","",'Cisco ISE'!G10) | I25: =IF('Cisco ISE'!H10="","",'Cisco ISE'!H10) | J25: =IF('Cisco ISE'!I10="","",'Cisco ISE'!I10) | ... M25: =IF('Cisco ISE'!L10="","",'Cisco ISE'!L10)
A26: =IF('Cisco AnyConnect'!A3="","",'Cisco AnyConnect'!A3) | B26: Cisco AnyConnect | C26: =IF('Cisco AnyConnect'!B3="","",'Cisco AnyConnect'!B3) | D26: =IF('Cisco AnyConnect'!C3="","",'Cisco AnyConnect'!C3) | E26: =IF('Cisco AnyConnect'!D3="","",'Cisco AnyConnect'!D3) | F26: =IF('Cisco AnyConnect'!E3="","",'Cisco AnyConnect'!E3) | G26: =IF('Cisco AnyConnect'!F3="","",'Cisco AnyConnect'!F3) | H26: =IF('Cisco AnyConnect'!G3="","",'Cisco AnyConnect'!G3) | I26: =IF('Cisco AnyConnect'!H3="","",'Cisco AnyConnect'!H3) | J26: =IF('Cisco AnyConnect'!I3="","",'Cisco AnyConnect'!I3) | ... M26: =IF('Cisco AnyConnect'!L3="","",'Cisco AnyConnect'!L3)
A27: =IF('Cisco AnyConnect'!A4="","",'Cisco AnyConnect'!A4) | B27: Cisco AnyConnect | C27: =IF('Cisco AnyConnect'!B4="","",'Cisco AnyConnect'!B4) | D27: =IF('Cisco AnyConnect'!C4="","",'Cisco AnyConnect'!C4) | E27: =IF('Cisco AnyConnect'!D4="","",'Cisco AnyConnect'!D4) | F27: =IF('Cisco AnyConnect'!E4="","",'Cisco AnyConnect'!E4) | G27: =IF('Cisco AnyConnect'!F4="","",'Cisco AnyConnect'!F4) | H27: =IF('Cisco AnyConnect'!G4="","",'Cisco AnyConnect'!G4) | I27: =IF('Cisco AnyConnect'!H4="","",'Cisco AnyConnect'!H4) | J27: =IF('Cisco AnyConnect'!I4="","",'Cisco AnyConnect'!I4) | ... M27: =IF('Cisco AnyConnect'!L4="","",'Cisco AnyConnect'!L4)
A28: =IF('Cisco AnyConnect'!A5="","",'Cisco AnyConnect'!A5) | B28: Cisco AnyConnect | C28: =IF('Cisco AnyConnect'!B5="","",'Cisco AnyConnect'!B5) | D28: =IF('Cisco AnyConnect'!C5="","",'Cisco AnyConnect'!C5) | E28: =IF('Cisco AnyConnect'!D5="","",'Cisco AnyConnect'!D5) | F28: =IF('Cisco AnyConnect'!E5="","",'Cisco AnyConnect'!E5) | G28: =IF('Cisco AnyConnect'!F5="","",'Cisco AnyConnect'!F5) | H28: =IF('Cisco AnyConnect'!G5="","",'Cisco AnyConnect'!G5) | I28: =IF('Cisco AnyConnect'!H5="","",'Cisco AnyConnect'!H5) | J28: =IF('Cisco AnyConnect'!I5="","",'Cisco AnyConnect'!I5) | ... M28: =IF('Cisco AnyConnect'!L5="","",'Cisco AnyConnect'!L5)
A29: =IF('Cisco AnyConnect'!A6="","",'Cisco AnyConnect'!A6) | B29: Cisco AnyConnect | C29: =IF('Cisco AnyConnect'!B6="","",'Cisco AnyConnect'!B6) | D29: =IF('Cisco AnyConnect'!C6="","",'Cisco AnyConnect'!C6) | E29: =IF('Cisco AnyConnect'!D6="","",'Cisco AnyConnect'!D6) | F29: =IF('Cisco AnyConnect'!E6="","",'Cisco AnyConnect'!E6) | G29: =IF('Cisco AnyConnect'!F6="","",'Cisco AnyConnect'!F6) | H29: =IF('Cisco AnyConnect'!G6="","",'Cisco AnyConnect'!G6) | I29: =IF('Cisco AnyConnect'!H6="","",'Cisco AnyConnect'!H6) | J29: =IF('Cisco AnyConnect'!I6="","",'Cisco AnyConnect'!I6) | ... M29: =IF('Cisco AnyConnect'!L6="","",'Cisco AnyConnect'!L6)
A30: =IF('Cisco AnyConnect'!A7="","",'Cisco AnyConnect'!A7) | B30: Cisco AnyConnect | C30: =IF('Cisco AnyConnect'!B7="","",'Cisco AnyConnect'!B7) | D30: =IF('Cisco AnyConnect'!C7="","",'Cisco AnyConnect'!C7) | E30: =IF('Cisco AnyConnect'!D7="","",'Cisco AnyConnect'!D7) | F30: =IF('Cisco AnyConnect'!E7="","",'Cisco AnyConnect'!E7) | G30: =IF('Cisco AnyConnect'!F7="","",'Cisco AnyConnect'!F7) | H30: =IF('Cisco AnyConnect'!G7="","",'Cisco AnyConnect'!G7) | I30: =IF('Cisco AnyConnect'!H7="","",'Cisco AnyConnect'!H7) | J30: =IF('Cisco AnyConnect'!I7="","",'Cisco AnyConnect'!I7) | ... M30: =IF('Cisco AnyConnect'!L7="","",'Cisco AnyConnect'!L7)
A31: =IF('Cisco SecureX'!A3="","",'Cisco SecureX'!A3) | B31: Cisco SecureX | C31: =IF('Cisco SecureX'!B3="","",'Cisco SecureX'!B3) | D31: =IF('Cisco SecureX'!C3="","",'Cisco SecureX'!C3) | E31: =IF('Cisco SecureX'!D3="","",'Cisco SecureX'!D3) | F31: =IF('Cisco SecureX'!E3="","",'Cisco SecureX'!E3) | G31: =IF('Cisco SecureX'!F3="","",'Cisco SecureX'!F3) | H31: =IF('Cisco SecureX'!G3="","",'Cisco SecureX'!G3) | I31: =IF('Cisco SecureX'!H3="","",'Cisco SecureX'!H3) | J31: =IF('Cisco SecureX'!I3="","",'Cisco SecureX'!I3) | ... M31: =IF('Cisco SecureX'!L3="","",'Cisco SecureX'!L3)
A32: =IF('Cisco SecureX'!A4="","",'Cisco SecureX'!A4) | B32: Cisco SecureX | C32: =IF('Cisco SecureX'!B4="","",'Cisco SecureX'!B4) | D32: =IF('Cisco SecureX'!C4="","",'Cisco SecureX'!C4) | E32: =IF('Cisco SecureX'!D4="","",'Cisco SecureX'!D4) | F32: =IF('Cisco SecureX'!E4="","",'Cisco SecureX'!E4) | G32: =IF('Cisco SecureX'!F4="","",'Cisco SecureX'!F4) | H32: =IF('Cisco SecureX'!G4="","",'Cisco SecureX'!G4) | I32: =IF('Cisco SecureX'!H4="","",'Cisco SecureX'!H4) | J32: =IF('Cisco SecureX'!I4="","",'Cisco SecureX'!I4) | ... M32: =IF('Cisco SecureX'!L4="","",'Cisco SecureX'!L4)
A33: =IF('Cisco SecureX'!A5="","",'Cisco SecureX'!A5) | B33: Cisco SecureX | C33: =IF('Cisco SecureX'!B5="","",'Cisco SecureX'!B5) | D33: =IF('Cisco SecureX'!C5="","",'Cisco SecureX'!C5) | E33: =IF('Cisco SecureX'!D5="","",'Cisco SecureX'!D5) | F33: =IF('Cisco SecureX'!E5="","",'Cisco SecureX'!E5) | G33: =IF('Cisco SecureX'!F5="","",'Cisco SecureX'!F5) | H33: =IF('Cisco SecureX'!G5="","",'Cisco SecureX'!G5) | I33: =IF('Cisco SecureX'!H5="","",'Cisco SecureX'!H5) | J33: =IF('Cisco SecureX'!I5="","",'Cisco SecureX'!I5) | ... M33: =IF('Cisco SecureX'!L5="","",'Cisco SecureX'!L5)
A34: =IF('Cisco SecureX'!A6="","",'Cisco SecureX'!A6) | B34: Cisco SecureX | C34: =IF('Cisco SecureX'!B6="","",'Cisco SecureX'!B6) | D34: =IF('Cisco SecureX'!C6="","",'Cisco SecureX'!C6) | E34: =IF('Cisco SecureX'!D6="","",'Cisco SecureX'!D6) | F34: =IF('Cisco SecureX'!E6="","",'Cisco SecureX'!E6) | G34: =IF('Cisco SecureX'!F6="","",'Cisco SecureX'!F6) | H34: =IF('Cisco SecureX'!G6="","",'Cisco SecureX'!G6) | I34: =IF('Cisco SecureX'!H6="","",'Cisco SecureX'!H6) | J34: =IF('Cisco SecureX'!I6="","",'Cisco SecureX'!I6) | ... M34: =IF('Cisco SecureX'!L6="","",'Cisco SecureX'!L6)
A35: =IF('Active Directory'!A3="","",'Active Directory'!A3) | B35: Active Directory | C35: =IF('Active Directory'!B3="","",'Active Directory'!B3) | D35: =IF('Active Directory'!C3="","",'Active Directory'!C3) | E35: =IF('Active Directory'!D3="","",'Active Directory'!D3) | F35: =IF('Active Directory'!E3="","",'Active Directory'!E3) | G35: =IF('Active Directory'!F3="","",'Active Directory'!F3) | H35: =IF('Active Directory'!G3="","",'Active Directory'!G3) | I35: =IF('Active Directory'!H3="","",'Active Directory'!H3) | J35: =IF('Active Directory'!I3="","",'Active Directory'!I3) | ... M35: =IF('Active Directory'!L3="","",'Active Directory'!L3)
A36: =IF('Active Directory'!A4="","",'Active Directory'!A4) | B36: Active Directory | C36: =IF('Active Directory'!B4="","",'Active Directory'!B4) | D36: =IF('Active Directory'!C4="","",'Active Directory'!C4) | E36: =IF('Active Directory'!D4="","",'Active Directory'!D4) | F36: =IF('Active Directory'!E4="","",'Active Directory'!E4) | G36: =IF('Active Directory'!F4="","",'Active Directory'!F4) | H36: =IF('Active Directory'!G4="","",'Active Directory'!G4) | I36: =IF('Active Directory'!H4="","",'Active Directory'!H4) | J36: =IF('Active Directory'!I4="","",'Active Directory'!I4) | ... M36: =IF('Active Directory'!L4="","",'Active Directory'!L4)
A37: =IF('Active Directory'!A5="","",'Active Directory'!A5) | B37: Active Directory | C37: =IF('Active Directory'!B5="","",'Active Directory'!B5) | D37: =IF('Active Directory'!C5="","",'Active Directory'!C5) | E37: =IF('Active Directory'!D5="","",'Active Directory'!D5) | F37: =IF('Active Directory'!E5="","",'Active Directory'!E5) | G37: =IF('Active Directory'!F5="","",'Active Directory'!F5) | H37: =IF('Active Directory'!G5="","",'Active Directory'!G5) | I37: =IF('Active Directory'!H5="","",'Active Directory'!H5) | J37: =IF('Active Directory'!I5="","",'Active Directory'!I5) | ... M37: =IF('Active Directory'!L5="","",'Active Directory'!L5)
A38: =IF('Active Directory'!A6="","",'Active Directory'!A6) | B38: Active Directory | C38: =IF('Active Directory'!B6="","",'Active Directory'!B6) | D38: =IF('Active Directory'!C6="","",'Active Directory'!C6) | E38: =IF('Active Directory'!D6="","",'Active Directory'!D6) | F38: =IF('Active Directory'!E6="","",'Active Directory'!E6) | G38: =IF('Active Directory'!F6="","",'Active Directory'!F6) | H38: =IF('Active Directory'!G6="","",'Active Directory'!G6) | I38: =IF('Active Directory'!H6="","",'Active Directory'!H6) | J38: =IF('Active Directory'!I6="","",'Active Directory'!I6) | ... M38: =IF('Active Directory'!L6="","",'Active Directory'!L6)
A39: =IF('Active Directory'!A7="","",'Active Directory'!A7) | B39: Active Directory | C39: =IF('Active Directory'!B7="","",'Active Directory'!B7) | D39: =IF('Active Directory'!C7="","",'Active Directory'!C7) | E39: =IF('Active Directory'!D7="","",'Active Directory'!D7) | F39: =IF('Active Directory'!E7="","",'Active Directory'!E7) | G39: =IF('Active Directory'!F7="","",'Active Directory'!F7) | H39: =IF('Active Directory'!G7="","",'Active Directory'!G7) | I39: =IF('Active Directory'!H7="","",'Active Directory'!H7) | J39: =IF('Active Directory'!I7="","",'Active Directory'!I7) | ... M39: =IF('Active Directory'!L7="","",'Active Directory'!L7)
A40: =IF('Active Directory'!A8="","",'Active Directory'!A8) | B40: Active Directory | C40: =IF('Active Directory'!B8="","",'Active Directory'!B8) | D40: =IF('Active Directory'!C8="","",'Active Directory'!C8) | E40: =IF('Active Directory'!D8="","",'Active Directory'!D8) | F40: =IF('Active Directory'!E8="","",'Active Directory'!E8) | G40: =IF('Active Directory'!F8="","",'Active Directory'!F8) | H40: =IF('Active Directory'!G8="","",'Active Directory'!G8) | I40: =IF('Active Directory'!H8="","",'Active Directory'!H8) | J40: =IF('Active Directory'!I8="","",'Active Directory'!I8) | ... M40: =IF('Active Directory'!L8="","",'Active Directory'!L8)
A41: =IF('SAML-SSO'!A3="","",'SAML-SSO'!A3) | B41: SAML/SSO | C41: =IF('SAML-SSO'!B3="","",'SAML-SSO'!B3) | D41: =IF('SAML-SSO'!C3="","",'SAML-SSO'!C3) | E41: =IF('SAML-SSO'!D3="","",'SAML-SSO'!D3) | F41: =IF('SAML-SSO'!E3="","",'SAML-SSO'!E3) | G41: =IF('SAML-SSO'!F3="","",'SAML-SSO'!F3) | H41: =IF('SAML-SSO'!G3="","",'SAML-SSO'!G3) | I41: =IF('SAML-SSO'!H3="","",'SAML-SSO'!H3) | J41: =IF('SAML-SSO'!I3="","",'SAML-SSO'!I3) | ... M41: =IF('SAML-SSO'!L3="","",'SAML-SSO'!L3)
...

Sheet Cisco Duo
A1: Cisco Duo Parameters
A2: Parameter Name | B2: Environment | C2: Default Value | D2: Description | E2: Required | F2: Data Type | G2: Validation Rules | H2: Security Level | I2: Owner Team | J2: Dependencies | K2: Notes | L2: Last Updated
A3: DUO_API_HOSTNAME | B3: All | C3: [********] | D3: Duo API hostname for authentication | E3: Yes | F3: String | G3: Valid Duo API hostname | H3: Confidential | I3: Security Team | J3: Duo account | K3: From Duo Admin Panel | L3: [DATE]
A4: DUO_INTEGRATION_KEY | B4: All | C4: [********] | D4: Duo application integration key | E4: Yes | F4: String | G4: Valid integration key format | H4: Secret | I4: Security Team | J4: DUO_API_HOSTNAME | K4: Per application type | L4: [DATE]
A5: DUO_SECRET_KEY | B5: All | C5: [********] | D5: Duo application secret key | E5: Yes | F5: String | G5: Valid secret key format | H5: Secret | I5: Security Team | J5: DUO_INTEGRATION_KEY | K5: Securely stored | L5: [DATE]
A6: DUO_ADMIN_HOSTNAME | B6: All | C6: [********] | D6: Duo admin API hostname | E6: Yes | F6: String | G6: Valid admin API hostname | H6: Confidential | I6: Security Team | J6: Duo account | K6: For user management | L6: [DATE]
A7: DUO_ENROLLMENT_METHOD | B7: All | C7: self-service | D7: User enrollment method | E7: Yes | F7: String | G7: self-service|admin-initiated | H7: Public | I7: Security Team | J7: None | K7: Self-service recommended | L7: [DATE]
A8: DUO_POLICY_DEFAULT | B8: All | C8: adaptive | D8: Default authentication policy | E8: Yes | F8: String | G8: allow|deny|adaptive | H8: Public | I8: Security Team | J8: None | K8: Risk-based authentication | L8: [DATE]
A9: DUO_DEVICE_TRUST | B9: All | C9: enabled | D9: Enable device health verification | E9: Yes | F9: Boolean | G9: true|false | H9: Public | I9: Security Team | J9: Endpoint agents | K9: Requires Duo Health App | L9: [DATE]

Sheet Cisco Umbrella
A1: Cisco Umbrella Parameters
A2: Parameter Name | B2: Environment | C2: Default Value | D2: Description | E2: Required | F2: Data Type | G2: Validation Rules | H2: Security Level | I2: Owner Team | J2: Dependencies | K2: Notes | L2: Last Updated
A3: UMBRELLA_ORG_ID | B3: All | C3: [********] | D3: Umbrella organization identifier | E3: Yes | F3: String | G3: Valid org ID | H3: Confidential | I3: Security Team | J3: Umbrella account | K3: From dashboard | L3: [DATE]
A4: UMBRELLA_API_KEY | B4: All | C4: [********] | D4: Umbrella API key for integration | E4: Yes | F4: String | G4: Valid API key format | H4: Secret | I4: Security Team | J4: UMBRELLA_ORG_ID | K4: Management API | L4: [DATE]
A5: UMBRELLA_SECRET | B5: All | C5: [********] | D5: Umbrella API secret | E5: Yes | F5: String | G5: Valid secret format | H5: Secret | I5: Security Team | J5: UMBRELLA_API_KEY | K5: Securely stored | L5: [DATE]
A6: UMBRELLA_POLICY_DEFAULT | B6: All | C6: block-malware | D6: Default DNS security policy | E6: Yes | F6: String | G6: Valid policy name | H6: Public | I6: Security Team | J6: None | K6: Block known threats | L6: [DATE]
A7: UMBRELLA_SWG_ENABLED | B7: All | C7: true | D7: Enable Secure Web Gateway | E7: Yes | F7: Boolean | G7: true|false | H7: Public | I7: Security Team | J7: Cloud connector | K7: Full proxy inspection | L7: [DATE]
A8: UMBRELLA_ROAMING_CLIENT | B8: All | C8: true | D8: Deploy roaming client to endpoints | E8: Yes | F8: Boolean | G8: true|false | H8: Public | I8: Security Team | J8: Endpoint access | K8: Off-network protection | L8: [DATE]

Sheet Cisco ISE
A1: Cisco ISE Parameters
A2: Parameter Name | B2: Environment | C2: Default Value | D2: Description | E2: Required | F2: Data Type | G2: Validation Rules | H2: Security Level | I2: Owner Team | J2: Dependencies | K2: Notes | L2: Last Updated
A3: ISE_PRIMARY_PAN | B3: All | C3: [********] | D3: Primary Policy Administration Node | E3: Yes | F3: String | G3: Valid FQDN | H3: Confidential | I3: Network Team | J3: Network connectivity | K3: Management interface | L3: [DATE]
A4: ISE_SECONDARY_PAN | B4: All | C4: [********] | D4: Secondary PAN for HA | E4: No | F4: String | G4: Valid FQDN | H4: Confidential | I4: Network Team | J4: ISE_PRIMARY_PAN | K4: High availability | L4: [DATE]
A5: ISE_PSN_NODES | B5: All | C5: [********] | D5: Policy Service Nodes | E5: Yes | F5: String | G5: Space-separated FQDNs | H5: Confidential | I5: Network Team | J5: ISE_PRIMARY_PAN | K5: RADIUS authentication | L5: [DATE]
A6: ISE_ADMIN_USER | B6: All | C6: [********] | D6: ISE administrative username | E6: Yes | F6: String | G6: Valid username | H6: Confidential | I6: Network Team | J6: ISE deployment | K6: Initial admin | L6: [DATE]
A7: ISE_RADIUS_SECRET | B7: All | C7: [********] | D7: RADIUS shared secret | E7: Yes | F7: String | G7: Min 16 characters | H7: Secret | I7: Network Team | J7: Network devices | K7: Per device group | L7: [DATE]
A8: ISE_AD_JOIN_POINT | B8: All | C8: [********] | D8: Active Directory join point | E8: Yes | F8: String | G8: Valid AD domain | H8: Confidential | I8: Network Team | J8: AD connectivity | K8: For identity lookup | L8: [DATE]
A9: ISE_GUEST_PORTAL | B9: All | C9: enabled | D9: Enable guest access portal | E9: Yes | F9: Boolean | G9: true|false | H9: Public | I9: Network Team | J9: ISE deployment | K9: Sponsor-based access | L9: [DATE]
A10: ISE_POSTURE_POLICY | B10: All | C10: corporate-compliance | D10: Default posture assessment policy | E10: Yes | F10: String | G10: Valid policy name | H10: Public | I10: Security Team | J10: ISE_PRIMARY_PAN | K10: Endpoint compliance | L10: [DATE]

Sheet Cisco AnyConnect
A1: Cisco AnyConnect Parameters
A2: Parameter Name | B2: Environment | C2: Default Value | D2: Description | E2: Required | F2: Data Type | G2: Validation Rules | H2: Security Level | I2: Owner Team | J2: Dependencies | K2: Notes | L2: Last Updated
A3: ANYCONNECT_HEADEND | B3: All | C3: [********] | D3: AnyConnect VPN headend FQDN | E3: Yes | F3: String | G3: Valid FQDN | H3: Confidential | I3: Network Team | J3: ASA/FTD device | K3: Public DNS required | L3: [DATE]
A4: ANYCONNECT_GROUP_URL | B4: All | C4: [********] | D4: Connection profile URL | E4: Yes | F4: String | G4: Valid HTTPS URL | H4: Confidential | I4: Network Team | J4: ANYCONNECT_HEADEND | K4: User connection URL | L4: [DATE]
A5: ANYCONNECT_PROFILE | B5: All | C5: secure-access-profile | D5: VPN connection profile name | E5: Yes | F5: String | G5: Valid profile name | H5: Public | I5: Network Team | J5: VPN config | K5: XML profile | L5: [DATE]
A6: ANYCONNECT_POSTURE | B6: All | C6: enabled | D6: Enable posture assessment module | E6: Yes | F6: Boolean | G6: true|false | H6: Public | I6: Security Team | J6: ISE integration | K6: Endpoint compliance | L6: [DATE]
A7: ANYCONNECT_UMBRELLA | B7: All | C7: enabled | D7: Enable Umbrella roaming module | E7: Yes | F7: Boolean | G7: true|false | H7: Public | I7: Security Team | J7: Umbrella config | K7: DNS protection | L7: [DATE]

Sheet Cisco SecureX
A1: Cisco SecureX Parameters
A2: Parameter Name | B2: Environment | C2: Default Value | D2: Description | E2: Required | F2: Data Type | G2: Validation Rules | H2: Security Level | I2: Owner Team | J2: Dependencies | K2: Notes | L2: Last Updated
A3: SECUREX_TENANT | B3: All | C3: [********] | D3: SecureX tenant identifier | E3: Yes | F3: String | G3: Valid tenant ID | H3: Confidential | I3: Security Team | J3: SecureX account | K3: From admin console | L3: [DATE]
A4: SECUREX_API_CLIENT | B4: All | C4: [********] | D4: SecureX API client ID | E4: Yes | F4: String | G4: Valid client ID | H4: Confidential | I4: Security Team | J4: SECUREX_TENANT | K4: For API access | L4: [DATE]
A5: SECUREX_API_SECRET | B5: All | C5: [********] | D5: SecureX API client secret | E5: Yes | F5: String | G5: Valid secret format | H5: Secret | I5: Security Team | J5: SECUREX_API_CLIENT | K5: Securely stored | L5: [DATE]
A6: SECUREX_DASHBOARD_URL | B6: All | C6: securex.cisco.com | D6: SecureX dashboard URL | E6: Yes | F6: String | G6: Valid URL | H6: Public | I6: Security Team | J6: SECUREX_TENANT | K6: SOC dashboard | L6: [DATE]

Sheet Active Directory
A1: Active Directory Parameters
A2: Parameter Name | B2: Environment | C2: Default Value | D2: Description | E2: Required | F2: Data Type | G2: Validation Rules | H2: Security Level | I2: Owner Team | J2: Dependencies | K2: Notes | L2: Last Updated
A3: AD_DOMAIN | B3: All | C3: [********] | D3: Active Directory domain name | E3: Yes | F3: String | G3: Valid domain format | H3: Confidential | I3: Security Team | J3: None | K3: User authentication | L3: [DATE]
A4: AD_SERVER_PRIMARY | B4: All | C4: [********] | D4: Primary AD domain controller | E4: Yes | F4: String | G4: Valid IPv4 address | H4: Confidential | I4: Security Team | J4: Network connectivity | K4: LDAPS recommended | L4: [DATE]
A5: AD_SERVER_SECONDARY | B5: All | C5: [********] | D5: Secondary AD domain controller | E5: No | F5: String | G5: Valid IPv4 address | H5: Confidential | I5: Security Team | J5: Network connectivity | K5: Failover | L5: [DATE]
A6: AD_SERVICE_ACCOUNT | B6: All | C6: [********] | D6: Service account for Cisco products | E6: Yes | F6: String | G6: Valid username | H6: Confidential | I6: Security Team | J6: AD account created | K6: Read access to AD | L6: [DATE]
A7: AD_BIND_DN | B7: All | C7: [********] | D7: LDAP bind distinguished name | E7: Yes | F7: String | G7: Valid DN format | H7: Confidential | I7: Security Team | J7: AD_SERVICE_ACCOUNT | K7: For LDAP queries | L7: [DATE]
A8: AD_USER_GROUP | B8: All | C8: Cisco-Secure-Access-Users | D8: AD group for authorized users | E8: Yes | F8: String | G8: Valid group name | H8: Public | I8: Security Team | J8: AD group created | K8: User scope | L8: [DATE]

Sheet SAML-SSO
A1: SAML/SSO Parameters
A2: Parameter Name | B2: Environment | C2: Default Value | D2: Description | E2: Required | F2: Data Type | G2: Validation Rules | H2: Security Level | I2: Owner Team | J2: Dependencies | K2: Notes | L2: Last Updated
A3: SAML_IDP_ENTITY | B3: All | C3: [********] | D3: SAML Identity Provider entity ID | E3: Yes | F3: String | G3: Valid URI | H3: Confidential | I3: Security Team | J3: IdP configuration | K3: Metadata exchange | L3: [DATE]
A4: SAML_SSO_URL | B4: All | C4: [********] | D4: SAML SSO endpoint URL | E4: Yes | F4: String | G4: Valid HTTPS URL | H4: Confidential | I4: Security Team | J4: SAML_IDP_ENTITY | K4: Authentication endpoint | L4: [DATE]
A5: SAML_CERTIFICATE | B5: All | C5: [********] | D5: SAML signing certificate | E5: Yes | F5: String | G5: Valid X.509 certificate | H5: Secret | I5: Security Team | J5: IdP certificate | K5: For signature validation | L5: [DATE]

Sheet Monitoring
A1: Monitoring Parameters
A2: Parameter Name | B2: Environment | C2: Default Value | D2: Description | E2: Required | F2: Data Type | G2: Validation Rules | H2: Security Level | I2: Owner Team | J2: Dependencies | K2: Notes | L2: Last Updated
A3: SIEM_SERVER | B3: All | C3: [********] | D3: SIEM server hostname | E3: Yes | F3: String | G3: Valid hostname or IP | H3: Confidential | I3: Security Team | J3: Network connectivity | K3: Log aggregation | L3: [DATE]
A4: SIEM_PORT | B4: All | C4: 514 | D4: Syslog port for SIEM | E4: Yes | F4: Integer | G4: Valid port number | H4: Public | I4: Security Team | J4: Firewall rules | K4: UDP or TCP | L4: [DATE]
A5: SIEM_PROTOCOL | B5: All | C5: tcp-tls | D5: Syslog transport protocol | E5: Yes | F5: String | G5: udp|tcp|tcp-tls | H5: Public | I5: Security Team | J5: Certificate config | K5: TLS recommended | L5: [DATE]
A6: SYSLOG_FACILITY | B6: All | C6: local0 | D6: Syslog facility code | E6: Yes | F6: String | G6: Valid syslog facility | H6: Public | I6: Security Team | J6: SIEM configuration | K6: Log categorization | L6: [DATE]

Sheet Infrastructure
A1: Infrastructure Parameters
A2: Parameter Name | B2: Environment | C2: Default Value | D2: Description | E2: Required | F2: Data Type | G2: Validation Rules | H2: Security Level | I2: Owner Team | J2: Dependencies | K2: Notes | L2: Last Updated
A3: NTP_SERVER_PRIMARY | B3: All | C3: [********] | D3: Primary NTP server | E3: Yes | F3: String | G3: Valid IPv4 address | H3: Confidential | I3: Infrastructure Team | J3: Network connectivity | K3: Time synchronization | L3: [DATE]
A4: DNS_SERVER_PRIMARY | B4: All | C4: [********] | D4: Primary DNS server | E4: Yes | F4: String | G4: Valid IPv4 address | H4: Confidential | I4: Infrastructure Team | J4: Network connectivity | K4: Name resolution | L4: [DATE]

Sheet Alerts
A1: Notifications Parameters
A2: Parameter Name | B2: Environment | C2: Default Value | D2: Description | E2: Required | F2: Data Type | G2: Validation Rules | H2: Security Level | I2: Owner Team | J2: Dependencies | K2: Notes | L2: Last Updated
A3: ALERT_EMAIL_RECIPIENTS | B3: All | C3: [********] | D3: Email recipients for security alerts | E3: Yes | F3: String | G3: Valid email addresses | H3: Confidential | I3: Security Team | J3: SMTP relay | K3: SOC distribution | L3: [DATE]

Sheet Support
A1: Support Parameters
A2: Parameter Name | B2: Environment | C2: Default Value | D2: Description | E2: Required | F2: Data Type | G2: Validation Rules | H2: Security Level | I2: Owner Team | J2: Dependencies | K2: Notes | L2: Last Updated
A3: CISCO_SMARTNET_CONTRACT | B3: All | C3: [********] | D3: Cisco SmartNet contract number | E3: Yes | F3: String | G3: Valid contract ID | H3: Confidential | I3: Support Team | J3: Vendor relationship | K3: 24x7 support | L3: [DATE]
