Workbook

Sheet Cover
B3: Configuration Parameters
B5: Generated: | C5: December 03, 2025
B6: Solution: | C6: Virtual Wan Global
B7: Customer: | C7: [Customer Name]
B8: Version: | C8: 1.0
B9: Status: | C9: Draft
C12: eoframework.org

Sheet All Parameters (Read Only)
A1: Total Parameters | B1: Categories | C1: Required | D1: Confidential/Secret
A2: 41 | B2: 5 | C2: 40 | D2: 3
A4: Parameter Name | B4: Category | C4: Production | D4: Test | E4: DR | F4: Description | G4: Required | H4: Data Type | I4: Validation Rules | J4: Security Level
A5: =IF('Project'!A3="","",'Project'!A3) | B5: Project | C5: =IF('Project'!B3="","",'Project'!B3) | D5: =IF('Project'!C3="","",'Project'!C3) | E5: =IF('Project'!D3="","",'Project'!D3) | F5: =IF('Project'!E3="","",'Project'!E3) | G5: =IF('Project'!F3="","",'Project'!F3) | H5: =IF('Project'!G3="","",'Project'!G3) | I5: =IF('Project'!H3="","",'Project'!H3) | J5: =IF('Project'!I3="","",'Project'!I3)
A6: =IF('Project'!A4="","",'Project'!A4) | B6: Project | C6: =IF('Project'!B4="","",'Project'!B4) | D6: =IF('Project'!C4="","",'Project'!C4) | E6: =IF('Project'!D4="","",'Project'!D4) | F6: =IF('Project'!E4="","",'Project'!E4) | G6: =IF('Project'!F4="","",'Project'!F4) | H6: =IF('Project'!G4="","",'Project'!G4) | I6: =IF('Project'!H4="","",'Project'!H4) | J6: =IF('Project'!I4="","",'Project'!I4)
A7: =IF('Project'!A5="","",'Project'!A5) | B7: Project | C7: =IF('Project'!B5="","",'Project'!B5) | D7: =IF('Project'!C5="","",'Project'!C5) | E7: =IF('Project'!D5="","",'Project'!D5) | F7: =IF('Project'!E5="","",'Project'!E5) | G7: =IF('Project'!F5="","",'Project'!F5) | H7: =IF('Project'!G5="","",'Project'!G5) | I7: =IF('Project'!H5="","",'Project'!H5) | J7: =IF('Project'!I5="","",'Project'!I5)
A8: =IF('Project'!A6="","",'Project'!A6) | B8: Project | C8: =IF('Project'!B6="","",'Project'!B6) | D8: =IF('Project'!C6="","",'Project'!C6) | E8: =IF('Project'!D6="","",'Project'!D6) | F8: =IF('Project'!E6="","",'Project'!E6) | G8: =IF('Project'!F6="","",'Project'!F6) | H8: =IF('Project'!G6="","",'Project'!G6) | I8: =IF('Project'!H6="","",'Project'!H6) | J8: =IF('Project'!I6="","",'Project'!I6)
A9: =IF('Project'!A7="","",'Project'!A7) | B9: Project | C9: =IF('Project'!B7="","",'Project'!B7) | D9: =IF('Project'!C7="","",'Project'!C7) | E9: =IF('Project'!D7="","",'Project'!D7) | F9: =IF('Project'!E7="","",'Project'!E7) | G9: =IF('Project'!F7="","",'Project'!F7) | H9: =IF('Project'!G7="","",'Project'!G7) | I9: =IF('Project'!H7="","",'Project'!H7) | J9: =IF('Project'!I7="","",'Project'!I7)
A10: =IF('Project'!A8="","",'Project'!A8) | B10: Project | C10: =IF('Project'!B8="","",'Project'!B8) | D10: =IF('Project'!C8="","",'Project'!C8) | E10: =IF('Project'!D8="","",'Project'!D8) | F10: =IF('Project'!E8="","",'Project'!E8) | G10: =IF('Project'!F8="","",'Project'!F8) | H10: =IF('Project'!G8="","",'Project'!G8) | I10: =IF('Project'!H8="","",'Project'!H8) | J10: =IF('Project'!I8="","",'Project'!I8)
A11: =IF('Project'!A9="","",'Project'!A9) | B11: Project | C11: =IF('Project'!B9="","",'Project'!B9) | D11: =IF('Project'!C9="","",'Project'!C9) | E11: =IF('Project'!D9="","",'Project'!D9) | F11: =IF('Project'!E9="","",'Project'!E9) | G11: =IF('Project'!F9="","",'Project'!F9) | H11: =IF('Project'!G9="","",'Project'!G9) | I11: =IF('Project'!H9="","",'Project'!H9) | J11: =IF('Project'!I9="","",'Project'!I9)
A12: =IF('Project'!A10="","",'Project'!A10) | B12: Project | C12: =IF('Project'!B10="","",'Project'!B10) | D12: =IF('Project'!C10="","",'Project'!C10) | E12: =IF('Project'!D10="","",'Project'!D10) | F12: =IF('Project'!E10="","",'Project'!E10) | G12: =IF('Project'!F10="","",'Project'!F10) | H12: =IF('Project'!G10="","",'Project'!G10) | I12: =IF('Project'!H10="","",'Project'!H10) | J12: =IF('Project'!I10="","",'Project'!I10)
A13: =IF('Project'!A11="","",'Project'!A11) | B13: Project | C13: =IF('Project'!B11="","",'Project'!B11) | D13: =IF('Project'!C11="","",'Project'!C11) | E13: =IF('Project'!D11="","",'Project'!D11) | F13: =IF('Project'!E11="","",'Project'!E11) | G13: =IF('Project'!F11="","",'Project'!F11) | H13: =IF('Project'!G11="","",'Project'!G11) | I13: =IF('Project'!H11="","",'Project'!H11) | J13: =IF('Project'!I11="","",'Project'!I11)
A14: =IF('Project'!A12="","",'Project'!A12) | B14: Project | C14: =IF('Project'!B12="","",'Project'!B12) | D14: =IF('Project'!C12="","",'Project'!C12) | E14: =IF('Project'!D12="","",'Project'!D12) | F14: =IF('Project'!E12="","",'Project'!E12) | G14: =IF('Project'!F12="","",'Project'!F12) | H14: =IF('Project'!G12="","",'Project'!G12) | I14: =IF('Project'!H12="","",'Project'!H12) | J14: =IF('Project'!I12="","",'Project'!I12)
A15: =IF('Project'!A13="","",'Project'!A13) | B15: Project | C15: =IF('Project'!B13="","",'Project'!B13) | D15: =IF('Project'!C13="","",'Project'!C13) | E15: =IF('Project'!D13="","",'Project'!D13) | F15: =IF('Project'!E13="","",'Project'!E13) | G15: =IF('Project'!F13="","",'Project'!F13) | H15: =IF('Project'!G13="","",'Project'!G13) | I15: =IF('Project'!H13="","",'Project'!H13) | J15: =IF('Project'!I13="","",'Project'!I13)
A16: =IF('Security'!A3="","",'Security'!A3) | B16: Security | C16: =IF('Security'!B3="","",'Security'!B3) | D16: =IF('Security'!C3="","",'Security'!C3) | E16: =IF('Security'!D3="","",'Security'!D3) | F16: =IF('Security'!E3="","",'Security'!E3) | G16: =IF('Security'!F3="","",'Security'!F3) | H16: =IF('Security'!G3="","",'Security'!G3) | I16: =IF('Security'!H3="","",'Security'!H3) | J16: =IF('Security'!I3="","",'Security'!I3)
A17: =IF('Security'!A4="","",'Security'!A4) | B17: Security | C17: =IF('Security'!B4="","",'Security'!B4) | D17: =IF('Security'!C4="","",'Security'!C4) | E17: =IF('Security'!D4="","",'Security'!D4) | F17: =IF('Security'!E4="","",'Security'!E4) | G17: =IF('Security'!F4="","",'Security'!F4) | H17: =IF('Security'!G4="","",'Security'!G4) | I17: =IF('Security'!H4="","",'Security'!H4) | J17: =IF('Security'!I4="","",'Security'!I4)
A18: =IF('Security'!A5="","",'Security'!A5) | B18: Security | C18: =IF('Security'!B5="","",'Security'!B5) | D18: =IF('Security'!C5="","",'Security'!C5) | E18: =IF('Security'!D5="","",'Security'!D5) | F18: =IF('Security'!E5="","",'Security'!E5) | G18: =IF('Security'!F5="","",'Security'!F5) | H18: =IF('Security'!G5="","",'Security'!G5) | I18: =IF('Security'!H5="","",'Security'!H5) | J18: =IF('Security'!I5="","",'Security'!I5)
A19: =IF('Security'!A6="","",'Security'!A6) | B19: Security | C19: =IF('Security'!B6="","",'Security'!B6) | D19: =IF('Security'!C6="","",'Security'!C6) | E19: =IF('Security'!D6="","",'Security'!D6) | F19: =IF('Security'!E6="","",'Security'!E6) | G19: =IF('Security'!F6="","",'Security'!F6) | H19: =IF('Security'!G6="","",'Security'!G6) | I19: =IF('Security'!H6="","",'Security'!H6) | J19: =IF('Security'!I6="","",'Security'!I6)
A20: =IF('Security'!A7="","",'Security'!A7) | B20: Security | C20: =IF('Security'!B7="","",'Security'!B7) | D20: =IF('Security'!C7="","",'Security'!C7) | E20: =IF('Security'!D7="","",'Security'!D7) | F20: =IF('Security'!E7="","",'Security'!E7) | G20: =IF('Security'!F7="","",'Security'!F7) | H20: =IF('Security'!G7="","",'Security'!G7) | I20: =IF('Security'!H7="","",'Security'!H7) | J20: =IF('Security'!I7="","",'Security'!I7)
A21: =IF('Security'!A8="","",'Security'!A8) | B21: Security | C21: =IF('Security'!B8="","",'Security'!B8) | D21: =IF('Security'!C8="","",'Security'!C8) | E21: =IF('Security'!D8="","",'Security'!D8) | F21: =IF('Security'!E8="","",'Security'!E8) | G21: =IF('Security'!F8="","",'Security'!F8) | H21: =IF('Security'!G8="","",'Security'!G8) | I21: =IF('Security'!H8="","",'Security'!H8) | J21: =IF('Security'!I8="","",'Security'!I8)
A22: =IF('Security'!A9="","",'Security'!A9) | B22: Security | C22: =IF('Security'!B9="","",'Security'!B9) | D22: =IF('Security'!C9="","",'Security'!C9) | E22: =IF('Security'!D9="","",'Security'!D9) | F22: =IF('Security'!E9="","",'Security'!E9) | G22: =IF('Security'!F9="","",'Security'!F9) | H22: =IF('Security'!G9="","",'Security'!G9) | I22: =IF('Security'!H9="","",'Security'!H9) | J22: =IF('Security'!I9="","",'Security'!I9)
A23: =IF('Security'!A10="","",'Security'!A10) | B23: Security | C23: =IF('Security'!B10="","",'Security'!B10) | D23: =IF('Security'!C10="","",'Security'!C10) | E23: =IF('Security'!D10="","",'Security'!D10) | F23: =IF('Security'!E10="","",'Security'!E10) | G23: =IF('Security'!F10="","",'Security'!F10) | H23: =IF('Security'!G10="","",'Security'!G10) | I23: =IF('Security'!H10="","",'Security'!H10) | J23: =IF('Security'!I10="","",'Security'!I10)
A24: =IF('Monitoring'!A3="","",'Monitoring'!A3) | B24: Monitoring | C24: =IF('Monitoring'!B3="","",'Monitoring'!B3) | D24: =IF('Monitoring'!C3="","",'Monitoring'!C3) | E24: =IF('Monitoring'!D3="","",'Monitoring'!D3) | F24: =IF('Monitoring'!E3="","",'Monitoring'!E3) | G24: =IF('Monitoring'!F3="","",'Monitoring'!F3) | H24: =IF('Monitoring'!G3="","",'Monitoring'!G3) | I24: =IF('Monitoring'!H3="","",'Monitoring'!H3) | J24: =IF('Monitoring'!I3="","",'Monitoring'!I3)
A25: =IF('Monitoring'!A4="","",'Monitoring'!A4) | B25: Monitoring | C25: =IF('Monitoring'!B4="","",'Monitoring'!B4) | D25: =IF('Monitoring'!C4="","",'Monitoring'!C4) | E25: =IF('Monitoring'!D4="","",'Monitoring'!D4) | F25: =IF('Monitoring'!E4="","",'Monitoring'!E4) | G25: =IF('Monitoring'!F4="","",'Monitoring'!F4) | H25: =IF('Monitoring'!G4="","",'Monitoring'!G4) | I25: =IF('Monitoring'!H4="","",'Monitoring'!H4) | J25: =IF('Monitoring'!I4="","",'Monitoring'!I4)
A26: =IF('Monitoring'!A5="","",'Monitoring'!A5) | B26: Monitoring | C26: =IF('Monitoring'!B5="","",'Monitoring'!B5) | D26: =IF('Monitoring'!C5="","",'Monitoring'!C5) | E26: =IF('Monitoring'!D5="","",'Monitoring'!D5) | F26: =IF('Monitoring'!E5="","",'Monitoring'!E5) | G26: =IF('Monitoring'!F5="","",'Monitoring'!F5) | H26: =IF('Monitoring'!G5="","",'Monitoring'!G5) | I26: =IF('Monitoring'!H5="","",'Monitoring'!H5) | J26: =IF('Monitoring'!I5="","",'Monitoring'!I5)
A27: =IF('Monitoring'!A6="","",'Monitoring'!A6) | B27: Monitoring | C27: =IF('Monitoring'!B6="","",'Monitoring'!B6) | D27: =IF('Monitoring'!C6="","",'Monitoring'!C6) | E27: =IF('Monitoring'!D6="","",'Monitoring'!D6) | F27: =IF('Monitoring'!E6="","",'Monitoring'!E6) | G27: =IF('Monitoring'!F6="","",'Monitoring'!F6) | H27: =IF('Monitoring'!G6="","",'Monitoring'!G6) | I27: =IF('Monitoring'!H6="","",'Monitoring'!H6) | J27: =IF('Monitoring'!I6="","",'Monitoring'!I6)
A28: =IF('Monitoring'!A7="","",'Monitoring'!A7) | B28: Monitoring | C28: =IF('Monitoring'!B7="","",'Monitoring'!B7) | D28: =IF('Monitoring'!C7="","",'Monitoring'!C7) | E28: =IF('Monitoring'!D7="","",'Monitoring'!D7) | F28: =IF('Monitoring'!E7="","",'Monitoring'!E7) | G28: =IF('Monitoring'!F7="","",'Monitoring'!F7) | H28: =IF('Monitoring'!G7="","",'Monitoring'!G7) | I28: =IF('Monitoring'!H7="","",'Monitoring'!H7) | J28: =IF('Monitoring'!I7="","",'Monitoring'!I7)
A29: =IF('Connectivity'!A3="","",'Connectivity'!A3) | B29: Connectivity | C29: =IF('Connectivity'!B3="","",'Connectivity'!B3) | D29: =IF('Connectivity'!C3="","",'Connectivity'!C3) | E29: =IF('Connectivity'!D3="","",'Connectivity'!D3) | F29: =IF('Connectivity'!E3="","",'Connectivity'!E3) | G29: =IF('Connectivity'!F3="","",'Connectivity'!F3) | H29: =IF('Connectivity'!G3="","",'Connectivity'!G3) | I29: =IF('Connectivity'!H3="","",'Connectivity'!H3) | J29: =IF('Connectivity'!I3="","",'Connectivity'!I3)
A30: =IF('Connectivity'!A4="","",'Connectivity'!A4) | B30: Connectivity | C30: =IF('Connectivity'!B4="","",'Connectivity'!B4) | D30: =IF('Connectivity'!C4="","",'Connectivity'!C4) | E30: =IF('Connectivity'!D4="","",'Connectivity'!D4) | F30: =IF('Connectivity'!E4="","",'Connectivity'!E4) | G30: =IF('Connectivity'!F4="","",'Connectivity'!F4) | H30: =IF('Connectivity'!G4="","",'Connectivity'!G4) | I30: =IF('Connectivity'!H4="","",'Connectivity'!H4) | J30: =IF('Connectivity'!I4="","",'Connectivity'!I4)
A31: =IF('Connectivity'!A5="","",'Connectivity'!A5) | B31: Connectivity | C31: =IF('Connectivity'!B5="","",'Connectivity'!B5) | D31: =IF('Connectivity'!C5="","",'Connectivity'!C5) | E31: =IF('Connectivity'!D5="","",'Connectivity'!D5) | F31: =IF('Connectivity'!E5="","",'Connectivity'!E5) | G31: =IF('Connectivity'!F5="","",'Connectivity'!F5) | H31: =IF('Connectivity'!G5="","",'Connectivity'!G5) | I31: =IF('Connectivity'!H5="","",'Connectivity'!H5) | J31: =IF('Connectivity'!I5="","",'Connectivity'!I5)
A32: =IF('Connectivity'!A6="","",'Connectivity'!A6) | B32: Connectivity | C32: =IF('Connectivity'!B6="","",'Connectivity'!B6) | D32: =IF('Connectivity'!C6="","",'Connectivity'!C6) | E32: =IF('Connectivity'!D6="","",'Connectivity'!D6) | F32: =IF('Connectivity'!E6="","",'Connectivity'!E6) | G32: =IF('Connectivity'!F6="","",'Connectivity'!F6) | H32: =IF('Connectivity'!G6="","",'Connectivity'!G6) | I32: =IF('Connectivity'!H6="","",'Connectivity'!H6) | J32: =IF('Connectivity'!I6="","",'Connectivity'!I6)
A33: =IF('Connectivity'!A7="","",'Connectivity'!A7) | B33: Connectivity | C33: =IF('Connectivity'!B7="","",'Connectivity'!B7) | D33: =IF('Connectivity'!C7="","",'Connectivity'!C7) | E33: =IF('Connectivity'!D7="","",'Connectivity'!D7) | F33: =IF('Connectivity'!E7="","",'Connectivity'!E7) | G33: =IF('Connectivity'!F7="","",'Connectivity'!F7) | H33: =IF('Connectivity'!G7="","",'Connectivity'!G7) | I33: =IF('Connectivity'!H7="","",'Connectivity'!H7) | J33: =IF('Connectivity'!I7="","",'Connectivity'!I7)
A34: =IF('Connectivity'!A8="","",'Connectivity'!A8) | B34: Connectivity | C34: =IF('Connectivity'!B8="","",'Connectivity'!B8) | D34: =IF('Connectivity'!C8="","",'Connectivity'!C8) | E34: =IF('Connectivity'!D8="","",'Connectivity'!D8) | F34: =IF('Connectivity'!E8="","",'Connectivity'!E8) | G34: =IF('Connectivity'!F8="","",'Connectivity'!F8) | H34: =IF('Connectivity'!G8="","",'Connectivity'!G8) | I34: =IF('Connectivity'!H8="","",'Connectivity'!H8) | J34: =IF('Connectivity'!I8="","",'Connectivity'!I8)
A35: =IF('Connectivity'!A9="","",'Connectivity'!A9) | B35: Connectivity | C35: =IF('Connectivity'!B9="","",'Connectivity'!B9) | D35: =IF('Connectivity'!C9="","",'Connectivity'!C9) | E35: =IF('Connectivity'!D9="","",'Connectivity'!D9) | F35: =IF('Connectivity'!E9="","",'Connectivity'!E9) | G35: =IF('Connectivity'!F9="","",'Connectivity'!F9) | H35: =IF('Connectivity'!G9="","",'Connectivity'!G9) | I35: =IF('Connectivity'!H9="","",'Connectivity'!H9) | J35: =IF('Connectivity'!I9="","",'Connectivity'!I9)
A36: =IF('Connectivity'!A10="","",'Connectivity'!A10) | B36: Connectivity | C36: =IF('Connectivity'!B10="","",'Connectivity'!B10) | D36: =IF('Connectivity'!C10="","",'Connectivity'!C10) | E36: =IF('Connectivity'!D10="","",'Connectivity'!D10) | F36: =IF('Connectivity'!E10="","",'Connectivity'!E10) | G36: =IF('Connectivity'!F10="","",'Connectivity'!F10) | H36: =IF('Connectivity'!G10="","",'Connectivity'!G10) | I36: =IF('Connectivity'!H10="","",'Connectivity'!H10) | J36: =IF('Connectivity'!I10="","",'Connectivity'!I10)
A37: =IF('VWAN'!A3="","",'VWAN'!A3) | B37: VWAN | C37: =IF('VWAN'!B3="","",'VWAN'!B3) | D37: =IF('VWAN'!C3="","",'VWAN'!C3) | E37: =IF('VWAN'!D3="","",'VWAN'!D3) | F37: =IF('VWAN'!E3="","",'VWAN'!E3) | G37: =IF('VWAN'!F3="","",'VWAN'!F3) | H37: =IF('VWAN'!G3="","",'VWAN'!G3) | I37: =IF('VWAN'!H3="","",'VWAN'!H3) | J37: =IF('VWAN'!I3="","",'VWAN'!I3)
A38: =IF('VWAN'!A4="","",'VWAN'!A4) | B38: VWAN | C38: =IF('VWAN'!B4="","",'VWAN'!B4) | D38: =IF('VWAN'!C4="","",'VWAN'!C4) | E38: =IF('VWAN'!D4="","",'VWAN'!D4) | F38: =IF('VWAN'!E4="","",'VWAN'!E4) | G38: =IF('VWAN'!F4="","",'VWAN'!F4) | H38: =IF('VWAN'!G4="","",'VWAN'!G4) | I38: =IF('VWAN'!H4="","",'VWAN'!H4) | J38: =IF('VWAN'!I4="","",'VWAN'!I4)
A39: =IF('VWAN'!A5="","",'VWAN'!A5) | B39: VWAN | C39: =IF('VWAN'!B5="","",'VWAN'!B5) | D39: =IF('VWAN'!C5="","",'VWAN'!C5) | E39: =IF('VWAN'!D5="","",'VWAN'!D5) | F39: =IF('VWAN'!E5="","",'VWAN'!E5) | G39: =IF('VWAN'!F5="","",'VWAN'!F5) | H39: =IF('VWAN'!G5="","",'VWAN'!G5) | I39: =IF('VWAN'!H5="","",'VWAN'!H5) | J39: =IF('VWAN'!I5="","",'VWAN'!I5)
A40: =IF('VWAN'!A6="","",'VWAN'!A6) | B40: VWAN | C40: =IF('VWAN'!B6="","",'VWAN'!B6) | D40: =IF('VWAN'!C6="","",'VWAN'!C6) | E40: =IF('VWAN'!D6="","",'VWAN'!D6) | F40: =IF('VWAN'!E6="","",'VWAN'!E6) | G40: =IF('VWAN'!F6="","",'VWAN'!F6) | H40: =IF('VWAN'!G6="","",'VWAN'!G6) | I40: =IF('VWAN'!H6="","",'VWAN'!H6) | J40: =IF('VWAN'!I6="","",'VWAN'!I6)
A41: =IF('VWAN'!A7="","",'VWAN'!A7) | B41: VWAN | C41: =IF('VWAN'!B7="","",'VWAN'!B7) | D41: =IF('VWAN'!C7="","",'VWAN'!C7) | E41: =IF('VWAN'!D7="","",'VWAN'!D7) | F41: =IF('VWAN'!E7="","",'VWAN'!E7) | G41: =IF('VWAN'!F7="","",'VWAN'!F7) | H41: =IF('VWAN'!G7="","",'VWAN'!G7) | I41: =IF('VWAN'!H7="","",'VWAN'!H7) | J41: =IF('VWAN'!I7="","",'VWAN'!I7)
...

Sheet Project
A1: Project Parameters
A2: Parameter Name | B2: Production | C2: Test | D2: DR | E2: Description | F2: Required | G2: Data Type | H2: Validation Rules | I2: Security Level
A3: solution.name | B3: Azure Virtual WAN Global | C3: Azure Virtual WAN Global | D3: Azure Virtual WAN Global | E3: Solution display name for tagging | F3: Yes | G3: String | H3: Max 50 characters | I3: Public
A4: solution.abbr | B4: vwan-global | C4: vwan-global | D4: vwan-global | E4: Solution abbreviation for resource naming | F4: Yes | G4: String | H4: Max 15 characters | I4: Public
A5: solution.provider_name | B5: azure | C5: azure | D5: azure | E5: Cloud provider name | F5: Yes | G5: String | H5: aws|azure|gcp | I5: Public
A6: solution.category_name | B6: network | C6: network | D6: network | E6: Solution category | F6: Yes | G6: String | H6: Valid category | I6: Public
A7: azure.subscription_id | B7: [SUBSCRIPTION_ID] | C7: [SUBSCRIPTION_ID] | D7: [SUBSCRIPTION_ID] | E7: Azure subscription identifier | F7: Yes | G7: String | H7: GUID format | I7: Confidential
A8: azure.tenant_id | B8: [TENANT_ID] | C8: [TENANT_ID] | D8: [TENANT_ID] | E8: Azure AD tenant identifier | F8: Yes | G8: String | H8: GUID format | I8: Confidential
A9: azure.region | B9: eastus | C9: eastus | D9: westus2 | E9: Primary Azure region for deployment | F9: Yes | G9: String | H9: Valid Azure region | I9: Public
A10: azure.secondary_region | B10: westus2 | C10: westus2 | D10: eastus | E10: Secondary region for multi-region deployment | F10: Yes | G10: String | H10: Valid Azure region | I10: Public
A11: ownership.cost_center | B11: CC-NET-001 | C11: CC-NET-001 | D11: CC-NET-001 | E11: Cost center for billing | F11: Yes | G11: String | H11: CC format | I11: Public
A12: ownership.owner_email | B12: network-team@company.com | C12: dev-team@company.com | D12: network-team@company.com | E12: Team email for ownership | F12: Yes | G12: String | H12: Valid email | I12: Public
A13: ownership.project_code | B13: PRJ-VWAN-2025 | C13: PRJ-VWAN-2025 | D13: PRJ-VWAN-2025 | E13: Project tracking code | F13: Yes | G13: String | H13: PRJ format | I13: Public

Sheet Security
A1: Security Parameters
A2: Parameter Name | B2: Production | C2: Test | D2: DR | E2: Description | F2: Required | G2: Data Type | H2: Validation Rules | I2: Security Level
A3: security.enable_firewall | B3: true | C3: false | D3: true | E3: Enable Azure Firewall in hubs | F3: Yes | G3: Boolean | H3: true|false | I3: Public
A4: security.firewall_sku_tier | B4: Standard | C4: Standard | D4: Standard | E4: Azure Firewall SKU tier | F4: Yes | G4: String | H4: Standard|Premium|Basic | I4: Public
A5: security.firewall_public_ip_count | B5: 2 | C5: 1 | D5: 1 | E5: Number of public IPs for firewall | F5: Yes | G5: Integer | H5: 1-100 | I5: Public
A6: security.create_firewall_policy | B6: true | C6: false | D6: true | E6: Create firewall policy | F6: Yes | G6: Boolean | H6: true|false | I6: Public
A7: security.share_firewall_policy | B7: true | C7: false | D7: true | E7: Share policy between primary and secondary | F7: Yes | G7: Boolean | H7: true|false | I7: Public
A8: security.dns_proxy_enabled | B8: true | C8: false | D8: true | E8: Enable DNS proxy in firewall | F8: Yes | G8: Boolean | H8: true|false | I8: Public
A9: security.threat_intelligence_mode | B9: Alert | C9: Off | D9: Alert | E9: Threat intelligence mode | F9: Yes | G9: String | H9: Alert|Deny|Off | I9: Public
A10: security.intrusion_detection_mode | B10: Alert | C10: Off | D10: Alert | E10: Intrusion detection mode (Premium SKU) | F10: Yes | G10: String | H10: Alert|Deny|Off | I10: Public

Sheet Monitoring
A1: Monitoring Parameters
A2: Parameter Name | B2: Production | C2: Test | D2: DR | E2: Description | F2: Required | G2: Data Type | H2: Validation Rules | I2: Security Level
A3: monitoring.log_analytics_sku | B3: PerGB2018 | C3: PerGB2018 | D3: PerGB2018 | E3: Log Analytics Workspace SKU | F3: Yes | G3: String | H3: Free|PerNode|PerGB2018 | I3: Public
A4: monitoring.log_retention_days | B4: 90 | C4: 30 | D4: 90 | E4: Log retention in days | F4: Yes | G4: Integer | H4: 30-730 | I4: Public
A5: monitoring.enable_alerts | B5: true | C5: false | D5: true | E5: Enable monitoring alerts | F5: Yes | G5: Boolean | H5: true|false | I5: Public
A6: monitoring.alert_email | B6: ops-team@company.com | C6: dev-team@company.com | D6: ops-team@company.com | E6: Email address for alerts | F6: Yes | G6: String | H6: Valid email | I6: Confidential
A7: monitoring.enable_network_watcher | B7: true | C7: false | D7: true | E7: Enable Network Watcher | F7: Yes | G7: Boolean | H7: true|false | I7: Public

Sheet Connectivity
A1: Connectivity Parameters
A2: Parameter Name | B2: Production | C2: Test | D2: DR | E2: Description | F2: Required | G2: Data Type | H2: Validation Rules | I2: Security Level
A3: connectivity.enable_vpn_gateway | B3: true | C3: true | D3: true | E3: Enable VPN Gateway in hubs | F3: Yes | G3: Boolean | H3: true|false | I3: Public
A4: connectivity.vpn_gateway_scale_unit | B4: 2 | C4: 1 | D4: 1 | E4: VPN Gateway scale units (defines throughput) | F4: Yes | G4: Integer | H4: 1-100 | I4: Public
A5: connectivity.vpn_routing_preference | B5: Microsoft Network | C5: Microsoft Network | D5: Microsoft Network | E5: VPN Gateway routing preference | F5: Yes | G5: String | H5: Microsoft Network|Internet | I5: Public
A6: connectivity.vpn_bgp_asn | B6: 65515 | C6: 65515 | D6: 65515 | E6: BGP ASN for VPN Gateway | F6: Yes | G6: Integer | H6: Valid ASN | I6: Public
A7: connectivity.vpn_bgp_peer_weight | B7: 0 | C7: 0 | D7: 0 | E7: BGP peer weight | F7: Yes | G7: Integer | H7: 0-100 | I7: Public
A8: connectivity.enable_expressroute_gateway | B8: true | C8: false | D8: true | E8: Enable ExpressRoute Gateway in hubs | F8: Yes | G8: Boolean | H8: true|false | I8: Public
A9: connectivity.er_gateway_scale_units | B9: 2 | C9: 1 | D9: 1 | E9: ExpressRoute Gateway scale units | F9: Yes | G9: Integer | H9: 1-10 | I9: Public
A10: connectivity.er_allow_non_vwan_traffic | B10: false | C10: false | D10: false | E10: Allow non-VWAN traffic through ER Gateway | F10: Yes | G10: Boolean | H10: true|false | I10: Public

Sheet VWAN
A1: VWAN Parameters
A2: Parameter Name | B2: Production | C2: Test | D2: DR | E2: Description | F2: Required | G2: Data Type | H2: Validation Rules | I2: Security Level
A3: vwan.type | B3: Standard | C3: Standard | D3: Standard | E3: Virtual WAN type (Basic or Standard) | F3: Yes | G3: String | H3: Basic|Standard | I3: Public
A4: vwan.allow_branch_to_branch | B4: true | C4: true | D4: true | E4: Allow branch to branch traffic | F4: Yes | G4: Boolean | H4: true|false | I4: Public
A5: vwan.office365_breakout | B5: Optimize | C5: None | D5: Optimize | E5: Office365 local breakout category | F5: Yes | G5: String | H5: None|Optimize|OptimizeAndAllow|All | I5: Public
A6: vwan.hub_sku | B6: Standard | C6: Standard | D6: Standard | E6: Virtual Hub SKU | F6: Yes | G6: String | H6: Basic|Standard | I6: Public
A7: vwan.hub_routing_preference | B7: ExpressRoute | C7: ExpressRoute | D7: ExpressRoute | E7: Hub routing preference | F7: Yes | G7: String | H7: ExpressRoute|VpnGateway|ASPath | I7: Public
A8: vwan.enable_secondary_hub | B8: true | C8: false | D8: true | E8: Enable secondary hub for multi-region | F8: Yes | G8: Boolean | H8: true|false | I8: Public
A9: vwan.primary_hub_prefix | B9: 10.0.0.0/23 | C9: 10.10.0.0/23 | D9: 10.2.0.0/23 | E9: Address prefix for primary hub | F9: Yes | G9: String | H9: Valid CIDR | I9: Public
A10: vwan.secondary_hub_prefix | B10: 10.1.0.0/23 | D10: 10.3.0.0/23 | E10: Address prefix for secondary hub | F10: No | G10: String | H10: Valid CIDR | I10: Public
A11: vwan.create_custom_route_tables | B11: false | C11: false | D11: false | E11: Create custom route tables for hubs | F11: Yes | G11: Boolean | H11: true|false | I11: Public
