Workbook

Sheet Cover
B4: Discovery Questionnaire
B5: Presales Document
B7: Generated: | C7: November 09, 2025
B8: Solution: | C8: Sample Solution
B9: Customer Name: | C9: [Customer Name]
B10: Version: | C10: 1.0

Sheet All Categories (Read Only)
A1: Total Questions | B1: Answered | C1: Remaining | D1: % Complete
A2: 49 | B2: =SUMPRODUCT(--(LEN(F5:F53)>0)) | C2: =A2-B2 | D2: =B2/A2
A4: Question ID | B4: Category | C4: Sub-Category | D4: Question | E4: Guidance | F4: Customer Response | G4: Notes
A5: =IF('Project Information'!A2="","",'Project Information'!A2) | B5: =IF('Project Information'!B2="","",'Project Information'!B2) | C5: =IF('Project Information'!C2="","",'Project Information'!C2) | D5: =IF('Project Information'!D2="","",'Project Information'!D2) | E5: =IF('Project Information'!E2="","",'Project Information'!E2) | F5: =IF('Project Information'!F2="","",'Project Information'!F2) | G5: =IF('Project Information'!G2="","",'Project Information'!G2)
A6: =IF('Project Information'!A3="","",'Project Information'!A3) | B6: =IF('Project Information'!B3="","",'Project Information'!B3) | C6: =IF('Project Information'!C3="","",'Project Information'!C3) | D6: =IF('Project Information'!D3="","",'Project Information'!D3) | E6: =IF('Project Information'!E3="","",'Project Information'!E3) | F6: =IF('Project Information'!F3="","",'Project Information'!F3) | G6: =IF('Project Information'!G3="","",'Project Information'!G3)
A7: =IF('Project Information'!A4="","",'Project Information'!A4) | B7: =IF('Project Information'!B4="","",'Project Information'!B4) | C7: =IF('Project Information'!C4="","",'Project Information'!C4) | D7: =IF('Project Information'!D4="","",'Project Information'!D4) | E7: =IF('Project Information'!E4="","",'Project Information'!E4) | F7: =IF('Project Information'!F4="","",'Project Information'!F4) | G7: =IF('Project Information'!G4="","",'Project Information'!G4)
A8: =IF('Project Information'!A5="","",'Project Information'!A5) | B8: =IF('Project Information'!B5="","",'Project Information'!B5) | C8: =IF('Project Information'!C5="","",'Project Information'!C5) | D8: =IF('Project Information'!D5="","",'Project Information'!D5) | E8: =IF('Project Information'!E5="","",'Project Information'!E5) | F8: =IF('Project Information'!F5="","",'Project Information'!F5) | G8: =IF('Project Information'!G5="","",'Project Information'!G5)
A9: =IF('Project Information'!A6="","",'Project Information'!A6) | B9: =IF('Project Information'!B6="","",'Project Information'!B6) | C9: =IF('Project Information'!C6="","",'Project Information'!C6) | D9: =IF('Project Information'!D6="","",'Project Information'!D6) | E9: =IF('Project Information'!E6="","",'Project Information'!E6) | F9: =IF('Project Information'!F6="","",'Project Information'!F6) | G9: =IF('Project Information'!G6="","",'Project Information'!G6)
A10: =IF('Business Requirements'!A2="","",'Business Requirements'!A2) | B10: =IF('Business Requirements'!B2="","",'Business Requirements'!B2) | C10: =IF('Business Requirements'!C2="","",'Business Requirements'!C2) | D10: =IF('Business Requirements'!D2="","",'Business Requirements'!D2) | E10: =IF('Business Requirements'!E2="","",'Business Requirements'!E2) | F10: =IF('Business Requirements'!F2="","",'Business Requirements'!F2) | G10: =IF('Business Requirements'!G2="","",'Business Requirements'!G2)
A11: =IF('Business Requirements'!A3="","",'Business Requirements'!A3) | B11: =IF('Business Requirements'!B3="","",'Business Requirements'!B3) | C11: =IF('Business Requirements'!C3="","",'Business Requirements'!C3) | D11: =IF('Business Requirements'!D3="","",'Business Requirements'!D3) | E11: =IF('Business Requirements'!E3="","",'Business Requirements'!E3) | F11: =IF('Business Requirements'!F3="","",'Business Requirements'!F3) | G11: =IF('Business Requirements'!G3="","",'Business Requirements'!G3)
A12: =IF('Business Requirements'!A4="","",'Business Requirements'!A4) | B12: =IF('Business Requirements'!B4="","",'Business Requirements'!B4) | C12: =IF('Business Requirements'!C4="","",'Business Requirements'!C4) | D12: =IF('Business Requirements'!D4="","",'Business Requirements'!D4) | E12: =IF('Business Requirements'!E4="","",'Business Requirements'!E4) | F12: =IF('Business Requirements'!F4="","",'Business Requirements'!F4) | G12: =IF('Business Requirements'!G4="","",'Business Requirements'!G4)
A13: =IF('Business Requirements'!A5="","",'Business Requirements'!A5) | B13: =IF('Business Requirements'!B5="","",'Business Requirements'!B5) | C13: =IF('Business Requirements'!C5="","",'Business Requirements'!C5) | D13: =IF('Business Requirements'!D5="","",'Business Requirements'!D5) | E13: =IF('Business Requirements'!E5="","",'Business Requirements'!E5) | F13: =IF('Business Requirements'!F5="","",'Business Requirements'!F5) | G13: =IF('Business Requirements'!G5="","",'Business Requirements'!G5)
A14: =IF('Business Requirements'!A6="","",'Business Requirements'!A6) | B14: =IF('Business Requirements'!B6="","",'Business Requirements'!B6) | C14: =IF('Business Requirements'!C6="","",'Business Requirements'!C6) | D14: =IF('Business Requirements'!D6="","",'Business Requirements'!D6) | E14: =IF('Business Requirements'!E6="","",'Business Requirements'!E6) | F14: =IF('Business Requirements'!F6="","",'Business Requirements'!F6) | G14: =IF('Business Requirements'!G6="","",'Business Requirements'!G6)
A15: =IF('Business Requirements'!A7="","",'Business Requirements'!A7) | B15: =IF('Business Requirements'!B7="","",'Business Requirements'!B7) | C15: =IF('Business Requirements'!C7="","",'Business Requirements'!C7) | D15: =IF('Business Requirements'!D7="","",'Business Requirements'!D7) | E15: =IF('Business Requirements'!E7="","",'Business Requirements'!E7) | F15: =IF('Business Requirements'!F7="","",'Business Requirements'!F7) | G15: =IF('Business Requirements'!G7="","",'Business Requirements'!G7)
A16: =IF('Business Requirements'!A8="","",'Business Requirements'!A8) | B16: =IF('Business Requirements'!B8="","",'Business Requirements'!B8) | C16: =IF('Business Requirements'!C8="","",'Business Requirements'!C8) | D16: =IF('Business Requirements'!D8="","",'Business Requirements'!D8) | E16: =IF('Business Requirements'!E8="","",'Business Requirements'!E8) | F16: =IF('Business Requirements'!F8="","",'Business Requirements'!F8) | G16: =IF('Business Requirements'!G8="","",'Business Requirements'!G8)
A17: =IF('Business Requirements'!A9="","",'Business Requirements'!A9) | B17: =IF('Business Requirements'!B9="","",'Business Requirements'!B9) | C17: =IF('Business Requirements'!C9="","",'Business Requirements'!C9) | D17: =IF('Business Requirements'!D9="","",'Business Requirements'!D9) | E17: =IF('Business Requirements'!E9="","",'Business Requirements'!E9) | F17: =IF('Business Requirements'!F9="","",'Business Requirements'!F9) | G17: =IF('Business Requirements'!G9="","",'Business Requirements'!G9)
A18: =IF('Business Requirements'!A10="","",'Business Requirements'!A10) | B18: =IF('Business Requirements'!B10="","",'Business Requirements'!B10) | C18: =IF('Business Requirements'!C10="","",'Business Requirements'!C10) | D18: =IF('Business Requirements'!D10="","",'Business Requirements'!D10) | E18: =IF('Business Requirements'!E10="","",'Business Requirements'!E10) | F18: =IF('Business Requirements'!F10="","",'Business Requirements'!F10) | G18: =IF('Business Requirements'!G10="","",'Business Requirements'!G10)
A19: =IF('Business Requirements'!A11="","",'Business Requirements'!A11) | B19: =IF('Business Requirements'!B11="","",'Business Requirements'!B11) | C19: =IF('Business Requirements'!C11="","",'Business Requirements'!C11) | D19: =IF('Business Requirements'!D11="","",'Business Requirements'!D11) | E19: =IF('Business Requirements'!E11="","",'Business Requirements'!E11) | F19: =IF('Business Requirements'!F11="","",'Business Requirements'!F11) | G19: =IF('Business Requirements'!G11="","",'Business Requirements'!G11)
A20: =IF('Technical Requirements'!A2="","",'Technical Requirements'!A2) | B20: =IF('Technical Requirements'!B2="","",'Technical Requirements'!B2) | C20: =IF('Technical Requirements'!C2="","",'Technical Requirements'!C2) | D20: =IF('Technical Requirements'!D2="","",'Technical Requirements'!D2) | E20: =IF('Technical Requirements'!E2="","",'Technical Requirements'!E2) | F20: =IF('Technical Requirements'!F2="","",'Technical Requirements'!F2) | G20: =IF('Technical Requirements'!G2="","",'Technical Requirements'!G2)
A21: =IF('Technical Requirements'!A3="","",'Technical Requirements'!A3) | B21: =IF('Technical Requirements'!B3="","",'Technical Requirements'!B3) | C21: =IF('Technical Requirements'!C3="","",'Technical Requirements'!C3) | D21: =IF('Technical Requirements'!D3="","",'Technical Requirements'!D3) | E21: =IF('Technical Requirements'!E3="","",'Technical Requirements'!E3) | F21: =IF('Technical Requirements'!F3="","",'Technical Requirements'!F3) | G21: =IF('Technical Requirements'!G3="","",'Technical Requirements'!G3)
A22: =IF('Technical Requirements'!A4="","",'Technical Requirements'!A4) | B22: =IF('Technical Requirements'!B4="","",'Technical Requirements'!B4) | C22: =IF('Technical Requirements'!C4="","",'Technical Requirements'!C4) | D22: =IF('Technical Requirements'!D4="","",'Technical Requirements'!D4) | E22: =IF('Technical Requirements'!E4="","",'Technical Requirements'!E4) | F22: =IF('Technical Requirements'!F4="","",'Technical Requirements'!F4) | G22: =IF('Technical Requirements'!G4="","",'Technical Requirements'!G4)
A23: =IF('Technical Requirements'!A5="","",'Technical Requirements'!A5) | B23: =IF('Technical Requirements'!B5="","",'Technical Requirements'!B5) | C23: =IF('Technical Requirements'!C5="","",'Technical Requirements'!C5) | D23: =IF('Technical Requirements'!D5="","",'Technical Requirements'!D5) | E23: =IF('Technical Requirements'!E5="","",'Technical Requirements'!E5) | F23: =IF('Technical Requirements'!F5="","",'Technical Requirements'!F5) | G23: =IF('Technical Requirements'!G5="","",'Technical Requirements'!G5)
A24: =IF('Technical Requirements'!A6="","",'Technical Requirements'!A6) | B24: =IF('Technical Requirements'!B6="","",'Technical Requirements'!B6) | C24: =IF('Technical Requirements'!C6="","",'Technical Requirements'!C6) | D24: =IF('Technical Requirements'!D6="","",'Technical Requirements'!D6) | E24: =IF('Technical Requirements'!E6="","",'Technical Requirements'!E6) | F24: =IF('Technical Requirements'!F6="","",'Technical Requirements'!F6) | G24: =IF('Technical Requirements'!G6="","",'Technical Requirements'!G6)
A25: =IF('Technical Requirements'!A7="","",'Technical Requirements'!A7) | B25: =IF('Technical Requirements'!B7="","",'Technical Requirements'!B7) | C25: =IF('Technical Requirements'!C7="","",'Technical Requirements'!C7) | D25: =IF('Technical Requirements'!D7="","",'Technical Requirements'!D7) | E25: =IF('Technical Requirements'!E7="","",'Technical Requirements'!E7) | F25: =IF('Technical Requirements'!F7="","",'Technical Requirements'!F7) | G25: =IF('Technical Requirements'!G7="","",'Technical Requirements'!G7)
A26: =IF('Technical Requirements'!A8="","",'Technical Requirements'!A8) | B26: =IF('Technical Requirements'!B8="","",'Technical Requirements'!B8) | C26: =IF('Technical Requirements'!C8="","",'Technical Requirements'!C8) | D26: =IF('Technical Requirements'!D8="","",'Technical Requirements'!D8) | E26: =IF('Technical Requirements'!E8="","",'Technical Requirements'!E8) | F26: =IF('Technical Requirements'!F8="","",'Technical Requirements'!F8) | G26: =IF('Technical Requirements'!G8="","",'Technical Requirements'!G8)
A27: =IF('Technical Requirements'!A9="","",'Technical Requirements'!A9) | B27: =IF('Technical Requirements'!B9="","",'Technical Requirements'!B9) | C27: =IF('Technical Requirements'!C9="","",'Technical Requirements'!C9) | D27: =IF('Technical Requirements'!D9="","",'Technical Requirements'!D9) | E27: =IF('Technical Requirements'!E9="","",'Technical Requirements'!E9) | F27: =IF('Technical Requirements'!F9="","",'Technical Requirements'!F9) | G27: =IF('Technical Requirements'!G9="","",'Technical Requirements'!G9)
A28: =IF('Technical Requirements'!A10="","",'Technical Requirements'!A10) | B28: =IF('Technical Requirements'!B10="","",'Technical Requirements'!B10) | C28: =IF('Technical Requirements'!C10="","",'Technical Requirements'!C10) | D28: =IF('Technical Requirements'!D10="","",'Technical Requirements'!D10) | E28: =IF('Technical Requirements'!E10="","",'Technical Requirements'!E10) | F28: =IF('Technical Requirements'!F10="","",'Technical Requirements'!F10) | G28: =IF('Technical Requirements'!G10="","",'Technical Requirements'!G10)
A29: =IF('Technical Requirements'!A11="","",'Technical Requirements'!A11) | B29: =IF('Technical Requirements'!B11="","",'Technical Requirements'!B11) | C29: =IF('Technical Requirements'!C11="","",'Technical Requirements'!C11) | D29: =IF('Technical Requirements'!D11="","",'Technical Requirements'!D11) | E29: =IF('Technical Requirements'!E11="","",'Technical Requirements'!E11) | F29: =IF('Technical Requirements'!F11="","",'Technical Requirements'!F11) | G29: =IF('Technical Requirements'!G11="","",'Technical Requirements'!G11)
A30: =IF('Technical Requirements'!A12="","",'Technical Requirements'!A12) | B30: =IF('Technical Requirements'!B12="","",'Technical Requirements'!B12) | C30: =IF('Technical Requirements'!C12="","",'Technical Requirements'!C12) | D30: =IF('Technical Requirements'!D12="","",'Technical Requirements'!D12) | E30: =IF('Technical Requirements'!E12="","",'Technical Requirements'!E12) | F30: =IF('Technical Requirements'!F12="","",'Technical Requirements'!F12) | G30: =IF('Technical Requirements'!G12="","",'Technical Requirements'!G12)
A31: =IF('Technical Requirements'!A13="","",'Technical Requirements'!A13) | B31: =IF('Technical Requirements'!B13="","",'Technical Requirements'!B13) | C31: =IF('Technical Requirements'!C13="","",'Technical Requirements'!C13) | D31: =IF('Technical Requirements'!D13="","",'Technical Requirements'!D13) | E31: =IF('Technical Requirements'!E13="","",'Technical Requirements'!E13) | F31: =IF('Technical Requirements'!F13="","",'Technical Requirements'!F13) | G31: =IF('Technical Requirements'!G13="","",'Technical Requirements'!G13)
A32: =IF('Organizational'!A2="","",'Organizational'!A2) | B32: =IF('Organizational'!B2="","",'Organizational'!B2) | C32: =IF('Organizational'!C2="","",'Organizational'!C2) | D32: =IF('Organizational'!D2="","",'Organizational'!D2) | E32: =IF('Organizational'!E2="","",'Organizational'!E2) | F32: =IF('Organizational'!F2="","",'Organizational'!F2) | G32: =IF('Organizational'!G2="","",'Organizational'!G2)
A33: =IF('Organizational'!A3="","",'Organizational'!A3) | B33: =IF('Organizational'!B3="","",'Organizational'!B3) | C33: =IF('Organizational'!C3="","",'Organizational'!C3) | D33: =IF('Organizational'!D3="","",'Organizational'!D3) | E33: =IF('Organizational'!E3="","",'Organizational'!E3) | F33: =IF('Organizational'!F3="","",'Organizational'!F3) | G33: =IF('Organizational'!G3="","",'Organizational'!G3)
A34: =IF('Organizational'!A4="","",'Organizational'!A4) | B34: =IF('Organizational'!B4="","",'Organizational'!B4) | C34: =IF('Organizational'!C4="","",'Organizational'!C4) | D34: =IF('Organizational'!D4="","",'Organizational'!D4) | E34: =IF('Organizational'!E4="","",'Organizational'!E4) | F34: =IF('Organizational'!F4="","",'Organizational'!F4) | G34: =IF('Organizational'!G4="","",'Organizational'!G4)
A35: =IF('Organizational'!A5="","",'Organizational'!A5) | B35: =IF('Organizational'!B5="","",'Organizational'!B5) | C35: =IF('Organizational'!C5="","",'Organizational'!C5) | D35: =IF('Organizational'!D5="","",'Organizational'!D5) | E35: =IF('Organizational'!E5="","",'Organizational'!E5) | F35: =IF('Organizational'!F5="","",'Organizational'!F5) | G35: =IF('Organizational'!G5="","",'Organizational'!G5)
A36: =IF('Organizational'!A6="","",'Organizational'!A6) | B36: =IF('Organizational'!B6="","",'Organizational'!B6) | C36: =IF('Organizational'!C6="","",'Organizational'!C6) | D36: =IF('Organizational'!D6="","",'Organizational'!D6) | E36: =IF('Organizational'!E6="","",'Organizational'!E6) | F36: =IF('Organizational'!F6="","",'Organizational'!F6) | G36: =IF('Organizational'!G6="","",'Organizational'!G6)
A37: =IF('Organizational'!A7="","",'Organizational'!A7) | B37: =IF('Organizational'!B7="","",'Organizational'!B7) | C37: =IF('Organizational'!C7="","",'Organizational'!C7) | D37: =IF('Organizational'!D7="","",'Organizational'!D7) | E37: =IF('Organizational'!E7="","",'Organizational'!E7) | F37: =IF('Organizational'!F7="","",'Organizational'!F7) | G37: =IF('Organizational'!G7="","",'Organizational'!G7)
A38: =IF('Organizational'!A8="","",'Organizational'!A8) | B38: =IF('Organizational'!B8="","",'Organizational'!B8) | C38: =IF('Organizational'!C8="","",'Organizational'!C8) | D38: =IF('Organizational'!D8="","",'Organizational'!D8) | E38: =IF('Organizational'!E8="","",'Organizational'!E8) | F38: =IF('Organizational'!F8="","",'Organizational'!F8) | G38: =IF('Organizational'!G8="","",'Organizational'!G8)
A39: =IF('Organizational'!A9="","",'Organizational'!A9) | B39: =IF('Organizational'!B9="","",'Organizational'!B9) | C39: =IF('Organizational'!C9="","",'Organizational'!C9) | D39: =IF('Organizational'!D9="","",'Organizational'!D9) | E39: =IF('Organizational'!E9="","",'Organizational'!E9) | F39: =IF('Organizational'!F9="","",'Organizational'!F9) | G39: =IF('Organizational'!G9="","",'Organizational'!G9)
A40: =IF('Project Constraints'!A2="","",'Project Constraints'!A2) | B40: =IF('Project Constraints'!B2="","",'Project Constraints'!B2) | C40: =IF('Project Constraints'!C2="","",'Project Constraints'!C2) | D40: =IF('Project Constraints'!D2="","",'Project Constraints'!D2) | E40: =IF('Project Constraints'!E2="","",'Project Constraints'!E2) | F40: =IF('Project Constraints'!F2="","",'Project Constraints'!F2) | G40: =IF('Project Constraints'!G2="","",'Project Constraints'!G2)
A41: =IF('Project Constraints'!A3="","",'Project Constraints'!A3) | B41: =IF('Project Constraints'!B3="","",'Project Constraints'!B3) | C41: =IF('Project Constraints'!C3="","",'Project Constraints'!C3) | D41: =IF('Project Constraints'!D3="","",'Project Constraints'!D3) | E41: =IF('Project Constraints'!E3="","",'Project Constraints'!E3) | F41: =IF('Project Constraints'!F3="","",'Project Constraints'!F3) | G41: =IF('Project Constraints'!G3="","",'Project Constraints'!G3)
...

Sheet Project Information
A1: Question ID | B1: Category | C1: Sub-Category | D1: Question | E1: Guidance | F1: Customer Response | G1: Notes
A2: PROJ-001 | B2: Project Information | C2: Basic Details | D2: What is the solution name? | G2: Internal project reference
A3: PROJ-002 | B3: Project Information | C3: Basic Details | D3: What is your company name? | G3: Client identification
A4: PROJ-003 | B4: Project Information | C4: Basic Details | D4: Who is the primary stakeholder for this project? | G4: Main point of contact
A5: PROJ-004 | B5: Project Information | C5: Basic Details | D5: What is the stakeholder's role? | G5: Decision-making authority
A6: PROJ-005 | B6: Project Information | C6: Basic Details | D6: What is today's date? | G6: Questionnaire completion date

Sheet Business Requirements
A1: Question ID | B1: Category | C1: Sub-Category | D1: Question | E1: Guidance | F1: Customer Response | G1: Notes
A2: BUS-001 | B2: Business Requirements | C2: Current State | D2: What is the current challenge or pain point this solution aims to address? | E2: Common challenges: Performance issues, scalability limitations, security concerns, cost optimization, compliance requirements | G2: Primary business driver
A3: BUS-002 | B3: Business Requirements | C3: Current State | D3: What systems or processes are currently in place? | G3: Current state assessment
A4: BUS-003 | B4: Business Requirements | C4: Current State | D4: What is working well with the current setup? | G4: Strengths to preserve
A5: BUS-004 | B5: Business Requirements | C5: Current State | D5: What are the specific limitations or failures? | G5: Pain points to address
A6: BUS-005 | B6: Business Requirements | C6: Objectives | D6: What are the primary business goals for this project? | E6: Common goals: Reduce operational costs, improve performance, enhance security, enable scalability, ensure compliance, accelerate time-to-market | G6: Business objectives
A7: BUS-006 | B7: Business Requirements | C7: Objectives | D7: What does success look like? (Measurable outcomes) | G7: Success criteria definition
A8: BUS-007 | B8: Business Requirements | C8: Timeline | D8: What is the expected timeline for implementation? | E8: Typical ranges: 0-3 months, 3-6 months, 6-12 months, 12+ months | G8: Project timeline expectations
A9: BUS-008 | B9: Business Requirements | C9: Budget | D9: What is the approved budget range? | E9: Common ranges: $0-50K, $50K-250K, $250K-1M, $1M+ | G9: Budget constraints
A10: BUS-009 | B10: Business Requirements | C10: Stakeholders | D10: Who are the key stakeholders and decision makers? | G10: Stakeholder mapping
A11: BUS-010 | B11: Business Requirements | C11: Success Metrics | D11: How will you measure the success of this project? | G11: KPI definition

Sheet Technical Requirements
A1: Question ID | B1: Category | C1: Sub-Category | D1: Question | E1: Guidance | F1: Customer Response | G1: Notes
A2: TECH-001 | B2: Technical Requirements | C2: Infrastructure | D2: What is your current technology infrastructure? | G2: Current tech stack
A3: TECH-002 | B3: Technical Requirements | C3: Infrastructure | D3: What cloud platforms do you currently use? | E3: Common platforms: AWS, Azure, Google Cloud, on-premises, hybrid | G3: Cloud strategy
A4: TECH-003 | B4: Technical Requirements | C4: Integration | D4: What systems need to integrate with this solution? | G4: Integration requirements
A5: TECH-004 | B5: Technical Requirements | C5: Integration | D5: What data sources need to be connected? | G5: Data integration needs
A6: TECH-005 | B6: Technical Requirements | C6: Performance | D6: What are your performance requirements? | G6: Performance expectations
A7: TECH-006 | B7: Technical Requirements | C7: Performance | D7: How many concurrent users do you expect? | E7: Typical ranges: 1-50, 51-500, 501-5000, 5000+ | G7: User capacity planning
A8: TECH-007 | B8: Technical Requirements | C8: Security | D8: What are your security requirements? | E8: Common requirements: Basic authentication, multi-factor authentication, single sign-on, RBAC, advanced encryption | G8: Security needs
A9: TECH-008 | B9: Technical Requirements | C9: Security | D9: What compliance standards must be met? | E9: Common standards: SOC 2, ISO 27001, HIPAA, PCI DSS, GDPR, FedRAMP | G9: Compliance requirements
A10: TECH-009 | B10: Technical Requirements | C10: Data | D10: What types of data will the system handle? | E10: Common types: Customer data, financial data, healthcare data, personal data, public data, proprietary data | G10: Data classification
A11: TECH-010 | B11: Technical Requirements | C11: Data | D11: What are your data retention requirements? | G11: Data lifecycle management
A12: TECH-011 | B12: Technical Requirements | C12: Availability | D12: What are your uptime requirements? | E12: Common targets: 99%, 99.5%, 99.9%, 99.95%, 99.99% | G12: SLA requirements
A13: TECH-012 | B13: Technical Requirements | C13: Disaster Recovery | D13: What are your disaster recovery requirements? | G13: Business continuity needs

Sheet Organizational
A1: Question ID | B1: Category | C1: Sub-Category | D1: Question | E1: Guidance | F1: Customer Response | G1: Notes
A2: ORG-001 | B2: Organizational | C2: Resources | D2: Who will be the technical lead for this project? | G2: Technical ownership
A3: ORG-002 | B3: Organizational | C3: Resources | D3: What internal resources are available for this project? | G3: Team availability
A4: ORG-003 | B4: Organizational | C4: Resources | D4: What are the skill levels of your technical team? | E4: Typical levels: Beginner, intermediate, advanced, expert | G4: Training needs assessment
A5: ORG-004 | B5: Organizational | C5: Change Management | D5: How do you typically handle technology changes? | G5: Change readiness
A6: ORG-005 | B6: Organizational | C6: Change Management | D6: What training and support will be needed? | G6: Enablement requirements
A7: ORG-006 | B7: Organizational | C7: Governance | D7: What approval processes are required? | G7: Decision-making process
A8: ORG-007 | B8: Organizational | C8: Governance | D8: Who has final approval authority? | G8: Decision authority
A9: ORG-008 | B9: Organizational | C9: Communication | D9: How do you prefer project communication? | E9: Common channels: Email, Slack, Teams, weekly meetings, bi-weekly meetings, monthly meetings | G9: Communication preferences

Sheet Project Constraints
A1: Question ID | B1: Category | C1: Sub-Category | D1: Question | E1: Guidance | F1: Customer Response | G1: Notes
A2: PROJ-010 | B2: Project Constraints | C2: Timing | D2: Are there any critical business dates or deadlines? | G2: Timeline constraints
A3: PROJ-011 | B3: Project Constraints | C3: Timing | D3: Are there any blackout periods when work cannot be done? | G3: Implementation restrictions
A4: PROJ-012 | B4: Project Constraints | C4: Budget | D4: Are there any budget constraints or considerations? | G4: Financial constraints
A5: PROJ-013 | B5: Project Constraints | C5: Technical | D5: Are there any technical constraints or limitations? | G5: Technical limitations
A6: PROJ-014 | B6: Project Constraints | C6: Regulatory | D6: Are there any regulatory or compliance constraints? | G6: Regulatory requirements

Sheet Risk Assessment
A1: Question ID | B1: Category | C1: Sub-Category | D1: Question | E1: Guidance | F1: Customer Response | G1: Notes
A2: RISK-001 | B2: Risk Assessment | C2: Implementation | D2: What are your main concerns about this implementation? | G2: Primary concerns
A3: RISK-002 | B3: Risk Assessment | C3: Implementation | D3: What could cause this project to fail? | G3: Failure modes
A4: RISK-003 | B4: Risk Assessment | C4: Business | D4: What business risks are you trying to mitigate? | G4: Business risk factors
A5: RISK-004 | B5: Risk Assessment | C5: Technical | D5: What technical risks are you most concerned about? | G5: Technical risk factors
A6: RISK-005 | B6: Risk Assessment | C6: Organizational | D6: What organizational challenges do you anticipate? | G6: Change management risks

Sheet Future State
A1: Question ID | B1: Category | C1: Sub-Category | D1: Question | E1: Guidance | F1: Customer Response | G1: Notes
A2: FUTURE-001 | B2: Future State | C2: Vision | D2: What is your long-term vision for this solution? | G2: Future roadmap
A3: FUTURE-002 | B3: Future State | C3: Growth | D3: How do you expect your needs to grow over time? | G3: Scalability planning
A4: FUTURE-003 | B4: Future State | C4: Integration | D4: What future integrations might be needed? | G4: Future integration needs
A5: FUTURE-004 | B5: Future State | C5: Features | D5: What additional features might you need in the future? | G5: Future feature requirements
