Workbook

Sheet Cover
B3: Configuration Parameters
B5: Generated: | C5: November 28, 2025
B6: Solution: | C6: Advanced Security
B7: Customer: | C7: [Customer Name]
B8: Version: | C8: 1.0
B9: Status: | C9: Draft
C12: eoframework.org

Sheet All Parameters (Read Only)
A1: Total Parameters | B1: Categories | C1: Required | D1: Confidential/Secret
A2: 53 | B2: 11 | C2: 49 | D2: 20
A4: Parameter Name | B4: Category | C4: Environment | D4: Default Value | E4: Description | F4: Required | G4: Data Type | H4: Validation Rules | I4: Security Level | J4: Owner Team | K4: Dependencies | L4: Notes | M4: Last Updated
A5: =IF('Application'!A3="","",'Application'!A3) | B5: Application | C5: =IF('Application'!B3="","",'Application'!B3) | D5: =IF('Application'!C3="","",'Application'!C3) | E5: =IF('Application'!D3="","",'Application'!D3) | F5: =IF('Application'!E3="","",'Application'!E3) | G5: =IF('Application'!F3="","",'Application'!F3) | H5: =IF('Application'!G3="","",'Application'!G3) | I5: =IF('Application'!H3="","",'Application'!H3) | J5: =IF('Application'!I3="","",'Application'!I3) | ... M5: =IF('Application'!L3="","",'Application'!L3)
A6: =IF('Application'!A4="","",'Application'!A4) | B6: Application | C6: =IF('Application'!B4="","",'Application'!B4) | D6: =IF('Application'!C4="","",'Application'!C4) | E6: =IF('Application'!D4="","",'Application'!D4) | F6: =IF('Application'!E4="","",'Application'!E4) | G6: =IF('Application'!F4="","",'Application'!F4) | H6: =IF('Application'!G4="","",'Application'!G4) | I6: =IF('Application'!H4="","",'Application'!H4) | J6: =IF('Application'!I4="","",'Application'!I4) | ... M6: =IF('Application'!L4="","",'Application'!L4)
A7: =IF('Application'!A5="","",'Application'!A5) | B7: Application | C7: =IF('Application'!B5="","",'Application'!B5) | D7: =IF('Application'!C5="","",'Application'!C5) | E7: =IF('Application'!D5="","",'Application'!D5) | F7: =IF('Application'!E5="","",'Application'!E5) | G7: =IF('Application'!F5="","",'Application'!F5) | H7: =IF('Application'!G5="","",'Application'!G5) | I7: =IF('Application'!H5="","",'Application'!H5) | J7: =IF('Application'!I5="","",'Application'!I5) | ... M7: =IF('Application'!L5="","",'Application'!L5)
A8: =IF('GitHub'!A3="","",'GitHub'!A3) | B8: GitHub | C8: =IF('GitHub'!B3="","",'GitHub'!B3) | D8: =IF('GitHub'!C3="","",'GitHub'!C3) | E8: =IF('GitHub'!D3="","",'GitHub'!D3) | F8: =IF('GitHub'!E3="","",'GitHub'!E3) | G8: =IF('GitHub'!F3="","",'GitHub'!F3) | H8: =IF('GitHub'!G3="","",'GitHub'!G3) | I8: =IF('GitHub'!H3="","",'GitHub'!H3) | J8: =IF('GitHub'!I3="","",'GitHub'!I3) | ... M8: =IF('GitHub'!L3="","",'GitHub'!L3)
A9: =IF('GitHub'!A4="","",'GitHub'!A4) | B9: GitHub | C9: =IF('GitHub'!B4="","",'GitHub'!B4) | D9: =IF('GitHub'!C4="","",'GitHub'!C4) | E9: =IF('GitHub'!D4="","",'GitHub'!D4) | F9: =IF('GitHub'!E4="","",'GitHub'!E4) | G9: =IF('GitHub'!F4="","",'GitHub'!F4) | H9: =IF('GitHub'!G4="","",'GitHub'!G4) | I9: =IF('GitHub'!H4="","",'GitHub'!H4) | J9: =IF('GitHub'!I4="","",'GitHub'!I4) | ... M9: =IF('GitHub'!L4="","",'GitHub'!L4)
A10: =IF('GitHub'!A5="","",'GitHub'!A5) | B10: GitHub | C10: =IF('GitHub'!B5="","",'GitHub'!B5) | D10: =IF('GitHub'!C5="","",'GitHub'!C5) | E10: =IF('GitHub'!D5="","",'GitHub'!D5) | F10: =IF('GitHub'!E5="","",'GitHub'!E5) | G10: =IF('GitHub'!F5="","",'GitHub'!F5) | H10: =IF('GitHub'!G5="","",'GitHub'!G5) | I10: =IF('GitHub'!H5="","",'GitHub'!H5) | J10: =IF('GitHub'!I5="","",'GitHub'!I5) | ... M10: =IF('GitHub'!L5="","",'GitHub'!L5)
A11: =IF('GitHub'!A6="","",'GitHub'!A6) | B11: GitHub | C11: =IF('GitHub'!B6="","",'GitHub'!B6) | D11: =IF('GitHub'!C6="","",'GitHub'!C6) | E11: =IF('GitHub'!D6="","",'GitHub'!D6) | F11: =IF('GitHub'!E6="","",'GitHub'!E6) | G11: =IF('GitHub'!F6="","",'GitHub'!F6) | H11: =IF('GitHub'!G6="","",'GitHub'!G6) | I11: =IF('GitHub'!H6="","",'GitHub'!H6) | J11: =IF('GitHub'!I6="","",'GitHub'!I6) | ... M11: =IF('GitHub'!L6="","",'GitHub'!L6)
A12: =IF('GitHub'!A7="","",'GitHub'!A7) | B12: GitHub | C12: =IF('GitHub'!B7="","",'GitHub'!B7) | D12: =IF('GitHub'!C7="","",'GitHub'!C7) | E12: =IF('GitHub'!D7="","",'GitHub'!D7) | F12: =IF('GitHub'!E7="","",'GitHub'!E7) | G12: =IF('GitHub'!F7="","",'GitHub'!F7) | H12: =IF('GitHub'!G7="","",'GitHub'!G7) | I12: =IF('GitHub'!H7="","",'GitHub'!H7) | J12: =IF('GitHub'!I7="","",'GitHub'!I7) | ... M12: =IF('GitHub'!L7="","",'GitHub'!L7)
A13: =IF('Authentication'!A3="","",'Authentication'!A3) | B13: Authentication | C13: =IF('Authentication'!B3="","",'Authentication'!B3) | D13: =IF('Authentication'!C3="","",'Authentication'!C3) | E13: =IF('Authentication'!D3="","",'Authentication'!D3) | F13: =IF('Authentication'!E3="","",'Authentication'!E3) | G13: =IF('Authentication'!F3="","",'Authentication'!F3) | H13: =IF('Authentication'!G3="","",'Authentication'!G3) | I13: =IF('Authentication'!H3="","",'Authentication'!H3) | J13: =IF('Authentication'!I3="","",'Authentication'!I3) | ... M13: =IF('Authentication'!L3="","",'Authentication'!L3)
A14: =IF('Authentication'!A4="","",'Authentication'!A4) | B14: Authentication | C14: =IF('Authentication'!B4="","",'Authentication'!B4) | D14: =IF('Authentication'!C4="","",'Authentication'!C4) | E14: =IF('Authentication'!D4="","",'Authentication'!D4) | F14: =IF('Authentication'!E4="","",'Authentication'!E4) | G14: =IF('Authentication'!F4="","",'Authentication'!F4) | H14: =IF('Authentication'!G4="","",'Authentication'!G4) | I14: =IF('Authentication'!H4="","",'Authentication'!H4) | J14: =IF('Authentication'!I4="","",'Authentication'!I4) | ... M14: =IF('Authentication'!L4="","",'Authentication'!L4)
A15: =IF('Authentication'!A5="","",'Authentication'!A5) | B15: Authentication | C15: =IF('Authentication'!B5="","",'Authentication'!B5) | D15: =IF('Authentication'!C5="","",'Authentication'!C5) | E15: =IF('Authentication'!D5="","",'Authentication'!D5) | F15: =IF('Authentication'!E5="","",'Authentication'!E5) | G15: =IF('Authentication'!F5="","",'Authentication'!F5) | H15: =IF('Authentication'!G5="","",'Authentication'!G5) | I15: =IF('Authentication'!H5="","",'Authentication'!H5) | J15: =IF('Authentication'!I5="","",'Authentication'!I5) | ... M15: =IF('Authentication'!L5="","",'Authentication'!L5)
A16: =IF('Authentication'!A6="","",'Authentication'!A6) | B16: Authentication | C16: =IF('Authentication'!B6="","",'Authentication'!B6) | D16: =IF('Authentication'!C6="","",'Authentication'!C6) | E16: =IF('Authentication'!D6="","",'Authentication'!D6) | F16: =IF('Authentication'!E6="","",'Authentication'!E6) | G16: =IF('Authentication'!F6="","",'Authentication'!F6) | H16: =IF('Authentication'!G6="","",'Authentication'!G6) | I16: =IF('Authentication'!H6="","",'Authentication'!H6) | J16: =IF('Authentication'!I6="","",'Authentication'!I6) | ... M16: =IF('Authentication'!L6="","",'Authentication'!L6)
A17: =IF('Code Scanning'!A3="","",'Code Scanning'!A3) | B17: Code Scanning | C17: =IF('Code Scanning'!B3="","",'Code Scanning'!B3) | D17: =IF('Code Scanning'!C3="","",'Code Scanning'!C3) | E17: =IF('Code Scanning'!D3="","",'Code Scanning'!D3) | F17: =IF('Code Scanning'!E3="","",'Code Scanning'!E3) | G17: =IF('Code Scanning'!F3="","",'Code Scanning'!F3) | H17: =IF('Code Scanning'!G3="","",'Code Scanning'!G3) | I17: =IF('Code Scanning'!H3="","",'Code Scanning'!H3) | J17: =IF('Code Scanning'!I3="","",'Code Scanning'!I3) | ... M17: =IF('Code Scanning'!L3="","",'Code Scanning'!L3)
A18: =IF('Code Scanning'!A4="","",'Code Scanning'!A4) | B18: Code Scanning | C18: =IF('Code Scanning'!B4="","",'Code Scanning'!B4) | D18: =IF('Code Scanning'!C4="","",'Code Scanning'!C4) | E18: =IF('Code Scanning'!D4="","",'Code Scanning'!D4) | F18: =IF('Code Scanning'!E4="","",'Code Scanning'!E4) | G18: =IF('Code Scanning'!F4="","",'Code Scanning'!F4) | H18: =IF('Code Scanning'!G4="","",'Code Scanning'!G4) | I18: =IF('Code Scanning'!H4="","",'Code Scanning'!H4) | J18: =IF('Code Scanning'!I4="","",'Code Scanning'!I4) | ... M18: =IF('Code Scanning'!L4="","",'Code Scanning'!L4)
A19: =IF('Code Scanning'!A5="","",'Code Scanning'!A5) | B19: Code Scanning | C19: =IF('Code Scanning'!B5="","",'Code Scanning'!B5) | D19: =IF('Code Scanning'!C5="","",'Code Scanning'!C5) | E19: =IF('Code Scanning'!D5="","",'Code Scanning'!D5) | F19: =IF('Code Scanning'!E5="","",'Code Scanning'!E5) | G19: =IF('Code Scanning'!F5="","",'Code Scanning'!F5) | H19: =IF('Code Scanning'!G5="","",'Code Scanning'!G5) | I19: =IF('Code Scanning'!H5="","",'Code Scanning'!H5) | J19: =IF('Code Scanning'!I5="","",'Code Scanning'!I5) | ... M19: =IF('Code Scanning'!L5="","",'Code Scanning'!L5)
A20: =IF('Code Scanning'!A6="","",'Code Scanning'!A6) | B20: Code Scanning | C20: =IF('Code Scanning'!B6="","",'Code Scanning'!B6) | D20: =IF('Code Scanning'!C6="","",'Code Scanning'!C6) | E20: =IF('Code Scanning'!D6="","",'Code Scanning'!D6) | F20: =IF('Code Scanning'!E6="","",'Code Scanning'!E6) | G20: =IF('Code Scanning'!F6="","",'Code Scanning'!F6) | H20: =IF('Code Scanning'!G6="","",'Code Scanning'!G6) | I20: =IF('Code Scanning'!H6="","",'Code Scanning'!H6) | J20: =IF('Code Scanning'!I6="","",'Code Scanning'!I6) | ... M20: =IF('Code Scanning'!L6="","",'Code Scanning'!L6)
A21: =IF('Code Scanning'!A7="","",'Code Scanning'!A7) | B21: Code Scanning | C21: =IF('Code Scanning'!B7="","",'Code Scanning'!B7) | D21: =IF('Code Scanning'!C7="","",'Code Scanning'!C7) | E21: =IF('Code Scanning'!D7="","",'Code Scanning'!D7) | F21: =IF('Code Scanning'!E7="","",'Code Scanning'!E7) | G21: =IF('Code Scanning'!F7="","",'Code Scanning'!F7) | H21: =IF('Code Scanning'!G7="","",'Code Scanning'!G7) | I21: =IF('Code Scanning'!H7="","",'Code Scanning'!H7) | J21: =IF('Code Scanning'!I7="","",'Code Scanning'!I7) | ... M21: =IF('Code Scanning'!L7="","",'Code Scanning'!L7)
A22: =IF('Code Scanning'!A8="","",'Code Scanning'!A8) | B22: Code Scanning | C22: =IF('Code Scanning'!B8="","",'Code Scanning'!B8) | D22: =IF('Code Scanning'!C8="","",'Code Scanning'!C8) | E22: =IF('Code Scanning'!D8="","",'Code Scanning'!D8) | F22: =IF('Code Scanning'!E8="","",'Code Scanning'!E8) | G22: =IF('Code Scanning'!F8="","",'Code Scanning'!F8) | H22: =IF('Code Scanning'!G8="","",'Code Scanning'!G8) | I22: =IF('Code Scanning'!H8="","",'Code Scanning'!H8) | J22: =IF('Code Scanning'!I8="","",'Code Scanning'!I8) | ... M22: =IF('Code Scanning'!L8="","",'Code Scanning'!L8)
A23: =IF('Code Scanning'!A9="","",'Code Scanning'!A9) | B23: Code Scanning | C23: =IF('Code Scanning'!B9="","",'Code Scanning'!B9) | D23: =IF('Code Scanning'!C9="","",'Code Scanning'!C9) | E23: =IF('Code Scanning'!D9="","",'Code Scanning'!D9) | F23: =IF('Code Scanning'!E9="","",'Code Scanning'!E9) | G23: =IF('Code Scanning'!F9="","",'Code Scanning'!F9) | H23: =IF('Code Scanning'!G9="","",'Code Scanning'!G9) | I23: =IF('Code Scanning'!H9="","",'Code Scanning'!H9) | J23: =IF('Code Scanning'!I9="","",'Code Scanning'!I9) | ... M23: =IF('Code Scanning'!L9="","",'Code Scanning'!L9)
A24: =IF('Code Scanning'!A10="","",'Code Scanning'!A10) | B24: Code Scanning | C24: =IF('Code Scanning'!B10="","",'Code Scanning'!B10) | D24: =IF('Code Scanning'!C10="","",'Code Scanning'!C10) | E24: =IF('Code Scanning'!D10="","",'Code Scanning'!D10) | F24: =IF('Code Scanning'!E10="","",'Code Scanning'!E10) | G24: =IF('Code Scanning'!F10="","",'Code Scanning'!F10) | H24: =IF('Code Scanning'!G10="","",'Code Scanning'!G10) | I24: =IF('Code Scanning'!H10="","",'Code Scanning'!H10) | J24: =IF('Code Scanning'!I10="","",'Code Scanning'!I10) | ... M24: =IF('Code Scanning'!L10="","",'Code Scanning'!L10)
A25: =IF('Secret Scanning'!A3="","",'Secret Scanning'!A3) | B25: Secret Scanning | C25: =IF('Secret Scanning'!B3="","",'Secret Scanning'!B3) | D25: =IF('Secret Scanning'!C3="","",'Secret Scanning'!C3) | E25: =IF('Secret Scanning'!D3="","",'Secret Scanning'!D3) | F25: =IF('Secret Scanning'!E3="","",'Secret Scanning'!E3) | G25: =IF('Secret Scanning'!F3="","",'Secret Scanning'!F3) | H25: =IF('Secret Scanning'!G3="","",'Secret Scanning'!G3) | I25: =IF('Secret Scanning'!H3="","",'Secret Scanning'!H3) | J25: =IF('Secret Scanning'!I3="","",'Secret Scanning'!I3) | ... M25: =IF('Secret Scanning'!L3="","",'Secret Scanning'!L3)
A26: =IF('Secret Scanning'!A4="","",'Secret Scanning'!A4) | B26: Secret Scanning | C26: =IF('Secret Scanning'!B4="","",'Secret Scanning'!B4) | D26: =IF('Secret Scanning'!C4="","",'Secret Scanning'!C4) | E26: =IF('Secret Scanning'!D4="","",'Secret Scanning'!D4) | F26: =IF('Secret Scanning'!E4="","",'Secret Scanning'!E4) | G26: =IF('Secret Scanning'!F4="","",'Secret Scanning'!F4) | H26: =IF('Secret Scanning'!G4="","",'Secret Scanning'!G4) | I26: =IF('Secret Scanning'!H4="","",'Secret Scanning'!H4) | J26: =IF('Secret Scanning'!I4="","",'Secret Scanning'!I4) | ... M26: =IF('Secret Scanning'!L4="","",'Secret Scanning'!L4)
A27: =IF('Secret Scanning'!A5="","",'Secret Scanning'!A5) | B27: Secret Scanning | C27: =IF('Secret Scanning'!B5="","",'Secret Scanning'!B5) | D27: =IF('Secret Scanning'!C5="","",'Secret Scanning'!C5) | E27: =IF('Secret Scanning'!D5="","",'Secret Scanning'!D5) | F27: =IF('Secret Scanning'!E5="","",'Secret Scanning'!E5) | G27: =IF('Secret Scanning'!F5="","",'Secret Scanning'!F5) | H27: =IF('Secret Scanning'!G5="","",'Secret Scanning'!G5) | I27: =IF('Secret Scanning'!H5="","",'Secret Scanning'!H5) | J27: =IF('Secret Scanning'!I5="","",'Secret Scanning'!I5) | ... M27: =IF('Secret Scanning'!L5="","",'Secret Scanning'!L5)
A28: =IF('Secret Scanning'!A6="","",'Secret Scanning'!A6) | B28: Secret Scanning | C28: =IF('Secret Scanning'!B6="","",'Secret Scanning'!B6) | D28: =IF('Secret Scanning'!C6="","",'Secret Scanning'!C6) | E28: =IF('Secret Scanning'!D6="","",'Secret Scanning'!D6) | F28: =IF('Secret Scanning'!E6="","",'Secret Scanning'!E6) | G28: =IF('Secret Scanning'!F6="","",'Secret Scanning'!F6) | H28: =IF('Secret Scanning'!G6="","",'Secret Scanning'!G6) | I28: =IF('Secret Scanning'!H6="","",'Secret Scanning'!H6) | J28: =IF('Secret Scanning'!I6="","",'Secret Scanning'!I6) | ... M28: =IF('Secret Scanning'!L6="","",'Secret Scanning'!L6)
A29: =IF('Dependency Scanning'!A3="","",'Dependency Scanning'!A3) | B29: Dependency Scanning | C29: =IF('Dependency Scanning'!B3="","",'Dependency Scanning'!B3) | D29: =IF('Dependency Scanning'!C3="","",'Dependency Scanning'!C3) | E29: =IF('Dependency Scanning'!D3="","",'Dependency Scanning'!D3) | F29: =IF('Dependency Scanning'!E3="","",'Dependency Scanning'!E3) | G29: =IF('Dependency Scanning'!F3="","",'Dependency Scanning'!F3) | H29: =IF('Dependency Scanning'!G3="","",'Dependency Scanning'!G3) | I29: =IF('Dependency Scanning'!H3="","",'Dependency Scanning'!H3) | J29: =IF('Dependency Scanning'!I3="","",'Dependency Scanning'!I3) | ... M29: =IF('Dependency Scanning'!L3="","",'Dependency Scanning'!L3)
A30: =IF('Dependency Scanning'!A4="","",'Dependency Scanning'!A4) | B30: Dependency Scanning | C30: =IF('Dependency Scanning'!B4="","",'Dependency Scanning'!B4) | D30: =IF('Dependency Scanning'!C4="","",'Dependency Scanning'!C4) | E30: =IF('Dependency Scanning'!D4="","",'Dependency Scanning'!D4) | F30: =IF('Dependency Scanning'!E4="","",'Dependency Scanning'!E4) | G30: =IF('Dependency Scanning'!F4="","",'Dependency Scanning'!F4) | H30: =IF('Dependency Scanning'!G4="","",'Dependency Scanning'!G4) | I30: =IF('Dependency Scanning'!H4="","",'Dependency Scanning'!H4) | J30: =IF('Dependency Scanning'!I4="","",'Dependency Scanning'!I4) | ... M30: =IF('Dependency Scanning'!L4="","",'Dependency Scanning'!L4)
A31: =IF('Dependency Scanning'!A5="","",'Dependency Scanning'!A5) | B31: Dependency Scanning | C31: =IF('Dependency Scanning'!B5="","",'Dependency Scanning'!B5) | D31: =IF('Dependency Scanning'!C5="","",'Dependency Scanning'!C5) | E31: =IF('Dependency Scanning'!D5="","",'Dependency Scanning'!D5) | F31: =IF('Dependency Scanning'!E5="","",'Dependency Scanning'!E5) | G31: =IF('Dependency Scanning'!F5="","",'Dependency Scanning'!F5) | H31: =IF('Dependency Scanning'!G5="","",'Dependency Scanning'!G5) | I31: =IF('Dependency Scanning'!H5="","",'Dependency Scanning'!H5) | J31: =IF('Dependency Scanning'!I5="","",'Dependency Scanning'!I5) | ... M31: =IF('Dependency Scanning'!L5="","",'Dependency Scanning'!L5)
A32: =IF('Dependency Scanning'!A6="","",'Dependency Scanning'!A6) | B32: Dependency Scanning | C32: =IF('Dependency Scanning'!B6="","",'Dependency Scanning'!B6) | D32: =IF('Dependency Scanning'!C6="","",'Dependency Scanning'!C6) | E32: =IF('Dependency Scanning'!D6="","",'Dependency Scanning'!D6) | F32: =IF('Dependency Scanning'!E6="","",'Dependency Scanning'!E6) | G32: =IF('Dependency Scanning'!F6="","",'Dependency Scanning'!F6) | H32: =IF('Dependency Scanning'!G6="","",'Dependency Scanning'!G6) | I32: =IF('Dependency Scanning'!H6="","",'Dependency Scanning'!H6) | J32: =IF('Dependency Scanning'!I6="","",'Dependency Scanning'!I6) | ... M32: =IF('Dependency Scanning'!L6="","",'Dependency Scanning'!L6)
A33: =IF('Security Policies'!A3="","",'Security Policies'!A3) | B33: Security Policies | C33: =IF('Security Policies'!B3="","",'Security Policies'!B3) | D33: =IF('Security Policies'!C3="","",'Security Policies'!C3) | E33: =IF('Security Policies'!D3="","",'Security Policies'!D3) | F33: =IF('Security Policies'!E3="","",'Security Policies'!E3) | G33: =IF('Security Policies'!F3="","",'Security Policies'!F3) | H33: =IF('Security Policies'!G3="","",'Security Policies'!G3) | I33: =IF('Security Policies'!H3="","",'Security Policies'!H3) | J33: =IF('Security Policies'!I3="","",'Security Policies'!I3) | ... M33: =IF('Security Policies'!L3="","",'Security Policies'!L3)
A34: =IF('Security Policies'!A4="","",'Security Policies'!A4) | B34: Security Policies | C34: =IF('Security Policies'!B4="","",'Security Policies'!B4) | D34: =IF('Security Policies'!C4="","",'Security Policies'!C4) | E34: =IF('Security Policies'!D4="","",'Security Policies'!D4) | F34: =IF('Security Policies'!E4="","",'Security Policies'!E4) | G34: =IF('Security Policies'!F4="","",'Security Policies'!F4) | H34: =IF('Security Policies'!G4="","",'Security Policies'!G4) | I34: =IF('Security Policies'!H4="","",'Security Policies'!H4) | J34: =IF('Security Policies'!I4="","",'Security Policies'!I4) | ... M34: =IF('Security Policies'!L4="","",'Security Policies'!L4)
A35: =IF('Security Policies'!A5="","",'Security Policies'!A5) | B35: Security Policies | C35: =IF('Security Policies'!B5="","",'Security Policies'!B5) | D35: =IF('Security Policies'!C5="","",'Security Policies'!C5) | E35: =IF('Security Policies'!D5="","",'Security Policies'!D5) | F35: =IF('Security Policies'!E5="","",'Security Policies'!E5) | G35: =IF('Security Policies'!F5="","",'Security Policies'!F5) | H35: =IF('Security Policies'!G5="","",'Security Policies'!G5) | I35: =IF('Security Policies'!H5="","",'Security Policies'!H5) | J35: =IF('Security Policies'!I5="","",'Security Policies'!I5) | ... M35: =IF('Security Policies'!L5="","",'Security Policies'!L5)
A36: =IF('Security Policies'!A6="","",'Security Policies'!A6) | B36: Security Policies | C36: =IF('Security Policies'!B6="","",'Security Policies'!B6) | D36: =IF('Security Policies'!C6="","",'Security Policies'!C6) | E36: =IF('Security Policies'!D6="","",'Security Policies'!D6) | F36: =IF('Security Policies'!E6="","",'Security Policies'!E6) | G36: =IF('Security Policies'!F6="","",'Security Policies'!F6) | H36: =IF('Security Policies'!G6="","",'Security Policies'!G6) | I36: =IF('Security Policies'!H6="","",'Security Policies'!H6) | J36: =IF('Security Policies'!I6="","",'Security Policies'!I6) | ... M36: =IF('Security Policies'!L6="","",'Security Policies'!L6)
A37: =IF('Security Policies'!A7="","",'Security Policies'!A7) | B37: Security Policies | C37: =IF('Security Policies'!B7="","",'Security Policies'!B7) | D37: =IF('Security Policies'!C7="","",'Security Policies'!C7) | E37: =IF('Security Policies'!D7="","",'Security Policies'!D7) | F37: =IF('Security Policies'!E7="","",'Security Policies'!E7) | G37: =IF('Security Policies'!F7="","",'Security Policies'!F7) | H37: =IF('Security Policies'!G7="","",'Security Policies'!G7) | I37: =IF('Security Policies'!H7="","",'Security Policies'!H7) | J37: =IF('Security Policies'!I7="","",'Security Policies'!I7) | ... M37: =IF('Security Policies'!L7="","",'Security Policies'!L7)
A38: =IF('Security Policies'!A8="","",'Security Policies'!A8) | B38: Security Policies | C38: =IF('Security Policies'!B8="","",'Security Policies'!B8) | D38: =IF('Security Policies'!C8="","",'Security Policies'!C8) | E38: =IF('Security Policies'!D8="","",'Security Policies'!D8) | F38: =IF('Security Policies'!E8="","",'Security Policies'!E8) | G38: =IF('Security Policies'!F8="","",'Security Policies'!F8) | H38: =IF('Security Policies'!G8="","",'Security Policies'!G8) | I38: =IF('Security Policies'!H8="","",'Security Policies'!H8) | J38: =IF('Security Policies'!I8="","",'Security Policies'!I8) | ... M38: =IF('Security Policies'!L8="","",'Security Policies'!L8)
A39: =IF('Security Policies'!A9="","",'Security Policies'!A9) | B39: Security Policies | C39: =IF('Security Policies'!B9="","",'Security Policies'!B9) | D39: =IF('Security Policies'!C9="","",'Security Policies'!C9) | E39: =IF('Security Policies'!D9="","",'Security Policies'!D9) | F39: =IF('Security Policies'!E9="","",'Security Policies'!E9) | G39: =IF('Security Policies'!F9="","",'Security Policies'!F9) | H39: =IF('Security Policies'!G9="","",'Security Policies'!G9) | I39: =IF('Security Policies'!H9="","",'Security Policies'!H9) | J39: =IF('Security Policies'!I9="","",'Security Policies'!I9) | ... M39: =IF('Security Policies'!L9="","",'Security Policies'!L9)
A40: =IF('Security Policies'!A10="","",'Security Policies'!A10) | B40: Security Policies | C40: =IF('Security Policies'!B10="","",'Security Policies'!B10) | D40: =IF('Security Policies'!C10="","",'Security Policies'!C10) | E40: =IF('Security Policies'!D10="","",'Security Policies'!D10) | F40: =IF('Security Policies'!E10="","",'Security Policies'!E10) | G40: =IF('Security Policies'!F10="","",'Security Policies'!F10) | H40: =IF('Security Policies'!G10="","",'Security Policies'!G10) | I40: =IF('Security Policies'!H10="","",'Security Policies'!H10) | J40: =IF('Security Policies'!I10="","",'Security Policies'!I10) | ... M40: =IF('Security Policies'!L10="","",'Security Policies'!L10)
A41: =IF('AI-ML'!A3="","",'AI-ML'!A3) | B41: AI/ML | C41: =IF('AI-ML'!B3="","",'AI-ML'!B3) | D41: =IF('AI-ML'!C3="","",'AI-ML'!C3) | E41: =IF('AI-ML'!D3="","",'AI-ML'!D3) | F41: =IF('AI-ML'!E3="","",'AI-ML'!E3) | G41: =IF('AI-ML'!F3="","",'AI-ML'!F3) | H41: =IF('AI-ML'!G3="","",'AI-ML'!G3) | I41: =IF('AI-ML'!H3="","",'AI-ML'!H3) | J41: =IF('AI-ML'!I3="","",'AI-ML'!I3) | ... M41: =IF('AI-ML'!L3="","",'AI-ML'!L3)
...

Sheet Application
A1: Application Parameters
A2: Parameter Name | B2: Environment | C2: Default Value | D2: Description | E2: Required | F2: Data Type | G2: Validation Rules | H2: Security Level | I2: Owner Team | J2: Dependencies | K2: Notes | L2: Last Updated
A3: GHAS_SOLUTION_NAME | B3: All | C3: GitHub Advanced Security | D3: Solution identifier for logging and metrics | E3: Yes | F3: String | G3: Max 50 characters | H3: Public | I3: Security Team | J3: None | K3: Used in dashboards and reports | L3: [DATE]
A4: GHAS_VERSION | B4: All | C4: 1.0.0 | D4: Current GHAS deployment version | E4: Yes | F4: String | G4: Semantic versioning format | H4: Public | I4: Security Team | J4: None | K4: Updated with configuration changes | L4: [DATE]
A5: GHAS_ENVIRONMENT | B5: All | C5: development | D5: Deployment environment identifier | E5: Yes | F5: String | G5: development|staging|production | H5: Public | I5: Security Team | J5: None | K5: Controls policy enforcement levels | L5: [DATE]

Sheet GitHub
A1: GitHub Parameters
A2: Parameter Name | B2: Environment | C2: Default Value | D2: Description | E2: Required | F2: Data Type | G2: Validation Rules | H2: Security Level | I2: Owner Team | J2: Dependencies | K2: Notes | L2: Last Updated
A3: GITHUB_ENTERPRISE_URL | B3: All | C3: https://github.com | D3: GitHub Enterprise Cloud base URL | E3: Yes | F3: String | G3: Valid HTTPS URL | H3: Public | I3: GitHub Admin | J3: None | K3: Enterprise Cloud uses github.com | L3: [DATE]
A4: GITHUB_ORG_NAME | B4: All | C4: [********] | D4: GitHub organization name | E4: Yes | F4: String | G4: Valid GitHub org name | H4: Confidential | I4: GitHub Admin | J4: Enterprise license | K4: Primary organization for GHAS | L4: [DATE]
A5: GITHUB_ENTERPRISE_LICENSE | B5: All | C5: [********] | D5: GitHub Enterprise Cloud license identifier | E5: Yes | F5: String | G5: Valid license ID | H5: Secret | I5: GitHub Admin | J5: Billing | K5: 100 users licensed per SOW | L5: [DATE]
A6: GHAS_LICENSE_COMMITTERS | B6: All | C6: [********] | D6: GitHub Advanced Security active committers | E6: Yes | F6: Integer | G6: 1-1000 | H6: Confidential | I6: GitHub Admin | J6: Billing | K6: 90-day rolling count per GitHub | L6: [DATE]
A7: GITHUB_API_TOKEN | B7: All | C7: [********] | D7: GitHub personal access token for API access | E7: Yes | F7: String | G7: ghp_* format | H7: Secret | I7: Security Team | J7: Org admin scope | K7: Rotate quarterly | L7: [DATE]

Sheet Authentication
A1: Authentication Parameters
A2: Parameter Name | B2: Environment | C2: Default Value | D2: Description | E2: Required | F2: Data Type | G2: Validation Rules | H2: Security Level | I2: Owner Team | J2: Dependencies | K2: Notes | L2: Last Updated
A3: SAML_IDP_ENTITY_ID | B3: All | C3: [********] | D3: SAML Identity Provider entity ID | E3: Yes | F3: String | G3: Valid entity ID URI | H3: Confidential | I3: Identity Team | J3: IdP configuration | K3: Corporate identity provider | L3: [DATE]
A4: SAML_SSO_URL | B4: All | C4: [********] | D4: SAML Single Sign-On URL | E4: Yes | F4: String | G4: Valid HTTPS URL | H4: Confidential | I4: Identity Team | J4: IdP configuration | K4: Login endpoint URL | L4: [DATE]
A5: SAML_CERTIFICATE | B5: All | C5: [********] | D5: SAML signing certificate from IdP | E5: Yes | F5: String | G5: Valid X.509 cert base64 | H5: Secret | I5: Identity Team | J5: IdP configuration | K5: Certificate for signature validation | L5: [DATE]
A6: MFA_ENFORCEMENT | B6: All | C6: required | D6: Multi-factor authentication requirement | E6: Yes | F6: String | G6: required|optional | H6: Public | I6: Security Team | J6: SAML configuration | K6: Required for all GitHub users | L6: [DATE]

Sheet Code Scanning
A1: Code Scanning Parameters
A2: Parameter Name | B2: Environment | C2: Default Value | D2: Description | E2: Required | F2: Data Type | G2: Validation Rules | H2: Security Level | I2: Owner Team | J2: Dependencies | K2: Notes | L2: Last Updated
A3: CODEQL_LANGUAGES | B3: All | C3: javascript,python,java,csharp,go | D3: Languages enabled for CodeQL analysis | E3: Yes | F3: String | G3: Comma-separated language list | H3: Public | I3: Security Team | J3: CodeQL support | K3: 5 languages per SOW scope | L3: [DATE]
A4: CODEQL_QUERY_SUITES | B4: All | C4: security-extended | D4: CodeQL query suite for scanning | E4: Yes | F4: String | G4: default|security-extended|security-and-quality | H4: Public | I4: Security Team | J4: CodeQL configuration | K4: Extended security coverage | L4: [DATE]
A5: CODEQL_SCHEDULE | B5: All | C5: 0 2 * * * | D5: Cron schedule for full repository scans | E5: Yes | F5: String | G5: Valid cron expression | H5: Public | I5: Security Team | J5: GitHub Actions | K5: Daily at 2 AM UTC | L5: [DATE]
A6: CODEQL_TIMEOUT_MINUTES | B6: All | C6: 60 | D6: Maximum CodeQL scan duration in minutes | E6: Yes | F6: Integer | G6: 15-120 | H6: Public | I6: Security Team | J6: Performance requirements | K6: Extended for large repositories | L6: [DATE]
A7: CODEQL_RAM_MB | B7: All | C7: 4096 | D7: Memory allocation for CodeQL analysis | E7: Yes | F7: Integer | G7: 2048-16384 | H7: Public | I7: Security Team | J7: Performance requirements | K7: Default GitHub-hosted runner | L7: [DATE]
A8: CODEQL_THREADS | B8: All | C8: 2 | D8: CPU threads for CodeQL analysis | E8: Yes | F8: Integer | G8: 1-4 | H8: Public | I8: Security Team | J8: Performance requirements | K8: GitHub-hosted runner limit | L8: [DATE]
A9: CUSTOM_QUERIES_REPO | B9: All | C9: [********] | D9: Repository containing custom CodeQL queries | E9: Yes | F9: String | G9: Valid repo path | H9: Confidential | I9: Security Team | J9: Custom queries | K9: 15 custom queries per SOW | L9: [DATE]
A10: CUSTOM_QUERIES_PATH | B10: All | C10: queries | D10: Path to custom queries in repository | E10: Yes | F10: String | G10: Valid directory path | H10: Public | I10: Security Team | J10: Custom queries repo | K10: Query directory location | L10: [DATE]

Sheet Secret Scanning
A1: Secret Scanning Parameters
A2: Parameter Name | B2: Environment | C2: Default Value | D2: Description | E2: Required | F2: Data Type | G2: Validation Rules | H2: Security Level | I2: Owner Team | J2: Dependencies | K2: Notes | L2: Last Updated
A3: SECRET_SCANNING_ENABLED | B3: All | C3: true | D3: Enable secret scanning for repositories | E3: Yes | F3: Boolean | G3: true|false | H3: Public | I3: Security Team | J3: GHAS license | K3: Organization-wide enablement | L3: [DATE]
A4: PUSH_PROTECTION_ENABLED | B4: All | C4: true | D4: Enable push protection to block secrets | E4: Yes | F4: Boolean | G4: true|false | H4: Public | I4: Security Team | J4: Secret scanning | K4: Real-time secret blocking | L4: [DATE]
A5: SECRET_SCANNING_CUSTOM_PATTERNS | B5: All | C5: 5 | D5: Number of custom secret patterns | E5: Yes | F5: Integer | G5: 0-100 | H5: Public | I5: Security Team | J5: Secret scanning | K5: Proprietary API patterns | L5: [DATE]
A6: SECRET_BYPASS_WORKFLOW | B6: All | C6: [********] | D6: Push protection bypass workflow | E6: Yes | F6: String | G6: require-approval|self-approve | H6: Confidential | I6: Security Team | J6: Push protection | K6: Manager approval required | L6: [DATE]

Sheet Dependency Scanning
A1: Dependency Scanning Parameters
A2: Parameter Name | B2: Environment | C2: Default Value | D2: Description | E2: Required | F2: Data Type | G2: Validation Rules | H2: Security Level | I2: Owner Team | J2: Dependencies | K2: Notes | L2: Last Updated
A3: DEPENDABOT_ENABLED | B3: All | C3: true | D3: Enable Dependabot vulnerability alerts | E3: Yes | F3: Boolean | G3: true|false | H3: Public | I3: Security Team | J3: GitHub configuration | K3: Automated dependency scanning | L3: [DATE]
A4: DEPENDABOT_SECURITY_UPDATES | B4: All | C4: true | D4: Enable Dependabot security update PRs | E4: Yes | F4: Boolean | G4: true|false | H4: Public | I4: Security Team | J4: Dependabot alerts | K4: Auto-generated fix PRs | L4: [DATE]
A5: DEPENDABOT_VERSION_UPDATES | B5: All | C5: false | D5: Enable Dependabot version updates | E5: Yes | F5: Boolean | G5: true|false | H5: Public | I5: Security Team | J5: Dependabot alerts | K5: Disabled per SOW scope | L5: [DATE]
A6: DEPENDABOT_SCHEDULE | B6: All | C6: daily | D6: Dependabot check frequency | E6: Yes | F6: String | G6: daily|weekly|monthly | H6: Public | I6: Security Team | J6: Dependabot config | K6: Daily vulnerability checks | L6: [DATE]

Sheet Security Policies
A1: Security Policies Parameters
A2: Parameter Name | B2: Environment | C2: Default Value | D2: Description | E2: Required | F2: Data Type | G2: Validation Rules | H2: Security Level | I2: Owner Team | J2: Dependencies | K2: Notes | L2: Last Updated
A3: BRANCH_PROTECTION_ENABLED | B3: All | C3: true | D3: Enable branch protection rules | E3: Yes | F3: Boolean | G3: true|false | H3: Public | I3: Security Team | J3: Repository settings | K3: Required for security gates | L3: [DATE]
A4: REQUIRE_CODEQL_PASS | B4: All | C4: true | D4: Require CodeQL check to pass before merge | E4: Yes | F4: Boolean | G4: true|false | H4: Public | I4: Security Team | J4: Branch protection | K4: Block merges on critical findings | L4: [DATE]
A5: REQUIRE_REVIEWS | B5: All | C5: 1 | D5: Number of required PR approvals | E5: Yes | F5: Integer | G5: 0-6 | H5: Public | I5: Security Team | J5: Branch protection | K5: Security review requirement | L5: [DATE]
A6: DISMISS_STALE_REVIEWS | B6: All | C6: true | D6: Dismiss approvals on new commits | E6: Yes | F6: Boolean | G6: true|false | H6: Public | I6: Security Team | J6: Branch protection | K6: Re-review after changes | L6: [DATE]
A7: VULNERABILITY_SLA_CRITICAL | B7: All | C7: 24 | D7: Critical vulnerability SLA in hours | E7: Yes | F7: Integer | G7: 1-168 | H7: Public | I7: Security Team | J7: Vulnerability management | K7: 24-hour remediation per SOW | L7: [DATE]
A8: VULNERABILITY_SLA_HIGH | B8: All | C8: 168 | D8: High vulnerability SLA in hours | E8: Yes | F8: Integer | G8: 24-720 | H8: Public | I8: Security Team | J8: Vulnerability management | K8: 7-day remediation per SOW | L8: [DATE]
A9: VULNERABILITY_SLA_MEDIUM | B9: All | C9: 720 | D9: Medium vulnerability SLA in hours | E9: Yes | F9: Integer | G9: 168-2160 | H9: Public | I9: Security Team | J9: Vulnerability management | K9: 30-day remediation per SOW | L9: [DATE]
A10: VULNERABILITY_SLA_LOW | B10: All | C10: 2160 | D10: Low vulnerability SLA in hours | E10: Yes | F10: Integer | G10: 720-8760 | H10: Public | I10: Security Team | J10: Vulnerability management | K10: 90-day remediation per SOW | L10: [DATE]

Sheet AI-ML
A1: AI/ML Parameters
A2: Parameter Name | B2: Environment | C2: Default Value | D2: Description | E2: Required | F2: Data Type | G2: Validation Rules | H2: Security Level | I2: Owner Team | J2: Dependencies | K2: Notes | L2: Last Updated
A3: CONFIDENCE_THRESHOLD | B3: All | C3: 0.85 | D3: Minimum confidence for auto-processing | E3: Yes | F3: Float | G3: 0.0-1.0 | H3: Public | I3: Security Team | J3: Detection accuracy | K3: Below threshold routes to review | L3: [DATE]
A4: DETECTION_ACCURACY_TARGET | B4: All | C4: 0.95 | D4: Target detection accuracy rate | E4: Yes | F4: Float | G4: 0.80-0.99 | H4: Public | I4: Security Team | J4: Quality assurance | K4: 95%+ per presales SOW | L4: [DATE]
A5: FALSE_POSITIVE_THRESHOLD | B5: All | C5: 0.10 | D5: Maximum acceptable false positive rate | E5: Yes | F5: Float | G5: 0.01-0.20 | H5: Public | I5: Security Team | J5: Quality assurance | K5: <10% per presales SOW | L5: [DATE]

Sheet Integration
A1: Integration Parameters
A2: Parameter Name | B2: Environment | C2: Default Value | D2: Description | E2: Required | F2: Data Type | G2: Validation Rules | H2: Security Level | I2: Owner Team | J2: Dependencies | K2: Notes | L2: Last Updated
A3: SIEM_WEBHOOK_URL | B3: All | C3: [********] | D3: SIEM webhook URL for alerts | E3: Yes | F3: String | G3: Valid HTTPS URL | H3: Secret | I3: Integration Team | J3: SIEM platform | K3: Splunk or Azure Sentinel | L3: [DATE]
A4: SIEM_WEBHOOK_SECRET | B4: All | C4: [********] | D4: Shared secret for webhook validation | E4: Yes | F4: String | G4: Min 32 characters | H4: Secret | I4: Integration Team | J4: SIEM webhook | K4: HMAC signature validation | L4: [DATE]
A5: SIEM_EVENT_TYPES | B5: All | C5: [********] | D5: Event types to forward to SIEM | E5: Yes | F5: String | G5: Comma-separated event list | H5: Confidential | I5: Integration Team | J5: SIEM webhook | K5: Security alert events | L5: [DATE]
A6: JIRA_BASE_URL | B6: All | C6: [********] | D6: JIRA instance base URL | E6: Yes | F6: String | G6: Valid HTTPS URL | H6: Confidential | I6: Integration Team | J6: JIRA license | K6: Vulnerability ticket creation | L6: [DATE]
A7: JIRA_PROJECT_KEY | B7: All | C7: [********] | D7: JIRA project key for security tickets | E7: Yes | F7: String | G7: Valid project key | H7: Confidential | I7: Integration Team | J7: JIRA project | K7: Security backlog project | L7: [DATE]
A8: JIRA_API_TOKEN | B8: All | C8: [********] | D8: JIRA API token for authentication | E8: Yes | F8: String | G8: Valid API token | H8: Secret | I8: Integration Team | J8: JIRA user | K8: Service account token | L8: [DATE]

Sheet Alerts
A1: Notifications Parameters
A2: Parameter Name | B2: Environment | C2: Default Value | D2: Description | E2: Required | F2: Data Type | G2: Validation Rules | H2: Security Level | I2: Owner Team | J2: Dependencies | K2: Notes | L2: Last Updated
A3: SLACK_WEBHOOK_URL | B3: All | C3: [********] | D3: Slack webhook for security notifications | E3: No | F3: String | G3: Valid Slack webhook URL | H3: Secret | I3: Integration Team | J3: Slack workspace | K3: Critical alerts channel | L3: [DATE]
A4: TEAMS_WEBHOOK_URL | B4: All | C4: [********] | D4: Microsoft Teams webhook URL | E4: No | F4: String | G4: Valid Teams webhook URL | H4: Secret | I4: Integration Team | J4: Teams channel | K4: Security team channel | L4: [DATE]
A5: PAGERDUTY_ROUTING_KEY | B5: All | C5: [********] | D5: PagerDuty routing key for incidents | E5: No | F5: String | G5: Valid routing key | H5: Secret | I5: Integration Team | J5: PagerDuty service | K5: Critical incident escalation | L5: [DATE]
A6: ALERT_EMAIL_RECIPIENTS | B6: All | C6: [********] | D6: Email distribution for critical alerts | E6: Yes | F6: String | G6: Valid email addresses | H6: Confidential | I6: Security Team | J6: Email service | K6: Security team distribution | L6: [DATE]

Sheet Monitoring
A1: Monitoring Parameters
A2: Parameter Name | B2: Environment | C2: Default Value | D2: Description | E2: Required | F2: Data Type | G2: Validation Rules | H2: Security Level | I2: Owner Team | J2: Dependencies | K2: Notes | L2: Last Updated
A3: AUDIT_LOG_RETENTION_DAYS | B3: All | C3: 365 | D3: GitHub audit log retention period | E3: Yes | F3: Integer | G3: 90-730 | H3: Public | I3: Security Team | J3: Compliance requirements | K3: 1-year retention for SOC 2 | L3: [DATE]
A4: CLOUDWATCH_LOG_GROUP | B4: All | C4: [********] | D4: CloudWatch log group for alerts | E4: No | F4: String | G4: Valid log group name | H4: Confidential | I4: Operations Team | J4: AWS integration | K4: Optional AWS logging | L4: [DATE]
A5: METRICS_ENABLED | B5: All | C5: true | D5: Enable security metrics collection | E5: Yes | F5: Boolean | G5: true|false | H5: Public | I5: Security Team | J5: Monitoring tools | K5: Dashboard metrics | L5: [DATE]
A6: SECURITY_OVERVIEW_ENABLED | B6: All | C6: true | D6: Enable GitHub Security Overview dashboard | E6: Yes | F6: Boolean | G6: true|false | H6: Public | I6: Security Team | J6: GitHub Enterprise | K6: Organization-wide visibility | L6: [DATE]
