Workbook

Sheet Cover
B3: Configuration Parameters
B5: Generated: | C5: November 27, 2025
B6: Solution: | C6: Srx Firewall Platform
B7: Customer: | C7: [Customer Name]
B8: Version: | C8: 1.0
B9: Status: | C9: Draft
C12: eoframework.org

Sheet All Parameters (Read Only)
A1: Total Parameters | B1: Categories | C1: Required | D1: Confidential/Secret
A2: 39 | B2: 8 | C2: 39 | D2: 12
A4: Parameter Name | B4: Category | C4: Environment | D4: Default Value | E4: Description | F4: Required | G4: Data Type | H4: Validation Rules | I4: Security Level | J4: Owner Team | K4: Dependencies | L4: Notes | M4: Last Updated
A5: =IF('Cluster'!A3="","",'Cluster'!A3) | B5: Cluster | C5: =IF('Cluster'!B3="","",'Cluster'!B3) | D5: =IF('Cluster'!C3="","",'Cluster'!C3) | E5: =IF('Cluster'!D3="","",'Cluster'!D3) | F5: =IF('Cluster'!E3="","",'Cluster'!E3) | G5: =IF('Cluster'!F3="","",'Cluster'!F3) | H5: =IF('Cluster'!G3="","",'Cluster'!G3) | I5: =IF('Cluster'!H3="","",'Cluster'!H3) | J5: =IF('Cluster'!I3="","",'Cluster'!I3) | ... M5: =IF('Cluster'!L3="","",'Cluster'!L3)
A6: =IF('Cluster'!A4="","",'Cluster'!A4) | B6: Cluster | C6: =IF('Cluster'!B4="","",'Cluster'!B4) | D6: =IF('Cluster'!C4="","",'Cluster'!C4) | E6: =IF('Cluster'!D4="","",'Cluster'!D4) | F6: =IF('Cluster'!E4="","",'Cluster'!E4) | G6: =IF('Cluster'!F4="","",'Cluster'!F4) | H6: =IF('Cluster'!G4="","",'Cluster'!G4) | I6: =IF('Cluster'!H4="","",'Cluster'!H4) | J6: =IF('Cluster'!I4="","",'Cluster'!I4) | ... M6: =IF('Cluster'!L4="","",'Cluster'!L4)
A7: =IF('Cluster'!A5="","",'Cluster'!A5) | B7: Cluster | C7: =IF('Cluster'!B5="","",'Cluster'!B5) | D7: =IF('Cluster'!C5="","",'Cluster'!C5) | E7: =IF('Cluster'!D5="","",'Cluster'!D5) | F7: =IF('Cluster'!E5="","",'Cluster'!E5) | G7: =IF('Cluster'!F5="","",'Cluster'!F5) | H7: =IF('Cluster'!G5="","",'Cluster'!G5) | I7: =IF('Cluster'!H5="","",'Cluster'!H5) | J7: =IF('Cluster'!I5="","",'Cluster'!I5) | ... M7: =IF('Cluster'!L5="","",'Cluster'!L5)
A8: =IF('Cluster'!A6="","",'Cluster'!A6) | B8: Cluster | C8: =IF('Cluster'!B6="","",'Cluster'!B6) | D8: =IF('Cluster'!C6="","",'Cluster'!C6) | E8: =IF('Cluster'!D6="","",'Cluster'!D6) | F8: =IF('Cluster'!E6="","",'Cluster'!E6) | G8: =IF('Cluster'!F6="","",'Cluster'!F6) | H8: =IF('Cluster'!G6="","",'Cluster'!G6) | I8: =IF('Cluster'!H6="","",'Cluster'!H6) | J8: =IF('Cluster'!I6="","",'Cluster'!I6) | ... M8: =IF('Cluster'!L6="","",'Cluster'!L6)
A9: =IF('Cluster'!A7="","",'Cluster'!A7) | B9: Cluster | C9: =IF('Cluster'!B7="","",'Cluster'!B7) | D9: =IF('Cluster'!C7="","",'Cluster'!C7) | E9: =IF('Cluster'!D7="","",'Cluster'!D7) | F9: =IF('Cluster'!E7="","",'Cluster'!E7) | G9: =IF('Cluster'!F7="","",'Cluster'!F7) | H9: =IF('Cluster'!G7="","",'Cluster'!G7) | I9: =IF('Cluster'!H7="","",'Cluster'!H7) | J9: =IF('Cluster'!I7="","",'Cluster'!I7) | ... M9: =IF('Cluster'!L7="","",'Cluster'!L7)
A10: =IF('Cluster'!A8="","",'Cluster'!A8) | B10: Cluster | C10: =IF('Cluster'!B8="","",'Cluster'!B8) | D10: =IF('Cluster'!C8="","",'Cluster'!C8) | E10: =IF('Cluster'!D8="","",'Cluster'!D8) | F10: =IF('Cluster'!E8="","",'Cluster'!E8) | G10: =IF('Cluster'!F8="","",'Cluster'!F8) | H10: =IF('Cluster'!G8="","",'Cluster'!G8) | I10: =IF('Cluster'!H8="","",'Cluster'!H8) | J10: =IF('Cluster'!I8="","",'Cluster'!I8) | ... M10: =IF('Cluster'!L8="","",'Cluster'!L8)
A11: =IF('Network'!A3="","",'Network'!A3) | B11: Network | C11: =IF('Network'!B3="","",'Network'!B3) | D11: =IF('Network'!C3="","",'Network'!C3) | E11: =IF('Network'!D3="","",'Network'!D3) | F11: =IF('Network'!E3="","",'Network'!E3) | G11: =IF('Network'!F3="","",'Network'!F3) | H11: =IF('Network'!G3="","",'Network'!G3) | I11: =IF('Network'!H3="","",'Network'!H3) | J11: =IF('Network'!I3="","",'Network'!I3) | ... M11: =IF('Network'!L3="","",'Network'!L3)
A12: =IF('Network'!A4="","",'Network'!A4) | B12: Network | C12: =IF('Network'!B4="","",'Network'!B4) | D12: =IF('Network'!C4="","",'Network'!C4) | E12: =IF('Network'!D4="","",'Network'!D4) | F12: =IF('Network'!E4="","",'Network'!E4) | G12: =IF('Network'!F4="","",'Network'!F4) | H12: =IF('Network'!G4="","",'Network'!G4) | I12: =IF('Network'!H4="","",'Network'!H4) | J12: =IF('Network'!I4="","",'Network'!I4) | ... M12: =IF('Network'!L4="","",'Network'!L4)
A13: =IF('Network'!A5="","",'Network'!A5) | B13: Network | C13: =IF('Network'!B5="","",'Network'!B5) | D13: =IF('Network'!C5="","",'Network'!C5) | E13: =IF('Network'!D5="","",'Network'!D5) | F13: =IF('Network'!E5="","",'Network'!E5) | G13: =IF('Network'!F5="","",'Network'!F5) | H13: =IF('Network'!G5="","",'Network'!G5) | I13: =IF('Network'!H5="","",'Network'!H5) | J13: =IF('Network'!I5="","",'Network'!I5) | ... M13: =IF('Network'!L5="","",'Network'!L5)
A14: =IF('Network'!A6="","",'Network'!A6) | B14: Network | C14: =IF('Network'!B6="","",'Network'!B6) | D14: =IF('Network'!C6="","",'Network'!C6) | E14: =IF('Network'!D6="","",'Network'!D6) | F14: =IF('Network'!E6="","",'Network'!E6) | G14: =IF('Network'!F6="","",'Network'!F6) | H14: =IF('Network'!G6="","",'Network'!G6) | I14: =IF('Network'!H6="","",'Network'!H6) | J14: =IF('Network'!I6="","",'Network'!I6) | ... M14: =IF('Network'!L6="","",'Network'!L6)
A15: =IF('Network'!A7="","",'Network'!A7) | B15: Network | C15: =IF('Network'!B7="","",'Network'!B7) | D15: =IF('Network'!C7="","",'Network'!C7) | E15: =IF('Network'!D7="","",'Network'!D7) | F15: =IF('Network'!E7="","",'Network'!E7) | G15: =IF('Network'!F7="","",'Network'!F7) | H15: =IF('Network'!G7="","",'Network'!G7) | I15: =IF('Network'!H7="","",'Network'!H7) | J15: =IF('Network'!I7="","",'Network'!I7) | ... M15: =IF('Network'!L7="","",'Network'!L7)
A16: =IF('Network'!A8="","",'Network'!A8) | B16: Network | C16: =IF('Network'!B8="","",'Network'!B8) | D16: =IF('Network'!C8="","",'Network'!C8) | E16: =IF('Network'!D8="","",'Network'!D8) | F16: =IF('Network'!E8="","",'Network'!E8) | G16: =IF('Network'!F8="","",'Network'!F8) | H16: =IF('Network'!G8="","",'Network'!G8) | I16: =IF('Network'!H8="","",'Network'!H8) | J16: =IF('Network'!I8="","",'Network'!I8) | ... M16: =IF('Network'!L8="","",'Network'!L8)
A17: =IF('Security'!A3="","",'Security'!A3) | B17: Security | C17: =IF('Security'!B3="","",'Security'!B3) | D17: =IF('Security'!C3="","",'Security'!C3) | E17: =IF('Security'!D3="","",'Security'!D3) | F17: =IF('Security'!E3="","",'Security'!E3) | G17: =IF('Security'!F3="","",'Security'!F3) | H17: =IF('Security'!G3="","",'Security'!G3) | I17: =IF('Security'!H3="","",'Security'!H3) | J17: =IF('Security'!I3="","",'Security'!I3) | ... M17: =IF('Security'!L3="","",'Security'!L3)
A18: =IF('Security'!A4="","",'Security'!A4) | B18: Security | C18: =IF('Security'!B4="","",'Security'!B4) | D18: =IF('Security'!C4="","",'Security'!C4) | E18: =IF('Security'!D4="","",'Security'!D4) | F18: =IF('Security'!E4="","",'Security'!E4) | G18: =IF('Security'!F4="","",'Security'!F4) | H18: =IF('Security'!G4="","",'Security'!G4) | I18: =IF('Security'!H4="","",'Security'!H4) | J18: =IF('Security'!I4="","",'Security'!I4) | ... M18: =IF('Security'!L4="","",'Security'!L4)
A19: =IF('Security'!A5="","",'Security'!A5) | B19: Security | C19: =IF('Security'!B5="","",'Security'!B5) | D19: =IF('Security'!C5="","",'Security'!C5) | E19: =IF('Security'!D5="","",'Security'!D5) | F19: =IF('Security'!E5="","",'Security'!E5) | G19: =IF('Security'!F5="","",'Security'!F5) | H19: =IF('Security'!G5="","",'Security'!G5) | I19: =IF('Security'!H5="","",'Security'!H5) | J19: =IF('Security'!I5="","",'Security'!I5) | ... M19: =IF('Security'!L5="","",'Security'!L5)
A20: =IF('Security'!A6="","",'Security'!A6) | B20: Security | C20: =IF('Security'!B6="","",'Security'!B6) | D20: =IF('Security'!C6="","",'Security'!C6) | E20: =IF('Security'!D6="","",'Security'!D6) | F20: =IF('Security'!E6="","",'Security'!E6) | G20: =IF('Security'!F6="","",'Security'!F6) | H20: =IF('Security'!G6="","",'Security'!G6) | I20: =IF('Security'!H6="","",'Security'!H6) | J20: =IF('Security'!I6="","",'Security'!I6) | ... M20: =IF('Security'!L6="","",'Security'!L6)
A21: =IF('Security'!A7="","",'Security'!A7) | B21: Security | C21: =IF('Security'!B7="","",'Security'!B7) | D21: =IF('Security'!C7="","",'Security'!C7) | E21: =IF('Security'!D7="","",'Security'!D7) | F21: =IF('Security'!E7="","",'Security'!E7) | G21: =IF('Security'!F7="","",'Security'!F7) | H21: =IF('Security'!G7="","",'Security'!G7) | I21: =IF('Security'!H7="","",'Security'!H7) | J21: =IF('Security'!I7="","",'Security'!I7) | ... M21: =IF('Security'!L7="","",'Security'!L7)
A22: =IF('Security'!A8="","",'Security'!A8) | B22: Security | C22: =IF('Security'!B8="","",'Security'!B8) | D22: =IF('Security'!C8="","",'Security'!C8) | E22: =IF('Security'!D8="","",'Security'!D8) | F22: =IF('Security'!E8="","",'Security'!E8) | G22: =IF('Security'!F8="","",'Security'!F8) | H22: =IF('Security'!G8="","",'Security'!G8) | I22: =IF('Security'!H8="","",'Security'!H8) | J22: =IF('Security'!I8="","",'Security'!I8) | ... M22: =IF('Security'!L8="","",'Security'!L8)
A23: =IF('Security'!A9="","",'Security'!A9) | B23: Security | C23: =IF('Security'!B9="","",'Security'!B9) | D23: =IF('Security'!C9="","",'Security'!C9) | E23: =IF('Security'!D9="","",'Security'!D9) | F23: =IF('Security'!E9="","",'Security'!E9) | G23: =IF('Security'!F9="","",'Security'!F9) | H23: =IF('Security'!G9="","",'Security'!G9) | I23: =IF('Security'!H9="","",'Security'!H9) | J23: =IF('Security'!I9="","",'Security'!I9) | ... M23: =IF('Security'!L9="","",'Security'!L9)
A24: =IF('Security'!A10="","",'Security'!A10) | B24: Security | C24: =IF('Security'!B10="","",'Security'!B10) | D24: =IF('Security'!C10="","",'Security'!C10) | E24: =IF('Security'!D10="","",'Security'!D10) | F24: =IF('Security'!E10="","",'Security'!E10) | G24: =IF('Security'!F10="","",'Security'!F10) | H24: =IF('Security'!G10="","",'Security'!G10) | I24: =IF('Security'!H10="","",'Security'!H10) | J24: =IF('Security'!I10="","",'Security'!I10) | ... M24: =IF('Security'!L10="","",'Security'!L10)
A25: =IF('VPN'!A3="","",'VPN'!A3) | B25: VPN | C25: =IF('VPN'!B3="","",'VPN'!B3) | D25: =IF('VPN'!C3="","",'VPN'!C3) | E25: =IF('VPN'!D3="","",'VPN'!D3) | F25: =IF('VPN'!E3="","",'VPN'!E3) | G25: =IF('VPN'!F3="","",'VPN'!F3) | H25: =IF('VPN'!G3="","",'VPN'!G3) | I25: =IF('VPN'!H3="","",'VPN'!H3) | J25: =IF('VPN'!I3="","",'VPN'!I3) | ... M25: =IF('VPN'!L3="","",'VPN'!L3)
A26: =IF('VPN'!A4="","",'VPN'!A4) | B26: VPN | C26: =IF('VPN'!B4="","",'VPN'!B4) | D26: =IF('VPN'!C4="","",'VPN'!C4) | E26: =IF('VPN'!D4="","",'VPN'!D4) | F26: =IF('VPN'!E4="","",'VPN'!E4) | G26: =IF('VPN'!F4="","",'VPN'!F4) | H26: =IF('VPN'!G4="","",'VPN'!G4) | I26: =IF('VPN'!H4="","",'VPN'!H4) | J26: =IF('VPN'!I4="","",'VPN'!I4) | ... M26: =IF('VPN'!L4="","",'VPN'!L4)
A27: =IF('VPN'!A5="","",'VPN'!A5) | B27: VPN | C27: =IF('VPN'!B5="","",'VPN'!B5) | D27: =IF('VPN'!C5="","",'VPN'!C5) | E27: =IF('VPN'!D5="","",'VPN'!D5) | F27: =IF('VPN'!E5="","",'VPN'!E5) | G27: =IF('VPN'!F5="","",'VPN'!F5) | H27: =IF('VPN'!G5="","",'VPN'!G5) | I27: =IF('VPN'!H5="","",'VPN'!H5) | J27: =IF('VPN'!I5="","",'VPN'!I5) | ... M27: =IF('VPN'!L5="","",'VPN'!L5)
A28: =IF('VPN'!A6="","",'VPN'!A6) | B28: VPN | C28: =IF('VPN'!B6="","",'VPN'!B6) | D28: =IF('VPN'!C6="","",'VPN'!C6) | E28: =IF('VPN'!D6="","",'VPN'!D6) | F28: =IF('VPN'!E6="","",'VPN'!E6) | G28: =IF('VPN'!F6="","",'VPN'!F6) | H28: =IF('VPN'!G6="","",'VPN'!G6) | I28: =IF('VPN'!H6="","",'VPN'!H6) | J28: =IF('VPN'!I6="","",'VPN'!I6) | ... M28: =IF('VPN'!L6="","",'VPN'!L6)
A29: =IF('Integration'!A3="","",'Integration'!A3) | B29: Integration | C29: =IF('Integration'!B3="","",'Integration'!B3) | D29: =IF('Integration'!C3="","",'Integration'!C3) | E29: =IF('Integration'!D3="","",'Integration'!D3) | F29: =IF('Integration'!E3="","",'Integration'!E3) | G29: =IF('Integration'!F3="","",'Integration'!F3) | H29: =IF('Integration'!G3="","",'Integration'!G3) | I29: =IF('Integration'!H3="","",'Integration'!H3) | J29: =IF('Integration'!I3="","",'Integration'!I3) | ... M29: =IF('Integration'!L3="","",'Integration'!L3)
A30: =IF('Integration'!A4="","",'Integration'!A4) | B30: Integration | C30: =IF('Integration'!B4="","",'Integration'!B4) | D30: =IF('Integration'!C4="","",'Integration'!C4) | E30: =IF('Integration'!D4="","",'Integration'!D4) | F30: =IF('Integration'!E4="","",'Integration'!E4) | G30: =IF('Integration'!F4="","",'Integration'!F4) | H30: =IF('Integration'!G4="","",'Integration'!G4) | I30: =IF('Integration'!H4="","",'Integration'!H4) | J30: =IF('Integration'!I4="","",'Integration'!I4) | ... M30: =IF('Integration'!L4="","",'Integration'!L4)
A31: =IF('Integration'!A5="","",'Integration'!A5) | B31: Integration | C31: =IF('Integration'!B5="","",'Integration'!B5) | D31: =IF('Integration'!C5="","",'Integration'!C5) | E31: =IF('Integration'!D5="","",'Integration'!D5) | F31: =IF('Integration'!E5="","",'Integration'!E5) | G31: =IF('Integration'!F5="","",'Integration'!F5) | H31: =IF('Integration'!G5="","",'Integration'!G5) | I31: =IF('Integration'!H5="","",'Integration'!H5) | J31: =IF('Integration'!I5="","",'Integration'!I5) | ... M31: =IF('Integration'!L5="","",'Integration'!L5)
A32: =IF('Integration'!A6="","",'Integration'!A6) | B32: Integration | C32: =IF('Integration'!B6="","",'Integration'!B6) | D32: =IF('Integration'!C6="","",'Integration'!C6) | E32: =IF('Integration'!D6="","",'Integration'!D6) | F32: =IF('Integration'!E6="","",'Integration'!E6) | G32: =IF('Integration'!F6="","",'Integration'!F6) | H32: =IF('Integration'!G6="","",'Integration'!G6) | I32: =IF('Integration'!H6="","",'Integration'!H6) | J32: =IF('Integration'!I6="","",'Integration'!I6) | ... M32: =IF('Integration'!L6="","",'Integration'!L6)
A33: =IF('Integration'!A7="","",'Integration'!A7) | B33: Integration | C33: =IF('Integration'!B7="","",'Integration'!B7) | D33: =IF('Integration'!C7="","",'Integration'!C7) | E33: =IF('Integration'!D7="","",'Integration'!D7) | F33: =IF('Integration'!E7="","",'Integration'!E7) | G33: =IF('Integration'!F7="","",'Integration'!F7) | H33: =IF('Integration'!G7="","",'Integration'!G7) | I33: =IF('Integration'!H7="","",'Integration'!H7) | J33: =IF('Integration'!I7="","",'Integration'!I7) | ... M33: =IF('Integration'!L7="","",'Integration'!L7)
A34: =IF('System'!A3="","",'System'!A3) | B34: System | C34: =IF('System'!B3="","",'System'!B3) | D34: =IF('System'!C3="","",'System'!C3) | E34: =IF('System'!D3="","",'System'!D3) | F34: =IF('System'!E3="","",'System'!E3) | G34: =IF('System'!F3="","",'System'!F3) | H34: =IF('System'!G3="","",'System'!G3) | I34: =IF('System'!H3="","",'System'!H3) | J34: =IF('System'!I3="","",'System'!I3) | ... M34: =IF('System'!L3="","",'System'!L3)
A35: =IF('System'!A4="","",'System'!A4) | B35: System | C35: =IF('System'!B4="","",'System'!B4) | D35: =IF('System'!C4="","",'System'!C4) | E35: =IF('System'!D4="","",'System'!D4) | F35: =IF('System'!E4="","",'System'!E4) | G35: =IF('System'!F4="","",'System'!F4) | H35: =IF('System'!G4="","",'System'!G4) | I35: =IF('System'!H4="","",'System'!H4) | J35: =IF('System'!I4="","",'System'!I4) | ... M35: =IF('System'!L4="","",'System'!L4)
A36: =IF('System'!A5="","",'System'!A5) | B36: System | C36: =IF('System'!B5="","",'System'!B5) | D36: =IF('System'!C5="","",'System'!C5) | E36: =IF('System'!D5="","",'System'!D5) | F36: =IF('System'!E5="","",'System'!E5) | G36: =IF('System'!F5="","",'System'!F5) | H36: =IF('System'!G5="","",'System'!G5) | I36: =IF('System'!H5="","",'System'!H5) | J36: =IF('System'!I5="","",'System'!I5) | ... M36: =IF('System'!L5="","",'System'!L5)
A37: =IF('System'!A6="","",'System'!A6) | B37: System | C37: =IF('System'!B6="","",'System'!B6) | D37: =IF('System'!C6="","",'System'!C6) | E37: =IF('System'!D6="","",'System'!D6) | F37: =IF('System'!E6="","",'System'!E6) | G37: =IF('System'!F6="","",'System'!F6) | H37: =IF('System'!G6="","",'System'!G6) | I37: =IF('System'!H6="","",'System'!H6) | J37: =IF('System'!I6="","",'System'!I6) | ... M37: =IF('System'!L6="","",'System'!L6)
A38: =IF('System'!A7="","",'System'!A7) | B38: System | C38: =IF('System'!B7="","",'System'!B7) | D38: =IF('System'!C7="","",'System'!C7) | E38: =IF('System'!D7="","",'System'!D7) | F38: =IF('System'!E7="","",'System'!E7) | G38: =IF('System'!F7="","",'System'!F7) | H38: =IF('System'!G7="","",'System'!G7) | I38: =IF('System'!H7="","",'System'!H7) | J38: =IF('System'!I7="","",'System'!I7) | ... M38: =IF('System'!L7="","",'System'!L7)
A39: =IF('Management'!A3="","",'Management'!A3) | B39: Management | C39: =IF('Management'!B3="","",'Management'!B3) | D39: =IF('Management'!C3="","",'Management'!C3) | E39: =IF('Management'!D3="","",'Management'!D3) | F39: =IF('Management'!E3="","",'Management'!E3) | G39: =IF('Management'!F3="","",'Management'!F3) | H39: =IF('Management'!G3="","",'Management'!G3) | I39: =IF('Management'!H3="","",'Management'!H3) | J39: =IF('Management'!I3="","",'Management'!I3) | ... M39: =IF('Management'!L3="","",'Management'!L3)
A40: =IF('Management'!A4="","",'Management'!A4) | B40: Management | C40: =IF('Management'!B4="","",'Management'!B4) | D40: =IF('Management'!C4="","",'Management'!C4) | E40: =IF('Management'!D4="","",'Management'!D4) | F40: =IF('Management'!E4="","",'Management'!E4) | G40: =IF('Management'!F4="","",'Management'!F4) | H40: =IF('Management'!G4="","",'Management'!G4) | I40: =IF('Management'!H4="","",'Management'!H4) | J40: =IF('Management'!I4="","",'Management'!I4) | ... M40: =IF('Management'!L4="","",'Management'!L4)
A41: =IF('Branch'!A3="","",'Branch'!A3) | B41: Branch | C41: =IF('Branch'!B3="","",'Branch'!B3) | D41: =IF('Branch'!C3="","",'Branch'!C3) | E41: =IF('Branch'!D3="","",'Branch'!D3) | F41: =IF('Branch'!E3="","",'Branch'!E3) | G41: =IF('Branch'!F3="","",'Branch'!F3) | H41: =IF('Branch'!G3="","",'Branch'!G3) | I41: =IF('Branch'!H3="","",'Branch'!H3) | J41: =IF('Branch'!I3="","",'Branch'!I3) | ... M41: =IF('Branch'!L3="","",'Branch'!L3)
...

Sheet Cluster
A1: Cluster Parameters
A2: Parameter Name | B2: Environment | C2: Default Value | D2: Description | E2: Required | F2: Data Type | G2: Validation Rules | H2: Security Level | I2: Owner Team | J2: Dependencies | K2: Notes | L2: Last Updated
A3: SRX_CLUSTER_ID | B3: All | C3: 1 | D3: Chassis cluster identifier for HA pair | E3: Yes | F3: Integer | G3: 1-15 | H3: Public | I3: Network Team | J3: None | K3: Must be unique per cluster | L3: [DATE]
A4: SRX_NODE0_MGMT_IP | B4: Production | C4: [********] | D4: Management IP for cluster node 0 | E4: Yes | F4: IP Address | G4: Valid IPv4 CIDR | H4: Confidential | I4: Network Team | J4: Management network | K4: Primary node management | L4: [DATE]
A5: SRX_NODE1_MGMT_IP | B5: Production | C5: [********] | D5: Management IP for cluster node 1 | E5: Yes | F5: IP Address | G5: Valid IPv4 CIDR | H5: Confidential | I5: Network Team | J5: Management network | K5: Secondary node management | L5: [DATE]
A6: SRX_FABRIC_INTERFACE | B6: All | C6: et-0/0/0 | D6: Fabric interconnect interface | E6: Yes | F6: String | G6: Valid interface name | H6: Public | I6: Network Team | J6: Physical cabling | K6: Direct connection between nodes | L6: [DATE]
A7: HA_RG0_PRIORITY_NODE0 | B7: All | C7: 200 | D7: Redundancy group 0 priority for node 0 | E7: Yes | F7: Integer | G7: 1-254 | H7: Public | I7: Network Team | J7: HA configuration | K7: Higher value is primary | L7: [DATE]
A8: HA_RG0_PRIORITY_NODE1 | B8: All | C8: 100 | D8: Redundancy group 0 priority for node 1 | E8: Yes | F8: Integer | G8: 1-254 | H8: Public | I8: Network Team | J8: HA configuration | K8: Lower value is secondary | L8: [DATE]

Sheet Network
A1: Network Parameters
A2: Parameter Name | B2: Environment | C2: Default Value | D2: Description | E2: Required | F2: Data Type | G2: Validation Rules | H2: Security Level | I2: Owner Team | J2: Dependencies | K2: Notes | L2: Last Updated
A3: ZONE_DMZ_INTERFACE | B3: All | C3: reth1.100 | D3: DMZ zone interface assignment | E3: Yes | F3: String | G3: Valid reth interface | H3: Public | I3: Network Team | J3: VLAN 100 | K3: Public-facing services zone | L3: [DATE]
A4: ZONE_INTERNAL_INTERFACE | B4: All | C4: reth2.200 | D4: Internal zone interface assignment | E4: Yes | F4: String | G4: Valid reth interface | H4: Public | I4: Network Team | J4: VLAN 200 | K4: Corporate internal network | L4: [DATE]
A5: ZONE_VPN_INTERFACE | B5: All | C5: st0.0 | D5: VPN zone tunnel interface | E5: Yes | F5: String | G5: Valid st interface | H5: Public | I5: Network Team | J5: VPN configuration | K5: Site-to-site VPN termination | L5: [DATE]
A6: WAN_INTERFACE_IP | B6: Production | C6: [********] | D6: WAN uplink IP address | E6: Yes | F6: IP Address | G6: Valid IPv4 CIDR | H6: Confidential | I6: Network Team | J6: ISP circuit | K6: Public-facing interface | L6: [DATE]
A7: DMZ_SUBNET | B7: All | C7: 192.168.1.0/24 | D7: DMZ network subnet | E7: Yes | F7: IP Address | G7: Valid IPv4 CIDR | H7: Public | I7: Network Team | J7: Zone configuration | K7: Web servers and public services | L7: [DATE]
A8: INTERNAL_SUBNET | B8: All | C8: 10.10.0.0/24 | D8: Internal network subnet | E8: Yes | F8: IP Address | G8: Valid IPv4 CIDR | H8: Public | I8: Network Team | J8: Zone configuration | K8: Corporate LAN segment | L8: [DATE]

Sheet Security
A1: Security Parameters
A2: Parameter Name | B2: Environment | C2: Default Value | D2: Description | E2: Required | F2: Data Type | G2: Validation Rules | H2: Security Level | I2: Owner Team | J2: Dependencies | K2: Notes | L2: Last Updated
A3: IPS_POLICY_NAME | B3: All | C3: Production-IDP | D3: IPS policy name for production | E3: Yes | F3: String | G3: Valid policy name | H3: Public | I3: Security Team | J3: IPS license | K3: Recommended signature group | L3: [DATE]
A4: IPS_ACTION | B4: All | C4: drop-connection | D4: Default IPS action for threats | E4: Yes | F4: String | G4: drop-connection|drop-packet|none | H4: Public | I4: Security Team | J4: IPS configuration | K4: Block and log threats | L4: [DATE]
A5: IPS_UPDATE_INTERVAL | B5: All | C5: 24 | D5: IPS signature update interval hours | E5: Yes | F5: Integer | G5: 1-168 | H5: Public | I5: Security Team | J5: Internet connectivity | K5: Daily signature updates | L5: [DATE]
A6: ATP_CLOUD_URL | B6: All | C6: https://atp.juniper.net | D6: ATP Cloud service endpoint | E6: Yes | F6: URL | G6: Valid HTTPS URL | H6: Public | I6: Security Team | J6: Internet connectivity | K6: Juniper ATP Cloud service | L6: [DATE]
A7: ATP_API_KEY | B7: All | C7: [********] | D7: ATP Cloud API authentication key | E7: Yes | F7: String | G7: Valid API key format | H7: Secret | I7: Security Team | J7: ATP license | K7: Obtain from Juniper portal | L7: [DATE]
A8: ATP_VERDICT_ACTION | B8: All | C8: block | D8: Action for malware verdict | E8: Yes | F8: String | G8: block|permit|quarantine | H8: Public | I8: Security Team | J8: ATP configuration | K8: Block confirmed malware | L8: [DATE]
A9: SECINTEL_CC_FEED | B9: All | C9: https://secintel.juniper.net/feeds/cc | D9: SecIntel C2 feed URL | E9: Yes | F9: URL | G9: Valid HTTPS URL | H9: Public | I9: Security Team | J9: SecIntel license | K9: Command and control blocking | L9: [DATE]
A10: SECINTEL_REFRESH | B10: All | C10: 1800 | D10: SecIntel feed refresh seconds | E10: Yes | F10: Integer | G10: 300-86400 | H10: Public | I10: Security Team | J10: Internet connectivity | K10: 30-minute refresh interval | L10: [DATE]

Sheet VPN
A1: VPN Parameters
A2: Parameter Name | B2: Environment | C2: Default Value | D2: Description | E2: Required | F2: Data Type | G2: Validation Rules | H2: Security Level | I2: Owner Team | J2: Dependencies | K2: Notes | L2: Last Updated
A3: VPN_IKE_DH_GROUP | B3: All | C3: group20 | D3: IKE Diffie-Hellman group | E3: Yes | F3: String | G3: group14|group19|group20|group21 | H3: Public | I3: Security Team | J3: VPN configuration | K3: 384-bit ECDH | L3: [DATE]
A4: VPN_IKE_ENCRYPTION | B4: All | C4: aes-256-gcm | D4: IKE encryption algorithm | E4: Yes | F4: String | G4: aes-256-gcm|aes-256-cbc | H4: Public | I4: Security Team | J4: VPN configuration | K4: GCM for authenticated encryption | L4: [DATE]
A5: VPN_IPSEC_ENCRYPTION | B5: All | C5: aes-256-gcm | D5: IPsec encryption algorithm | E5: Yes | F5: String | G5: aes-256-gcm|aes-256-cbc | H5: Public | I5: Security Team | J5: VPN configuration | K5: GCM for authenticated encryption | L5: [DATE]
A6: VPN_PSK | B6: All | C6: [********] | D6: VPN pre-shared key | E6: Yes | F6: String | G6: Min 32 characters | H6: Secret | I6: Security Team | J6: VPN peers | K6: Rotate quarterly | L6: [DATE]

Sheet Integration
A1: Integration Parameters
A2: Parameter Name | B2: Environment | C2: Default Value | D2: Description | E2: Required | F2: Data Type | G2: Validation Rules | H2: Security Level | I2: Owner Team | J2: Dependencies | K2: Notes | L2: Last Updated
A3: SYSLOG_HOST | B3: Production | C3: [********] | D3: Syslog destination IP for SIEM | E3: Yes | F3: IP Address | G3: Valid IPv4 address | H3: Confidential | I3: Security Team | J3: Splunk collector | K3: Structured syslog format | L3: [DATE]
A4: SYSLOG_PORT | B4: All | C4: 514 | D4: Syslog destination port | E4: Yes | F4: Integer | G4: 1-65535 | H4: Public | I4: Security Team | J4: Firewall rules | K4: Standard syslog port | L4: [DATE]
A5: SYSLOG_FORMAT | B5: All | C5: sd-syslog | D5: Syslog message format | E5: Yes | F5: String | G5: sd-syslog|syslog | H5: Public | I5: Security Team | J5: SIEM configuration | K5: Structured data format | L5: [DATE]
A6: TACACS_SERVER | B6: Production | C6: [********] | D6: TACACS+ server for admin auth | E6: Yes | F6: IP Address | G6: Valid IPv4 address | H6: Confidential | I6: Security Team | J6: AAA infrastructure | K6: Primary authentication server | L6: [DATE]
A7: TACACS_SECRET | B7: All | C7: [********] | D7: TACACS+ shared secret | E7: Yes | F7: String | G7: Min 16 characters | H7: Secret | I7: Security Team | J7: TACACS server | K7: Rotate quarterly | L7: [DATE]

Sheet System
A1: System Parameters
A2: Parameter Name | B2: Environment | C2: Default Value | D2: Description | E2: Required | F2: Data Type | G2: Validation Rules | H2: Security Level | I2: Owner Team | J2: Dependencies | K2: Notes | L2: Last Updated
A3: NTP_SERVER_1 | B3: All | C3: 10.0.0.20 | D3: Primary NTP server | E3: Yes | F3: IP Address | G3: Valid IPv4 address | H3: Public | I3: Network Team | J3: Network connectivity | K3: Time synchronization | L3: [DATE]
A4: NTP_SERVER_2 | B4: All | C4: 10.0.0.21 | D4: Secondary NTP server | E4: Yes | F4: IP Address | G4: Valid IPv4 address | H4: Public | I4: Network Team | J4: Network connectivity | K4: Backup NTP source | L4: [DATE]
A5: DNS_SERVER_1 | B5: All | C5: 10.0.0.10 | D5: Primary DNS server | E5: Yes | F5: IP Address | G5: Valid IPv4 address | H5: Public | I5: Network Team | J5: Network connectivity | K5: Name resolution | L5: [DATE]
A6: DNS_SERVER_2 | B6: All | C6: 10.0.0.11 | D6: Secondary DNS server | E6: Yes | F6: IP Address | G6: Valid IPv4 address | H6: Public | I6: Network Team | J6: Network connectivity | K6: Backup DNS source | L6: [DATE]
A7: DOMAIN_NAME | B7: All | C7: corp.example.com | D7: DNS domain name | E7: Yes | F7: String | G7: Valid domain name | H7: Public | I7: Network Team | J7: DNS configuration | K7: Corporate domain | L7: [DATE]

Sheet Management
A1: Management Parameters
A2: Parameter Name | B2: Environment | C2: Default Value | D2: Description | E2: Required | F2: Data Type | G2: Validation Rules | H2: Security Level | I2: Owner Team | J2: Dependencies | K2: Notes | L2: Last Updated
A3: SD_MGMT_IP | B3: Production | C3: [********] | D3: Security Director management IP | E3: Yes | F3: IP Address | G3: Valid IPv4 CIDR | H3: Confidential | I3: Platform Team | J3: VM infrastructure | K3: Centralized management | L3: [DATE]
A4: SD_ADMIN_PASSWORD | B4: All | C4: [********] | D4: Security Director admin password | E4: Yes | F4: String | G4: Min 12 chars with complexity | H4: Secret | I4: Platform Team | J4: Initial setup | K4: Change from default | L4: [DATE]

Sheet Branch
A1: Branch Parameters
A2: Parameter Name | B2: Environment | C2: Default Value | D2: Description | E2: Required | F2: Data Type | G2: Validation Rules | H2: Security Level | I2: Owner Team | J2: Dependencies | K2: Notes | L2: Last Updated
A3: BRANCH_WAN_PRIMARY | B3: All | C3: [********] | D3: Branch primary WAN IP | E3: Yes | F3: IP Address | G3: Valid IPv4 CIDR | H3: Confidential | I3: Network Team | J3: ISP circuit | K3: Site-specific addressing | L3: [DATE]
A4: BRANCH_WAN_SECONDARY | B4: All | C4: [********] | D4: Branch secondary WAN IP | E4: Yes | F4: IP Address | G4: Valid IPv4 CIDR | H4: Confidential | I4: Network Team | J4: ISP circuit | K4: SD-WAN failover | L4: [DATE]
A5: BRANCH_LAN_SUBNET | B5: All | C5: [LAN_SUBNET] | D5: Branch LAN subnet | E5: Yes | F5: IP Address | G5: Valid IPv4 CIDR | H5: Public | I5: Network Team | J5: Site design | K5: Site-specific addressing | L5: [DATE]
