Workbook

Sheet Cover
B3: [DOCUMENT TITLE]
B4: Discovery Questionnaire
B5: Presales Document
B6: Generated: | C6: November 16, 2025
B7: Solution: | C7: November 24, 2025
B8: Customer: | C8: Advanced Security
B9: Version: | C9: [Customer Name]
B10: Status: | C10: Draft
C12: eoframework.org

Sheet All Categories (Read Only)
A1: Total Questions | B1: Answered | C1: Remaining | D1: % Complete
A2: 55 | B2: =SUMPRODUCT(--(LEN(F5:F59)>0)) | C2: =A2-B2 | D2: =B2/A2
A4: Question ID | B4: Category | C4: Sub-Category | D4: Question | E4: Guidance | F4: Customer Response | G4: Notes
A5: =IF('Business Requirements'!A2="","",'Business Requirements'!A2) | B5: =IF('Business Requirements'!B2="","",'Business Requirements'!B2) | C5: =IF('Business Requirements'!C2="","",'Business Requirements'!C2) | D5: =IF('Business Requirements'!D2="","",'Business Requirements'!D2) | E5: =IF('Business Requirements'!E2="","",'Business Requirements'!E2) | F5: =IF('Business Requirements'!F2="","",'Business Requirements'!F2) | G5: =IF('Business Requirements'!G2="","",'Business Requirements'!G2)
A6: =IF('Business Requirements'!A3="","",'Business Requirements'!A3) | B6: =IF('Business Requirements'!B3="","",'Business Requirements'!B3) | C6: =IF('Business Requirements'!C3="","",'Business Requirements'!C3) | D6: =IF('Business Requirements'!D3="","",'Business Requirements'!D3) | E6: =IF('Business Requirements'!E3="","",'Business Requirements'!E3) | F6: =IF('Business Requirements'!F3="","",'Business Requirements'!F3) | G6: =IF('Business Requirements'!G3="","",'Business Requirements'!G3)
A7: =IF('Business Requirements'!A4="","",'Business Requirements'!A4) | B7: =IF('Business Requirements'!B4="","",'Business Requirements'!B4) | C7: =IF('Business Requirements'!C4="","",'Business Requirements'!C4) | D7: =IF('Business Requirements'!D4="","",'Business Requirements'!D4) | E7: =IF('Business Requirements'!E4="","",'Business Requirements'!E4) | F7: =IF('Business Requirements'!F4="","",'Business Requirements'!F4) | G7: =IF('Business Requirements'!G4="","",'Business Requirements'!G4)
A8: =IF('Business Requirements'!A5="","",'Business Requirements'!A5) | B8: =IF('Business Requirements'!B5="","",'Business Requirements'!B5) | C8: =IF('Business Requirements'!C5="","",'Business Requirements'!C5) | D8: =IF('Business Requirements'!D5="","",'Business Requirements'!D5) | E8: =IF('Business Requirements'!E5="","",'Business Requirements'!E5) | F8: =IF('Business Requirements'!F5="","",'Business Requirements'!F5) | G8: =IF('Business Requirements'!G5="","",'Business Requirements'!G5)
A9: =IF('Business Requirements'!A6="","",'Business Requirements'!A6) | B9: =IF('Business Requirements'!B6="","",'Business Requirements'!B6) | C9: =IF('Business Requirements'!C6="","",'Business Requirements'!C6) | D9: =IF('Business Requirements'!D6="","",'Business Requirements'!D6) | E9: =IF('Business Requirements'!E6="","",'Business Requirements'!E6) | F9: =IF('Business Requirements'!F6="","",'Business Requirements'!F6) | G9: =IF('Business Requirements'!G6="","",'Business Requirements'!G6)
A10: =IF('Business Requirements'!A7="","",'Business Requirements'!A7) | B10: =IF('Business Requirements'!B7="","",'Business Requirements'!B7) | C10: =IF('Business Requirements'!C7="","",'Business Requirements'!C7) | D10: =IF('Business Requirements'!D7="","",'Business Requirements'!D7) | E10: =IF('Business Requirements'!E7="","",'Business Requirements'!E7) | F10: =IF('Business Requirements'!F7="","",'Business Requirements'!F7) | G10: =IF('Business Requirements'!G7="","",'Business Requirements'!G7)
A11: =IF('Business Requirements'!A8="","",'Business Requirements'!A8) | B11: =IF('Business Requirements'!B8="","",'Business Requirements'!B8) | C11: =IF('Business Requirements'!C8="","",'Business Requirements'!C8) | D11: =IF('Business Requirements'!D8="","",'Business Requirements'!D8) | E11: =IF('Business Requirements'!E8="","",'Business Requirements'!E8) | F11: =IF('Business Requirements'!F8="","",'Business Requirements'!F8) | G11: =IF('Business Requirements'!G8="","",'Business Requirements'!G8)
A12: =IF('Business Requirements'!A9="","",'Business Requirements'!A9) | B12: =IF('Business Requirements'!B9="","",'Business Requirements'!B9) | C12: =IF('Business Requirements'!C9="","",'Business Requirements'!C9) | D12: =IF('Business Requirements'!D9="","",'Business Requirements'!D9) | E12: =IF('Business Requirements'!E9="","",'Business Requirements'!E9) | F12: =IF('Business Requirements'!F9="","",'Business Requirements'!F9) | G12: =IF('Business Requirements'!G9="","",'Business Requirements'!G9)
A13: =IF('Business Requirements'!A10="","",'Business Requirements'!A10) | B13: =IF('Business Requirements'!B10="","",'Business Requirements'!B10) | C13: =IF('Business Requirements'!C10="","",'Business Requirements'!C10) | D13: =IF('Business Requirements'!D10="","",'Business Requirements'!D10) | E13: =IF('Business Requirements'!E10="","",'Business Requirements'!E10) | F13: =IF('Business Requirements'!F10="","",'Business Requirements'!F10) | G13: =IF('Business Requirements'!G10="","",'Business Requirements'!G10)
A14: =IF('Business Requirements'!A11="","",'Business Requirements'!A11) | B14: =IF('Business Requirements'!B11="","",'Business Requirements'!B11) | C14: =IF('Business Requirements'!C11="","",'Business Requirements'!C11) | D14: =IF('Business Requirements'!D11="","",'Business Requirements'!D11) | E14: =IF('Business Requirements'!E11="","",'Business Requirements'!E11) | F14: =IF('Business Requirements'!F11="","",'Business Requirements'!F11) | G14: =IF('Business Requirements'!G11="","",'Business Requirements'!G11)
A15: =IF('Business Requirements'!A12="","",'Business Requirements'!A12) | B15: =IF('Business Requirements'!B12="","",'Business Requirements'!B12) | C15: =IF('Business Requirements'!C12="","",'Business Requirements'!C12) | D15: =IF('Business Requirements'!D12="","",'Business Requirements'!D12) | E15: =IF('Business Requirements'!E12="","",'Business Requirements'!E12) | F15: =IF('Business Requirements'!F12="","",'Business Requirements'!F12) | G15: =IF('Business Requirements'!G12="","",'Business Requirements'!G12)
A16: =IF('Business Requirements'!A13="","",'Business Requirements'!A13) | B16: =IF('Business Requirements'!B13="","",'Business Requirements'!B13) | C16: =IF('Business Requirements'!C13="","",'Business Requirements'!C13) | D16: =IF('Business Requirements'!D13="","",'Business Requirements'!D13) | E16: =IF('Business Requirements'!E13="","",'Business Requirements'!E13) | F16: =IF('Business Requirements'!F13="","",'Business Requirements'!F13) | G16: =IF('Business Requirements'!G13="","",'Business Requirements'!G13)
A17: =IF('Technical Requirements'!A2="","",'Technical Requirements'!A2) | B17: =IF('Technical Requirements'!B2="","",'Technical Requirements'!B2) | C17: =IF('Technical Requirements'!C2="","",'Technical Requirements'!C2) | D17: =IF('Technical Requirements'!D2="","",'Technical Requirements'!D2) | E17: =IF('Technical Requirements'!E2="","",'Technical Requirements'!E2) | F17: =IF('Technical Requirements'!F2="","",'Technical Requirements'!F2) | G17: =IF('Technical Requirements'!G2="","",'Technical Requirements'!G2)
A18: =IF('Technical Requirements'!A3="","",'Technical Requirements'!A3) | B18: =IF('Technical Requirements'!B3="","",'Technical Requirements'!B3) | C18: =IF('Technical Requirements'!C3="","",'Technical Requirements'!C3) | D18: =IF('Technical Requirements'!D3="","",'Technical Requirements'!D3) | E18: =IF('Technical Requirements'!E3="","",'Technical Requirements'!E3) | F18: =IF('Technical Requirements'!F3="","",'Technical Requirements'!F3) | G18: =IF('Technical Requirements'!G3="","",'Technical Requirements'!G3)
A19: =IF('Technical Requirements'!A4="","",'Technical Requirements'!A4) | B19: =IF('Technical Requirements'!B4="","",'Technical Requirements'!B4) | C19: =IF('Technical Requirements'!C4="","",'Technical Requirements'!C4) | D19: =IF('Technical Requirements'!D4="","",'Technical Requirements'!D4) | E19: =IF('Technical Requirements'!E4="","",'Technical Requirements'!E4) | F19: =IF('Technical Requirements'!F4="","",'Technical Requirements'!F4) | G19: =IF('Technical Requirements'!G4="","",'Technical Requirements'!G4)
A20: =IF('Technical Requirements'!A5="","",'Technical Requirements'!A5) | B20: =IF('Technical Requirements'!B5="","",'Technical Requirements'!B5) | C20: =IF('Technical Requirements'!C5="","",'Technical Requirements'!C5) | D20: =IF('Technical Requirements'!D5="","",'Technical Requirements'!D5) | E20: =IF('Technical Requirements'!E5="","",'Technical Requirements'!E5) | F20: =IF('Technical Requirements'!F5="","",'Technical Requirements'!F5) | G20: =IF('Technical Requirements'!G5="","",'Technical Requirements'!G5)
A21: =IF('Technical Requirements'!A6="","",'Technical Requirements'!A6) | B21: =IF('Technical Requirements'!B6="","",'Technical Requirements'!B6) | C21: =IF('Technical Requirements'!C6="","",'Technical Requirements'!C6) | D21: =IF('Technical Requirements'!D6="","",'Technical Requirements'!D6) | E21: =IF('Technical Requirements'!E6="","",'Technical Requirements'!E6) | F21: =IF('Technical Requirements'!F6="","",'Technical Requirements'!F6) | G21: =IF('Technical Requirements'!G6="","",'Technical Requirements'!G6)
A22: =IF('Technical Requirements'!A7="","",'Technical Requirements'!A7) | B22: =IF('Technical Requirements'!B7="","",'Technical Requirements'!B7) | C22: =IF('Technical Requirements'!C7="","",'Technical Requirements'!C7) | D22: =IF('Technical Requirements'!D7="","",'Technical Requirements'!D7) | E22: =IF('Technical Requirements'!E7="","",'Technical Requirements'!E7) | F22: =IF('Technical Requirements'!F7="","",'Technical Requirements'!F7) | G22: =IF('Technical Requirements'!G7="","",'Technical Requirements'!G7)
A23: =IF('Technical Requirements'!A8="","",'Technical Requirements'!A8) | B23: =IF('Technical Requirements'!B8="","",'Technical Requirements'!B8) | C23: =IF('Technical Requirements'!C8="","",'Technical Requirements'!C8) | D23: =IF('Technical Requirements'!D8="","",'Technical Requirements'!D8) | E23: =IF('Technical Requirements'!E8="","",'Technical Requirements'!E8) | F23: =IF('Technical Requirements'!F8="","",'Technical Requirements'!F8) | G23: =IF('Technical Requirements'!G8="","",'Technical Requirements'!G8)
A24: =IF('Technical Requirements'!A9="","",'Technical Requirements'!A9) | B24: =IF('Technical Requirements'!B9="","",'Technical Requirements'!B9) | C24: =IF('Technical Requirements'!C9="","",'Technical Requirements'!C9) | D24: =IF('Technical Requirements'!D9="","",'Technical Requirements'!D9) | E24: =IF('Technical Requirements'!E9="","",'Technical Requirements'!E9) | F24: =IF('Technical Requirements'!F9="","",'Technical Requirements'!F9) | G24: =IF('Technical Requirements'!G9="","",'Technical Requirements'!G9)
A25: =IF('Technical Requirements'!A10="","",'Technical Requirements'!A10) | B25: =IF('Technical Requirements'!B10="","",'Technical Requirements'!B10) | C25: =IF('Technical Requirements'!C10="","",'Technical Requirements'!C10) | D25: =IF('Technical Requirements'!D10="","",'Technical Requirements'!D10) | E25: =IF('Technical Requirements'!E10="","",'Technical Requirements'!E10) | F25: =IF('Technical Requirements'!F10="","",'Technical Requirements'!F10) | G25: =IF('Technical Requirements'!G10="","",'Technical Requirements'!G10)
A26: =IF('Technical Requirements'!A11="","",'Technical Requirements'!A11) | B26: =IF('Technical Requirements'!B11="","",'Technical Requirements'!B11) | C26: =IF('Technical Requirements'!C11="","",'Technical Requirements'!C11) | D26: =IF('Technical Requirements'!D11="","",'Technical Requirements'!D11) | E26: =IF('Technical Requirements'!E11="","",'Technical Requirements'!E11) | F26: =IF('Technical Requirements'!F11="","",'Technical Requirements'!F11) | G26: =IF('Technical Requirements'!G11="","",'Technical Requirements'!G11)
A27: =IF('Technical Requirements'!A12="","",'Technical Requirements'!A12) | B27: =IF('Technical Requirements'!B12="","",'Technical Requirements'!B12) | C27: =IF('Technical Requirements'!C12="","",'Technical Requirements'!C12) | D27: =IF('Technical Requirements'!D12="","",'Technical Requirements'!D12) | E27: =IF('Technical Requirements'!E12="","",'Technical Requirements'!E12) | F27: =IF('Technical Requirements'!F12="","",'Technical Requirements'!F12) | G27: =IF('Technical Requirements'!G12="","",'Technical Requirements'!G12)
A28: =IF('Technical Requirements'!A13="","",'Technical Requirements'!A13) | B28: =IF('Technical Requirements'!B13="","",'Technical Requirements'!B13) | C28: =IF('Technical Requirements'!C13="","",'Technical Requirements'!C13) | D28: =IF('Technical Requirements'!D13="","",'Technical Requirements'!D13) | E28: =IF('Technical Requirements'!E13="","",'Technical Requirements'!E13) | F28: =IF('Technical Requirements'!F13="","",'Technical Requirements'!F13) | G28: =IF('Technical Requirements'!G13="","",'Technical Requirements'!G13)
... A30: =IF('Technical Requirements'!A15="","",'Technical Requirements'!A15) | B30: =IF('Technical Requirements'!B15="","",'Technical Requirements'!B15) | C30: =IF('Technical Requirements'!C15="","",'Technical Requirements'!C15) | D30: =IF('Technical Requirements'!D15="","",'Technical Requirements'!D15) | E30: =IF('Technical Requirements'!E15="","",'Technical Requirements'!E15) | F30: =IF('Technical Requirements'!F15="","",'Technical Requirements'!F15) | G30: =IF('Technical Requirements'!G15="","",'Technical Requirements'!G15)
A31: =IF('Security & Compliance'!A2="","",'Security & Compliance'!A2) | B31: =IF('Security & Compliance'!B2="","",'Security & Compliance'!B2) | C31: =IF('Security & Compliance'!C2="","",'Security & Compliance'!C2) | D31: =IF('Security & Compliance'!D2="","",'Security & Compliance'!D2) | E31: =IF('Security & Compliance'!E2="","",'Security & Compliance'!E2) | F31: =IF('Security & Compliance'!F2="","",'Security & Compliance'!F2) | G31: =IF('Security & Compliance'!G2="","",'Security & Compliance'!G2)
A32: =IF('Security & Compliance'!A3="","",'Security & Compliance'!A3) | B32: =IF('Security & Compliance'!B3="","",'Security & Compliance'!B3) | C32: =IF('Security & Compliance'!C3="","",'Security & Compliance'!C3) | D32: =IF('Security & Compliance'!D3="","",'Security & Compliance'!D3) | E32: =IF('Security & Compliance'!E3="","",'Security & Compliance'!E3) | F32: =IF('Security & Compliance'!F3="","",'Security & Compliance'!F3) | G32: =IF('Security & Compliance'!G3="","",'Security & Compliance'!G3)
A33: =IF('Security & Compliance'!A4="","",'Security & Compliance'!A4) | B33: =IF('Security & Compliance'!B4="","",'Security & Compliance'!B4) | C33: =IF('Security & Compliance'!C4="","",'Security & Compliance'!C4) | D33: =IF('Security & Compliance'!D4="","",'Security & Compliance'!D4) | E33: =IF('Security & Compliance'!E4="","",'Security & Compliance'!E4) | F33: =IF('Security & Compliance'!F4="","",'Security & Compliance'!F4) | G33: =IF('Security & Compliance'!G4="","",'Security & Compliance'!G4)
A34: =IF('Security & Compliance'!A5="","",'Security & Compliance'!A5) | B34: =IF('Security & Compliance'!B5="","",'Security & Compliance'!B5) | C34: =IF('Security & Compliance'!C5="","",'Security & Compliance'!C5) | D34: =IF('Security & Compliance'!D5="","",'Security & Compliance'!D5) | E34: =IF('Security & Compliance'!E5="","",'Security & Compliance'!E5) | F34: =IF('Security & Compliance'!F5="","",'Security & Compliance'!F5) | G34: =IF('Security & Compliance'!G5="","",'Security & Compliance'!G5)
A35: =IF('Security & Compliance'!A6="","",'Security & Compliance'!A6) | B35: =IF('Security & Compliance'!B6="","",'Security & Compliance'!B6) | C35: =IF('Security & Compliance'!C6="","",'Security & Compliance'!C6) | D35: =IF('Security & Compliance'!D6="","",'Security & Compliance'!D6) | E35: =IF('Security & Compliance'!E6="","",'Security & Compliance'!E6) | F35: =IF('Security & Compliance'!F6="","",'Security & Compliance'!F6) | G35: =IF('Security & Compliance'!G6="","",'Security & Compliance'!G6)
A36: =IF('Security & Compliance'!A7="","",'Security & Compliance'!A7) | B36: =IF('Security & Compliance'!B7="","",'Security & Compliance'!B7) | C36: =IF('Security & Compliance'!C7="","",'Security & Compliance'!C7) | D36: =IF('Security & Compliance'!D7="","",'Security & Compliance'!D7) | E36: =IF('Security & Compliance'!E7="","",'Security & Compliance'!E7) | F36: =IF('Security & Compliance'!F7="","",'Security & Compliance'!F7) | G36: =IF('Security & Compliance'!G7="","",'Security & Compliance'!G7)
A37: =IF('Security & Compliance'!A8="","",'Security & Compliance'!A8) | B37: =IF('Security & Compliance'!B8="","",'Security & Compliance'!B8) | C37: =IF('Security & Compliance'!C8="","",'Security & Compliance'!C8) | D37: =IF('Security & Compliance'!D8="","",'Security & Compliance'!D8) | E37: =IF('Security & Compliance'!E8="","",'Security & Compliance'!E8) | F37: =IF('Security & Compliance'!F8="","",'Security & Compliance'!F8) | G37: =IF('Security & Compliance'!G8="","",'Security & Compliance'!G8)
A38: =IF('Security & Compliance'!A9="","",'Security & Compliance'!A9) | B38: =IF('Security & Compliance'!B9="","",'Security & Compliance'!B9) | C38: =IF('Security & Compliance'!C9="","",'Security & Compliance'!C9) | D38: =IF('Security & Compliance'!D9="","",'Security & Compliance'!D9) | E38: =IF('Security & Compliance'!E9="","",'Security & Compliance'!E9) | F38: =IF('Security & Compliance'!F9="","",'Security & Compliance'!F9) | G38: =IF('Security & Compliance'!G9="","",'Security & Compliance'!G9)
A39: =IF('Operations & Support'!A2="","",'Operations & Support'!A2) | B39: =IF('Operations & Support'!B2="","",'Operations & Support'!B2) | C39: =IF('Operations & Support'!C2="","",'Operations & Support'!C2) | D39: =IF('Operations & Support'!D2="","",'Operations & Support'!D2) | E39: =IF('Operations & Support'!E2="","",'Operations & Support'!E2) | F39: =IF('Operations & Support'!F2="","",'Operations & Support'!F2) | G39: =IF('Operations & Support'!G2="","",'Operations & Support'!G2)
A40: =IF('Operations & Support'!A3="","",'Operations & Support'!A3) | B40: =IF('Operations & Support'!B3="","",'Operations & Support'!B3) | C40: =IF('Operations & Support'!C3="","",'Operations & Support'!C3) | D40: =IF('Operations & Support'!D3="","",'Operations & Support'!D3) | E40: =IF('Operations & Support'!E3="","",'Operations & Support'!E3) | F40: =IF('Operations & Support'!F3="","",'Operations & Support'!F3) | G40: =IF('Operations & Support'!G3="","",'Operations & Support'!G3)
A41: =IF('Operations & Support'!A4="","",'Operations & Support'!A4) | B41: =IF('Operations & Support'!B4="","",'Operations & Support'!B4) | C41: =IF('Operations & Support'!C4="","",'Operations & Support'!C4) | D41: =IF('Operations & Support'!D4="","",'Operations & Support'!D4) | E41: =IF('Operations & Support'!E4="","",'Operations & Support'!E4) | F41: =IF('Operations & Support'!F4="","",'Operations & Support'!F4) | G41: =IF('Operations & Support'!G4="","",'Operations & Support'!G4)
A42: =IF('Operations & Support'!A5="","",'Operations & Support'!A5) | B42: =IF('Operations & Support'!B5="","",'Operations & Support'!B5) | C42: =IF('Operations & Support'!C5="","",'Operations & Support'!C5) | D42: =IF('Operations & Support'!D5="","",'Operations & Support'!D5) | E42: =IF('Operations & Support'!E5="","",'Operations & Support'!E5) | F42: =IF('Operations & Support'!F5="","",'Operations & Support'!F5) | G42: =IF('Operations & Support'!G5="","",'Operations & Support'!G5)
...

Sheet Business Requirements
A1: Question ID | B1: Category | C1: Sub-Category | D1: Question | E1: Guidance | F1: Customer Response | G1: Notes
A2: BUS-001 | B2: Business Requirements | C2: Project Information | D2: What is the name of your GitHub Advanced Security project? | E2: Provide internal project reference name | G2: Internal project reference for tracking
A3: BUS-002 | B3: Business Requirements | C3: Project Information | D3: Who is the primary stakeholder for this security initiative? | E3: Name, role, and decision-making authority | G3: Main point of contact and decision authority
A4: BUS-003 | B4: Business Requirements | C4: Business Drivers | D4: What security challenges are you trying to solve? | E4: Common challenges: Security vulnerabilities in production, Compliance gaps, Manual code reviews, Third-party dependency risks, Secret leaks, Lack of security automation | G4: Primary business driver for GHAS investment
A5: BUS-004 | B5: Business Requirements | C5: Current State | D5: What is your current application security workflow? | E5: Describe manual reviews, security tools, and pain points | G5: Current state baseline assessment
A6: BUS-005 | B6: Business Requirements | C6: Current State | D6: What security tools are you currently using? | E6: Common tools: Snyk, Checkmarx, Veracode, SonarQube, BlackDuck, Manual code review | G6: Existing security tooling landscape
A7: BUS-006 | B7: Business Requirements | C7: Incidents | D7: Have you experienced security breaches or vulnerabilities in production? | E7: Describe incidents, impact, and cost of remediation | G7: Security risk assessment
A8: BUS-007 | B8: Business Requirements | C8: Objectives | D8: What are your primary goals for implementing GitHub Advanced Security? | E8: Common goals: Shift-left security, Reduce vulnerabilities, Meet compliance, Automate SAST/SCA, Prevent secret leaks, Reduce security debt | G8: Business objectives and expected outcomes
A9: BUS-008 | B9: Business Requirements | C9: Success Criteria | D9: How will you measure GHAS success? | E9: Define KPIs: vulnerabilities detected in PRs, mean time to fix, security debt reduction, compliance audit pass rate | G9: Success metrics for project evaluation
A10: BUS-009 | B10: Business Requirements | C10: Timeline | D10: What is your expected timeline for GHAS implementation? | E10: Typical ranges: 0-3 months, 3-6 months, 6-12 months | G10: Project timeline expectations and constraints
A11: BUS-010 | B11: Business Requirements | C11: Budget | D11: What is your approved budget range for this security solution? | E11: Include GitHub Enterprise + GHAS licenses, professional services, training | G11: Budget constraints for solution sizing
A12: BUS-011 | B12: Business Requirements | C12: Future Vision | D12: What is your long-term vision for application security? | E12: Consider expansion to more repos, custom policies, security training | G12: Future roadmap and scalability planning
A13: BUS-012 | B13: Business Requirements | C13: Compliance | D13: What compliance standards must you meet? | E13: Common: SOC 2, PCI-DSS, HIPAA, FedRAMP, ISO 27001, GDPR | G13: Compliance requirements driving security investment

Sheet Technical Requirements
A1: Question ID | B1: Category | C1: Sub-Category | D1: Question | E1: Guidance | F1: Customer Response | G1: Notes
A2: TECH-001 | B2: Technical Requirements | C2: GitHub Environment | D2: What GitHub platform are you using? | E2: Options: GitHub.com (public/private), GitHub Enterprise Cloud, GitHub Enterprise Server | G2: Current GitHub deployment model
A3: TECH-002 | B3: Technical Requirements | C3: GitHub Environment | D3: How many GitHub organizations and repositories do you have? | E3: Provide org count, total repos, and repos requiring security scanning | G3: Repository scope and coverage planning
A4: TECH-003 | B4: Technical Requirements | C4: Developer Count | D4: How many active developers/committers do you have? | E4: Active committers = unique users with commits in past 90 days (GHAS pricing) | G4: License count for GHAS pricing
A5: TECH-004 | B5: Technical Requirements | C5: Development Teams | D5: How many development teams will use GHAS? | E5: List teams, repos per team, and primary languages | G5: Team structure and rollout planning
A6: TECH-005 | B6: Technical Requirements | C6: Programming Languages | D6: What programming languages are used in your codebase? | E6: Languages: JavaScript/TypeScript, Python, Java, C#, Go, Ruby, C/C++, PHP, Swift, Kotlin | G6: CodeQL language support requirements
A7: TECH-006 | B7: Technical Requirements | C7: Application Types | D7: What types of applications do you build? | E7: Types: Web apps, APIs, Mobile apps, Desktop apps, Serverless, Microservices | G7: Application security scanning requirements
A8: TECH-007 | B8: Technical Requirements | C8: Code Repositories | D8: What is the size and complexity of your repositories? | E8: Metrics: lines of code, file count, monorepo vs multi-repo | G8: Scanning duration and resource planning
A9: TECH-008 | B9: Technical Requirements | C9: CI/CD Platform | D9: What CI/CD platform do you use? | E9: Platforms: GitHub Actions, Jenkins, GitLab CI, CircleCI, Azure DevOps, TeamCity | G9: Integration and workflow automation
A10: TECH-009 | B10: Technical Requirements | C10: Deployment Frequency | D10: How often do you deploy to production? | E10: Options: Multiple times per day, Daily, Weekly, Monthly | G10: Scan frequency and automation requirements
A11: TECH-010 | B11: Technical Requirements | C11: Branch Strategy | D11: What branching strategy do you follow? | E11: Strategies: GitHub Flow, Git Flow, Trunk-based development | G11: Security checkpoint and PR integration
A12: TECH-011 | B12: Technical Requirements | C12: Dependency Management | D12: What package managers do you use? | E12: Managers: npm, pip, Maven, NuGet, RubyGems, Go modules, Composer | G12: Dependency scanning configuration
A13: TECH-012 | B13: Technical Requirements | C13: Dependency Count | D13: How many third-party dependencies do you use per application? | E13: Typical ranges: 10-50, 50-200, 200-500, 500+ | G13: Software composition analysis scope
... A15: TECH-014 | B15: Technical Requirements | C15: Security Policies | D15: What security policies need enforcement in pull requests? | E15: Examples: Critical vulnerabilities block merge, require security reviews, dependency version constraints | G15: Policy configuration and enforcement

Sheet Security & Compliance
A1: Question ID | B1: Category | C1: Sub-Category | D1: Question | E1: Guidance | F1: Customer Response | G1: Notes
A2: SEC-001 | B2: Security & Compliance | C2: Vulnerability Types | D2: What vulnerability types are most critical for your organization? | E2: Common CWEs: SQL injection, XSS, CSRF, authentication bypass, path traversal, deserialization | G2: Security scanning priorities
A3: SEC-002 | B3: Security & Compliance | C3: Secret Types | D3: What types of secrets appear in your code? | E3: Secret types: API keys, AWS credentials, database passwords, GitHub tokens, SSH keys, certificates | G3: Secret scanning configuration
A4: SEC-003 | B4: Security & Compliance | C4: Secret Remediation | D4: How do you handle secrets detected in code? | E4: Options: Immediate revocation, Alert developer, Security team review, Automated rotation | G4: Secret leak response workflow
A5: SEC-004 | B5: Security & Compliance | C5: Dependency Vulnerabilities | D5: What severity levels require immediate action? | E5: Severity: Critical, High, Medium, Low - define SLAs for each | G5: Vulnerability management and SLA
A6: SEC-005 | B6: Security & Compliance | C6: Security Team | D6: What is your security team structure? | E6: Roles: AppSec engineers, Security champions, CISO, SOC analysts | G6: Security team roles and responsibilities
A7: SEC-006 | B7: Security & Compliance | C7: Security Training | D7: Do developers receive security training? | E7: Topics: OWASP Top 10, secure coding, vulnerability remediation | G7: Developer security awareness level
A8: SEC-007 | B8: Security & Compliance | C8: Audit Requirements | D8: What audit and reporting requirements do you have? | E8: Requirements: Vulnerability reports, Audit logs, Compliance dashboards, Executive summaries | G8: Reporting and compliance needs
A9: SEC-008 | B9: Security & Compliance | C9: Data Classification | D9: What is the highest data classification in your applications? | E9: Levels: Public, Internal, Confidential, Restricted/Regulated | G9: Risk level and compliance requirements

Sheet Operations & Support
A1: Question ID | B1: Category | C1: Sub-Category | D1: Question | E1: Guidance | F1: Customer Response | G1: Notes
A2: OPS-001 | B2: Operations & Support | C2: Code Scanning Frequency | D2: How often should code scanning run? | E2: Options: Every commit, Every pull request, Daily, Weekly | G2: Scan automation and frequency
A3: OPS-002 | B3: Operations & Support | C3: Scan Duration | D3: What is acceptable scan duration for pull requests? | E3: Typical ranges: 5-15 minutes, 15-30 minutes, 30-60 minutes | G3: CI/CD performance requirements
A4: OPS-003 | B4: Operations & Support | C4: Alert Management | D4: How should security alerts be managed? | E4: Options: GitHub Security tab, Email notifications, Slack/Teams integration, SIEM integration | G4: Notification and alert routing
A5: OPS-004 | B5: Operations & Support | C5: Vulnerability Triage | D5: What is your vulnerability triage process? | E5: Process: Security team review, assign to developers, track in Jira/GitHub Issues, verify fix | G5: Workflow and issue management
A6: OPS-005 | B6: Operations & Support | C6: False Positives | D6: How will you handle false positive alerts? | E6: Options: Dismiss with justification, Custom CodeQL suppressions, Severity adjustment | G6: Alert quality and noise reduction
A7: OPS-006 | B7: Operations & Support | C7: Pull Request Blocking | D7: Should security findings block pull request merges? | E7: Options: Block on critical, Block on high+, Advisory only, Custom policy | G7: Merge protection and enforcement
A8: OPS-007 | B8: Operations & Support | C8: Remediation SLA | D8: What are your SLAs for fixing vulnerabilities? | E8: Example SLAs: Critical - 24 hours, High - 7 days, Medium - 30 days, Low - 90 days | G8: Vulnerability management timelines
A9: OPS-008 | B9: Operations & Support | C9: Monitoring | D9: What security metrics do you need to track? | E9: Metrics: Vulnerabilities by severity, MTTR, Scan coverage, Dependency freshness, Secret leak count | G9: Security dashboard and KPIs
A10: OPS-009 | B10: Operations & Support | C10: Reporting Frequency | D10: How often do you need security reports? | E10: Options: Real-time dashboard, Daily, Weekly, Monthly executive summary | G10: Reporting cadence for stakeholders
A11: OPS-010 | B11: Operations & Support | C11: Integration Requirements | D11: What systems need integration with GHAS? | E11: Systems: JIRA, ServiceNow, Slack, PagerDuty, Splunk, Azure Sentinel | G11: Third-party integrations

Sheet Integration Requirements
A1: Question ID | B1: Category | C1: Sub-Category | D1: Question | E1: Guidance | F1: Customer Response | G1: Notes
A2: INT-001 | B2: Integration Requirements | C2: CI/CD Integration | D2: Do you use GitHub Actions for CI/CD? | E2: If yes, security scanning can be fully automated in workflows | G2: GitHub Actions workflow automation
A3: INT-002 | B3: Integration Requirements | C3: Issue Tracking | D3: What issue tracking system do you use? | E3: Systems: GitHub Issues, JIRA, Azure Boards, ServiceNow | G3: Vulnerability tracking integration
A4: INT-003 | B4: Integration Requirements | C4: SIEM Integration | D4: Do you need SIEM integration for security events? | E4: SIEM platforms: Splunk, Azure Sentinel, Datadog, Sumo Logic | G4: Security event aggregation
A5: INT-004 | B5: Integration Requirements | C5: Notification Channels | D5: What notification channels do you use? | E5: Channels: Email, Slack, Microsoft Teams, PagerDuty, Webhooks | G5: Alert delivery mechanisms

Sheet Implementation Planning
A1: Question ID | B1: Category | C1: Sub-Category | D1: Question | E1: Guidance | F1: Customer Response | G1: Notes
A2: IMPL-001 | B2: Implementation Planning | C2: Existing Tools | D2: What security tools will GHAS replace? | E2: Tools: Snyk, Checkmarx, Veracode, SonarQube - plan migration and comparison | G2: Tool migration and transition
A3: IMPL-002 | B3: Implementation Planning | C3: Historical Data | D3: Do you need to import historical security findings? | E3: Options: Fresh start, Import open vulnerabilities, Full historical import | G3: Data migration requirements
A4: IMPL-003 | B4: Implementation Planning | C4: Rollout Strategy | D4: What is your preferred rollout approach? | E4: Strategies: Pilot with 1-2 repos, Phased by team, All repos at once | G4: Implementation and adoption strategy
A5: IMPL-004 | B5: Implementation Planning | C5: Pilot Repositories | D5: Which repositories will you pilot GHAS on first? | E5: Select representative repos with different languages and complexity | G5: Pilot selection and validation
A6: IMPL-0001 | B6: Implementation Planning | C6: Security Champion Training | D6: Who will be trained as security champions? | E6: Identify 1-2 champions per team to lead GHAS adoption | G6: Security champion program
A7: IMPL-0002 | B7: Implementation Planning | C7: Developer Training | D7: What training do developers need? | E7: Topics: GHAS overview, Interpreting alerts, Fixing vulnerabilities, CodeQL basics | G7: Developer enablement and adoption
A8: IMPL-0003 | B8: Implementation Planning | C8: Administrator Training | D8: Who will administer GHAS policies and configurations? | E8: Roles: Security team, Platform team, DevOps | G8: Administrative training requirements
