Workbook

Sheet Cover
B3: Configuration Parameters
B5: Generated: | C5: November 28, 2025
B6: Solution: | C6: Dgx Superpod
B7: Customer: | C7: [Customer Name]
B8: Version: | C8: 1.0
B9: Status: | C9: Draft
C12: eoframework.org

Sheet All Parameters (Read Only)
A1: Total Parameters | B1: Categories | C1: Required | D1: Confidential/Secret
A2: 57 | B2: 14 | C2: 57 | D2: 5
A4: Parameter Name | B4: Category | C4: Environment | D4: Default Value | E4: Description | F4: Required | G4: Data Type | H4: Validation Rules | I4: Security Level | J4: Owner Team | K4: Dependencies | L4: Notes | M4: Last Updated
A5: =IF('Application'!A3="","",'Application'!A3) | B5: Application | C5: =IF('Application'!B3="","",'Application'!B3) | D5: =IF('Application'!C3="","",'Application'!C3) | E5: =IF('Application'!D3="","",'Application'!D3) | F5: =IF('Application'!E3="","",'Application'!E3) | G5: =IF('Application'!F3="","",'Application'!F3) | H5: =IF('Application'!G3="","",'Application'!G3) | I5: =IF('Application'!H3="","",'Application'!H3) | J5: =IF('Application'!I3="","",'Application'!I3) | ... M5: =IF('Application'!L3="","",'Application'!L3)
A6: =IF('Hardware'!A3="","",'Hardware'!A3) | B6: Hardware | C6: =IF('Hardware'!B3="","",'Hardware'!B3) | D6: =IF('Hardware'!C3="","",'Hardware'!C3) | E6: =IF('Hardware'!D3="","",'Hardware'!D3) | F6: =IF('Hardware'!E3="","",'Hardware'!E3) | G6: =IF('Hardware'!F3="","",'Hardware'!F3) | H6: =IF('Hardware'!G3="","",'Hardware'!G3) | I6: =IF('Hardware'!H3="","",'Hardware'!H3) | J6: =IF('Hardware'!I3="","",'Hardware'!I3) | ... M6: =IF('Hardware'!L3="","",'Hardware'!L3)
A7: =IF('Hardware'!A4="","",'Hardware'!A4) | B7: Hardware | C7: =IF('Hardware'!B4="","",'Hardware'!B4) | D7: =IF('Hardware'!C4="","",'Hardware'!C4) | E7: =IF('Hardware'!D4="","",'Hardware'!D4) | F7: =IF('Hardware'!E4="","",'Hardware'!E4) | G7: =IF('Hardware'!F4="","",'Hardware'!F4) | H7: =IF('Hardware'!G4="","",'Hardware'!G4) | I7: =IF('Hardware'!H4="","",'Hardware'!H4) | J7: =IF('Hardware'!I4="","",'Hardware'!I4) | ... M7: =IF('Hardware'!L4="","",'Hardware'!L4)
A8: =IF('Hardware'!A5="","",'Hardware'!A5) | B8: Hardware | C8: =IF('Hardware'!B5="","",'Hardware'!B5) | D8: =IF('Hardware'!C5="","",'Hardware'!C5) | E8: =IF('Hardware'!D5="","",'Hardware'!D5) | F8: =IF('Hardware'!E5="","",'Hardware'!E5) | G8: =IF('Hardware'!F5="","",'Hardware'!F5) | H8: =IF('Hardware'!G5="","",'Hardware'!G5) | I8: =IF('Hardware'!H5="","",'Hardware'!H5) | J8: =IF('Hardware'!I5="","",'Hardware'!I5) | ... M8: =IF('Hardware'!L5="","",'Hardware'!L5)
A9: =IF('Hardware'!A6="","",'Hardware'!A6) | B9: Hardware | C9: =IF('Hardware'!B6="","",'Hardware'!B6) | D9: =IF('Hardware'!C6="","",'Hardware'!C6) | E9: =IF('Hardware'!D6="","",'Hardware'!D6) | F9: =IF('Hardware'!E6="","",'Hardware'!E6) | G9: =IF('Hardware'!F6="","",'Hardware'!F6) | H9: =IF('Hardware'!G6="","",'Hardware'!G6) | I9: =IF('Hardware'!H6="","",'Hardware'!H6) | J9: =IF('Hardware'!I6="","",'Hardware'!I6) | ... M9: =IF('Hardware'!L6="","",'Hardware'!L6)
A10: =IF('Hardware'!A7="","",'Hardware'!A7) | B10: Hardware | C10: =IF('Hardware'!B7="","",'Hardware'!B7) | D10: =IF('Hardware'!C7="","",'Hardware'!C7) | E10: =IF('Hardware'!D7="","",'Hardware'!D7) | F10: =IF('Hardware'!E7="","",'Hardware'!E7) | G10: =IF('Hardware'!F7="","",'Hardware'!F7) | H10: =IF('Hardware'!G7="","",'Hardware'!G7) | I10: =IF('Hardware'!H7="","",'Hardware'!H7) | J10: =IF('Hardware'!I7="","",'Hardware'!I7) | ... M10: =IF('Hardware'!L7="","",'Hardware'!L7)
A11: =IF('Hardware'!A8="","",'Hardware'!A8) | B11: Hardware | C11: =IF('Hardware'!B8="","",'Hardware'!B8) | D11: =IF('Hardware'!C8="","",'Hardware'!C8) | E11: =IF('Hardware'!D8="","",'Hardware'!D8) | F11: =IF('Hardware'!E8="","",'Hardware'!E8) | G11: =IF('Hardware'!F8="","",'Hardware'!F8) | H11: =IF('Hardware'!G8="","",'Hardware'!G8) | I11: =IF('Hardware'!H8="","",'Hardware'!H8) | J11: =IF('Hardware'!I8="","",'Hardware'!I8) | ... M11: =IF('Hardware'!L8="","",'Hardware'!L8)
A12: =IF('Hardware'!A9="","",'Hardware'!A9) | B12: Hardware | C12: =IF('Hardware'!B9="","",'Hardware'!B9) | D12: =IF('Hardware'!C9="","",'Hardware'!C9) | E12: =IF('Hardware'!D9="","",'Hardware'!D9) | F12: =IF('Hardware'!E9="","",'Hardware'!E9) | G12: =IF('Hardware'!F9="","",'Hardware'!F9) | H12: =IF('Hardware'!G9="","",'Hardware'!G9) | I12: =IF('Hardware'!H9="","",'Hardware'!H9) | J12: =IF('Hardware'!I9="","",'Hardware'!I9) | ... M12: =IF('Hardware'!L9="","",'Hardware'!L9)
A13: =IF('Storage'!A3="","",'Storage'!A3) | B13: Storage | C13: =IF('Storage'!B3="","",'Storage'!B3) | D13: =IF('Storage'!C3="","",'Storage'!C3) | E13: =IF('Storage'!D3="","",'Storage'!D3) | F13: =IF('Storage'!E3="","",'Storage'!E3) | G13: =IF('Storage'!F3="","",'Storage'!F3) | H13: =IF('Storage'!G3="","",'Storage'!G3) | I13: =IF('Storage'!H3="","",'Storage'!H3) | J13: =IF('Storage'!I3="","",'Storage'!I3) | ... M13: =IF('Storage'!L3="","",'Storage'!L3)
A14: =IF('Storage'!A4="","",'Storage'!A4) | B14: Storage | C14: =IF('Storage'!B4="","",'Storage'!B4) | D14: =IF('Storage'!C4="","",'Storage'!C4) | E14: =IF('Storage'!D4="","",'Storage'!D4) | F14: =IF('Storage'!E4="","",'Storage'!E4) | G14: =IF('Storage'!F4="","",'Storage'!F4) | H14: =IF('Storage'!G4="","",'Storage'!G4) | I14: =IF('Storage'!H4="","",'Storage'!H4) | J14: =IF('Storage'!I4="","",'Storage'!I4) | ... M14: =IF('Storage'!L4="","",'Storage'!L4)
A15: =IF('Storage'!A5="","",'Storage'!A5) | B15: Storage | C15: =IF('Storage'!B5="","",'Storage'!B5) | D15: =IF('Storage'!C5="","",'Storage'!C5) | E15: =IF('Storage'!D5="","",'Storage'!D5) | F15: =IF('Storage'!E5="","",'Storage'!E5) | G15: =IF('Storage'!F5="","",'Storage'!F5) | H15: =IF('Storage'!G5="","",'Storage'!G5) | I15: =IF('Storage'!H5="","",'Storage'!H5) | J15: =IF('Storage'!I5="","",'Storage'!I5) | ... M15: =IF('Storage'!L5="","",'Storage'!L5)
A16: =IF('Storage'!A6="","",'Storage'!A6) | B16: Storage | C16: =IF('Storage'!B6="","",'Storage'!B6) | D16: =IF('Storage'!C6="","",'Storage'!C6) | E16: =IF('Storage'!D6="","",'Storage'!D6) | F16: =IF('Storage'!E6="","",'Storage'!E6) | G16: =IF('Storage'!F6="","",'Storage'!F6) | H16: =IF('Storage'!G6="","",'Storage'!G6) | I16: =IF('Storage'!H6="","",'Storage'!H6) | J16: =IF('Storage'!I6="","",'Storage'!I6) | ... M16: =IF('Storage'!L6="","",'Storage'!L6)
A17: =IF('Storage'!A7="","",'Storage'!A7) | B17: Storage | C17: =IF('Storage'!B7="","",'Storage'!B7) | D17: =IF('Storage'!C7="","",'Storage'!C7) | E17: =IF('Storage'!D7="","",'Storage'!D7) | F17: =IF('Storage'!E7="","",'Storage'!E7) | G17: =IF('Storage'!F7="","",'Storage'!F7) | H17: =IF('Storage'!G7="","",'Storage'!G7) | I17: =IF('Storage'!H7="","",'Storage'!H7) | J17: =IF('Storage'!I7="","",'Storage'!I7) | ... M17: =IF('Storage'!L7="","",'Storage'!L7)
A18: =IF('Storage'!A8="","",'Storage'!A8) | B18: Storage | C18: =IF('Storage'!B8="","",'Storage'!B8) | D18: =IF('Storage'!C8="","",'Storage'!C8) | E18: =IF('Storage'!D8="","",'Storage'!D8) | F18: =IF('Storage'!E8="","",'Storage'!E8) | G18: =IF('Storage'!F8="","",'Storage'!F8) | H18: =IF('Storage'!G8="","",'Storage'!G8) | I18: =IF('Storage'!H8="","",'Storage'!H8) | J18: =IF('Storage'!I8="","",'Storage'!I8) | ... M18: =IF('Storage'!L8="","",'Storage'!L8)
A19: =IF('Storage'!A9="","",'Storage'!A9) | B19: Storage | C19: =IF('Storage'!B9="","",'Storage'!B9) | D19: =IF('Storage'!C9="","",'Storage'!C9) | E19: =IF('Storage'!D9="","",'Storage'!D9) | F19: =IF('Storage'!E9="","",'Storage'!E9) | G19: =IF('Storage'!F9="","",'Storage'!F9) | H19: =IF('Storage'!G9="","",'Storage'!G9) | I19: =IF('Storage'!H9="","",'Storage'!H9) | J19: =IF('Storage'!I9="","",'Storage'!I9) | ... M19: =IF('Storage'!L9="","",'Storage'!L9)
A20: =IF('Storage'!A10="","",'Storage'!A10) | B20: Storage | C20: =IF('Storage'!B10="","",'Storage'!B10) | D20: =IF('Storage'!C10="","",'Storage'!C10) | E20: =IF('Storage'!D10="","",'Storage'!D10) | F20: =IF('Storage'!E10="","",'Storage'!E10) | G20: =IF('Storage'!F10="","",'Storage'!F10) | H20: =IF('Storage'!G10="","",'Storage'!G10) | I20: =IF('Storage'!H10="","",'Storage'!H10) | J20: =IF('Storage'!I10="","",'Storage'!I10) | ... M20: =IF('Storage'!L10="","",'Storage'!L10)
A21: =IF('Network'!A3="","",'Network'!A3) | B21: Network | C21: =IF('Network'!B3="","",'Network'!B3) | D21: =IF('Network'!C3="","",'Network'!C3) | E21: =IF('Network'!D3="","",'Network'!D3) | F21: =IF('Network'!E3="","",'Network'!E3) | G21: =IF('Network'!F3="","",'Network'!F3) | H21: =IF('Network'!G3="","",'Network'!G3) | I21: =IF('Network'!H3="","",'Network'!H3) | J21: =IF('Network'!I3="","",'Network'!I3) | ... M21: =IF('Network'!L3="","",'Network'!L3)
A22: =IF('Network'!A4="","",'Network'!A4) | B22: Network | C22: =IF('Network'!B4="","",'Network'!B4) | D22: =IF('Network'!C4="","",'Network'!C4) | E22: =IF('Network'!D4="","",'Network'!D4) | F22: =IF('Network'!E4="","",'Network'!E4) | G22: =IF('Network'!F4="","",'Network'!F4) | H22: =IF('Network'!G4="","",'Network'!G4) | I22: =IF('Network'!H4="","",'Network'!H4) | J22: =IF('Network'!I4="","",'Network'!I4) | ... M22: =IF('Network'!L4="","",'Network'!L4)
A23: =IF('Network'!A5="","",'Network'!A5) | B23: Network | C23: =IF('Network'!B5="","",'Network'!B5) | D23: =IF('Network'!C5="","",'Network'!C5) | E23: =IF('Network'!D5="","",'Network'!D5) | F23: =IF('Network'!E5="","",'Network'!E5) | G23: =IF('Network'!F5="","",'Network'!F5) | H23: =IF('Network'!G5="","",'Network'!G5) | I23: =IF('Network'!H5="","",'Network'!H5) | J23: =IF('Network'!I5="","",'Network'!I5) | ... M23: =IF('Network'!L5="","",'Network'!L5)
A24: =IF('Network'!A6="","",'Network'!A6) | B24: Network | C24: =IF('Network'!B6="","",'Network'!B6) | D24: =IF('Network'!C6="","",'Network'!C6) | E24: =IF('Network'!D6="","",'Network'!D6) | F24: =IF('Network'!E6="","",'Network'!E6) | G24: =IF('Network'!F6="","",'Network'!F6) | H24: =IF('Network'!G6="","",'Network'!G6) | I24: =IF('Network'!H6="","",'Network'!H6) | J24: =IF('Network'!I6="","",'Network'!I6) | ... M24: =IF('Network'!L6="","",'Network'!L6)
A25: =IF('Network'!A7="","",'Network'!A7) | B25: Network | C25: =IF('Network'!B7="","",'Network'!B7) | D25: =IF('Network'!C7="","",'Network'!C7) | E25: =IF('Network'!D7="","",'Network'!D7) | F25: =IF('Network'!E7="","",'Network'!E7) | G25: =IF('Network'!F7="","",'Network'!F7) | H25: =IF('Network'!G7="","",'Network'!G7) | I25: =IF('Network'!H7="","",'Network'!H7) | J25: =IF('Network'!I7="","",'Network'!I7) | ... M25: =IF('Network'!L7="","",'Network'!L7)
A26: =IF('Workload Mgmt'!A3="","",'Workload Mgmt'!A3) | B26: Workload Mgmt | C26: =IF('Workload Mgmt'!B3="","",'Workload Mgmt'!B3) | D26: =IF('Workload Mgmt'!C3="","",'Workload Mgmt'!C3) | E26: =IF('Workload Mgmt'!D3="","",'Workload Mgmt'!D3) | F26: =IF('Workload Mgmt'!E3="","",'Workload Mgmt'!E3) | G26: =IF('Workload Mgmt'!F3="","",'Workload Mgmt'!F3) | H26: =IF('Workload Mgmt'!G3="","",'Workload Mgmt'!G3) | I26: =IF('Workload Mgmt'!H3="","",'Workload Mgmt'!H3) | J26: =IF('Workload Mgmt'!I3="","",'Workload Mgmt'!I3) | ... M26: =IF('Workload Mgmt'!L3="","",'Workload Mgmt'!L3)
A27: =IF('Workload Mgmt'!A4="","",'Workload Mgmt'!A4) | B27: Workload Mgmt | C27: =IF('Workload Mgmt'!B4="","",'Workload Mgmt'!B4) | D27: =IF('Workload Mgmt'!C4="","",'Workload Mgmt'!C4) | E27: =IF('Workload Mgmt'!D4="","",'Workload Mgmt'!D4) | F27: =IF('Workload Mgmt'!E4="","",'Workload Mgmt'!E4) | G27: =IF('Workload Mgmt'!F4="","",'Workload Mgmt'!F4) | H27: =IF('Workload Mgmt'!G4="","",'Workload Mgmt'!G4) | I27: =IF('Workload Mgmt'!H4="","",'Workload Mgmt'!H4) | J27: =IF('Workload Mgmt'!I4="","",'Workload Mgmt'!I4) | ... M27: =IF('Workload Mgmt'!L4="","",'Workload Mgmt'!L4)
A28: =IF('Workload Mgmt'!A5="","",'Workload Mgmt'!A5) | B28: Workload Mgmt | C28: =IF('Workload Mgmt'!B5="","",'Workload Mgmt'!B5) | D28: =IF('Workload Mgmt'!C5="","",'Workload Mgmt'!C5) | E28: =IF('Workload Mgmt'!D5="","",'Workload Mgmt'!D5) | F28: =IF('Workload Mgmt'!E5="","",'Workload Mgmt'!E5) | G28: =IF('Workload Mgmt'!F5="","",'Workload Mgmt'!F5) | H28: =IF('Workload Mgmt'!G5="","",'Workload Mgmt'!G5) | I28: =IF('Workload Mgmt'!H5="","",'Workload Mgmt'!H5) | J28: =IF('Workload Mgmt'!I5="","",'Workload Mgmt'!I5) | ... M28: =IF('Workload Mgmt'!L5="","",'Workload Mgmt'!L5)
A29: =IF('Workload Mgmt'!A6="","",'Workload Mgmt'!A6) | B29: Workload Mgmt | C29: =IF('Workload Mgmt'!B6="","",'Workload Mgmt'!B6) | D29: =IF('Workload Mgmt'!C6="","",'Workload Mgmt'!C6) | E29: =IF('Workload Mgmt'!D6="","",'Workload Mgmt'!D6) | F29: =IF('Workload Mgmt'!E6="","",'Workload Mgmt'!E6) | G29: =IF('Workload Mgmt'!F6="","",'Workload Mgmt'!F6) | H29: =IF('Workload Mgmt'!G6="","",'Workload Mgmt'!G6) | I29: =IF('Workload Mgmt'!H6="","",'Workload Mgmt'!H6) | J29: =IF('Workload Mgmt'!I6="","",'Workload Mgmt'!I6) | ... M29: =IF('Workload Mgmt'!L6="","",'Workload Mgmt'!L6)
A30: =IF('Workload Mgmt'!A7="","",'Workload Mgmt'!A7) | B30: Workload Mgmt | C30: =IF('Workload Mgmt'!B7="","",'Workload Mgmt'!B7) | D30: =IF('Workload Mgmt'!C7="","",'Workload Mgmt'!C7) | E30: =IF('Workload Mgmt'!D7="","",'Workload Mgmt'!D7) | F30: =IF('Workload Mgmt'!E7="","",'Workload Mgmt'!E7) | G30: =IF('Workload Mgmt'!F7="","",'Workload Mgmt'!F7) | H30: =IF('Workload Mgmt'!G7="","",'Workload Mgmt'!G7) | I30: =IF('Workload Mgmt'!H7="","",'Workload Mgmt'!H7) | J30: =IF('Workload Mgmt'!I7="","",'Workload Mgmt'!I7) | ... M30: =IF('Workload Mgmt'!L7="","",'Workload Mgmt'!L7)
A31: =IF('Software Stack'!A3="","",'Software Stack'!A3) | B31: Software Stack | C31: =IF('Software Stack'!B3="","",'Software Stack'!B3) | D31: =IF('Software Stack'!C3="","",'Software Stack'!C3) | E31: =IF('Software Stack'!D3="","",'Software Stack'!D3) | F31: =IF('Software Stack'!E3="","",'Software Stack'!E3) | G31: =IF('Software Stack'!F3="","",'Software Stack'!F3) | H31: =IF('Software Stack'!G3="","",'Software Stack'!G3) | I31: =IF('Software Stack'!H3="","",'Software Stack'!H3) | J31: =IF('Software Stack'!I3="","",'Software Stack'!I3) | ... M31: =IF('Software Stack'!L3="","",'Software Stack'!L3)
A32: =IF('Software Stack'!A4="","",'Software Stack'!A4) | B32: Software Stack | C32: =IF('Software Stack'!B4="","",'Software Stack'!B4) | D32: =IF('Software Stack'!C4="","",'Software Stack'!C4) | E32: =IF('Software Stack'!D4="","",'Software Stack'!D4) | F32: =IF('Software Stack'!E4="","",'Software Stack'!E4) | G32: =IF('Software Stack'!F4="","",'Software Stack'!F4) | H32: =IF('Software Stack'!G4="","",'Software Stack'!G4) | I32: =IF('Software Stack'!H4="","",'Software Stack'!H4) | J32: =IF('Software Stack'!I4="","",'Software Stack'!I4) | ... M32: =IF('Software Stack'!L4="","",'Software Stack'!L4)
A33: =IF('Software Stack'!A5="","",'Software Stack'!A5) | B33: Software Stack | C33: =IF('Software Stack'!B5="","",'Software Stack'!B5) | D33: =IF('Software Stack'!C5="","",'Software Stack'!C5) | E33: =IF('Software Stack'!D5="","",'Software Stack'!D5) | F33: =IF('Software Stack'!E5="","",'Software Stack'!E5) | G33: =IF('Software Stack'!F5="","",'Software Stack'!F5) | H33: =IF('Software Stack'!G5="","",'Software Stack'!G5) | I33: =IF('Software Stack'!H5="","",'Software Stack'!H5) | J33: =IF('Software Stack'!I5="","",'Software Stack'!I5) | ... M33: =IF('Software Stack'!L5="","",'Software Stack'!L5)
A34: =IF('Software Stack'!A6="","",'Software Stack'!A6) | B34: Software Stack | C34: =IF('Software Stack'!B6="","",'Software Stack'!B6) | D34: =IF('Software Stack'!C6="","",'Software Stack'!C6) | E34: =IF('Software Stack'!D6="","",'Software Stack'!D6) | F34: =IF('Software Stack'!E6="","",'Software Stack'!E6) | G34: =IF('Software Stack'!F6="","",'Software Stack'!F6) | H34: =IF('Software Stack'!G6="","",'Software Stack'!G6) | I34: =IF('Software Stack'!H6="","",'Software Stack'!H6) | J34: =IF('Software Stack'!I6="","",'Software Stack'!I6) | ... M34: =IF('Software Stack'!L6="","",'Software Stack'!L6)
A35: =IF('Software Stack'!A7="","",'Software Stack'!A7) | B35: Software Stack | C35: =IF('Software Stack'!B7="","",'Software Stack'!B7) | D35: =IF('Software Stack'!C7="","",'Software Stack'!C7) | E35: =IF('Software Stack'!D7="","",'Software Stack'!D7) | F35: =IF('Software Stack'!E7="","",'Software Stack'!E7) | G35: =IF('Software Stack'!F7="","",'Software Stack'!F7) | H35: =IF('Software Stack'!G7="","",'Software Stack'!G7) | I35: =IF('Software Stack'!H7="","",'Software Stack'!H7) | J35: =IF('Software Stack'!I7="","",'Software Stack'!I7) | ... M35: =IF('Software Stack'!L7="","",'Software Stack'!L7)
A36: =IF('AI Frameworks'!A3="","",'AI Frameworks'!A3) | B36: AI Frameworks | C36: =IF('AI Frameworks'!B3="","",'AI Frameworks'!B3) | D36: =IF('AI Frameworks'!C3="","",'AI Frameworks'!C3) | E36: =IF('AI Frameworks'!D3="","",'AI Frameworks'!D3) | F36: =IF('AI Frameworks'!E3="","",'AI Frameworks'!E3) | G36: =IF('AI Frameworks'!F3="","",'AI Frameworks'!F3) | H36: =IF('AI Frameworks'!G3="","",'AI Frameworks'!G3) | I36: =IF('AI Frameworks'!H3="","",'AI Frameworks'!H3) | J36: =IF('AI Frameworks'!I3="","",'AI Frameworks'!I3) | ... M36: =IF('AI Frameworks'!L3="","",'AI Frameworks'!L3)
A37: =IF('AI Frameworks'!A4="","",'AI Frameworks'!A4) | B37: AI Frameworks | C37: =IF('AI Frameworks'!B4="","",'AI Frameworks'!B4) | D37: =IF('AI Frameworks'!C4="","",'AI Frameworks'!C4) | E37: =IF('AI Frameworks'!D4="","",'AI Frameworks'!D4) | F37: =IF('AI Frameworks'!E4="","",'AI Frameworks'!E4) | G37: =IF('AI Frameworks'!F4="","",'AI Frameworks'!F4) | H37: =IF('AI Frameworks'!G4="","",'AI Frameworks'!G4) | I37: =IF('AI Frameworks'!H4="","",'AI Frameworks'!H4) | J37: =IF('AI Frameworks'!I4="","",'AI Frameworks'!I4) | ... M37: =IF('AI Frameworks'!L4="","",'AI Frameworks'!L4)
A38: =IF('AI Frameworks'!A5="","",'AI Frameworks'!A5) | B38: AI Frameworks | C38: =IF('AI Frameworks'!B5="","",'AI Frameworks'!B5) | D38: =IF('AI Frameworks'!C5="","",'AI Frameworks'!C5) | E38: =IF('AI Frameworks'!D5="","",'AI Frameworks'!D5) | F38: =IF('AI Frameworks'!E5="","",'AI Frameworks'!E5) | G38: =IF('AI Frameworks'!F5="","",'AI Frameworks'!F5) | H38: =IF('AI Frameworks'!G5="","",'AI Frameworks'!G5) | I38: =IF('AI Frameworks'!H5="","",'AI Frameworks'!H5) | J38: =IF('AI Frameworks'!I5="","",'AI Frameworks'!I5) | ... M38: =IF('AI Frameworks'!L5="","",'AI Frameworks'!L5)
A39: =IF('AI Frameworks'!A6="","",'AI Frameworks'!A6) | B39: AI Frameworks | C39: =IF('AI Frameworks'!B6="","",'AI Frameworks'!B6) | D39: =IF('AI Frameworks'!C6="","",'AI Frameworks'!C6) | E39: =IF('AI Frameworks'!D6="","",'AI Frameworks'!D6) | F39: =IF('AI Frameworks'!E6="","",'AI Frameworks'!E6) | G39: =IF('AI Frameworks'!F6="","",'AI Frameworks'!F6) | H39: =IF('AI Frameworks'!G6="","",'AI Frameworks'!G6) | I39: =IF('AI Frameworks'!H6="","",'AI Frameworks'!H6) | J39: =IF('AI Frameworks'!I6="","",'AI Frameworks'!I6) | ... M39: =IF('AI Frameworks'!L6="","",'AI Frameworks'!L6)
A40: =IF('AI Frameworks'!A7="","",'AI Frameworks'!A7) | B40: AI Frameworks | C40: =IF('AI Frameworks'!B7="","",'AI Frameworks'!B7) | D40: =IF('AI Frameworks'!C7="","",'AI Frameworks'!C7) | E40: =IF('AI Frameworks'!D7="","",'AI Frameworks'!D7) | F40: =IF('AI Frameworks'!E7="","",'AI Frameworks'!E7) | G40: =IF('AI Frameworks'!F7="","",'AI Frameworks'!F7) | H40: =IF('AI Frameworks'!G7="","",'AI Frameworks'!G7) | I40: =IF('AI Frameworks'!H7="","",'AI Frameworks'!H7) | J40: =IF('AI Frameworks'!I7="","",'AI Frameworks'!I7) | ... M40: =IF('AI Frameworks'!L7="","",'AI Frameworks'!L7)
A41: =IF('Development'!A3="","",'Development'!A3) | B41: Development | C41: =IF('Development'!B3="","",'Development'!B3) | D41: =IF('Development'!C3="","",'Development'!C3) | E41: =IF('Development'!D3="","",'Development'!D3) | F41: =IF('Development'!E3="","",'Development'!E3) | G41: =IF('Development'!F3="","",'Development'!F3) | H41: =IF('Development'!G3="","",'Development'!G3) | I41: =IF('Development'!H3="","",'Development'!H3) | J41: =IF('Development'!I3="","",'Development'!I3) | ... M41: =IF('Development'!L3="","",'Development'!L3)
...

Sheet Application
A1: Application Parameters
A2: Parameter Name | B2: Environment | C2: Default Value | D2: Description | E2: Required | F2: Data Type | G2: Validation Rules | H2: Security Level | I2: Owner Team | J2: Dependencies | K2: Notes | L2: Last Updated
A3: DGX_CLUSTER_NAME | B3: All | C3: dgx-superpod-prod | D3: DGX SuperPOD cluster identifier | E3: Yes | F3: String | G3: Max 30 alphanumeric chars | H3: Public | I3: AI Infrastructure | J3: None | K3: Used in Slurm and monitoring | L3: [DATE]

Sheet Hardware
A1: Hardware Parameters
A2: Parameter Name | B2: Environment | C2: Default Value | D2: Description | E2: Required | F2: Data Type | G2: Validation Rules | H2: Security Level | I2: Owner Team | J2: Dependencies | K2: Notes | L2: Last Updated
A3: DGX_NODE_COUNT | B3: All | C3: 8 | D3: Number of DGX H100 nodes in SuperPOD | E3: Yes | F3: Integer | G3: 8-256 | H3: Public | I3: Hardware Team | J3: Power and cooling | K3: Phase 1 deployment | L3: [DATE]
A4: DGX_NODE_MODEL | B4: All | C4: DGX H100 | D4: DGX system model specification | E4: Yes | F4: String | G4: Valid DGX model identifier | H4: Public | I4: Hardware Team | J4: Performance requirements | K4: Latest H100 generation | L4: [DATE]
A5: GPU_COUNT_PER_NODE | B5: All | C5: 8 | D5: Number of H100 GPUs per DGX node | E5: Yes | F5: Integer | G5: 8 | H5: Public | I5: Hardware Team | J5: DGX_NODE_MODEL | K5: Fixed for H100 platform | L5: [DATE]
A6: GPU_MODEL | B6: All | C6: H100 80GB SXM | D6: GPU model and memory specification | E6: Yes | F6: String | G6: Valid NVIDIA GPU model | H6: Public | I6: AI Team | J6: Workload requirements | K6: 80GB HBM3 memory | L6: [DATE]
A7: GPU_MEMORY_GB | B7: All | C7: 80 | D7: GPU HBM3 memory in GB per GPU | E7: Yes | F7: Integer | G7: 80 | H7: Public | I7: AI Team | J7: Model size requirements | K7: 640 GB per node total | L7: [DATE]
A8: TOTAL_GPU_COUNT | B8: All | C8: 64 | D8: Total GPUs across all DGX nodes | E8: Yes | F8: Integer | G8: Calculated | H8: Public | I8: AI Team | J8: GPU_COUNT_PER_NODE | K8: 8 nodes x 8 GPUs | L8: [DATE]
A9: SYSTEM_RAM_GB | B9: All | C9: 2048 | D9: System RAM per DGX node in GB | E9: Yes | F9: Integer | G9: 2048 | H9: Public | I9: Hardware Team | J9: Data preprocessing | K9: DDR5 memory | L9: [DATE]

Sheet Storage
A1: Storage Parameters
A2: Parameter Name | B2: Environment | C2: Default Value | D2: Description | E2: Required | F2: Data Type | G2: Validation Rules | H2: Security Level | I2: Owner Team | J2: Dependencies | K2: Notes | L2: Last Updated
A3: NVME_STORAGE_TB | B3: All | C3: 30 | D3: Local NVMe storage per node in TB | E3: Yes | F3: Integer | G3: 30 | H3: Public | I3: Storage Team | J3: Checkpoint storage | K3: High-speed scratch | L3: [DATE]
A4: STORAGE_SYSTEM | B4: All | C4: Base Command 1PB | D4: Shared storage platform | E4: Yes | F4: String | G4: Valid storage platform | H4: Public | I4: Storage Team | J4: Dataset storage | K4: NVMe all-flash | L4: [DATE]
A5: SHARED_STORAGE_PB | B5: All | C5: 1.0 | D5: Shared storage capacity in PB | E5: Yes | F5: Float | G5: 0.5-10.0 | H5: Public | I5: Storage Team | J5: Dataset requirements | K5: Expandable | L5: [DATE]
A6: STORAGE_THROUGHPUT_GBS | B6: All | C6: 14 | D6: Target storage throughput in GB/s | E6: Yes | F6: Integer | G6: 14-50 | H6: Public | I6: Storage Team | J6: Training I/O | K6: Sustained read/write | L6: [DATE]
A7: PARALLEL_FILESYSTEM | B7: All | C7: Lustre | D7: Parallel filesystem for AI workloads | E7: Yes | F7: String | G7: Lustre|GPFS|WekaFS | H7: Public | I7: Storage Team | J7: Performance optimization | K7: High-performance I/O | L7: [DATE]
A8: MODEL_STORAGE_PATH | B8: All | C8: /shared/models | D8: Shared path for trained models | E8: Yes | F8: String | G8: Valid Unix path | H8: Public | I8: AI Team | J8: Model deployment | K8: Cross-node access | L8: [DATE]
A9: DATASET_STORAGE_PATH | B9: All | C9: /shared/datasets | D9: Shared path for training datasets | E9: Yes | F9: String | G9: Valid Unix path | H9: Public | I9: AI Team | J9: Data access | K9: High-performance | L9: [DATE]
A10: CHECKPOINT_STORAGE_PATH | B10: All | C10: /shared/checkpoints | D10: Shared path for training checkpoints | E10: Yes | F10: String | G10: Valid Unix path | H10: Public | I10: AI Team | J10: Training recovery | K10: Fault tolerance | L10: [DATE]

Sheet Network
A1: Network Parameters
A2: Parameter Name | B2: Environment | C2: Default Value | D2: Description | E2: Required | F2: Data Type | G2: Validation Rules | H2: Security Level | I2: Owner Team | J2: Dependencies | K2: Notes | L2: Last Updated
A3: INFINIBAND_SPEED | B3: All | C3: 400 | D3: InfiniBand port speed in Gbps | E3: Yes | F3: Integer | G3: 400 | H3: Public | I3: Network Team | J3: NDR InfiniBand | K3: Quantum-2 fabric | L3: [DATE]
A4: INFINIBAND_PORTS_PER_NODE | B4: All | C4: 8 | D4: InfiniBand ports per DGX node | E4: Yes | F4: Integer | G4: 8 | H4: Public | I4: Network Team | J4: Fabric topology | K4: Full mesh capable | L4: [DATE]
A5: INFINIBAND_SWITCH_MODEL | B5: All | C5: QM9700 | D5: InfiniBand switch model | E5: Yes | F5: String | G5: Valid NVIDIA IB switch | H5: Public | I5: Network Team | J5: Port density | K5: 40-port NDR switches | L5: [DATE]
A6: INFINIBAND_SWITCH_COUNT | B6: All | C6: 4 | D6: Number of InfiniBand switches | E6: Yes | F6: Integer | G6: 4-8 | H6: Public | I6: Network Team | J6: Network topology | K6: Leaf-spine architecture | L6: [DATE]
A7: AGGREGATE_IB_BANDWIDTH_TBPS | B7: All | C7: 3.2 | D7: Aggregate InfiniBand bandwidth in Tbps | E7: Yes | F7: Float | G7: Calculated | H7: Public | I7: Network Team | J7: IB port count | K7: Bisection bandwidth | L7: [DATE]

Sheet Workload Mgmt
A1: Workload Mgmt Parameters
A2: Parameter Name | B2: Environment | C2: Default Value | D2: Description | E2: Required | F2: Data Type | G2: Validation Rules | H2: Security Level | I2: Owner Team | J2: Dependencies | K2: Notes | L2: Last Updated
A3: SLURM_VERSION | B3: All | C3: 23.02.6 | D3: Slurm workload manager version | E3: Yes | F3: String | G3: Valid Slurm version | H3: Public | I3: AI Operations | J3: Job scheduling | K3: Latest stable | L3: [DATE]
A4: SLURM_PARTITION_GPU | B4: All | C4: gpu-h100 | D4: Primary GPU partition name | E4: Yes | F4: String | G4: Valid partition name | H4: Public | I4: AI Operations | J4: Resource allocation | K4: Default partition | L4: [DATE]
A5: SLURM_MAX_JOB_TIME | B5: All | C5: 168:00:00 | D5: Maximum job runtime (7 days) | E5: Yes | F5: String | G5: Valid time format | H5: Public | I5: AI Operations | J5: Resource planning | K5: Long training support | L5: [DATE]
A6: SLURM_DEFAULT_CPUS_PER_GPU | B6: All | C6: 16 | D6: Default CPU cores per GPU allocation | E6: Yes | F6: Integer | G6: 8-32 | H6: Public | I6: AI Operations | J6: Resource allocation | K6: Balanced ratio | L6: [DATE]
A7: SLURM_GRES_CONFIG | B7: All | C7: gpu:h100:8 | D7: GRES configuration per node | E7: Yes | F7: String | G7: Valid GRES format | H7: Public | I7: AI Operations | J7: GPU scheduling | K7: 8 GPUs per node | L7: [DATE]

Sheet Software Stack
A1: Software Stack Parameters
A2: Parameter Name | B2: Environment | C2: Default Value | D2: Description | E2: Required | F2: Data Type | G2: Validation Rules | H2: Security Level | I2: Owner Team | J2: Dependencies | K2: Notes | L2: Last Updated
A3: CUDA_VERSION | B3: All | C3: 12.2 | D3: CUDA toolkit version | E3: Yes | F3: String | G3: Valid CUDA version | H3: Public | I3: Software Team | J3: GPU compatibility | K3: Latest stable | L3: [DATE]
A4: CUDNN_VERSION | B4: All | C4: 8.9.7 | D4: cuDNN library version | E4: Yes | F4: String | G4: Valid cuDNN version | H4: Public | I4: Software Team | J4: CUDA_VERSION | K4: Deep learning ops | L4: [DATE]
A5: NCCL_VERSION | B5: All | C5: 2.19.3 | D5: NCCL communication library version | E5: Yes | F5: String | G5: Valid NCCL version | H5: Public | I5: Software Team | J5: Multi-GPU comm | K5: Latest performance | L5: [DATE]
A6: NVIDIA_DRIVER_VERSION | B6: All | C6: 535.154.05 | D6: NVIDIA GPU driver version | E6: Yes | F6: String | G6: Valid driver version | H6: Public | I6: Software Team | J6: CUDA_VERSION | K6: Production driver | L6: [DATE]
A7: DGX_OS_VERSION | B7: All | C7: 6.0.0 | D7: DGX OS version | E7: Yes | F7: String | G7: Valid DGX OS version | H7: Public | I7: Software Team | J7: Driver support | K7: Ubuntu-based | L7: [DATE]

Sheet AI Frameworks
A1: AI Frameworks Parameters
A2: Parameter Name | B2: Environment | C2: Default Value | D2: Description | E2: Required | F2: Data Type | G2: Validation Rules | H2: Security Level | I2: Owner Team | J2: Dependencies | K2: Notes | L2: Last Updated
A3: NGC_CONTAINER_REGISTRY | B3: All | C3: nvcr.io | D3: NVIDIA NGC container registry URL | E3: Yes | F3: String | G3: Valid registry URL | H3: Public | I3: AI Team | J3: Container deployment | K3: Official containers | L3: [DATE]
A4: PYTORCH_NGC_TAG | B4: All | C4: 24.01-py3 | D4: PyTorch NGC container tag | E4: Yes | F4: String | G4: Valid container tag | H4: Public | I4: AI Team | J4: Model development | K4: Latest optimized | L4: [DATE]
A5: TENSORFLOW_NGC_TAG | B5: All | C5: 24.01-tf2-py3 | D5: TensorFlow NGC container tag | E5: Yes | F5: String | G5: Valid container tag | H5: Public | I5: AI Team | J5: Model development | K5: TF 2.x optimized | L5: [DATE]
A6: JAX_NGC_TAG | B6: All | C6: 24.01-py3 | D6: JAX NGC container tag | E6: Yes | F6: String | G6: Valid container tag | H6: Public | I6: AI Team | J6: Model development | K6: XLA backend | L6: [DATE]
A7: TRITON_NGC_TAG | B7: All | C7: 24.01-py3 | D7: Triton Inference Server tag | E7: Yes | F7: String | G7: Valid container tag | H7: Public | I7: AI Team | J7: Model serving | K7: Inference optimization | L7: [DATE]

Sheet Development
A1: Development Parameters
A2: Parameter Name | B2: Environment | C2: Default Value | D2: Description | E2: Required | F2: Data Type | G2: Validation Rules | H2: Security Level | I2: Owner Team | J2: Dependencies | K2: Notes | L2: Last Updated
A3: JUPYTER_ENABLED | B3: All | C3: true | D3: Enable JupyterHub for interactive dev | E3: Yes | F3: Boolean | G3: true|false | H3: Public | I3: AI Team | J3: Data science workflow | K3: GPU-enabled notebooks | L3: [DATE]
A4: TENSORBOARD_ENABLED | B4: All | C4: true | D4: Enable TensorBoard visualization | E4: Yes | F4: Boolean | G4: true|false | H4: Public | I4: AI Team | J4: Training monitoring | K4: Metrics visualization | L4: [DATE]

Sheet MLOps
A1: MLOps Parameters
A2: Parameter Name | B2: Environment | C2: Default Value | D2: Description | E2: Required | F2: Data Type | G2: Validation Rules | H2: Security Level | I2: Owner Team | J2: Dependencies | K2: Notes | L2: Last Updated
A3: MLFLOW_TRACKING_ENABLED | B3: All | C3: true | D3: Enable MLflow experiment tracking | E3: Yes | F3: Boolean | G3: true|false | H3: Public | I3: MLOps Team | J3: Model lifecycle | K3: Experiment management | L3: [DATE]

Sheet Monitoring
A1: Monitoring Parameters
A2: Parameter Name | B2: Environment | C2: Default Value | D2: Description | E2: Required | F2: Data Type | G2: Validation Rules | H2: Security Level | I2: Owner Team | J2: Dependencies | K2: Notes | L2: Last Updated
A3: MONITORING_STACK | B3: All | C3: Prometheus + Grafana | D3: Primary monitoring platform | E3: Yes | F3: String | G3: Valid monitoring stack | H3: Public | I3: Operations | J3: GPU monitoring | K3: DCGM integration | L3: [DATE]
A4: DCGM_EXPORTER_ENABLED | B4: All | C4: true | D4: Enable NVIDIA DCGM metrics export | E4: Yes | F4: Boolean | G4: true|false | H4: Public | I4: Operations | J4: GPU monitoring | K4: Real-time metrics | L4: [DATE]
A5: GPU_UTIL_ALERT_THRESHOLD | B5: All | C5: 95 | D5: GPU utilization alert threshold % | E5: Yes | F5: Integer | G5: 80-99 | H5: Public | I5: Operations | J5: Resource optimization | K5: High util alert | L5: [DATE]
A6: GPU_TEMP_ALERT_THRESHOLD | B6: All | C6: 83 | D6: GPU temperature alert threshold C | E6: Yes | F6: Integer | G6: 80-85 | H6: Public | I6: Operations | J6: Thermal management | K6: Throttle prevention | L6: [DATE]
A7: GPU_MEMORY_ALERT_THRESHOLD | B7: All | C7: 90 | D7: GPU memory usage alert threshold % | E7: Yes | F7: Integer | G7: 80-95 | H7: Public | I7: Operations | J7: Memory management | K7: OOM prevention | L7: [DATE]

Sheet Security
A1: Security Parameters
A2: Parameter Name | B2: Environment | C2: Default Value | D2: Description | E2: Required | F2: Data Type | G2: Validation Rules | H2: Security Level | I2: Owner Team | J2: Dependencies | K2: Notes | L2: Last Updated
A3: LDAP_ENABLED | B3: All | C3: [********] | D3: Enable LDAP user authentication | E3: Yes | F3: Boolean | G3: true|false | H3: Confidential | I3: Security Team | J3: User management | K3: Central auth | L3: [DATE]
A4: LDAP_SERVER_URL | B4: All | C4: [********] | D4: LDAP server endpoint | E4: Yes | F4: String | G4: Valid LDAP URL | H4: Secret | I4: Security Team | J4: Directory service | K4: AD integration | L4: [DATE]
A5: LDAP_BASE_DN | B5: All | C5: [********] | D5: LDAP base distinguished name | E5: Yes | F5: String | G5: Valid DN format | H5: Confidential | I5: Security Team | J5: User search | K5: Organization unit | L5: [DATE]
A6: SSH_KEY_AUTH_ONLY | B6: All | C6: true | D6: Enforce SSH key authentication only | E6: Yes | F6: Boolean | G6: true|false | H6: Public | I6: Security Team | J6: Secure access | K6: Disable passwords | L6: [DATE]
A7: FIREWALL_POLICY | B7: All | C7: [********] | D7: Network firewall configuration | E7: Yes | F7: String | G7: restrictive|standard | H7: Confidential | I7: Security Team | J7: Network security | K7: Minimal surface | L7: [DATE]

Sheet Operations
A1: Operations Parameters
A2: Parameter Name | B2: Environment | C2: Default Value | D2: Description | E2: Required | F2: Data Type | G2: Validation Rules | H2: Security Level | I2: Owner Team | J2: Dependencies | K2: Notes | L2: Last Updated
A3: BACKUP_RETENTION_DAYS | B3: All | C3: 90 | D3: Backup retention period in days | E3: Yes | F3: Integer | G3: 30-365 | H3: Public | I3: Operations | J3: Data protection | K3: Compliance req | L3: [DATE]
A4: BACKUP_SCHEDULE | B4: All | C4: 0 2 * * * | D4: Daily backup schedule (cron) | E4: Yes | F4: String | G4: Valid cron expression | H4: Public | I4: Operations | J4: Backup strategy | K4: 2 AM UTC | L4: [DATE]
A5: MAINTENANCE_WINDOW | B5: All | C5: Sunday 02:00-06:00 UTC | D5: Weekly maintenance window | E5: Yes | F5: String | G5: Valid time range | H5: Public | I5: Operations | J5: Minimal disruption | K5: Low-usage period | L5: [DATE]
A6: DR_ENABLED | B6: Production | C6: false | D6: Disaster recovery enabled | E6: Yes | F6: Boolean | G6: true|false | H6: Public | I6: DR Team | J6: Business continuity | K6: Phase 2 option | L6: [DATE]

Sheet Support
A1: Support Parameters
A2: Parameter Name | B2: Environment | C2: Default Value | D2: Description | E2: Required | F2: Data Type | G2: Validation Rules | H2: Security Level | I2: Owner Team | J2: Dependencies | K2: Notes | L2: Last Updated
A3: NVIDIA_SUPPORT_LEVEL | B3: All | C3: [********] | D3: NVIDIA support contract level | E3: Yes | F3: String | G3: Enterprise|Priority | H3: Confidential | I3: Support Team | J3: Critical workloads | K3: 24x7 support | L3: [DATE]
A4: SUPPORT_RESPONSE_SLA_HR | B4: All | C4: 4 | D4: Critical issue response SLA in hours | E4: Yes | F4: Integer | G4: 4-24 | H4: Public | I4: Support Team | J4: Incident response | K4: Hardware issues | L4: [DATE]

Sheet Facilities
A1: Facilities Parameters
A2: Parameter Name | B2: Environment | C2: Default Value | D2: Description | E2: Required | F2: Data Type | G2: Validation Rules | H2: Security Level | I2: Owner Team | J2: Dependencies | K2: Notes | L2: Last Updated
A3: POWER_CAPACITY_KW | B3: All | C3: 500 | D3: Total power capacity in kW | E3: Yes | F3: Integer | G3: 400-1000 | H3: Public | I3: Facilities Team | J3: Infrastructure | K3: Per 8 DGX nodes | L3: [DATE]
A4: COOLING_CAPACITY_KW | B4: All | C4: 500 | D4: Cooling capacity in kW | E4: Yes | F4: Integer | G4: 400-1000 | H4: Public | I4: Facilities Team | J4: Thermal management | K4: Match power load | L4: [DATE]
