Workbook

Sheet Cover
B3: Configuration Parameters
B5: Generated: | C5: November 27, 2025
B6: Solution: | C6: Openshift Container Platform
B7: Customer: | C7: [Customer Name]
B8: Version: | C8: 1.0
B9: Status: | C9: Draft
C12: eoframework.org

Sheet All Parameters (Read Only)
A1: Total Parameters | B1: Categories | C1: Required | D1: Confidential/Secret
A2: 42 | B2: 12 | C2: 42 | D2: 12
A4: Parameter Name | B4: Category | C4: Environment | D4: Default Value | E4: Description | F4: Required | G4: Data Type | H4: Validation Rules | I4: Security Level | J4: Owner Team | K4: Dependencies | L4: Notes | M4: Last Updated
A5: =IF('Cluster'!A3="","",'Cluster'!A3) | B5: Cluster | C5: =IF('Cluster'!B3="","",'Cluster'!B3) | D5: =IF('Cluster'!C3="","",'Cluster'!C3) | E5: =IF('Cluster'!D3="","",'Cluster'!D3) | F5: =IF('Cluster'!E3="","",'Cluster'!E3) | G5: =IF('Cluster'!F3="","",'Cluster'!F3) | H5: =IF('Cluster'!G3="","",'Cluster'!G3) | I5: =IF('Cluster'!H3="","",'Cluster'!H3) | J5: =IF('Cluster'!I3="","",'Cluster'!I3) | ... M5: =IF('Cluster'!L3="","",'Cluster'!L3)
A6: =IF('Cluster'!A4="","",'Cluster'!A4) | B6: Cluster | C6: =IF('Cluster'!B4="","",'Cluster'!B4) | D6: =IF('Cluster'!C4="","",'Cluster'!C4) | E6: =IF('Cluster'!D4="","",'Cluster'!D4) | F6: =IF('Cluster'!E4="","",'Cluster'!E4) | G6: =IF('Cluster'!F4="","",'Cluster'!F4) | H6: =IF('Cluster'!G4="","",'Cluster'!G4) | I6: =IF('Cluster'!H4="","",'Cluster'!H4) | J6: =IF('Cluster'!I4="","",'Cluster'!I4) | ... M6: =IF('Cluster'!L4="","",'Cluster'!L4)
A7: =IF('Cluster'!A5="","",'Cluster'!A5) | B7: Cluster | C7: =IF('Cluster'!B5="","",'Cluster'!B5) | D7: =IF('Cluster'!C5="","",'Cluster'!C5) | E7: =IF('Cluster'!D5="","",'Cluster'!D5) | F7: =IF('Cluster'!E5="","",'Cluster'!E5) | G7: =IF('Cluster'!F5="","",'Cluster'!F5) | H7: =IF('Cluster'!G5="","",'Cluster'!G5) | I7: =IF('Cluster'!H5="","",'Cluster'!H5) | J7: =IF('Cluster'!I5="","",'Cluster'!I5) | ... M7: =IF('Cluster'!L5="","",'Cluster'!L5)
A8: =IF('Cluster'!A6="","",'Cluster'!A6) | B8: Cluster | C8: =IF('Cluster'!B6="","",'Cluster'!B6) | D8: =IF('Cluster'!C6="","",'Cluster'!C6) | E8: =IF('Cluster'!D6="","",'Cluster'!D6) | F8: =IF('Cluster'!E6="","",'Cluster'!E6) | G8: =IF('Cluster'!F6="","",'Cluster'!F6) | H8: =IF('Cluster'!G6="","",'Cluster'!G6) | I8: =IF('Cluster'!H6="","",'Cluster'!H6) | J8: =IF('Cluster'!I6="","",'Cluster'!I6) | ... M8: =IF('Cluster'!L6="","",'Cluster'!L6)
A9: =IF('Cluster'!A7="","",'Cluster'!A7) | B9: Cluster | C9: =IF('Cluster'!B7="","",'Cluster'!B7) | D9: =IF('Cluster'!C7="","",'Cluster'!C7) | E9: =IF('Cluster'!D7="","",'Cluster'!D7) | F9: =IF('Cluster'!E7="","",'Cluster'!E7) | G9: =IF('Cluster'!F7="","",'Cluster'!F7) | H9: =IF('Cluster'!G7="","",'Cluster'!G7) | I9: =IF('Cluster'!H7="","",'Cluster'!H7) | J9: =IF('Cluster'!I7="","",'Cluster'!I7) | ... M9: =IF('Cluster'!L7="","",'Cluster'!L7)
A10: =IF('Cluster'!A8="","",'Cluster'!A8) | B10: Cluster | C10: =IF('Cluster'!B8="","",'Cluster'!B8) | D10: =IF('Cluster'!C8="","",'Cluster'!C8) | E10: =IF('Cluster'!D8="","",'Cluster'!D8) | F10: =IF('Cluster'!E8="","",'Cluster'!E8) | G10: =IF('Cluster'!F8="","",'Cluster'!F8) | H10: =IF('Cluster'!G8="","",'Cluster'!G8) | I10: =IF('Cluster'!H8="","",'Cluster'!H8) | J10: =IF('Cluster'!I8="","",'Cluster'!I8) | ... M10: =IF('Cluster'!L8="","",'Cluster'!L8)
A11: =IF('Cluster'!A9="","",'Cluster'!A9) | B11: Cluster | C11: =IF('Cluster'!B9="","",'Cluster'!B9) | D11: =IF('Cluster'!C9="","",'Cluster'!C9) | E11: =IF('Cluster'!D9="","",'Cluster'!D9) | F11: =IF('Cluster'!E9="","",'Cluster'!E9) | G11: =IF('Cluster'!F9="","",'Cluster'!F9) | H11: =IF('Cluster'!G9="","",'Cluster'!G9) | I11: =IF('Cluster'!H9="","",'Cluster'!H9) | J11: =IF('Cluster'!I9="","",'Cluster'!I9) | ... M11: =IF('Cluster'!L9="","",'Cluster'!L9)
A12: =IF('Compute'!A3="","",'Compute'!A3) | B12: Compute | C12: =IF('Compute'!B3="","",'Compute'!B3) | D12: =IF('Compute'!C3="","",'Compute'!C3) | E12: =IF('Compute'!D3="","",'Compute'!D3) | F12: =IF('Compute'!E3="","",'Compute'!E3) | G12: =IF('Compute'!F3="","",'Compute'!F3) | H12: =IF('Compute'!G3="","",'Compute'!G3) | I12: =IF('Compute'!H3="","",'Compute'!H3) | J12: =IF('Compute'!I3="","",'Compute'!I3) | ... M12: =IF('Compute'!L3="","",'Compute'!L3)
A13: =IF('Compute'!A4="","",'Compute'!A4) | B13: Compute | C13: =IF('Compute'!B4="","",'Compute'!B4) | D13: =IF('Compute'!C4="","",'Compute'!C4) | E13: =IF('Compute'!D4="","",'Compute'!D4) | F13: =IF('Compute'!E4="","",'Compute'!E4) | G13: =IF('Compute'!F4="","",'Compute'!F4) | H13: =IF('Compute'!G4="","",'Compute'!G4) | I13: =IF('Compute'!H4="","",'Compute'!H4) | J13: =IF('Compute'!I4="","",'Compute'!I4) | ... M13: =IF('Compute'!L4="","",'Compute'!L4)
A14: =IF('Compute'!A5="","",'Compute'!A5) | B14: Compute | C14: =IF('Compute'!B5="","",'Compute'!B5) | D14: =IF('Compute'!C5="","",'Compute'!C5) | E14: =IF('Compute'!D5="","",'Compute'!D5) | F14: =IF('Compute'!E5="","",'Compute'!E5) | G14: =IF('Compute'!F5="","",'Compute'!F5) | H14: =IF('Compute'!G5="","",'Compute'!G5) | I14: =IF('Compute'!H5="","",'Compute'!H5) | J14: =IF('Compute'!I5="","",'Compute'!I5) | ... M14: =IF('Compute'!L5="","",'Compute'!L5)
A15: =IF('Compute'!A6="","",'Compute'!A6) | B15: Compute | C15: =IF('Compute'!B6="","",'Compute'!B6) | D15: =IF('Compute'!C6="","",'Compute'!C6) | E15: =IF('Compute'!D6="","",'Compute'!D6) | F15: =IF('Compute'!E6="","",'Compute'!E6) | G15: =IF('Compute'!F6="","",'Compute'!F6) | H15: =IF('Compute'!G6="","",'Compute'!G6) | I15: =IF('Compute'!H6="","",'Compute'!H6) | J15: =IF('Compute'!I6="","",'Compute'!I6) | ... M15: =IF('Compute'!L6="","",'Compute'!L6)
A16: =IF('Network'!A3="","",'Network'!A3) | B16: Network | C16: =IF('Network'!B3="","",'Network'!B3) | D16: =IF('Network'!C3="","",'Network'!C3) | E16: =IF('Network'!D3="","",'Network'!D3) | F16: =IF('Network'!E3="","",'Network'!E3) | G16: =IF('Network'!F3="","",'Network'!F3) | H16: =IF('Network'!G3="","",'Network'!G3) | I16: =IF('Network'!H3="","",'Network'!H3) | J16: =IF('Network'!I3="","",'Network'!I3) | ... M16: =IF('Network'!L3="","",'Network'!L3)
A17: =IF('Network'!A4="","",'Network'!A4) | B17: Network | C17: =IF('Network'!B4="","",'Network'!B4) | D17: =IF('Network'!C4="","",'Network'!C4) | E17: =IF('Network'!D4="","",'Network'!D4) | F17: =IF('Network'!E4="","",'Network'!E4) | G17: =IF('Network'!F4="","",'Network'!F4) | H17: =IF('Network'!G4="","",'Network'!G4) | I17: =IF('Network'!H4="","",'Network'!H4) | J17: =IF('Network'!I4="","",'Network'!I4) | ... M17: =IF('Network'!L4="","",'Network'!L4)
A18: =IF('Network'!A5="","",'Network'!A5) | B18: Network | C18: =IF('Network'!B5="","",'Network'!B5) | D18: =IF('Network'!C5="","",'Network'!C5) | E18: =IF('Network'!D5="","",'Network'!D5) | F18: =IF('Network'!E5="","",'Network'!E5) | G18: =IF('Network'!F5="","",'Network'!F5) | H18: =IF('Network'!G5="","",'Network'!G5) | I18: =IF('Network'!H5="","",'Network'!H5) | J18: =IF('Network'!I5="","",'Network'!I5) | ... M18: =IF('Network'!L5="","",'Network'!L5)
A19: =IF('Network'!A6="","",'Network'!A6) | B19: Network | C19: =IF('Network'!B6="","",'Network'!B6) | D19: =IF('Network'!C6="","",'Network'!C6) | E19: =IF('Network'!D6="","",'Network'!D6) | F19: =IF('Network'!E6="","",'Network'!E6) | G19: =IF('Network'!F6="","",'Network'!F6) | H19: =IF('Network'!G6="","",'Network'!G6) | I19: =IF('Network'!H6="","",'Network'!H6) | J19: =IF('Network'!I6="","",'Network'!I6) | ... M19: =IF('Network'!L6="","",'Network'!L6)
A20: =IF('Storage'!A3="","",'Storage'!A3) | B20: Storage | C20: =IF('Storage'!B3="","",'Storage'!B3) | D20: =IF('Storage'!C3="","",'Storage'!C3) | E20: =IF('Storage'!D3="","",'Storage'!D3) | F20: =IF('Storage'!E3="","",'Storage'!E3) | G20: =IF('Storage'!F3="","",'Storage'!F3) | H20: =IF('Storage'!G3="","",'Storage'!G3) | I20: =IF('Storage'!H3="","",'Storage'!H3) | J20: =IF('Storage'!I3="","",'Storage'!I3) | ... M20: =IF('Storage'!L3="","",'Storage'!L3)
A21: =IF('Storage'!A4="","",'Storage'!A4) | B21: Storage | C21: =IF('Storage'!B4="","",'Storage'!B4) | D21: =IF('Storage'!C4="","",'Storage'!C4) | E21: =IF('Storage'!D4="","",'Storage'!D4) | F21: =IF('Storage'!E4="","",'Storage'!E4) | G21: =IF('Storage'!F4="","",'Storage'!F4) | H21: =IF('Storage'!G4="","",'Storage'!G4) | I21: =IF('Storage'!H4="","",'Storage'!H4) | J21: =IF('Storage'!I4="","",'Storage'!I4) | ... M21: =IF('Storage'!L4="","",'Storage'!L4)
A22: =IF('Storage'!A5="","",'Storage'!A5) | B22: Storage | C22: =IF('Storage'!B5="","",'Storage'!B5) | D22: =IF('Storage'!C5="","",'Storage'!C5) | E22: =IF('Storage'!D5="","",'Storage'!D5) | F22: =IF('Storage'!E5="","",'Storage'!E5) | G22: =IF('Storage'!F5="","",'Storage'!F5) | H22: =IF('Storage'!G5="","",'Storage'!G5) | I22: =IF('Storage'!H5="","",'Storage'!H5) | J22: =IF('Storage'!I5="","",'Storage'!I5) | ... M22: =IF('Storage'!L5="","",'Storage'!L5)
A23: =IF('Authentication'!A3="","",'Authentication'!A3) | B23: Authentication | C23: =IF('Authentication'!B3="","",'Authentication'!B3) | D23: =IF('Authentication'!C3="","",'Authentication'!C3) | E23: =IF('Authentication'!D3="","",'Authentication'!D3) | F23: =IF('Authentication'!E3="","",'Authentication'!E3) | G23: =IF('Authentication'!F3="","",'Authentication'!F3) | H23: =IF('Authentication'!G3="","",'Authentication'!G3) | I23: =IF('Authentication'!H3="","",'Authentication'!H3) | J23: =IF('Authentication'!I3="","",'Authentication'!I3) | ... M23: =IF('Authentication'!L3="","",'Authentication'!L3)
A24: =IF('Authentication'!A4="","",'Authentication'!A4) | B24: Authentication | C24: =IF('Authentication'!B4="","",'Authentication'!B4) | D24: =IF('Authentication'!C4="","",'Authentication'!C4) | E24: =IF('Authentication'!D4="","",'Authentication'!D4) | F24: =IF('Authentication'!E4="","",'Authentication'!E4) | G24: =IF('Authentication'!F4="","",'Authentication'!F4) | H24: =IF('Authentication'!G4="","",'Authentication'!G4) | I24: =IF('Authentication'!H4="","",'Authentication'!H4) | J24: =IF('Authentication'!I4="","",'Authentication'!I4) | ... M24: =IF('Authentication'!L4="","",'Authentication'!L4)
A25: =IF('Authentication'!A5="","",'Authentication'!A5) | B25: Authentication | C25: =IF('Authentication'!B5="","",'Authentication'!B5) | D25: =IF('Authentication'!C5="","",'Authentication'!C5) | E25: =IF('Authentication'!D5="","",'Authentication'!D5) | F25: =IF('Authentication'!E5="","",'Authentication'!E5) | G25: =IF('Authentication'!F5="","",'Authentication'!F5) | H25: =IF('Authentication'!G5="","",'Authentication'!G5) | I25: =IF('Authentication'!H5="","",'Authentication'!H5) | J25: =IF('Authentication'!I5="","",'Authentication'!I5) | ... M25: =IF('Authentication'!L5="","",'Authentication'!L5)
A26: =IF('Authentication'!A6="","",'Authentication'!A6) | B26: Authentication | C26: =IF('Authentication'!B6="","",'Authentication'!B6) | D26: =IF('Authentication'!C6="","",'Authentication'!C6) | E26: =IF('Authentication'!D6="","",'Authentication'!D6) | F26: =IF('Authentication'!E6="","",'Authentication'!E6) | G26: =IF('Authentication'!F6="","",'Authentication'!F6) | H26: =IF('Authentication'!G6="","",'Authentication'!G6) | I26: =IF('Authentication'!H6="","",'Authentication'!H6) | J26: =IF('Authentication'!I6="","",'Authentication'!I6) | ... M26: =IF('Authentication'!L6="","",'Authentication'!L6)
A27: =IF('Authentication'!A7="","",'Authentication'!A7) | B27: Authentication | C27: =IF('Authentication'!B7="","",'Authentication'!B7) | D27: =IF('Authentication'!C7="","",'Authentication'!C7) | E27: =IF('Authentication'!D7="","",'Authentication'!D7) | F27: =IF('Authentication'!E7="","",'Authentication'!E7) | G27: =IF('Authentication'!F7="","",'Authentication'!F7) | H27: =IF('Authentication'!G7="","",'Authentication'!G7) | I27: =IF('Authentication'!H7="","",'Authentication'!H7) | J27: =IF('Authentication'!I7="","",'Authentication'!I7) | ... M27: =IF('Authentication'!L7="","",'Authentication'!L7)
A28: =IF('Authentication'!A8="","",'Authentication'!A8) | B28: Authentication | C28: =IF('Authentication'!B8="","",'Authentication'!B8) | D28: =IF('Authentication'!C8="","",'Authentication'!C8) | E28: =IF('Authentication'!D8="","",'Authentication'!D8) | F28: =IF('Authentication'!E8="","",'Authentication'!E8) | G28: =IF('Authentication'!F8="","",'Authentication'!F8) | H28: =IF('Authentication'!G8="","",'Authentication'!G8) | I28: =IF('Authentication'!H8="","",'Authentication'!H8) | J28: =IF('Authentication'!I8="","",'Authentication'!I8) | ... M28: =IF('Authentication'!L8="","",'Authentication'!L8)
A29: =IF('Monitoring'!A3="","",'Monitoring'!A3) | B29: Monitoring | C29: =IF('Monitoring'!B3="","",'Monitoring'!B3) | D29: =IF('Monitoring'!C3="","",'Monitoring'!C3) | E29: =IF('Monitoring'!D3="","",'Monitoring'!D3) | F29: =IF('Monitoring'!E3="","",'Monitoring'!E3) | G29: =IF('Monitoring'!F3="","",'Monitoring'!F3) | H29: =IF('Monitoring'!G3="","",'Monitoring'!G3) | I29: =IF('Monitoring'!H3="","",'Monitoring'!H3) | J29: =IF('Monitoring'!I3="","",'Monitoring'!I3) | ... M29: =IF('Monitoring'!L3="","",'Monitoring'!L3)
A30: =IF('Monitoring'!A4="","",'Monitoring'!A4) | B30: Monitoring | C30: =IF('Monitoring'!B4="","",'Monitoring'!B4) | D30: =IF('Monitoring'!C4="","",'Monitoring'!C4) | E30: =IF('Monitoring'!D4="","",'Monitoring'!D4) | F30: =IF('Monitoring'!E4="","",'Monitoring'!E4) | G30: =IF('Monitoring'!F4="","",'Monitoring'!F4) | H30: =IF('Monitoring'!G4="","",'Monitoring'!G4) | I30: =IF('Monitoring'!H4="","",'Monitoring'!H4) | J30: =IF('Monitoring'!I4="","",'Monitoring'!I4) | ... M30: =IF('Monitoring'!L4="","",'Monitoring'!L4)
A31: =IF('Monitoring'!A5="","",'Monitoring'!A5) | B31: Monitoring | C31: =IF('Monitoring'!B5="","",'Monitoring'!B5) | D31: =IF('Monitoring'!C5="","",'Monitoring'!C5) | E31: =IF('Monitoring'!D5="","",'Monitoring'!D5) | F31: =IF('Monitoring'!E5="","",'Monitoring'!E5) | G31: =IF('Monitoring'!F5="","",'Monitoring'!F5) | H31: =IF('Monitoring'!G5="","",'Monitoring'!G5) | I31: =IF('Monitoring'!H5="","",'Monitoring'!H5) | J31: =IF('Monitoring'!I5="","",'Monitoring'!I5) | ... M31: =IF('Monitoring'!L5="","",'Monitoring'!L5)
A32: =IF('Monitoring'!A6="","",'Monitoring'!A6) | B32: Monitoring | C32: =IF('Monitoring'!B6="","",'Monitoring'!B6) | D32: =IF('Monitoring'!C6="","",'Monitoring'!C6) | E32: =IF('Monitoring'!D6="","",'Monitoring'!D6) | F32: =IF('Monitoring'!E6="","",'Monitoring'!E6) | G32: =IF('Monitoring'!F6="","",'Monitoring'!F6) | H32: =IF('Monitoring'!G6="","",'Monitoring'!G6) | I32: =IF('Monitoring'!H6="","",'Monitoring'!H6) | J32: =IF('Monitoring'!I6="","",'Monitoring'!I6) | ... M32: =IF('Monitoring'!L6="","",'Monitoring'!L6)
A33: =IF('Logging'!A3="","",'Logging'!A3) | B33: Logging | C33: =IF('Logging'!B3="","",'Logging'!B3) | D33: =IF('Logging'!C3="","",'Logging'!C3) | E33: =IF('Logging'!D3="","",'Logging'!D3) | F33: =IF('Logging'!E3="","",'Logging'!E3) | G33: =IF('Logging'!F3="","",'Logging'!F3) | H33: =IF('Logging'!G3="","",'Logging'!G3) | I33: =IF('Logging'!H3="","",'Logging'!H3) | J33: =IF('Logging'!I3="","",'Logging'!I3) | ... M33: =IF('Logging'!L3="","",'Logging'!L3)
A34: =IF('Logging'!A4="","",'Logging'!A4) | B34: Logging | C34: =IF('Logging'!B4="","",'Logging'!B4) | D34: =IF('Logging'!C4="","",'Logging'!C4) | E34: =IF('Logging'!D4="","",'Logging'!D4) | F34: =IF('Logging'!E4="","",'Logging'!E4) | G34: =IF('Logging'!F4="","",'Logging'!F4) | H34: =IF('Logging'!G4="","",'Logging'!G4) | I34: =IF('Logging'!H4="","",'Logging'!H4) | J34: =IF('Logging'!I4="","",'Logging'!I4) | ... M34: =IF('Logging'!L4="","",'Logging'!L4)
A35: =IF('Registry'!A3="","",'Registry'!A3) | B35: Registry | C35: =IF('Registry'!B3="","",'Registry'!B3) | D35: =IF('Registry'!C3="","",'Registry'!C3) | E35: =IF('Registry'!D3="","",'Registry'!D3) | F35: =IF('Registry'!E3="","",'Registry'!E3) | G35: =IF('Registry'!F3="","",'Registry'!F3) | H35: =IF('Registry'!G3="","",'Registry'!G3) | I35: =IF('Registry'!H3="","",'Registry'!H3) | J35: =IF('Registry'!I3="","",'Registry'!I3) | ... M35: =IF('Registry'!L3="","",'Registry'!L3)
A36: =IF('Registry'!A4="","",'Registry'!A4) | B36: Registry | C36: =IF('Registry'!B4="","",'Registry'!B4) | D36: =IF('Registry'!C4="","",'Registry'!C4) | E36: =IF('Registry'!D4="","",'Registry'!D4) | F36: =IF('Registry'!E4="","",'Registry'!E4) | G36: =IF('Registry'!F4="","",'Registry'!F4) | H36: =IF('Registry'!G4="","",'Registry'!G4) | I36: =IF('Registry'!H4="","",'Registry'!H4) | J36: =IF('Registry'!I4="","",'Registry'!I4) | ... M36: =IF('Registry'!L4="","",'Registry'!L4)
A37: =IF('Registry'!A5="","",'Registry'!A5) | B37: Registry | C37: =IF('Registry'!B5="","",'Registry'!B5) | D37: =IF('Registry'!C5="","",'Registry'!C5) | E37: =IF('Registry'!D5="","",'Registry'!D5) | F37: =IF('Registry'!E5="","",'Registry'!E5) | G37: =IF('Registry'!F5="","",'Registry'!F5) | H37: =IF('Registry'!G5="","",'Registry'!G5) | I37: =IF('Registry'!H5="","",'Registry'!H5) | J37: =IF('Registry'!I5="","",'Registry'!I5) | ... M37: =IF('Registry'!L5="","",'Registry'!L5)
A38: =IF('GitOps'!A3="","",'GitOps'!A3) | B38: GitOps | C38: =IF('GitOps'!B3="","",'GitOps'!B3) | D38: =IF('GitOps'!C3="","",'GitOps'!C3) | E38: =IF('GitOps'!D3="","",'GitOps'!D3) | F38: =IF('GitOps'!E3="","",'GitOps'!E3) | G38: =IF('GitOps'!F3="","",'GitOps'!F3) | H38: =IF('GitOps'!G3="","",'GitOps'!G3) | I38: =IF('GitOps'!H3="","",'GitOps'!H3) | J38: =IF('GitOps'!I3="","",'GitOps'!I3) | ... M38: =IF('GitOps'!L3="","",'GitOps'!L3)
A39: =IF('GitOps'!A4="","",'GitOps'!A4) | B39: GitOps | C39: =IF('GitOps'!B4="","",'GitOps'!B4) | D39: =IF('GitOps'!C4="","",'GitOps'!C4) | E39: =IF('GitOps'!D4="","",'GitOps'!D4) | F39: =IF('GitOps'!E4="","",'GitOps'!E4) | G39: =IF('GitOps'!F4="","",'GitOps'!F4) | H39: =IF('GitOps'!G4="","",'GitOps'!G4) | I39: =IF('GitOps'!H4="","",'GitOps'!H4) | J39: =IF('GitOps'!I4="","",'GitOps'!I4) | ... M39: =IF('GitOps'!L4="","",'GitOps'!L4)
A40: =IF('GitOps'!A5="","",'GitOps'!A5) | B40: GitOps | C40: =IF('GitOps'!B5="","",'GitOps'!B5) | D40: =IF('GitOps'!C5="","",'GitOps'!C5) | E40: =IF('GitOps'!D5="","",'GitOps'!D5) | F40: =IF('GitOps'!E5="","",'GitOps'!E5) | G40: =IF('GitOps'!F5="","",'GitOps'!F5) | H40: =IF('GitOps'!G5="","",'GitOps'!G5) | I40: =IF('GitOps'!H5="","",'GitOps'!H5) | J40: =IF('GitOps'!I5="","",'GitOps'!I5) | ... M40: =IF('GitOps'!L5="","",'GitOps'!L5)
A41: =IF('Pipelines'!A3="","",'Pipelines'!A3) | B41: Pipelines | C41: =IF('Pipelines'!B3="","",'Pipelines'!B3) | D41: =IF('Pipelines'!C3="","",'Pipelines'!C3) | E41: =IF('Pipelines'!D3="","",'Pipelines'!D3) | F41: =IF('Pipelines'!E3="","",'Pipelines'!E3) | G41: =IF('Pipelines'!F3="","",'Pipelines'!F3) | H41: =IF('Pipelines'!G3="","",'Pipelines'!G3) | I41: =IF('Pipelines'!H3="","",'Pipelines'!H3) | J41: =IF('Pipelines'!I3="","",'Pipelines'!I3) | ... M41: =IF('Pipelines'!L3="","",'Pipelines'!L3)
...

Sheet Cluster
A1: Cluster Parameters
A2: Parameter Name | B2: Environment | C2: Default Value | D2: Description | E2: Required | F2: Data Type | G2: Validation Rules | H2: Security Level | I2: Owner Team | J2: Dependencies | K2: Notes | L2: Last Updated
A3: OCP_CLUSTER_NAME | B3: All | C3: ocp-prod | D3: OpenShift cluster identifier for console and API access | E3: Yes | F3: String | G3: Max 63 chars lowercase alphanumeric | H3: Public | I3: Platform Team | J3: DNS configuration | K3: Must be unique within DNS domain | L3: [DATE]
A4: OCP_BASE_DOMAIN | B4: All | C4: example.com | D4: Base domain for cluster DNS and routing | E4: Yes | F4: String | G4: Valid DNS domain format | H4: Public | I4: Network Team | J4: DNS zone management | K4: Wildcard DNS required for routes | L4: [DATE]
A5: OCP_VERSION | B5: All | C5: 4.14.10 | D5: Red Hat OpenShift Container Platform version | E5: Yes | F5: String | G5: 4.x.x format | H5: Public | I5: Platform Team | J5: Red Hat subscription | K5: LTS version recommended for production | L5: [DATE]
A6: OCP_API_ENDPOINT | B6: Production | C6: https://api.ocp-prod.example.com:6443 | D6: OpenShift API server endpoint URL | E6: Yes | F6: String | G6: Valid HTTPS URL | H6: Public | I6: Platform Team | J6: Network connectivity | K6: Load balanced endpoint | L6: [DATE]
A7: OCP_CONSOLE_URL | B7: Production | C7: https://console-openshift-console.apps.ocp-prod.example.com | D7: OpenShift web console URL | E7: Yes | F7: String | G7: Valid HTTPS URL | H7: Public | I7: Platform Team | J7: OCP_BASE_DOMAIN | K7: User-facing dashboard | L7: [DATE]
A8: CONTROL_PLANE_NODES | B8: Production | C8: 3 | D8: Number of control plane (master) nodes | E8: Yes | F8: Integer | G8: 1|3|5 | H8: Public | I8: Infrastructure Team | J8: Hardware provisioning | K8: Odd number for etcd quorum | L8: [DATE]
A9: WORKER_NODES | B9: Production | C9: 3 | D9: Number of worker nodes for application workloads | E9: Yes | F9: Integer | G9: Minimum 2 | H9: Public | I9: Infrastructure Team | J9: Hardware provisioning | K9: Scale based on workload requirements | L9: [DATE]

Sheet Compute
A1: Compute Parameters
A2: Parameter Name | B2: Environment | C2: Default Value | D2: Description | E2: Required | F2: Data Type | G2: Validation Rules | H2: Security Level | I2: Owner Team | J2: Dependencies | K2: Notes | L2: Last Updated
A3: CONTROL_PLANE_CPU | B3: Production | C3: 8 | D3: vCPU cores per control plane node | E3: Yes | F3: Integer | G3: Minimum 4 | H3: Public | I3: Infrastructure Team | J3: Hypervisor capacity | K3: 8 cores for production clusters | L3: [DATE]
A4: CONTROL_PLANE_MEMORY | B4: Production | C4: 32 | D4: Memory (GB) per control plane node | E4: Yes | F4: Integer | G4: Minimum 16 | H4: Public | I4: Infrastructure Team | J4: Hypervisor capacity | K4: 32GB minimum for production | L4: [DATE]
A5: WORKER_NODE_CPU | B5: Production | C5: 16 | D5: vCPU cores per worker node | E5: Yes | F5: Integer | G5: Minimum 4 | H5: Public | I5: Infrastructure Team | J5: Hypervisor capacity | K5: Size based on container density | L5: [DATE]
A6: WORKER_NODE_MEMORY | B6: Production | C6: 64 | D6: Memory (GB) per worker node | E6: Yes | F6: Integer | G6: Minimum 8 | H6: Public | I6: Infrastructure Team | J6: Hypervisor capacity | K6: 64GB for high-density workloads | L6: [DATE]

Sheet Network
A1: Network Parameters
A2: Parameter Name | B2: Environment | C2: Default Value | D2: Description | E2: Required | F2: Data Type | G2: Validation Rules | H2: Security Level | I2: Owner Team | J2: Dependencies | K2: Notes | L2: Last Updated
A3: OCP_NETWORK_TYPE | B3: All | C3: OVNKubernetes | D3: OpenShift network plugin type | E3: Yes | F3: String | G3: OVNKubernetes|OpenShiftSDN | H3: Public | I3: Network Team | J3: None | K3: OVN recommended for new clusters | L3: [DATE]
A4: POD_NETWORK_CIDR | B4: All | C4: 10.128.0.0/14 | D4: CIDR block for pod networking | E4: Yes | F4: String | G4: Valid CIDR notation | H4: Public | I4: Network Team | J4: No overlap with existing networks | K4: Default OpenShift pod network | L4: [DATE]
A5: SERVICE_NETWORK_CIDR | B5: All | C5: 172.30.0.0/16 | D5: CIDR block for service networking | E5: Yes | F5: String | G5: Valid CIDR notation | H5: Public | I5: Network Team | J5: No overlap with existing networks | K5: Default OpenShift service network | L5: [DATE]
A6: CLUSTER_NETWORK_MTU | B6: All | C6: 1400 | D6: Maximum transmission unit for cluster network | E6: Yes | F6: Integer | G6: 1200-9000 | H6: Public | I6: Network Team | J6: Infrastructure MTU | K6: Adjust for overlay overhead | L6: [DATE]

Sheet Storage
A1: Storage Parameters
A2: Parameter Name | B2: Environment | C2: Default Value | D2: Description | E2: Required | F2: Data Type | G2: Validation Rules | H2: Security Level | I2: Owner Team | J2: Dependencies | K2: Notes | L2: Last Updated
A3: ODF_STORAGE_SIZE | B3: Production | C3: 20TB | D3: Total storage capacity for OpenShift Data Foundation | E3: Yes | F3: String | G3: TB format | H3: Public | I3: Storage Team | J3: Hardware storage | K3: Persistent volume storage pool | L3: [DATE]
A4: STORAGE_CLASS_BLOCK | B4: All | C4: ocs-storagecluster-ceph-rbd | D4: Storage class for block storage PVCs | E4: Yes | F4: String | G4: Valid storage class name | H4: Public | I4: Storage Team | J4: ODF deployment | K4: RBD for databases and stateful apps | L4: [DATE]
A5: STORAGE_CLASS_FILE | B5: All | C5: ocs-storagecluster-cephfs | D5: Storage class for file storage PVCs | E5: Yes | F5: String | G5: Valid storage class name | H5: Public | I5: Storage Team | J5: ODF deployment | K5: CephFS for shared file access | L5: [DATE]

Sheet Authentication
A1: Authentication Parameters
A2: Parameter Name | B2: Environment | C2: Default Value | D2: Description | E2: Required | F2: Data Type | G2: Validation Rules | H2: Security Level | I2: Owner Team | J2: Dependencies | K2: Notes | L2: Last Updated
A3: LDAP_URL | B3: Production | C3: [********] | D3: Corporate LDAP/AD server URL | E3: Yes | F3: String | G3: Valid LDAPS URL | H3: Confidential | I3: Security Team | J3: Network connectivity | K3: Use LDAPS for encrypted connection | L3: [DATE]
A4: LDAP_BIND_DN | B4: Production | C4: [********] | D4: LDAP service account distinguished name | E4: Yes | F4: String | G4: Valid LDAP DN format | H4: Confidential | I4: Security Team | J4: LDAP user creation | K4: Read-only service account | L4: [DATE]
A5: LDAP_BIND_PASSWORD | B5: Production | C5: [********] | D5: LDAP service account password | E5: Yes | F5: String | G5: Minimum 16 characters | H5: Secret | I5: Security Team | J5: LDAP user creation | K5: Store in OpenShift Secret | L5: [DATE]
A6: LDAP_USER_SEARCH_BASE | B6: Production | C6: [********] | D6: LDAP base DN for user searches | E6: Yes | F6: String | G6: Valid LDAP DN format | H6: Confidential | I6: Security Team | J6: LDAP structure | K6: Scope users to specific OU | L6: [DATE]
A7: LDAP_GROUP_SEARCH_BASE | B7: Production | C7: [********] | D7: LDAP base DN for group searches | E7: Yes | F7: String | G7: Valid LDAP DN format | H7: Confidential | I7: Security Team | J7: LDAP structure | K7: Map groups to RBAC roles | L7: [DATE]
A8: OAUTH_TIMEOUT | B8: All | C8: 86400 | D8: OAuth token timeout in seconds | E8: Yes | F8: Integer | G8: 3600-604800 | H8: Public | I8: Security Team | J8: None | K8: 24 hours default | L8: [DATE]

Sheet Monitoring
A1: Monitoring Parameters
A2: Parameter Name | B2: Environment | C2: Default Value | D2: Description | E2: Required | F2: Data Type | G2: Validation Rules | H2: Security Level | I2: Owner Team | J2: Dependencies | K2: Notes | L2: Last Updated
A3: PROMETHEUS_RETENTION | B3: Production | C3: 15d | D3: Prometheus metrics retention period | E3: Yes | F3: String | G3: Valid time duration | H3: Public | I3: Operations Team | J3: Storage capacity | K3: Balance retention vs storage cost | L3: [DATE]
A4: ALERTMANAGER_CONFIG | B4: Production | C4: [********] | D4: Alertmanager notification target | E4: Yes | F4: String | G4: pagerduty|slack|email | H4: Confidential | I4: Operations Team | J4: External service config | K4: PagerDuty for production alerts | L4: [DATE]
A5: PAGERDUTY_SERVICE_KEY | B5: Production | C5: [********] | D5: PagerDuty integration service key | E5: Yes | F5: String | G5: 32-character hex string | H5: Secret | I5: Operations Team | J5: PagerDuty account | K5: Store in OpenShift Secret | L5: [DATE]
A6: GRAFANA_ADMIN_PASSWORD | B6: Production | C6: [********] | D6: Grafana administrator password | E6: Yes | F6: String | G6: Minimum 12 characters | H6: Secret | I6: Operations Team | J6: None | K6: Store in OpenShift Secret | L6: [DATE]

Sheet Logging
A1: Logging Parameters
A2: Parameter Name | B2: Environment | C2: Default Value | D2: Description | E2: Required | F2: Data Type | G2: Validation Rules | H2: Security Level | I2: Owner Team | J2: Dependencies | K2: Notes | L2: Last Updated
A3: EFK_LOG_RETENTION | B3: Production | C3: 7d | D3: Elasticsearch log retention period | E3: Yes | F3: String | G3: Valid time duration | H3: Public | I3: Operations Team | J3: Storage capacity | K3: 7 days hot storage default | L3: [DATE]
A4: ELASTICSEARCH_STORAGE | B4: Production | C4: 500Gi | D4: Elasticsearch storage per node | E4: Yes | F4: String | G4: Valid storage size | H4: Public | I4: Operations Team | J4: Storage class | K4: Size based on log volume | L4: [DATE]

Sheet Registry
A1: Registry Parameters
A2: Parameter Name | B2: Environment | C2: Default Value | D2: Description | E2: Required | F2: Data Type | G2: Validation Rules | H2: Security Level | I2: Owner Team | J2: Dependencies | K2: Notes | L2: Last Updated
A3: QUAY_HOSTNAME | B3: Production | C3: quay.apps.ocp-prod.example.com | D3: Quay container registry hostname | E3: Yes | F3: String | G3: Valid hostname | H3: Public | I3: Platform Team | J3: OCP_BASE_DOMAIN | K3: Internal registry for CI/CD | L3: [DATE]
A4: QUAY_ADMIN_PASSWORD | B4: Production | C4: [********] | D4: Quay administrator password | E4: Yes | F4: String | G4: Minimum 12 characters | H4: Secret | I4: Platform Team | J4: None | K4: Store in Quay config | L4: [DATE]
A5: QUAY_STORAGE_SIZE | B5: Production | C5: 1TB | D5: Quay image storage capacity | E5: Yes | F5: String | G5: Valid storage size | H5: Public | I5: Platform Team | J5: Storage class | K5: Size based on image count | L5: [DATE]

Sheet GitOps
A1: GitOps Parameters
A2: Parameter Name | B2: Environment | C2: Default Value | D2: Description | E2: Required | F2: Data Type | G2: Validation Rules | H2: Security Level | I2: Owner Team | J2: Dependencies | K2: Notes | L2: Last Updated
A3: ARGOCD_ADMIN_PASSWORD | B3: Production | C3: [********] | D3: ArgoCD administrator password | E3: Yes | F3: String | G3: Minimum 12 characters | H3: Secret | I3: DevOps Team | J3: None | K3: Store in OpenShift Secret | L3: [DATE]
A4: ARGOCD_REPO_URL | B4: Production | C4: https://github.com/company/gitops-config | D4: ArgoCD Git repository URL | E4: Yes | F4: String | G4: Valid Git URL | H4: Public | I4: DevOps Team | J4: Git access | K4: Contains application manifests | L4: [DATE]
A5: ARGOCD_REPO_CREDENTIALS | B5: Production | C5: [********] | D5: Git repository authentication token | E5: Yes | F5: String | G5: Valid token format | H5: Secret | I5: DevOps Team | J5: Git PAT creation | K5: Store in ArgoCD Secret | L5: [DATE]

Sheet Pipelines
A1: Pipelines Parameters
A2: Parameter Name | B2: Environment | C2: Default Value | D2: Description | E2: Required | F2: Data Type | G2: Validation Rules | H2: Security Level | I2: Owner Team | J2: Dependencies | K2: Notes | L2: Last Updated
A3: TEKTON_DEFAULT_SA | B3: All | C3: pipeline | D3: Default service account for Tekton pipelines | E3: Yes | F3: String | G3: Valid SA name | H3: Public | I3: DevOps Team | J3: RBAC configuration | K3: Standard pipeline service account | L3: [DATE]
A4: PIPELINE_TIMEOUT | B4: All | C4: 1h | D4: Default pipeline execution timeout | E4: Yes | F4: String | G4: Valid time duration | H4: Public | I4: DevOps Team | J4: None | K4: Adjust based on build complexity | L4: [DATE]

Sheet ServiceMesh
A1: ServiceMesh Parameters
A2: Parameter Name | B2: Environment | C2: Default Value | D2: Description | E2: Required | F2: Data Type | G2: Validation Rules | H2: Security Level | I2: Owner Team | J2: Dependencies | K2: Notes | L2: Last Updated
A3: ISTIO_ENABLED | B3: Production | C3: true | D3: Enable Istio service mesh | E3: Yes | F3: Boolean | G3: true|false | H3: Public | I3: Platform Team | J3: None | K3: Required for distributed tracing | L3: [DATE]
A4: ISTIO_MTLS_MODE | B4: Production | C4: [********] | D4: Istio mutual TLS mode | E4: Yes | F4: String | G4: STRICT|PERMISSIVE|DISABLE | H4: Confidential | I4: Security Team | J4: Certificate management | K4: STRICT for production security | L4: [DATE]

Sheet Operations
A1: Operations Parameters
A2: Parameter Name | B2: Environment | C2: Default Value | D2: Description | E2: Required | F2: Data Type | G2: Validation Rules | H2: Security Level | I2: Owner Team | J2: Dependencies | K2: Notes | L2: Last Updated
A3: BACKUP_SCHEDULE | B3: Production | C3: 0 2 * * * | D3: ETCD backup schedule in cron format | E3: Yes | F3: String | G3: Valid cron expression | H3: Public | I3: Operations Team | J3: Storage for backups | K3: Daily at 2 AM local time | L3: [DATE]
A4: BACKUP_RETENTION | B4: Production | C4: 30 | D4: Backup retention period in days | E4: Yes | F4: Integer | G4: 7-365 | H4: Public | I4: Operations Team | J4: Storage capacity | K4: 30 days for compliance | L4: [DATE]
