Workbook

Sheet Cover
B3: [DOCUMENT TITLE]
B4: Discovery Questionnaire
B5: Presales Document
B6: Generated: | C6: November 16, 2025
B7: Solution: | C7: November 22, 2025
B8: Customer: | C8: Multi Cloud Platform
B9: Version: | C9: [Customer Name]
B10: Status: | C10: Draft
C12: eoframework.org

Sheet All Categories (Read Only)
A1: Total Questions | B1: Answered | C1: Remaining | D1: % Complete
A2: 62 | B2: =SUMPRODUCT(--(LEN(F5:F66)>0)) | C2: =A2-B2 | D2: =B2/A2
A4: Question ID | B4: Category | C4: Sub-Category | D4: Question | E4: Guidance | F4: Customer Response | G4: Notes
A5: =IF('Business Requirements'!A2="","",'Business Requirements'!A2) | B5: =IF('Business Requirements'!B2="","",'Business Requirements'!B2) | C5: =IF('Business Requirements'!C2="","",'Business Requirements'!C2) | D5: =IF('Business Requirements'!D2="","",'Business Requirements'!D2) | E5: =IF('Business Requirements'!E2="","",'Business Requirements'!E2) | F5: =IF('Business Requirements'!F2="","",'Business Requirements'!F2) | G5: =IF('Business Requirements'!G2="","",'Business Requirements'!G2)
A6: =IF('Business Requirements'!A3="","",'Business Requirements'!A3) | B6: =IF('Business Requirements'!B3="","",'Business Requirements'!B3) | C6: =IF('Business Requirements'!C3="","",'Business Requirements'!C3) | D6: =IF('Business Requirements'!D3="","",'Business Requirements'!D3) | E6: =IF('Business Requirements'!E3="","",'Business Requirements'!E3) | F6: =IF('Business Requirements'!F3="","",'Business Requirements'!F3) | G6: =IF('Business Requirements'!G3="","",'Business Requirements'!G3)
A7: =IF('Business Requirements'!A4="","",'Business Requirements'!A4) | B7: =IF('Business Requirements'!B4="","",'Business Requirements'!B4) | C7: =IF('Business Requirements'!C4="","",'Business Requirements'!C4) | D7: =IF('Business Requirements'!D4="","",'Business Requirements'!D4) | E7: =IF('Business Requirements'!E4="","",'Business Requirements'!E4) | F7: =IF('Business Requirements'!F4="","",'Business Requirements'!F4) | G7: =IF('Business Requirements'!G4="","",'Business Requirements'!G4)
A8: =IF('Business Requirements'!A5="","",'Business Requirements'!A5) | B8: =IF('Business Requirements'!B5="","",'Business Requirements'!B5) | C8: =IF('Business Requirements'!C5="","",'Business Requirements'!C5) | D8: =IF('Business Requirements'!D5="","",'Business Requirements'!D5) | E8: =IF('Business Requirements'!E5="","",'Business Requirements'!E5) | F8: =IF('Business Requirements'!F5="","",'Business Requirements'!F5) | G8: =IF('Business Requirements'!G5="","",'Business Requirements'!G5)
A9: =IF('Business Requirements'!A6="","",'Business Requirements'!A6) | B9: =IF('Business Requirements'!B6="","",'Business Requirements'!B6) | C9: =IF('Business Requirements'!C6="","",'Business Requirements'!C6) | D9: =IF('Business Requirements'!D6="","",'Business Requirements'!D6) | E9: =IF('Business Requirements'!E6="","",'Business Requirements'!E6) | F9: =IF('Business Requirements'!F6="","",'Business Requirements'!F6) | G9: =IF('Business Requirements'!G6="","",'Business Requirements'!G6)
A10: =IF('Business Requirements'!A7="","",'Business Requirements'!A7) | B10: =IF('Business Requirements'!B7="","",'Business Requirements'!B7) | C10: =IF('Business Requirements'!C7="","",'Business Requirements'!C7) | D10: =IF('Business Requirements'!D7="","",'Business Requirements'!D7) | E10: =IF('Business Requirements'!E7="","",'Business Requirements'!E7) | F10: =IF('Business Requirements'!F7="","",'Business Requirements'!F7) | G10: =IF('Business Requirements'!G7="","",'Business Requirements'!G7)
A11: =IF('Business Requirements'!A8="","",'Business Requirements'!A8) | B11: =IF('Business Requirements'!B8="","",'Business Requirements'!B8) | C11: =IF('Business Requirements'!C8="","",'Business Requirements'!C8) | D11: =IF('Business Requirements'!D8="","",'Business Requirements'!D8) | E11: =IF('Business Requirements'!E8="","",'Business Requirements'!E8) | F11: =IF('Business Requirements'!F8="","",'Business Requirements'!F8) | G11: =IF('Business Requirements'!G8="","",'Business Requirements'!G8)
A12: =IF('Business Requirements'!A9="","",'Business Requirements'!A9) | B12: =IF('Business Requirements'!B9="","",'Business Requirements'!B9) | C12: =IF('Business Requirements'!C9="","",'Business Requirements'!C9) | D12: =IF('Business Requirements'!D9="","",'Business Requirements'!D9) | E12: =IF('Business Requirements'!E9="","",'Business Requirements'!E9) | F12: =IF('Business Requirements'!F9="","",'Business Requirements'!F9) | G12: =IF('Business Requirements'!G9="","",'Business Requirements'!G9)
A13: =IF('Business Requirements'!A10="","",'Business Requirements'!A10) | B13: =IF('Business Requirements'!B10="","",'Business Requirements'!B10) | C13: =IF('Business Requirements'!C10="","",'Business Requirements'!C10) | D13: =IF('Business Requirements'!D10="","",'Business Requirements'!D10) | E13: =IF('Business Requirements'!E10="","",'Business Requirements'!E10) | F13: =IF('Business Requirements'!F10="","",'Business Requirements'!F10) | G13: =IF('Business Requirements'!G10="","",'Business Requirements'!G10)
A14: =IF('Business Requirements'!A11="","",'Business Requirements'!A11) | B14: =IF('Business Requirements'!B11="","",'Business Requirements'!B11) | C14: =IF('Business Requirements'!C11="","",'Business Requirements'!C11) | D14: =IF('Business Requirements'!D11="","",'Business Requirements'!D11) | E14: =IF('Business Requirements'!E11="","",'Business Requirements'!E11) | F14: =IF('Business Requirements'!F11="","",'Business Requirements'!F11) | G14: =IF('Business Requirements'!G11="","",'Business Requirements'!G11)
A15: =IF('Business Requirements'!A12="","",'Business Requirements'!A12) | B15: =IF('Business Requirements'!B12="","",'Business Requirements'!B12) | C15: =IF('Business Requirements'!C12="","",'Business Requirements'!C12) | D15: =IF('Business Requirements'!D12="","",'Business Requirements'!D12) | E15: =IF('Business Requirements'!E12="","",'Business Requirements'!E12) | F15: =IF('Business Requirements'!F12="","",'Business Requirements'!F12) | G15: =IF('Business Requirements'!G12="","",'Business Requirements'!G12)
A16: =IF('Business Requirements'!A13="","",'Business Requirements'!A13) | B16: =IF('Business Requirements'!B13="","",'Business Requirements'!B13) | C16: =IF('Business Requirements'!C13="","",'Business Requirements'!C13) | D16: =IF('Business Requirements'!D13="","",'Business Requirements'!D13) | E16: =IF('Business Requirements'!E13="","",'Business Requirements'!E13) | F16: =IF('Business Requirements'!F13="","",'Business Requirements'!F13) | G16: =IF('Business Requirements'!G13="","",'Business Requirements'!G13)
A17: =IF('Technical Requirements'!A2="","",'Technical Requirements'!A2) | B17: =IF('Technical Requirements'!B2="","",'Technical Requirements'!B2) | C17: =IF('Technical Requirements'!C2="","",'Technical Requirements'!C2) | D17: =IF('Technical Requirements'!D2="","",'Technical Requirements'!D2) | E17: =IF('Technical Requirements'!E2="","",'Technical Requirements'!E2) | F17: =IF('Technical Requirements'!F2="","",'Technical Requirements'!F2) | G17: =IF('Technical Requirements'!G2="","",'Technical Requirements'!G2)
A18: =IF('Technical Requirements'!A3="","",'Technical Requirements'!A3) | B18: =IF('Technical Requirements'!B3="","",'Technical Requirements'!B3) | C18: =IF('Technical Requirements'!C3="","",'Technical Requirements'!C3) | D18: =IF('Technical Requirements'!D3="","",'Technical Requirements'!D3) | E18: =IF('Technical Requirements'!E3="","",'Technical Requirements'!E3) | F18: =IF('Technical Requirements'!F3="","",'Technical Requirements'!F3) | G18: =IF('Technical Requirements'!G3="","",'Technical Requirements'!G3)
A19: =IF('Technical Requirements'!A4="","",'Technical Requirements'!A4) | B19: =IF('Technical Requirements'!B4="","",'Technical Requirements'!B4) | C19: =IF('Technical Requirements'!C4="","",'Technical Requirements'!C4) | D19: =IF('Technical Requirements'!D4="","",'Technical Requirements'!D4) | E19: =IF('Technical Requirements'!E4="","",'Technical Requirements'!E4) | F19: =IF('Technical Requirements'!F4="","",'Technical Requirements'!F4) | G19: =IF('Technical Requirements'!G4="","",'Technical Requirements'!G4)
A20: =IF('Technical Requirements'!A5="","",'Technical Requirements'!A5) | B20: =IF('Technical Requirements'!B5="","",'Technical Requirements'!B5) | C20: =IF('Technical Requirements'!C5="","",'Technical Requirements'!C5) | D20: =IF('Technical Requirements'!D5="","",'Technical Requirements'!D5) | E20: =IF('Technical Requirements'!E5="","",'Technical Requirements'!E5) | F20: =IF('Technical Requirements'!F5="","",'Technical Requirements'!F5) | G20: =IF('Technical Requirements'!G5="","",'Technical Requirements'!G5)
A21: =IF('Technical Requirements'!A6="","",'Technical Requirements'!A6) | B21: =IF('Technical Requirements'!B6="","",'Technical Requirements'!B6) | C21: =IF('Technical Requirements'!C6="","",'Technical Requirements'!C6) | D21: =IF('Technical Requirements'!D6="","",'Technical Requirements'!D6) | E21: =IF('Technical Requirements'!E6="","",'Technical Requirements'!E6) | F21: =IF('Technical Requirements'!F6="","",'Technical Requirements'!F6) | G21: =IF('Technical Requirements'!G6="","",'Technical Requirements'!G6)
A22: =IF('Technical Requirements'!A7="","",'Technical Requirements'!A7) | B22: =IF('Technical Requirements'!B7="","",'Technical Requirements'!B7) | C22: =IF('Technical Requirements'!C7="","",'Technical Requirements'!C7) | D22: =IF('Technical Requirements'!D7="","",'Technical Requirements'!D7) | E22: =IF('Technical Requirements'!E7="","",'Technical Requirements'!E7) | F22: =IF('Technical Requirements'!F7="","",'Technical Requirements'!F7) | G22: =IF('Technical Requirements'!G7="","",'Technical Requirements'!G7)
A23: =IF('Technical Requirements'!A8="","",'Technical Requirements'!A8) | B23: =IF('Technical Requirements'!B8="","",'Technical Requirements'!B8) | C23: =IF('Technical Requirements'!C8="","",'Technical Requirements'!C8) | D23: =IF('Technical Requirements'!D8="","",'Technical Requirements'!D8) | E23: =IF('Technical Requirements'!E8="","",'Technical Requirements'!E8) | F23: =IF('Technical Requirements'!F8="","",'Technical Requirements'!F8) | G23: =IF('Technical Requirements'!G8="","",'Technical Requirements'!G8)
A24: =IF('Technical Requirements'!A9="","",'Technical Requirements'!A9) | B24: =IF('Technical Requirements'!B9="","",'Technical Requirements'!B9) | C24: =IF('Technical Requirements'!C9="","",'Technical Requirements'!C9) | D24: =IF('Technical Requirements'!D9="","",'Technical Requirements'!D9) | E24: =IF('Technical Requirements'!E9="","",'Technical Requirements'!E9) | F24: =IF('Technical Requirements'!F9="","",'Technical Requirements'!F9) | G24: =IF('Technical Requirements'!G9="","",'Technical Requirements'!G9)
A25: =IF('Technical Requirements'!A10="","",'Technical Requirements'!A10) | B25: =IF('Technical Requirements'!B10="","",'Technical Requirements'!B10) | C25: =IF('Technical Requirements'!C10="","",'Technical Requirements'!C10) | D25: =IF('Technical Requirements'!D10="","",'Technical Requirements'!D10) | E25: =IF('Technical Requirements'!E10="","",'Technical Requirements'!E10) | F25: =IF('Technical Requirements'!F10="","",'Technical Requirements'!F10) | G25: =IF('Technical Requirements'!G10="","",'Technical Requirements'!G10)
A26: =IF('Technical Requirements'!A11="","",'Technical Requirements'!A11) | B26: =IF('Technical Requirements'!B11="","",'Technical Requirements'!B11) | C26: =IF('Technical Requirements'!C11="","",'Technical Requirements'!C11) | D26: =IF('Technical Requirements'!D11="","",'Technical Requirements'!D11) | E26: =IF('Technical Requirements'!E11="","",'Technical Requirements'!E11) | F26: =IF('Technical Requirements'!F11="","",'Technical Requirements'!F11) | G26: =IF('Technical Requirements'!G11="","",'Technical Requirements'!G11)
A27: =IF('Technical Requirements'!A12="","",'Technical Requirements'!A12) | B27: =IF('Technical Requirements'!B12="","",'Technical Requirements'!B12) | C27: =IF('Technical Requirements'!C12="","",'Technical Requirements'!C12) | D27: =IF('Technical Requirements'!D12="","",'Technical Requirements'!D12) | E27: =IF('Technical Requirements'!E12="","",'Technical Requirements'!E12) | F27: =IF('Technical Requirements'!F12="","",'Technical Requirements'!F12) | G27: =IF('Technical Requirements'!G12="","",'Technical Requirements'!G12)
A28: =IF('Technical Requirements'!A13="","",'Technical Requirements'!A13) | B28: =IF('Technical Requirements'!B13="","",'Technical Requirements'!B13) | C28: =IF('Technical Requirements'!C13="","",'Technical Requirements'!C13) | D28: =IF('Technical Requirements'!D13="","",'Technical Requirements'!D13) | E28: =IF('Technical Requirements'!E13="","",'Technical Requirements'!E13) | F28: =IF('Technical Requirements'!F13="","",'Technical Requirements'!F13) | G28: =IF('Technical Requirements'!G13="","",'Technical Requirements'!G13)
... A34: =IF('Technical Requirements'!A19="","",'Technical Requirements'!A19) | B34: =IF('Technical Requirements'!B19="","",'Technical Requirements'!B19) | C34: =IF('Technical Requirements'!C19="","",'Technical Requirements'!C19) | D34: =IF('Technical Requirements'!D19="","",'Technical Requirements'!D19) | E34: =IF('Technical Requirements'!E19="","",'Technical Requirements'!E19) | F34: =IF('Technical Requirements'!F19="","",'Technical Requirements'!F19) | G34: =IF('Technical Requirements'!G19="","",'Technical Requirements'!G19)
A35: =IF('Security & Compliance'!A2="","",'Security & Compliance'!A2) | B35: =IF('Security & Compliance'!B2="","",'Security & Compliance'!B2) | C35: =IF('Security & Compliance'!C2="","",'Security & Compliance'!C2) | D35: =IF('Security & Compliance'!D2="","",'Security & Compliance'!D2) | E35: =IF('Security & Compliance'!E2="","",'Security & Compliance'!E2) | F35: =IF('Security & Compliance'!F2="","",'Security & Compliance'!F2) | G35: =IF('Security & Compliance'!G2="","",'Security & Compliance'!G2)
A36: =IF('Security & Compliance'!A3="","",'Security & Compliance'!A3) | B36: =IF('Security & Compliance'!B3="","",'Security & Compliance'!B3) | C36: =IF('Security & Compliance'!C3="","",'Security & Compliance'!C3) | D36: =IF('Security & Compliance'!D3="","",'Security & Compliance'!D3) | E36: =IF('Security & Compliance'!E3="","",'Security & Compliance'!E3) | F36: =IF('Security & Compliance'!F3="","",'Security & Compliance'!F3) | G36: =IF('Security & Compliance'!G3="","",'Security & Compliance'!G3)
A37: =IF('Security & Compliance'!A4="","",'Security & Compliance'!A4) | B37: =IF('Security & Compliance'!B4="","",'Security & Compliance'!B4) | C37: =IF('Security & Compliance'!C4="","",'Security & Compliance'!C4) | D37: =IF('Security & Compliance'!D4="","",'Security & Compliance'!D4) | E37: =IF('Security & Compliance'!E4="","",'Security & Compliance'!E4) | F37: =IF('Security & Compliance'!F4="","",'Security & Compliance'!F4) | G37: =IF('Security & Compliance'!G4="","",'Security & Compliance'!G4)
A38: =IF('Security & Compliance'!A5="","",'Security & Compliance'!A5) | B38: =IF('Security & Compliance'!B5="","",'Security & Compliance'!B5) | C38: =IF('Security & Compliance'!C5="","",'Security & Compliance'!C5) | D38: =IF('Security & Compliance'!D5="","",'Security & Compliance'!D5) | E38: =IF('Security & Compliance'!E5="","",'Security & Compliance'!E5) | F38: =IF('Security & Compliance'!F5="","",'Security & Compliance'!F5) | G38: =IF('Security & Compliance'!G5="","",'Security & Compliance'!G5)
A39: =IF('Security & Compliance'!A6="","",'Security & Compliance'!A6) | B39: =IF('Security & Compliance'!B6="","",'Security & Compliance'!B6) | C39: =IF('Security & Compliance'!C6="","",'Security & Compliance'!C6) | D39: =IF('Security & Compliance'!D6="","",'Security & Compliance'!D6) | E39: =IF('Security & Compliance'!E6="","",'Security & Compliance'!E6) | F39: =IF('Security & Compliance'!F6="","",'Security & Compliance'!F6) | G39: =IF('Security & Compliance'!G6="","",'Security & Compliance'!G6)
A40: =IF('Security & Compliance'!A7="","",'Security & Compliance'!A7) | B40: =IF('Security & Compliance'!B7="","",'Security & Compliance'!B7) | C40: =IF('Security & Compliance'!C7="","",'Security & Compliance'!C7) | D40: =IF('Security & Compliance'!D7="","",'Security & Compliance'!D7) | E40: =IF('Security & Compliance'!E7="","",'Security & Compliance'!E7) | F40: =IF('Security & Compliance'!F7="","",'Security & Compliance'!F7) | G40: =IF('Security & Compliance'!G7="","",'Security & Compliance'!G7)
A41: =IF('Security & Compliance'!A8="","",'Security & Compliance'!A8) | B41: =IF('Security & Compliance'!B8="","",'Security & Compliance'!B8) | C41: =IF('Security & Compliance'!C8="","",'Security & Compliance'!C8) | D41: =IF('Security & Compliance'!D8="","",'Security & Compliance'!D8) | E41: =IF('Security & Compliance'!E8="","",'Security & Compliance'!E8) | F41: =IF('Security & Compliance'!F8="","",'Security & Compliance'!F8) | G41: =IF('Security & Compliance'!G8="","",'Security & Compliance'!G8)
A42: =IF('Security & Compliance'!A9="","",'Security & Compliance'!A9) | B42: =IF('Security & Compliance'!B9="","",'Security & Compliance'!B9) | C42: =IF('Security & Compliance'!C9="","",'Security & Compliance'!C9) | D42: =IF('Security & Compliance'!D9="","",'Security & Compliance'!D9) | E42: =IF('Security & Compliance'!E9="","",'Security & Compliance'!E9) | F42: =IF('Security & Compliance'!F9="","",'Security & Compliance'!F9) | G42: =IF('Security & Compliance'!G9="","",'Security & Compliance'!G9)
A43: =IF('Security & Compliance'!A10="","",'Security & Compliance'!A10) | B43: =IF('Security & Compliance'!B10="","",'Security & Compliance'!B10) | C43: =IF('Security & Compliance'!C10="","",'Security & Compliance'!C10) | D43: =IF('Security & Compliance'!D10="","",'Security & Compliance'!D10) | E43: =IF('Security & Compliance'!E10="","",'Security & Compliance'!E10) | F43: =IF('Security & Compliance'!F10="","",'Security & Compliance'!F10) | G43: =IF('Security & Compliance'!G10="","",'Security & Compliance'!G10)
A44: =IF('Security & Compliance'!A11="","",'Security & Compliance'!A11) | B44: =IF('Security & Compliance'!B11="","",'Security & Compliance'!B11) | C44: =IF('Security & Compliance'!C11="","",'Security & Compliance'!C11) | D44: =IF('Security & Compliance'!D11="","",'Security & Compliance'!D11) | E44: =IF('Security & Compliance'!E11="","",'Security & Compliance'!E11) | F44: =IF('Security & Compliance'!F11="","",'Security & Compliance'!F11) | G44: =IF('Security & Compliance'!G11="","",'Security & Compliance'!G11)
A45: =IF('Governance & Policy'!A2="","",'Governance & Policy'!A2) | B45: =IF('Governance & Policy'!B2="","",'Governance & Policy'!B2) | C45: =IF('Governance & Policy'!C2="","",'Governance & Policy'!C2) | D45: =IF('Governance & Policy'!D2="","",'Governance & Policy'!D2) | E45: =IF('Governance & Policy'!E2="","",'Governance & Policy'!E2) | F45: =IF('Governance & Policy'!F2="","",'Governance & Policy'!F2) | G45: =IF('Governance & Policy'!G2="","",'Governance & Policy'!G2)
A46: =IF('Governance & Policy'!A3="","",'Governance & Policy'!A3) | B46: =IF('Governance & Policy'!B3="","",'Governance & Policy'!B3) | C46: =IF('Governance & Policy'!C3="","",'Governance & Policy'!C3) | D46: =IF('Governance & Policy'!D3="","",'Governance & Policy'!D3) | E46: =IF('Governance & Policy'!E3="","",'Governance & Policy'!E3) | F46: =IF('Governance & Policy'!F3="","",'Governance & Policy'!F3) | G46: =IF('Governance & Policy'!G3="","",'Governance & Policy'!G3)
...

Sheet Business Requirements
A1: Question ID | B1: Category | C1: Sub-Category | D1: Question | E1: Guidance | F1: Customer Response | G1: Notes
A2: BUS-001 | B2: Business Requirements | C2: Project Information | D2: What is the name of your multi-cloud platform initiative? | E2: Provide internal project reference name | G2: Internal project reference for tracking
A3: BUS-002 | B3: Business Requirements | C3: Project Information | D3: Who is the primary stakeholder for this multi-cloud initiative? | E3: Name, role, and decision-making authority | G3: Main point of contact and decision authority
A4: BUS-003 | B4: Business Requirements | C4: Business Drivers | D4: What multi-cloud challenges are you trying to solve? | E4: Common challenges: Manual infrastructure provisioning, Inconsistent configurations across clouds, Cloud vendor lock-in concerns, High operational overhead, Lack of governance and compliance, Infrastructure drift and state management issues | G4: Primary business driver for multi-cloud investment
A5: BUS-004 | B5: Business Requirements | C5: Current State | D5: What is your current infrastructure management workflow? | E5: Describe manual steps, tools used, pain points, and team responsibilities | G5: Current state baseline assessment
A6: BUS-005 | B6: Business Requirements | C6: Cloud Strategy | D6: Which cloud providers are you currently using or planning to use? | E6: AWS, Azure, GCP, Oracle Cloud, IBM Cloud, On-premises VMware, OpenStack, Other | G6: Multi-cloud provider scope
A7: BUS-006 | B7: Business Requirements | C7: Scale | D7: How many infrastructure resources do you manage across all clouds? | E7: Typical ranges: 1-100, 101-1000, 1001-10000, 10000+ | G7: Infrastructure scale drives platform sizing
A8: BUS-007 | B8: Business Requirements | C8: Objectives | D8: What are your primary goals for implementing a multi-cloud platform? | E8: Common goals: Standardize infrastructure as code, Enable self-service provisioning, Implement policy as code governance, Reduce cloud costs through optimization, Accelerate application delivery, Ensure compliance and security, Avoid vendor lock-in | G8: Business objectives and expected outcomes
A9: BUS-008 | B9: Business Requirements | C9: Success Criteria | D9: How will you measure multi-cloud platform success? | E9: Define KPIs: Infrastructure deployment speed, Policy compliance %, Cost reduction %, Team productivity improvement, Infrastructure drift reduction | G9: Success metrics for project evaluation
A10: BUS-009 | B10: Business Requirements | C10: Timeline | D10: What is your expected timeline for multi-cloud platform implementation? | E10: Typical ranges: 0-3 months, 3-6 months, 6-12 months, 12+ months | G10: Project timeline expectations and constraints
A11: BUS-010 | B11: Business Requirements | C11: Budget | D11: What is your approved budget range for this multi-cloud solution? | E11: Include: HashiCorp licenses, Professional services, Infrastructure costs, Training. Common ranges: $50K-250K, $250K-1M, $1M+ | G11: Budget constraints for solution sizing
A12: BUS-011 | B12: Business Requirements | C12: Future Vision | D12: What is your long-term vision for infrastructure automation? | E12: Consider expansion to additional clouds, workloads, teams, and automation capabilities | G12: Future roadmap and scalability planning
A13: BUS-012 | B13: Business Requirements | C13: Growth Projections | D13: How do you expect infrastructure scale to change over 3 years? | E13: Provide current resource count and projected annual growth rate | G13: Scalability requirements and capacity planning

Sheet Technical Requirements
A1: Question ID | B1: Category | C1: Sub-Category | D1: Question | E1: Guidance | F1: Customer Response | G1: Notes
A2: TECH-001 | B2: Technical Requirements | C2: Current IaC Usage | D2: What Infrastructure as Code tools are you currently using? | E2: Options: Terraform Open Source, CloudFormation, ARM Templates, Deployment Manager, Ansible, Chef, Puppet, Custom scripts, None | G2: Current IaC footprint and migration needs
A3: TECH-002 | B3: Technical Requirements | C3: Terraform Experience | D3: What is your current Terraform experience level? | E3: Options: No experience, Basic (simple modules), Intermediate (workspaces state mgmt), Advanced (complex modules providers), Expert (custom providers enterprise) | G3: Team skill level for training planning
A4: TECH-003 | B4: Technical Requirements | C4: Cloud Environments | D4: Which cloud environments need to be managed by this platform? | E4: AWS: Account count, Azure: Subscription count, GCP: Project count, On-prem: Data center count | G4: Cloud environment scope and complexity
A5: TECH-004 | B5: Technical Requirements | C5: Infrastructure Complexity | D5: What types of infrastructure resources need to be provisioned? | E5: Resource types: Compute (VMs containers serverless), Networking (VPC subnets firewalls), Storage (block object database), Security (IAM encryption secrets), Kubernetes, Databases, Load balancers, CDN | G5: Infrastructure scope and module requirements
A6: TECH-005 | B6: Technical Requirements | C6: Workload Types | D6: What types of workloads will be deployed on this infrastructure? | E6: Workload types: Web applications, Microservices, Databases, Analytics and data processing, Machine learning, Legacy applications, Container-based applications, Serverless functions | G6: Workload patterns for architecture design
A7: TECH-006 | B7: Technical Requirements | C7: Environment Strategy | D7: How many environments do you need to manage per application? | E7: Common patterns: Dev/Staging/Production, Feature branches, Multiple regions, Multi-tenant environments | G7: Environment strategy and workspace planning
A8: TECH-007 | B8: Technical Requirements | C8: State Management | D8: What are your Terraform state management requirements? | E8: Options: Remote state in S3/Azure/GCS, State locking, State encryption, Multi-region replication, State versioning and rollback | G8: State backend architecture requirements
A9: TECH-008 | B9: Technical Requirements | C9: VCS Integration | D9: What version control system do you use for infrastructure code? | E9: Options: GitHub, GitLab, Bitbucket, Azure DevOps, Other | G9: VCS integration requirements
A10: TECH-009 | B10: Technical Requirements | C10: Module Strategy | D10: What is your Terraform module organization approach? | E10: Options: Public registry modules only, Private module registry, Custom in-house modules, Combination approach | G10: Module governance and reusability strategy
A11: TECH-010 | B11: Technical Requirements | C11: Secrets Management | D11: What secrets management approach do you need? | E11: Options: HashiCorp Vault integration, Cloud-native (AWS Secrets Manager Azure Key Vault GCP Secret Manager), Environment variables, Other | G11: Secrets and credentials handling requirements
A12: TECH-011 | B12: Technical Requirements | C12: Integration | D12: What systems need to integrate with the infrastructure platform? | E12: Integration targets: CI/CD pipelines, Monitoring tools (Datadog Splunk), ITSM (ServiceNow Jira), CMDB, Cloud cost management, Security scanning tools | G12: Integration scope and API requirements
A13: TECH-012 | B13: Technical Requirements | C13: Networking | D13: What networking and connectivity requirements exist across clouds? | E13: Requirements: Cross-cloud VPN/interconnects, Network peering, Direct Connect/ExpressRoute, Hybrid connectivity, Bandwidth and latency needs | G13: Multi-cloud network architecture needs
... A19: TECH-018 | B19: Technical Requirements | C19: Concurrent Operations | D19: How many concurrent Terraform operations do you need to support? | E19: Consider: Peak concurrent runs, Queue depth, Team distribution, CI/CD parallelism | G19: Concurrency requirements for infrastructure sizing

Sheet Security & Compliance
A1: Question ID | B1: Category | C1: Sub-Category | D1: Question | E1: Guidance | F1: Customer Response | G1: Notes
A2: SEC-001 | B2: Security & Compliance | C2: Data Classification | D2: What is the highest data classification level for infrastructure metadata? | E2: Levels: Public, Internal, Confidential, Restricted | G2: Determines encryption and access control requirements
A3: SEC-002 | B3: Security & Compliance | C3: Sensitive Data | D3: What sensitive data is managed through infrastructure provisioning? | E3: Sensitive data types: Cloud credentials and API keys, Database connection strings, Application secrets, Encryption keys, Compliance data, Customer data | G3: Data protection and masking requirements
A4: SEC-003 | B4: Security & Compliance | C4: Compliance Standards | D4: What compliance standards must the platform meet? | E4: Common standards: SOC 2 Type II, ISO 27001, PCI DSS, HIPAA, FedRAMP, GDPR, NIST Cybersecurity Framework, CIS Benchmarks | G4: Compliance controls and audit requirements
A5: SEC-004 | B5: Security & Compliance | C5: Encryption | D5: What encryption requirements apply to infrastructure state and secrets? | E5: Requirements: State encryption at rest (AES-256), State encryption in transit (TLS 1.2+), Vault transit encryption, Customer-managed encryption keys (CMK) | G5: Security architecture and key management
A6: SEC-005 | B6: Security & Compliance | C6: Access Control | D6: What authentication and authorization requirements apply? | E6: Options: SSO (SAML/OIDC), MFA required, RBAC with team-based permissions, Attribute-based access control, Service account management, Just-in-time access | G6: Identity and access management requirements
A7: SEC-006 | B7: Security & Compliance | C7: Audit Logging | D7: What audit and logging requirements do you have? | E7: Requirements: All API calls logged, Infrastructure change audit trail, Policy evaluation logs, Compliance reports, SIEM integration (Splunk Datadog) | G7: Audit trail and compliance reporting needs
A8: SEC-007 | B8: Security & Compliance | C8: Policy Enforcement | D8: What infrastructure policy enforcement do you need? | E8: Policy types: Security policies (required encryption tagging), Cost policies (resource size limits region restrictions), Compliance policies (data residency approved resources), Naming conventions, Tagging standards | G8: Policy as code and governance requirements
A9: SEC-008 | B9: Security & Compliance | C9: Data Residency | D9: Do you have data residency or sovereignty requirements? | E9: Specify regions/countries for: State storage, Secrets storage, Application data, Compliance drivers | G9: Geographic data sovereignty requirements
A10: SEC-009 | B10: Security & Compliance | C10: Network Security | D10: What network security controls are required? | E10: Controls: Private network connectivity, VPN access only, IP whitelisting, Network segmentation, TLS mutual authentication, Certificate management | G10: Network security architecture requirements
A11: SEC-010 | B11: Security & Compliance | C11: Secret Rotation | D11: What secret rotation and lifecycle management is required? | E11: Requirements: Automated secret rotation, Dynamic credentials with TTL, Credential revocation on changes, Secrets versioning, Break-glass procedures | G11: Secrets lifecycle management approach

Sheet Governance & Policy
A1: Question ID | B1: Category | C1: Sub-Category | D1: Question | E1: Guidance | F1: Customer Response | G1: Notes
A2: GOV-001 | B2: Governance & Policy | C2: Approval Workflows | D2: What approval workflows are needed for infrastructure changes? | E2: Workflow types: Peer review required, Manager approval for production, Change advisory board for critical systems, Auto-approve for dev environments, Security team review | G2: Change management and approval requirements
A3: GOV-002 | B3: Governance & Policy | C3: Policy Framework | D3: What policy as code framework do you prefer? | E3: Options: Sentinel (HashiCorp native), OPA (Open Policy Agent), Cloud-native policies, Custom policy engine, Multiple frameworks | G3: Policy framework selection and integration
A4: GOV-003 | B4: Governance & Policy | C4: Cost Management | D4: What cost governance and optimization features do you need? | E4: Features: Cost estimation pre-apply, Budget alerts and limits, Resource tagging enforcement, Rightsizing recommendations, Unused resource detection, Multi-cloud cost comparison | G4: Cost governance and FinOps requirements
A5: GOV-004 | B5: Governance & Policy | C5: Workspace Organization | D5: How should workspaces be organized and governed? | E5: Organization models: By team, By application, By environment, By cloud provider, By business unit, Combination approach | G5: Workspace structure and governance model
A6: GOV-005 | B6: Governance & Policy | C6: RBAC Strategy | D6: What role-based access control model do you need? | E6: Roles: Read-only viewers, Terraform operators, Workspace admins, Organization owners, Custom roles with granular permissions | G6: RBAC design and permission requirements
A7: GOV-006 | B7: Governance & Policy | C7: Change Management | D7: What change management processes must be followed? | E7: Processes: Change tickets required, Maintenance windows, Rollback procedures, Emergency change procedures, Compliance documentation | G7: Change control integration requirements

Sheet Operations & Support
A1: Question ID | B1: Category | C1: Sub-Category | D1: Question | E1: Guidance | F1: Customer Response | G1: Notes
A2: OPS-001 | B2: Operations & Support | C2: Availability | D2: What uptime requirements do you have for the infrastructure platform? | E2: Common targets: 99% (Business hours), 99.5% (Extended hours), 99.9% (24x7), 99.95% (Mission critical) | G2: SLA requirements drive architecture design
A3: OPS-002 | B3: Operations & Support | C3: RTO/RPO | D3: What are your Recovery Time Objective and Recovery Point Objective? | E3: RTO: Maximum acceptable platform downtime, RPO: Maximum acceptable data/state loss, DR testing frequency | G3: Disaster recovery architecture requirements
A4: OPS-003 | B4: Operations & Support | C4: Support Coverage | D4: What support coverage do you require for the platform? | E4: Options: Business hours (8x5), Extended (24x5), Full (24x7), Follow-the-sun support | G4: Support staffing and cost planning
A5: OPS-004 | B5: Operations & Support | C5: Monitoring | D5: What monitoring and observability is required? | E5: Monitoring needs: Run status and duration, Policy compliance, State health checks, Workspace activity, Resource provisioning metrics, Cost tracking, Performance dashboards | G5: Operational visibility and alerting needs
A6: OPS-005 | B6: Operations & Support | C6: Alerting | D6: What alerting and notification requirements do you have? | E6: Alerts: Failed runs, Policy violations, Cost threshold exceeded, Security events, Slack/Teams/PagerDuty integration | G6: Notification and incident management integration
A7: OPS-006 | B7: Operations & Support | C7: Backup Strategy | D7: What backup and recovery strategy is needed? | E7: Requirements: State backup frequency, State retention period, Cross-region backup, Point-in-time recovery, Workspace configuration backup | G7: Backup architecture and data protection
A8: OPS-007 | B8: Operations & Support | C8: Drift Detection | D8: How should infrastructure drift be detected and managed? | E8: Options: Scheduled drift detection scans, Alert on drift detection, Auto-remediation of drift, Manual drift correction, Drift reporting and analytics | G8: Drift management and reconciliation approach
A9: OPS-008 | B9: Operations & Support | C9: Runbook Automation | D9: What operational runbooks need automation? | E9: Common runbooks: Environment provisioning, Disaster recovery, Security incident response, Cost optimization, Resource cleanup, Compliance reporting | G9: Operational automation requirements
A10: OPS-009 | B10: Operations & Support | C10: Self-Service | D10: What self-service capabilities do you need for teams? | E10: Capabilities: Workspace creation, Variable management, Run triggering, State management, Module discovery, Documentation access | G10: Self-service portal and UX requirements
A11: OPS-010 | B11: Operations & Support | C11: Migration Support | D11: What migration support do you need from existing infrastructure? | E11: Migration scope: Existing Terraform state import, CloudFormation/ARM conversion, Manual infrastructure discovery, Brownfield environment assessment | G11: Migration strategy and lift-and-shift planning

Sheet Team & Training
A1: Question ID | B1: Category | C1: Sub-Category | D1: Question | E1: Guidance | F1: Customer Response | G1: Notes
A2: TEAM-001 | B2: Team & Training | C2: Team Structure | D2: How is your infrastructure team currently structured? | E2: Team composition: Infrastructure engineers, DevOps engineers, Platform engineers, Cloud architects, Application developers, Security engineers | G2: Team organization for access control design
A3: TEAM-002 | B3: Team & Training | C3: Team Size | D3: How many people will use the multi-cloud platform? | E3: Ranges: 1-10, 11-50, 51-200, 200+. Include: Operators, Developers, Viewers | G3: User count for licensing and training
A4: TEAM-003 | B4: Team & Training | C4: Skill Level | D4: What is your team's current infrastructure automation skill level? | E4: Levels: Beginner (manual processes), Intermediate (basic scripting), Advanced (IaC experience), Expert (Terraform/automation mastery) | G4: Training needs assessment
A5: TEAM-004 | B5: Team & Training | C5: Training Needs | D5: What training and enablement do you need? | E5: Training types: HashiCorp Terraform certification, Vault administration, Policy as code with Sentinel, Multi-cloud architecture, Platform administration, Custom module development | G5: Training program design and delivery
A6: TEAM-005 | B6: Team & Training | C6: Knowledge Transfer | D6: What knowledge transfer and documentation do you require? | E6: Deliverables: Architecture documentation, Runbooks and procedures, Module development guide, Policy templates, Video tutorials, Best practices guide | G6: Documentation and enablement materials
A7: TEAM-006 | B7: Team & Training | C7: Support Model | D7: What ongoing support model do you prefer post-implementation? | E7: Options: Managed services (full platform management), Co-managed (shared responsibility), Self-managed with advisory, Training and handoff only | G7: Post-implementation support requirements
