Workbook

Sheet Cover
B3: Configuration Parameters
B5: Generated: | C5: November 27, 2025
B6: Solution: | C6: Hybrid Infrastructure
B7: Customer: | C7: [Customer Name]
B8: Version: | C8: 1.0
B9: Status: | C9: Draft
C12: eoframework.org

Sheet All Parameters (Read Only)
A1: Total Parameters | B1: Categories | C1: Required | D1: Confidential/Secret
A2: 50 | B2: 11 | C2: 47 | D2: 26
A4: Parameter Name | B4: Category | C4: Environment | D4: Default Value | E4: Description | F4: Required | G4: Data Type | H4: Validation Rules | I4: Security Level | J4: Owner Team | K4: Dependencies | L4: Notes | M4: Last Updated
A5: =IF('HyperFlex'!A3="","",'HyperFlex'!A3) | B5: HyperFlex | C5: =IF('HyperFlex'!B3="","",'HyperFlex'!B3) | D5: =IF('HyperFlex'!C3="","",'HyperFlex'!C3) | E5: =IF('HyperFlex'!D3="","",'HyperFlex'!D3) | F5: =IF('HyperFlex'!E3="","",'HyperFlex'!E3) | G5: =IF('HyperFlex'!F3="","",'HyperFlex'!F3) | H5: =IF('HyperFlex'!G3="","",'HyperFlex'!G3) | I5: =IF('HyperFlex'!H3="","",'HyperFlex'!H3) | J5: =IF('HyperFlex'!I3="","",'HyperFlex'!I3) | ... M5: =IF('HyperFlex'!L3="","",'HyperFlex'!L3)
A6: =IF('HyperFlex'!A4="","",'HyperFlex'!A4) | B6: HyperFlex | C6: =IF('HyperFlex'!B4="","",'HyperFlex'!B4) | D6: =IF('HyperFlex'!C4="","",'HyperFlex'!C4) | E6: =IF('HyperFlex'!D4="","",'HyperFlex'!D4) | F6: =IF('HyperFlex'!E4="","",'HyperFlex'!E4) | G6: =IF('HyperFlex'!F4="","",'HyperFlex'!F4) | H6: =IF('HyperFlex'!G4="","",'HyperFlex'!G4) | I6: =IF('HyperFlex'!H4="","",'HyperFlex'!H4) | J6: =IF('HyperFlex'!I4="","",'HyperFlex'!I4) | ... M6: =IF('HyperFlex'!L4="","",'HyperFlex'!L4)
A7: =IF('HyperFlex'!A5="","",'HyperFlex'!A5) | B7: HyperFlex | C7: =IF('HyperFlex'!B5="","",'HyperFlex'!B5) | D7: =IF('HyperFlex'!C5="","",'HyperFlex'!C5) | E7: =IF('HyperFlex'!D5="","",'HyperFlex'!D5) | F7: =IF('HyperFlex'!E5="","",'HyperFlex'!E5) | G7: =IF('HyperFlex'!F5="","",'HyperFlex'!F5) | H7: =IF('HyperFlex'!G5="","",'HyperFlex'!G5) | I7: =IF('HyperFlex'!H5="","",'HyperFlex'!H5) | J7: =IF('HyperFlex'!I5="","",'HyperFlex'!I5) | ... M7: =IF('HyperFlex'!L5="","",'HyperFlex'!L5)
A8: =IF('HyperFlex'!A6="","",'HyperFlex'!A6) | B8: HyperFlex | C8: =IF('HyperFlex'!B6="","",'HyperFlex'!B6) | D8: =IF('HyperFlex'!C6="","",'HyperFlex'!C6) | E8: =IF('HyperFlex'!D6="","",'HyperFlex'!D6) | F8: =IF('HyperFlex'!E6="","",'HyperFlex'!E6) | G8: =IF('HyperFlex'!F6="","",'HyperFlex'!F6) | H8: =IF('HyperFlex'!G6="","",'HyperFlex'!G6) | I8: =IF('HyperFlex'!H6="","",'HyperFlex'!H6) | J8: =IF('HyperFlex'!I6="","",'HyperFlex'!I6) | ... M8: =IF('HyperFlex'!L6="","",'HyperFlex'!L6)
A9: =IF('HyperFlex'!A7="","",'HyperFlex'!A7) | B9: HyperFlex | C9: =IF('HyperFlex'!B7="","",'HyperFlex'!B7) | D9: =IF('HyperFlex'!C7="","",'HyperFlex'!C7) | E9: =IF('HyperFlex'!D7="","",'HyperFlex'!D7) | F9: =IF('HyperFlex'!E7="","",'HyperFlex'!E7) | G9: =IF('HyperFlex'!F7="","",'HyperFlex'!F7) | H9: =IF('HyperFlex'!G7="","",'HyperFlex'!G7) | I9: =IF('HyperFlex'!H7="","",'HyperFlex'!H7) | J9: =IF('HyperFlex'!I7="","",'HyperFlex'!I7) | ... M9: =IF('HyperFlex'!L7="","",'HyperFlex'!L7)
A10: =IF('HyperFlex'!A8="","",'HyperFlex'!A8) | B10: HyperFlex | C10: =IF('HyperFlex'!B8="","",'HyperFlex'!B8) | D10: =IF('HyperFlex'!C8="","",'HyperFlex'!C8) | E10: =IF('HyperFlex'!D8="","",'HyperFlex'!D8) | F10: =IF('HyperFlex'!E8="","",'HyperFlex'!E8) | G10: =IF('HyperFlex'!F8="","",'HyperFlex'!F8) | H10: =IF('HyperFlex'!G8="","",'HyperFlex'!G8) | I10: =IF('HyperFlex'!H8="","",'HyperFlex'!H8) | J10: =IF('HyperFlex'!I8="","",'HyperFlex'!I8) | ... M10: =IF('HyperFlex'!L8="","",'HyperFlex'!L8)
A11: =IF('HyperFlex'!A9="","",'HyperFlex'!A9) | B11: HyperFlex | C11: =IF('HyperFlex'!B9="","",'HyperFlex'!B9) | D11: =IF('HyperFlex'!C9="","",'HyperFlex'!C9) | E11: =IF('HyperFlex'!D9="","",'HyperFlex'!D9) | F11: =IF('HyperFlex'!E9="","",'HyperFlex'!E9) | G11: =IF('HyperFlex'!F9="","",'HyperFlex'!F9) | H11: =IF('HyperFlex'!G9="","",'HyperFlex'!G9) | I11: =IF('HyperFlex'!H9="","",'HyperFlex'!H9) | J11: =IF('HyperFlex'!I9="","",'HyperFlex'!I9) | ... M11: =IF('HyperFlex'!L9="","",'HyperFlex'!L9)
A12: =IF('HyperFlex'!A10="","",'HyperFlex'!A10) | B12: HyperFlex | C12: =IF('HyperFlex'!B10="","",'HyperFlex'!B10) | D12: =IF('HyperFlex'!C10="","",'HyperFlex'!C10) | E12: =IF('HyperFlex'!D10="","",'HyperFlex'!D10) | F12: =IF('HyperFlex'!E10="","",'HyperFlex'!E10) | G12: =IF('HyperFlex'!F10="","",'HyperFlex'!F10) | H12: =IF('HyperFlex'!G10="","",'HyperFlex'!G10) | I12: =IF('HyperFlex'!H10="","",'HyperFlex'!H10) | J12: =IF('HyperFlex'!I10="","",'HyperFlex'!I10) | ... M12: =IF('HyperFlex'!L10="","",'HyperFlex'!L10)
A13: =IF('HyperFlex'!A11="","",'HyperFlex'!A11) | B13: HyperFlex | C13: =IF('HyperFlex'!B11="","",'HyperFlex'!B11) | D13: =IF('HyperFlex'!C11="","",'HyperFlex'!C11) | E13: =IF('HyperFlex'!D11="","",'HyperFlex'!D11) | F13: =IF('HyperFlex'!E11="","",'HyperFlex'!E11) | G13: =IF('HyperFlex'!F11="","",'HyperFlex'!F11) | H13: =IF('HyperFlex'!G11="","",'HyperFlex'!G11) | I13: =IF('HyperFlex'!H11="","",'HyperFlex'!H11) | J13: =IF('HyperFlex'!I11="","",'HyperFlex'!I11) | ... M13: =IF('HyperFlex'!L11="","",'HyperFlex'!L11)
A14: =IF('Fabric Interconnect'!A3="","",'Fabric Interconnect'!A3) | B14: Fabric Interconnect | C14: =IF('Fabric Interconnect'!B3="","",'Fabric Interconnect'!B3) | D14: =IF('Fabric Interconnect'!C3="","",'Fabric Interconnect'!C3) | E14: =IF('Fabric Interconnect'!D3="","",'Fabric Interconnect'!D3) | F14: =IF('Fabric Interconnect'!E3="","",'Fabric Interconnect'!E3) | G14: =IF('Fabric Interconnect'!F3="","",'Fabric Interconnect'!F3) | H14: =IF('Fabric Interconnect'!G3="","",'Fabric Interconnect'!G3) | I14: =IF('Fabric Interconnect'!H3="","",'Fabric Interconnect'!H3) | J14: =IF('Fabric Interconnect'!I3="","",'Fabric Interconnect'!I3) | ... M14: =IF('Fabric Interconnect'!L3="","",'Fabric Interconnect'!L3)
A15: =IF('Fabric Interconnect'!A4="","",'Fabric Interconnect'!A4) | B15: Fabric Interconnect | C15: =IF('Fabric Interconnect'!B4="","",'Fabric Interconnect'!B4) | D15: =IF('Fabric Interconnect'!C4="","",'Fabric Interconnect'!C4) | E15: =IF('Fabric Interconnect'!D4="","",'Fabric Interconnect'!D4) | F15: =IF('Fabric Interconnect'!E4="","",'Fabric Interconnect'!E4) | G15: =IF('Fabric Interconnect'!F4="","",'Fabric Interconnect'!F4) | H15: =IF('Fabric Interconnect'!G4="","",'Fabric Interconnect'!G4) | I15: =IF('Fabric Interconnect'!H4="","",'Fabric Interconnect'!H4) | J15: =IF('Fabric Interconnect'!I4="","",'Fabric Interconnect'!I4) | ... M15: =IF('Fabric Interconnect'!L4="","",'Fabric Interconnect'!L4)
A16: =IF('Fabric Interconnect'!A5="","",'Fabric Interconnect'!A5) | B16: Fabric Interconnect | C16: =IF('Fabric Interconnect'!B5="","",'Fabric Interconnect'!B5) | D16: =IF('Fabric Interconnect'!C5="","",'Fabric Interconnect'!C5) | E16: =IF('Fabric Interconnect'!D5="","",'Fabric Interconnect'!D5) | F16: =IF('Fabric Interconnect'!E5="","",'Fabric Interconnect'!E5) | G16: =IF('Fabric Interconnect'!F5="","",'Fabric Interconnect'!F5) | H16: =IF('Fabric Interconnect'!G5="","",'Fabric Interconnect'!G5) | I16: =IF('Fabric Interconnect'!H5="","",'Fabric Interconnect'!H5) | J16: =IF('Fabric Interconnect'!I5="","",'Fabric Interconnect'!I5) | ... M16: =IF('Fabric Interconnect'!L5="","",'Fabric Interconnect'!L5)
A17: =IF('Fabric Interconnect'!A6="","",'Fabric Interconnect'!A6) | B17: Fabric Interconnect | C17: =IF('Fabric Interconnect'!B6="","",'Fabric Interconnect'!B6) | D17: =IF('Fabric Interconnect'!C6="","",'Fabric Interconnect'!C6) | E17: =IF('Fabric Interconnect'!D6="","",'Fabric Interconnect'!D6) | F17: =IF('Fabric Interconnect'!E6="","",'Fabric Interconnect'!E6) | G17: =IF('Fabric Interconnect'!F6="","",'Fabric Interconnect'!F6) | H17: =IF('Fabric Interconnect'!G6="","",'Fabric Interconnect'!G6) | I17: =IF('Fabric Interconnect'!H6="","",'Fabric Interconnect'!H6) | J17: =IF('Fabric Interconnect'!I6="","",'Fabric Interconnect'!I6) | ... M17: =IF('Fabric Interconnect'!L6="","",'Fabric Interconnect'!L6)
A18: =IF('Fabric Interconnect'!A7="","",'Fabric Interconnect'!A7) | B18: Fabric Interconnect | C18: =IF('Fabric Interconnect'!B7="","",'Fabric Interconnect'!B7) | D18: =IF('Fabric Interconnect'!C7="","",'Fabric Interconnect'!C7) | E18: =IF('Fabric Interconnect'!D7="","",'Fabric Interconnect'!D7) | F18: =IF('Fabric Interconnect'!E7="","",'Fabric Interconnect'!E7) | G18: =IF('Fabric Interconnect'!F7="","",'Fabric Interconnect'!F7) | H18: =IF('Fabric Interconnect'!G7="","",'Fabric Interconnect'!G7) | I18: =IF('Fabric Interconnect'!H7="","",'Fabric Interconnect'!H7) | J18: =IF('Fabric Interconnect'!I7="","",'Fabric Interconnect'!I7) | ... M18: =IF('Fabric Interconnect'!L7="","",'Fabric Interconnect'!L7)
A19: =IF('Cisco Intersight'!A3="","",'Cisco Intersight'!A3) | B19: Cisco Intersight | C19: =IF('Cisco Intersight'!B3="","",'Cisco Intersight'!B3) | D19: =IF('Cisco Intersight'!C3="","",'Cisco Intersight'!C3) | E19: =IF('Cisco Intersight'!D3="","",'Cisco Intersight'!D3) | F19: =IF('Cisco Intersight'!E3="","",'Cisco Intersight'!E3) | G19: =IF('Cisco Intersight'!F3="","",'Cisco Intersight'!F3) | H19: =IF('Cisco Intersight'!G3="","",'Cisco Intersight'!G3) | I19: =IF('Cisco Intersight'!H3="","",'Cisco Intersight'!H3) | J19: =IF('Cisco Intersight'!I3="","",'Cisco Intersight'!I3) | ... M19: =IF('Cisco Intersight'!L3="","",'Cisco Intersight'!L3)
A20: =IF('Cisco Intersight'!A4="","",'Cisco Intersight'!A4) | B20: Cisco Intersight | C20: =IF('Cisco Intersight'!B4="","",'Cisco Intersight'!B4) | D20: =IF('Cisco Intersight'!C4="","",'Cisco Intersight'!C4) | E20: =IF('Cisco Intersight'!D4="","",'Cisco Intersight'!D4) | F20: =IF('Cisco Intersight'!E4="","",'Cisco Intersight'!E4) | G20: =IF('Cisco Intersight'!F4="","",'Cisco Intersight'!F4) | H20: =IF('Cisco Intersight'!G4="","",'Cisco Intersight'!G4) | I20: =IF('Cisco Intersight'!H4="","",'Cisco Intersight'!H4) | J20: =IF('Cisco Intersight'!I4="","",'Cisco Intersight'!I4) | ... M20: =IF('Cisco Intersight'!L4="","",'Cisco Intersight'!L4)
A21: =IF('Cisco Intersight'!A5="","",'Cisco Intersight'!A5) | B21: Cisco Intersight | C21: =IF('Cisco Intersight'!B5="","",'Cisco Intersight'!B5) | D21: =IF('Cisco Intersight'!C5="","",'Cisco Intersight'!C5) | E21: =IF('Cisco Intersight'!D5="","",'Cisco Intersight'!D5) | F21: =IF('Cisco Intersight'!E5="","",'Cisco Intersight'!E5) | G21: =IF('Cisco Intersight'!F5="","",'Cisco Intersight'!F5) | H21: =IF('Cisco Intersight'!G5="","",'Cisco Intersight'!G5) | I21: =IF('Cisco Intersight'!H5="","",'Cisco Intersight'!H5) | J21: =IF('Cisco Intersight'!I5="","",'Cisco Intersight'!I5) | ... M21: =IF('Cisco Intersight'!L5="","",'Cisco Intersight'!L5)
A22: =IF('Cisco Intersight'!A6="","",'Cisco Intersight'!A6) | B22: Cisco Intersight | C22: =IF('Cisco Intersight'!B6="","",'Cisco Intersight'!B6) | D22: =IF('Cisco Intersight'!C6="","",'Cisco Intersight'!C6) | E22: =IF('Cisco Intersight'!D6="","",'Cisco Intersight'!D6) | F22: =IF('Cisco Intersight'!E6="","",'Cisco Intersight'!E6) | G22: =IF('Cisco Intersight'!F6="","",'Cisco Intersight'!F6) | H22: =IF('Cisco Intersight'!G6="","",'Cisco Intersight'!G6) | I22: =IF('Cisco Intersight'!H6="","",'Cisco Intersight'!H6) | J22: =IF('Cisco Intersight'!I6="","",'Cisco Intersight'!I6) | ... M22: =IF('Cisco Intersight'!L6="","",'Cisco Intersight'!L6)
A23: =IF('VMware'!A3="","",'VMware'!A3) | B23: VMware | C23: =IF('VMware'!B3="","",'VMware'!B3) | D23: =IF('VMware'!C3="","",'VMware'!C3) | E23: =IF('VMware'!D3="","",'VMware'!D3) | F23: =IF('VMware'!E3="","",'VMware'!E3) | G23: =IF('VMware'!F3="","",'VMware'!F3) | H23: =IF('VMware'!G3="","",'VMware'!G3) | I23: =IF('VMware'!H3="","",'VMware'!H3) | J23: =IF('VMware'!I3="","",'VMware'!I3) | ... M23: =IF('VMware'!L3="","",'VMware'!L3)
A24: =IF('VMware'!A4="","",'VMware'!A4) | B24: VMware | C24: =IF('VMware'!B4="","",'VMware'!B4) | D24: =IF('VMware'!C4="","",'VMware'!C4) | E24: =IF('VMware'!D4="","",'VMware'!D4) | F24: =IF('VMware'!E4="","",'VMware'!E4) | G24: =IF('VMware'!F4="","",'VMware'!F4) | H24: =IF('VMware'!G4="","",'VMware'!G4) | I24: =IF('VMware'!H4="","",'VMware'!H4) | J24: =IF('VMware'!I4="","",'VMware'!I4) | ... M24: =IF('VMware'!L4="","",'VMware'!L4)
A25: =IF('VMware'!A5="","",'VMware'!A5) | B25: VMware | C25: =IF('VMware'!B5="","",'VMware'!B5) | D25: =IF('VMware'!C5="","",'VMware'!C5) | E25: =IF('VMware'!D5="","",'VMware'!D5) | F25: =IF('VMware'!E5="","",'VMware'!E5) | G25: =IF('VMware'!F5="","",'VMware'!F5) | H25: =IF('VMware'!G5="","",'VMware'!G5) | I25: =IF('VMware'!H5="","",'VMware'!H5) | J25: =IF('VMware'!I5="","",'VMware'!I5) | ... M25: =IF('VMware'!L5="","",'VMware'!L5)
A26: =IF('VMware'!A6="","",'VMware'!A6) | B26: VMware | C26: =IF('VMware'!B6="","",'VMware'!B6) | D26: =IF('VMware'!C6="","",'VMware'!C6) | E26: =IF('VMware'!D6="","",'VMware'!D6) | F26: =IF('VMware'!E6="","",'VMware'!E6) | G26: =IF('VMware'!F6="","",'VMware'!F6) | H26: =IF('VMware'!G6="","",'VMware'!G6) | I26: =IF('VMware'!H6="","",'VMware'!H6) | J26: =IF('VMware'!I6="","",'VMware'!I6) | ... M26: =IF('VMware'!L6="","",'VMware'!L6)
A27: =IF('VMware'!A7="","",'VMware'!A7) | B27: VMware | C27: =IF('VMware'!B7="","",'VMware'!B7) | D27: =IF('VMware'!C7="","",'VMware'!C7) | E27: =IF('VMware'!D7="","",'VMware'!D7) | F27: =IF('VMware'!E7="","",'VMware'!E7) | G27: =IF('VMware'!F7="","",'VMware'!F7) | H27: =IF('VMware'!G7="","",'VMware'!G7) | I27: =IF('VMware'!H7="","",'VMware'!H7) | J27: =IF('VMware'!I7="","",'VMware'!I7) | ... M27: =IF('VMware'!L7="","",'VMware'!L7)
A28: =IF('VMware'!A8="","",'VMware'!A8) | B28: VMware | C28: =IF('VMware'!B8="","",'VMware'!B8) | D28: =IF('VMware'!C8="","",'VMware'!C8) | E28: =IF('VMware'!D8="","",'VMware'!D8) | F28: =IF('VMware'!E8="","",'VMware'!E8) | G28: =IF('VMware'!F8="","",'VMware'!F8) | H28: =IF('VMware'!G8="","",'VMware'!G8) | I28: =IF('VMware'!H8="","",'VMware'!H8) | J28: =IF('VMware'!I8="","",'VMware'!I8) | ... M28: =IF('VMware'!L8="","",'VMware'!L8)
A29: =IF('VMware'!A9="","",'VMware'!A9) | B29: VMware | C29: =IF('VMware'!B9="","",'VMware'!B9) | D29: =IF('VMware'!C9="","",'VMware'!C9) | E29: =IF('VMware'!D9="","",'VMware'!D9) | F29: =IF('VMware'!E9="","",'VMware'!E9) | G29: =IF('VMware'!F9="","",'VMware'!F9) | H29: =IF('VMware'!G9="","",'VMware'!G9) | I29: =IF('VMware'!H9="","",'VMware'!H9) | J29: =IF('VMware'!I9="","",'VMware'!I9) | ... M29: =IF('VMware'!L9="","",'VMware'!L9)
A30: =IF('VMware'!A10="","",'VMware'!A10) | B30: VMware | C30: =IF('VMware'!B10="","",'VMware'!B10) | D30: =IF('VMware'!C10="","",'VMware'!C10) | E30: =IF('VMware'!D10="","",'VMware'!D10) | F30: =IF('VMware'!E10="","",'VMware'!E10) | G30: =IF('VMware'!F10="","",'VMware'!F10) | H30: =IF('VMware'!G10="","",'VMware'!G10) | I30: =IF('VMware'!H10="","",'VMware'!H10) | J30: =IF('VMware'!I10="","",'VMware'!I10) | ... M30: =IF('VMware'!L10="","",'VMware'!L10)
A31: =IF('VMware'!A11="","",'VMware'!A11) | B31: VMware | C31: =IF('VMware'!B11="","",'VMware'!B11) | D31: =IF('VMware'!C11="","",'VMware'!C11) | E31: =IF('VMware'!D11="","",'VMware'!D11) | F31: =IF('VMware'!E11="","",'VMware'!E11) | G31: =IF('VMware'!F11="","",'VMware'!F11) | H31: =IF('VMware'!G11="","",'VMware'!G11) | I31: =IF('VMware'!H11="","",'VMware'!H11) | J31: =IF('VMware'!I11="","",'VMware'!I11) | ... M31: =IF('VMware'!L11="","",'VMware'!L11)
A32: =IF('Backup'!A3="","",'Backup'!A3) | B32: Backup | C32: =IF('Backup'!B3="","",'Backup'!B3) | D32: =IF('Backup'!C3="","",'Backup'!C3) | E32: =IF('Backup'!D3="","",'Backup'!D3) | F32: =IF('Backup'!E3="","",'Backup'!E3) | G32: =IF('Backup'!F3="","",'Backup'!F3) | H32: =IF('Backup'!G3="","",'Backup'!G3) | I32: =IF('Backup'!H3="","",'Backup'!H3) | J32: =IF('Backup'!I3="","",'Backup'!I3) | ... M32: =IF('Backup'!L3="","",'Backup'!L3)
A33: =IF('Backup'!A4="","",'Backup'!A4) | B33: Backup | C33: =IF('Backup'!B4="","",'Backup'!B4) | D33: =IF('Backup'!C4="","",'Backup'!C4) | E33: =IF('Backup'!D4="","",'Backup'!D4) | F33: =IF('Backup'!E4="","",'Backup'!E4) | G33: =IF('Backup'!F4="","",'Backup'!F4) | H33: =IF('Backup'!G4="","",'Backup'!G4) | I33: =IF('Backup'!H4="","",'Backup'!H4) | J33: =IF('Backup'!I4="","",'Backup'!I4) | ... M33: =IF('Backup'!L4="","",'Backup'!L4)
A34: =IF('Backup'!A5="","",'Backup'!A5) | B34: Backup | C34: =IF('Backup'!B5="","",'Backup'!B5) | D34: =IF('Backup'!C5="","",'Backup'!C5) | E34: =IF('Backup'!D5="","",'Backup'!D5) | F34: =IF('Backup'!E5="","",'Backup'!E5) | G34: =IF('Backup'!F5="","",'Backup'!F5) | H34: =IF('Backup'!G5="","",'Backup'!G5) | I34: =IF('Backup'!H5="","",'Backup'!H5) | J34: =IF('Backup'!I5="","",'Backup'!I5) | ... M34: =IF('Backup'!L5="","",'Backup'!L5)
A35: =IF('Backup'!A6="","",'Backup'!A6) | B35: Backup | C35: =IF('Backup'!B6="","",'Backup'!B6) | D35: =IF('Backup'!C6="","",'Backup'!C6) | E35: =IF('Backup'!D6="","",'Backup'!D6) | F35: =IF('Backup'!E6="","",'Backup'!E6) | G35: =IF('Backup'!F6="","",'Backup'!F6) | H35: =IF('Backup'!G6="","",'Backup'!G6) | I35: =IF('Backup'!H6="","",'Backup'!H6) | J35: =IF('Backup'!I6="","",'Backup'!I6) | ... M35: =IF('Backup'!L6="","",'Backup'!L6)
A36: =IF('Backup'!A7="","",'Backup'!A7) | B36: Backup | C36: =IF('Backup'!B7="","",'Backup'!B7) | D36: =IF('Backup'!C7="","",'Backup'!C7) | E36: =IF('Backup'!D7="","",'Backup'!D7) | F36: =IF('Backup'!E7="","",'Backup'!E7) | G36: =IF('Backup'!F7="","",'Backup'!F7) | H36: =IF('Backup'!G7="","",'Backup'!G7) | I36: =IF('Backup'!H7="","",'Backup'!H7) | J36: =IF('Backup'!I7="","",'Backup'!I7) | ... M36: =IF('Backup'!L7="","",'Backup'!L7)
A37: =IF('Active Directory'!A3="","",'Active Directory'!A3) | B37: Active Directory | C37: =IF('Active Directory'!B3="","",'Active Directory'!B3) | D37: =IF('Active Directory'!C3="","",'Active Directory'!C3) | E37: =IF('Active Directory'!D3="","",'Active Directory'!D3) | F37: =IF('Active Directory'!E3="","",'Active Directory'!E3) | G37: =IF('Active Directory'!F3="","",'Active Directory'!F3) | H37: =IF('Active Directory'!G3="","",'Active Directory'!G3) | I37: =IF('Active Directory'!H3="","",'Active Directory'!H3) | J37: =IF('Active Directory'!I3="","",'Active Directory'!I3) | ... M37: =IF('Active Directory'!L3="","",'Active Directory'!L3)
A38: =IF('Active Directory'!A4="","",'Active Directory'!A4) | B38: Active Directory | C38: =IF('Active Directory'!B4="","",'Active Directory'!B4) | D38: =IF('Active Directory'!C4="","",'Active Directory'!C4) | E38: =IF('Active Directory'!D4="","",'Active Directory'!D4) | F38: =IF('Active Directory'!E4="","",'Active Directory'!E4) | G38: =IF('Active Directory'!F4="","",'Active Directory'!F4) | H38: =IF('Active Directory'!G4="","",'Active Directory'!G4) | I38: =IF('Active Directory'!H4="","",'Active Directory'!H4) | J38: =IF('Active Directory'!I4="","",'Active Directory'!I4) | ... M38: =IF('Active Directory'!L4="","",'Active Directory'!L4)
A39: =IF('Active Directory'!A5="","",'Active Directory'!A5) | B39: Active Directory | C39: =IF('Active Directory'!B5="","",'Active Directory'!B5) | D39: =IF('Active Directory'!C5="","",'Active Directory'!C5) | E39: =IF('Active Directory'!D5="","",'Active Directory'!D5) | F39: =IF('Active Directory'!E5="","",'Active Directory'!E5) | G39: =IF('Active Directory'!F5="","",'Active Directory'!F5) | H39: =IF('Active Directory'!G5="","",'Active Directory'!G5) | I39: =IF('Active Directory'!H5="","",'Active Directory'!H5) | J39: =IF('Active Directory'!I5="","",'Active Directory'!I5) | ... M39: =IF('Active Directory'!L5="","",'Active Directory'!L5)
A40: =IF('Active Directory'!A6="","",'Active Directory'!A6) | B40: Active Directory | C40: =IF('Active Directory'!B6="","",'Active Directory'!B6) | D40: =IF('Active Directory'!C6="","",'Active Directory'!C6) | E40: =IF('Active Directory'!D6="","",'Active Directory'!D6) | F40: =IF('Active Directory'!E6="","",'Active Directory'!E6) | G40: =IF('Active Directory'!F6="","",'Active Directory'!F6) | H40: =IF('Active Directory'!G6="","",'Active Directory'!G6) | I40: =IF('Active Directory'!H6="","",'Active Directory'!H6) | J40: =IF('Active Directory'!I6="","",'Active Directory'!I6) | ... M40: =IF('Active Directory'!L6="","",'Active Directory'!L6)
A41: =IF('Infrastructure'!A3="","",'Infrastructure'!A3) | B41: Infrastructure | C41: =IF('Infrastructure'!B3="","",'Infrastructure'!B3) | D41: =IF('Infrastructure'!C3="","",'Infrastructure'!C3) | E41: =IF('Infrastructure'!D3="","",'Infrastructure'!D3) | F41: =IF('Infrastructure'!E3="","",'Infrastructure'!E3) | G41: =IF('Infrastructure'!F3="","",'Infrastructure'!F3) | H41: =IF('Infrastructure'!G3="","",'Infrastructure'!G3) | I41: =IF('Infrastructure'!H3="","",'Infrastructure'!H3) | J41: =IF('Infrastructure'!I3="","",'Infrastructure'!I3) | ... M41: =IF('Infrastructure'!L3="","",'Infrastructure'!L3)
...

Sheet HyperFlex
A1: HyperFlex Parameters
A2: Parameter Name | B2: Environment | C2: Default Value | D2: Description | E2: Required | F2: Data Type | G2: Validation Rules | H2: Security Level | I2: Owner Team | J2: Dependencies | K2: Notes | L2: Last Updated
A3: HX_CLUSTER_NAME | B3: All | C3: hx-cluster-prod | D3: HyperFlex cluster identifier | E3: Yes | F3: String | G3: Alphanumeric max 32 chars | H3: Public | I3: HCI Team | J3: None | K3: Used in Intersight and vCenter | L3: [DATE]
A4: HX_NODE_COUNT | B4: All | C4: 4 | D4: Number of HyperFlex nodes in cluster | E4: Yes | F4: Integer | G4: 3-8 for standard cluster | H4: Public | I4: HCI Team | J4: Capacity planning | K4: Per SOW scope | L4: [DATE]
A5: HX_NODE_MODEL | B5: All | C5: HX240c M5 | D5: HyperFlex node hardware model | E5: Yes | F5: String | G5: Valid HX model | H5: Public | I5: HCI Team | J5: Hardware procurement | K5: All-flash NVMe configuration | L5: [DATE]
A6: HX_REPLICATION_FACTOR | B6: All | C6: 3 | D6: Data replication factor for protection | E6: Yes | F6: Integer | G6: 2-3 | H6: Public | I6: HCI Team | J6: Storage capacity | K6: RF3 for production workloads | L6: [DATE]
A7: HX_USABLE_CAPACITY_TB | B7: All | C7: 20 | D7: Usable storage capacity in TB | E7: Yes | F7: Integer | G7: Based on cluster size | H7: Public | I7: HCI Team | J7: Node count | K7: After dedup/compression | L7: [DATE]
A8: HX_DEDUP_ENABLED | B8: All | C8: true | D8: Enable inline deduplication | E8: Yes | F8: Boolean | G8: true|false | H8: Public | I8: HCI Team | J8: None | K8: Improves storage efficiency | L8: [DATE]
A9: HX_COMPRESSION_ENABLED | B9: All | C9: true | D9: Enable inline compression | E9: Yes | F9: Boolean | G9: true|false | H9: Public | I9: HCI Team | J9: None | K9: Improves storage efficiency | L9: [DATE]
A10: HX_MGMT_IP | B10: All | C10: [********] | D10: HyperFlex cluster management IP | E10: Yes | F10: String | G10: Valid IPv4 address | H10: Confidential | I10: HCI Team | J10: Network connectivity | K10: Management VLAN access | L10: [DATE]
A11: HX_DATA_IP_RANGE | B11: All | C11: [********] | D11: HyperFlex data network IP range | E11: Yes | F11: String | G11: Valid CIDR notation | H11: Confidential | I11: HCI Team | J11: Network design | K11: Storage traffic network | L11: [DATE]

Sheet Fabric Interconnect
A1: Fabric Interconnect Parameters
A2: Parameter Name | B2: Environment | C2: Default Value | D2: Description | E2: Required | F2: Data Type | G2: Validation Rules | H2: Security Level | I2: Owner Team | J2: Dependencies | K2: Notes | L2: Last Updated
A3: FI_PRIMARY_IP | B3: All | C3: [********] | D3: UCS Fabric Interconnect A IP | E3: Yes | F3: String | G3: Valid IPv4 address | H3: Confidential | I3: Network Team | J3: Network connectivity | K3: Management interface | L3: [DATE]
A4: FI_SECONDARY_IP | B4: All | C4: [********] | D4: UCS Fabric Interconnect B IP | E4: Yes | F4: String | G4: Valid IPv4 address | H4: Confidential | I4: Network Team | J4: Network connectivity | K4: HA pair | L4: [DATE]
A5: FI_MODEL | B5: All | C5: UCS 6454 | D5: Fabric Interconnect model | E5: Yes | F5: String | G5: Valid FI model | H5: Public | I5: Network Team | J5: Hardware procurement | K5: 48x25GbE + 6x100GbE | L5: [DATE]
A6: FI_CLUSTER_MODE | B6: All | C6: cluster | D6: FI clustering mode | E6: Yes | F6: String | G6: standalone|cluster | H6: Public | I6: Network Team | J6: High availability | K6: Always cluster for HA | L6: [DATE]
A7: FI_UPLINK_SPEED | B7: All | C7: 25GbE | D7: Uplink port speed to network | E7: Yes | F7: String | G7: 10GbE|25GbE|100GbE | H7: Public | I7: Network Team | J7: Network capacity | K7: Match upstream switches | L7: [DATE]

Sheet Cisco Intersight
A1: Cisco Intersight Parameters
A2: Parameter Name | B2: Environment | C2: Default Value | D2: Description | E2: Required | F2: Data Type | G2: Validation Rules | H2: Security Level | I2: Owner Team | J2: Dependencies | K2: Notes | L2: Last Updated
A3: INTERSIGHT_ENDPOINT | B3: All | C3: intersight.com | D3: Cisco Intersight cloud endpoint | E3: Yes | F3: String | G3: Valid FQDN | H3: Public | I3: HCI Team | J3: Internet connectivity | K3: SaaS management portal | L3: [DATE]
A4: INTERSIGHT_ACCOUNT_ID | B4: All | C4: [********] | D4: Intersight account identifier | E4: Yes | F4: String | G4: Valid account ID | H4: Confidential | I4: HCI Team | J4: Account creation | K4: From Intersight portal | L4: [DATE]
A5: INTERSIGHT_API_KEY | B5: All | C5: [********] | D5: Intersight API authentication key | E5: Yes | F5: String | G5: Valid API key format | H5: Secret | I5: HCI Team | J5: INTERSIGHT_ACCOUNT_ID | K5: For automation | L5: [DATE]
A6: INTERSIGHT_CLAIM_CODE | B6: All | C6: [********] | D6: Device connector claim code | E6: Yes | F6: String | G6: Valid claim code | H6: Secret | I6: HCI Team | J6: Device registration | K6: One-time use | L6: [DATE]

Sheet VMware
A1: VMware Parameters
A2: Parameter Name | B2: Environment | C2: Default Value | D2: Description | E2: Required | F2: Data Type | G2: Validation Rules | H2: Security Level | I2: Owner Team | J2: Dependencies | K2: Notes | L2: Last Updated
A3: VCENTER_FQDN | B3: All | C3: [********] | D3: vCenter Server FQDN | E3: Yes | F3: String | G3: Valid FQDN | H3: Confidential | I3: Virtualization Team | J3: DNS configuration | K3: SSO domain | L3: [DATE]
A4: VCENTER_IP | B4: All | C4: [********] | D4: vCenter Server IP address | E4: Yes | F4: String | G4: Valid IPv4 address | H4: Confidential | I4: Virtualization Team | J4: Network connectivity | K4: Management network | L4: [DATE]
A5: VCENTER_VERSION | B5: All | C5: 8.0 U2 | D5: vCenter Server version | E5: Yes | F5: String | G5: 8.x version | H5: Public | I5: Virtualization Team | J5: Compatibility | K5: Latest supported | L5: [DATE]
A6: VCENTER_ADMIN_USER | B6: All | C6: [********] | D6: vCenter SSO admin username | E6: Yes | F6: String | G6: Valid SSO user | H6: Confidential | I6: Virtualization Team | J6: SSO configuration | K6: Initial admin | L6: [DATE]
A7: ESXI_VERSION | B7: All | C7: 8.0 U2 | D7: ESXi hypervisor version | E7: Yes | F7: String | G7: 8.x version | H7: Public | I7: Virtualization Team | J7: VCENTER_VERSION | K7: Match vCenter | L7: [DATE]
A8: VMWARE_LICENSE_KEY | B8: All | C8: [********] | D8: VMware Enterprise Plus license | E8: Yes | F8: String | G8: Valid license format | H8: Secret | I8: Virtualization Team | J8: License procurement | K8: Per SOW scope | L8: [DATE]
A9: VMWARE_HA_ENABLED | B9: All | C9: true | D9: Enable vSphere High Availability | E9: Yes | F9: Boolean | G9: true|false | H9: Public | I9: Virtualization Team | J9: Cluster created | K9: Required for resilience | L9: [DATE]
A10: VMWARE_DRS_ENABLED | B10: All | C10: true | D10: Enable Distributed Resource Scheduler | E10: Yes | F10: Boolean | G10: true|false | H10: Public | I10: Virtualization Team | J10: VMWARE_HA_ENABLED | K10: Load balancing | L10: [DATE]
A11: VMWARE_DRS_LEVEL | B11: All | C11: FullyAutomated | D11: DRS automation level | E11: Yes | F11: String | G11: Manual|PartiallyAutomated|FullyAutomated | H11: Public | I11: Virtualization Team | J11: VMWARE_DRS_ENABLED | K11: Automatic vMotion | L11: [DATE]

Sheet Backup
A1: Backup Parameters
A2: Parameter Name | B2: Environment | C2: Default Value | D2: Description | E2: Required | F2: Data Type | G2: Validation Rules | H2: Security Level | I2: Owner Team | J2: Dependencies | K2: Notes | L2: Last Updated
A3: VEEAM_SERVER_IP | B3: All | C3: [********] | D3: Veeam Backup Server IP | E3: Yes | F3: String | G3: Valid IPv4 address | H3: Confidential | I3: Backup Team | J3: Network connectivity | K3: Backup infrastructure | L3: [DATE]
A4: VEEAM_VERSION | B4: All | C4: 12.0 | D4: Veeam Backup version | E4: Yes | F4: String | G4: Valid version | H4: Public | I4: Backup Team | J4: Compatibility | K4: HyperFlex plugin support | L4: [DATE]
A5: VEEAM_RETENTION_DAILY | B5: All | C5: 30 | D5: Daily backup retention in days | E5: Yes | F5: Integer | G5: 7-90 | H5: Public | I5: Backup Team | J5: Storage planning | K5: Per SOW scope | L5: [DATE]
A6: VEEAM_RETENTION_MONTHLY | B6: All | C6: 12 | D6: Monthly backup retention in months | E6: Yes | F6: Integer | G6: 6-24 | H6: Public | I6: Backup Team | J6: Compliance | K6: Long-term retention | L6: [DATE]
A7: VEEAM_BACKUP_WINDOW | B7: All | C7: 22:00-06:00 | D7: Backup window in 24-hour format | E7: Yes | F7: String | G7: HH:MM-HH:MM format | H7: Public | I7: Backup Team | J7: Business hours | K7: Off-peak hours | L7: [DATE]

Sheet Active Directory
A1: Active Directory Parameters
A2: Parameter Name | B2: Environment | C2: Default Value | D2: Description | E2: Required | F2: Data Type | G2: Validation Rules | H2: Security Level | I2: Owner Team | J2: Dependencies | K2: Notes | L2: Last Updated
A3: AD_SERVER_PRIMARY | B3: All | C3: [********] | D3: Primary AD server IP | E3: Yes | F3: String | G3: Valid IPv4 address | H3: Confidential | I3: Security Team | J3: Network connectivity | K3: LDAP authentication | L3: [DATE]
A4: AD_SERVER_SECONDARY | B4: All | C4: [********] | D4: Secondary AD server IP | E4: No | F4: String | G4: Valid IPv4 address | H4: Confidential | I4: Security Team | J4: Network connectivity | K4: Failover | L4: [DATE]
A5: AD_DOMAIN | B5: All | C5: [********] | D5: Active Directory domain name | E5: Yes | F5: String | G5: Valid domain format | H5: Confidential | I5: Security Team | J5: None | K5: User authentication | L5: [DATE]
A6: AD_SERVICE_ACCOUNT | B6: All | C6: [********] | D6: AD service account for vCenter | E6: Yes | F6: String | G6: Valid username | H6: Confidential | I6: Security Team | J6: AD account created | K6: Read access to AD | L6: [DATE]

Sheet Infrastructure
A1: Infrastructure Parameters
A2: Parameter Name | B2: Environment | C2: Default Value | D2: Description | E2: Required | F2: Data Type | G2: Validation Rules | H2: Security Level | I2: Owner Team | J2: Dependencies | K2: Notes | L2: Last Updated
A3: NTP_SERVER_PRIMARY | B3: All | C3: [********] | D3: Primary NTP server IP | E3: Yes | F3: String | G3: Valid IPv4 address | H3: Confidential | I3: Infrastructure Team | J3: Network connectivity | K3: Time sync critical | L3: [DATE]
A4: NTP_SERVER_SECONDARY | B4: All | C4: [********] | D4: Secondary NTP server IP | E4: No | F4: String | G4: Valid IPv4 address | H4: Confidential | I4: Infrastructure Team | J4: Network connectivity | K4: NTP failover | L4: [DATE]
A5: DNS_SERVER_PRIMARY | B5: All | C5: [********] | D5: Primary DNS server IP | E5: Yes | F5: String | G5: Valid IPv4 address | H5: Confidential | I5: Infrastructure Team | J5: Network connectivity | K5: Name resolution | L5: [DATE]
A6: DNS_SERVER_SECONDARY | B6: All | C6: [********] | D6: Secondary DNS server IP | E6: No | F6: String | G6: Valid IPv4 address | H6: Confidential | I6: Infrastructure Team | J6: Network connectivity | K6: DNS failover | L6: [DATE]

Sheet Network
A1: Network Parameters
A2: Parameter Name | B2: Environment | C2: Default Value | D2: Description | E2: Required | F2: Data Type | G2: Validation Rules | H2: Security Level | I2: Owner Team | J2: Dependencies | K2: Notes | L2: Last Updated
A3: MGMT_VLAN_ID | B3: All | C3: 100 | D3: Management VLAN ID | E3: Yes | F3: Integer | G3: 1-4094 | H3: Public | I3: Network Team | J3: Switch configuration | K3: Management traffic | L3: [DATE]
A4: VMOTION_VLAN_ID | B4: All | C4: 101 | D4: vMotion VLAN ID | E4: Yes | F4: Integer | G4: 1-4094 | H4: Public | I4: Network Team | J4: Switch configuration | K4: Live migration traffic | L4: [DATE]
A5: STORAGE_VLAN_ID | B5: All | C5: 102 | D5: Storage VLAN ID | E5: Yes | F5: Integer | G5: 1-4094 | H5: Public | I5: Network Team | J5: Switch configuration | K5: HyperFlex data traffic | L5: [DATE]
A6: VM_NETWORK_VLAN_RANGE | B6: All | C6: 200-250 | D6: VM network VLAN range | E6: Yes | F6: String | G6: VLAN range format | H6: Public | I6: Network Team | J6: Switch configuration | K6: Guest VM networks | L6: [DATE]

Sheet Monitoring
A1: Monitoring Parameters
A2: Parameter Name | B2: Environment | C2: Default Value | D2: Description | E2: Required | F2: Data Type | G2: Validation Rules | H2: Security Level | I2: Owner Team | J2: Dependencies | K2: Notes | L2: Last Updated
A3: SYSLOG_SERVER | B3: All | C3: [********] | D3: Centralized syslog server IP | E3: Yes | F3: String | G3: Valid IPv4 address | H3: Confidential | I3: Operations Team | J3: Network connectivity | K3: Log aggregation | L3: [DATE]
A4: SNMP_COMMUNITY | B4: All | C4: [********] | D4: SNMP community string | E4: Yes | F4: String | G4: Min 8 characters | H4: Secret | I4: Operations Team | J4: SNMP configuration | K4: Monitoring access | L4: [DATE]

Sheet Alerts
A1: Notifications Parameters
A2: Parameter Name | B2: Environment | C2: Default Value | D2: Description | E2: Required | F2: Data Type | G2: Validation Rules | H2: Security Level | I2: Owner Team | J2: Dependencies | K2: Notes | L2: Last Updated
A3: SMTP_SERVER | B3: All | C3: [********] | D3: SMTP server for notifications | E3: Yes | F3: String | G3: Valid hostname or IP | H3: Confidential | I3: Infrastructure Team | J3: SMTP relay | K3: Alert notifications | L3: [DATE]
A4: ALERT_EMAIL_RECIPIENTS | B4: All | C4: [********] | D4: Email recipients for alerts | E4: Yes | F4: String | G4: Valid email addresses | H4: Confidential | I4: Operations Team | J4: None | K4: NOC distribution | L4: [DATE]

Sheet Support
A1: Support Parameters
A2: Parameter Name | B2: Environment | C2: Default Value | D2: Description | E2: Required | F2: Data Type | G2: Validation Rules | H2: Security Level | I2: Owner Team | J2: Dependencies | K2: Notes | L2: Last Updated
A3: CISCO_SMARTNET_CONTRACT | B3: All | C3: [********] | D3: Cisco SmartNet contract number | E3: Yes | F3: String | G3: Valid contract ID | H3: Confidential | I3: Support Team | J3: Vendor relationship | K3: 24x7 support | L3: [DATE]
A4: VMWARE_SUPPORT_CONTRACT | B4: All | C4: [********] | D4: VMware support contract number | E4: Yes | F4: String | G4: Valid contract ID | H4: Confidential | I4: Support Team | J4: Vendor relationship | K4: Production support | L4: [DATE]
