Workbook

Sheet Cover
B3: [DOCUMENT TITLE]
B4: Discovery Questionnaire
B5: Presales Document
B6: Generated: | C6: November 16, 2025
B7: Solution: | C7: November 22, 2025
B8: Customer: | C8: Openshift Container Platform
B9: Version: | C9: [Customer Name]
B10: Status: | C10: Draft
C12: eoframework.org

Sheet All Categories (Read Only)
A1: Total Questions | B1: Answered | C1: Remaining | D1: % Complete
A2: 60 | B2: =SUMPRODUCT(--(LEN(F5:F64)>0)) | C2: =A2-B2 | D2: =B2/A2
A4: Question ID | B4: Category | C4: Sub-Category | D4: Question | E4: Guidance | F4: Customer Response | G4: Notes
A5: =IF('Business Requirements'!A2="","",'Business Requirements'!A2) | B5: =IF('Business Requirements'!B2="","",'Business Requirements'!B2) | C5: =IF('Business Requirements'!C2="","",'Business Requirements'!C2) | D5: =IF('Business Requirements'!D2="","",'Business Requirements'!D2) | E5: =IF('Business Requirements'!E2="","",'Business Requirements'!E2) | F5: =IF('Business Requirements'!F2="","",'Business Requirements'!F2) | G5: =IF('Business Requirements'!G2="","",'Business Requirements'!G2)
A6: =IF('Business Requirements'!A3="","",'Business Requirements'!A3) | B6: =IF('Business Requirements'!B3="","",'Business Requirements'!B3) | C6: =IF('Business Requirements'!C3="","",'Business Requirements'!C3) | D6: =IF('Business Requirements'!D3="","",'Business Requirements'!D3) | E6: =IF('Business Requirements'!E3="","",'Business Requirements'!E3) | F6: =IF('Business Requirements'!F3="","",'Business Requirements'!F3) | G6: =IF('Business Requirements'!G3="","",'Business Requirements'!G3)
A7: =IF('Business Requirements'!A4="","",'Business Requirements'!A4) | B7: =IF('Business Requirements'!B4="","",'Business Requirements'!B4) | C7: =IF('Business Requirements'!C4="","",'Business Requirements'!C4) | D7: =IF('Business Requirements'!D4="","",'Business Requirements'!D4) | E7: =IF('Business Requirements'!E4="","",'Business Requirements'!E4) | F7: =IF('Business Requirements'!F4="","",'Business Requirements'!F4) | G7: =IF('Business Requirements'!G4="","",'Business Requirements'!G4)
A8: =IF('Business Requirements'!A5="","",'Business Requirements'!A5) | B8: =IF('Business Requirements'!B5="","",'Business Requirements'!B5) | C8: =IF('Business Requirements'!C5="","",'Business Requirements'!C5) | D8: =IF('Business Requirements'!D5="","",'Business Requirements'!D5) | E8: =IF('Business Requirements'!E5="","",'Business Requirements'!E5) | F8: =IF('Business Requirements'!F5="","",'Business Requirements'!F5) | G8: =IF('Business Requirements'!G5="","",'Business Requirements'!G5)
A9: =IF('Business Requirements'!A6="","",'Business Requirements'!A6) | B9: =IF('Business Requirements'!B6="","",'Business Requirements'!B6) | C9: =IF('Business Requirements'!C6="","",'Business Requirements'!C6) | D9: =IF('Business Requirements'!D6="","",'Business Requirements'!D6) | E9: =IF('Business Requirements'!E6="","",'Business Requirements'!E6) | F9: =IF('Business Requirements'!F6="","",'Business Requirements'!F6) | G9: =IF('Business Requirements'!G6="","",'Business Requirements'!G6)
A10: =IF('Business Requirements'!A7="","",'Business Requirements'!A7) | B10: =IF('Business Requirements'!B7="","",'Business Requirements'!B7) | C10: =IF('Business Requirements'!C7="","",'Business Requirements'!C7) | D10: =IF('Business Requirements'!D7="","",'Business Requirements'!D7) | E10: =IF('Business Requirements'!E7="","",'Business Requirements'!E7) | F10: =IF('Business Requirements'!F7="","",'Business Requirements'!F7) | G10: =IF('Business Requirements'!G7="","",'Business Requirements'!G7)
A11: =IF('Business Requirements'!A8="","",'Business Requirements'!A8) | B11: =IF('Business Requirements'!B8="","",'Business Requirements'!B8) | C11: =IF('Business Requirements'!C8="","",'Business Requirements'!C8) | D11: =IF('Business Requirements'!D8="","",'Business Requirements'!D8) | E11: =IF('Business Requirements'!E8="","",'Business Requirements'!E8) | F11: =IF('Business Requirements'!F8="","",'Business Requirements'!F8) | G11: =IF('Business Requirements'!G8="","",'Business Requirements'!G8)
A12: =IF('Business Requirements'!A9="","",'Business Requirements'!A9) | B12: =IF('Business Requirements'!B9="","",'Business Requirements'!B9) | C12: =IF('Business Requirements'!C9="","",'Business Requirements'!C9) | D12: =IF('Business Requirements'!D9="","",'Business Requirements'!D9) | E12: =IF('Business Requirements'!E9="","",'Business Requirements'!E9) | F12: =IF('Business Requirements'!F9="","",'Business Requirements'!F9) | G12: =IF('Business Requirements'!G9="","",'Business Requirements'!G9)
A13: =IF('Business Requirements'!A10="","",'Business Requirements'!A10) | B13: =IF('Business Requirements'!B10="","",'Business Requirements'!B10) | C13: =IF('Business Requirements'!C10="","",'Business Requirements'!C10) | D13: =IF('Business Requirements'!D10="","",'Business Requirements'!D10) | E13: =IF('Business Requirements'!E10="","",'Business Requirements'!E10) | F13: =IF('Business Requirements'!F10="","",'Business Requirements'!F10) | G13: =IF('Business Requirements'!G10="","",'Business Requirements'!G10)
A14: =IF('Business Requirements'!A11="","",'Business Requirements'!A11) | B14: =IF('Business Requirements'!B11="","",'Business Requirements'!B11) | C14: =IF('Business Requirements'!C11="","",'Business Requirements'!C11) | D14: =IF('Business Requirements'!D11="","",'Business Requirements'!D11) | E14: =IF('Business Requirements'!E11="","",'Business Requirements'!E11) | F14: =IF('Business Requirements'!F11="","",'Business Requirements'!F11) | G14: =IF('Business Requirements'!G11="","",'Business Requirements'!G11)
A15: =IF('Business Requirements'!A12="","",'Business Requirements'!A12) | B15: =IF('Business Requirements'!B12="","",'Business Requirements'!B12) | C15: =IF('Business Requirements'!C12="","",'Business Requirements'!C12) | D15: =IF('Business Requirements'!D12="","",'Business Requirements'!D12) | E15: =IF('Business Requirements'!E12="","",'Business Requirements'!E12) | F15: =IF('Business Requirements'!F12="","",'Business Requirements'!F12) | G15: =IF('Business Requirements'!G12="","",'Business Requirements'!G12)
A16: =IF('Business Requirements'!A13="","",'Business Requirements'!A13) | B16: =IF('Business Requirements'!B13="","",'Business Requirements'!B13) | C16: =IF('Business Requirements'!C13="","",'Business Requirements'!C13) | D16: =IF('Business Requirements'!D13="","",'Business Requirements'!D13) | E16: =IF('Business Requirements'!E13="","",'Business Requirements'!E13) | F16: =IF('Business Requirements'!F13="","",'Business Requirements'!F13) | G16: =IF('Business Requirements'!G13="","",'Business Requirements'!G13)
A17: =IF('Technical Requirements'!A2="","",'Technical Requirements'!A2) | B17: =IF('Technical Requirements'!B2="","",'Technical Requirements'!B2) | C17: =IF('Technical Requirements'!C2="","",'Technical Requirements'!C2) | D17: =IF('Technical Requirements'!D2="","",'Technical Requirements'!D2) | E17: =IF('Technical Requirements'!E2="","",'Technical Requirements'!E2) | F17: =IF('Technical Requirements'!F2="","",'Technical Requirements'!F2) | G17: =IF('Technical Requirements'!G2="","",'Technical Requirements'!G2)
A18: =IF('Technical Requirements'!A3="","",'Technical Requirements'!A3) | B18: =IF('Technical Requirements'!B3="","",'Technical Requirements'!B3) | C18: =IF('Technical Requirements'!C3="","",'Technical Requirements'!C3) | D18: =IF('Technical Requirements'!D3="","",'Technical Requirements'!D3) | E18: =IF('Technical Requirements'!E3="","",'Technical Requirements'!E3) | F18: =IF('Technical Requirements'!F3="","",'Technical Requirements'!F3) | G18: =IF('Technical Requirements'!G3="","",'Technical Requirements'!G3)
A19: =IF('Technical Requirements'!A4="","",'Technical Requirements'!A4) | B19: =IF('Technical Requirements'!B4="","",'Technical Requirements'!B4) | C19: =IF('Technical Requirements'!C4="","",'Technical Requirements'!C4) | D19: =IF('Technical Requirements'!D4="","",'Technical Requirements'!D4) | E19: =IF('Technical Requirements'!E4="","",'Technical Requirements'!E4) | F19: =IF('Technical Requirements'!F4="","",'Technical Requirements'!F4) | G19: =IF('Technical Requirements'!G4="","",'Technical Requirements'!G4)
A20: =IF('Technical Requirements'!A5="","",'Technical Requirements'!A5) | B20: =IF('Technical Requirements'!B5="","",'Technical Requirements'!B5) | C20: =IF('Technical Requirements'!C5="","",'Technical Requirements'!C5) | D20: =IF('Technical Requirements'!D5="","",'Technical Requirements'!D5) | E20: =IF('Technical Requirements'!E5="","",'Technical Requirements'!E5) | F20: =IF('Technical Requirements'!F5="","",'Technical Requirements'!F5) | G20: =IF('Technical Requirements'!G5="","",'Technical Requirements'!G5)
A21: =IF('Technical Requirements'!A6="","",'Technical Requirements'!A6) | B21: =IF('Technical Requirements'!B6="","",'Technical Requirements'!B6) | C21: =IF('Technical Requirements'!C6="","",'Technical Requirements'!C6) | D21: =IF('Technical Requirements'!D6="","",'Technical Requirements'!D6) | E21: =IF('Technical Requirements'!E6="","",'Technical Requirements'!E6) | F21: =IF('Technical Requirements'!F6="","",'Technical Requirements'!F6) | G21: =IF('Technical Requirements'!G6="","",'Technical Requirements'!G6)
A22: =IF('Technical Requirements'!A7="","",'Technical Requirements'!A7) | B22: =IF('Technical Requirements'!B7="","",'Technical Requirements'!B7) | C22: =IF('Technical Requirements'!C7="","",'Technical Requirements'!C7) | D22: =IF('Technical Requirements'!D7="","",'Technical Requirements'!D7) | E22: =IF('Technical Requirements'!E7="","",'Technical Requirements'!E7) | F22: =IF('Technical Requirements'!F7="","",'Technical Requirements'!F7) | G22: =IF('Technical Requirements'!G7="","",'Technical Requirements'!G7)
A23: =IF('Technical Requirements'!A8="","",'Technical Requirements'!A8) | B23: =IF('Technical Requirements'!B8="","",'Technical Requirements'!B8) | C23: =IF('Technical Requirements'!C8="","",'Technical Requirements'!C8) | D23: =IF('Technical Requirements'!D8="","",'Technical Requirements'!D8) | E23: =IF('Technical Requirements'!E8="","",'Technical Requirements'!E8) | F23: =IF('Technical Requirements'!F8="","",'Technical Requirements'!F8) | G23: =IF('Technical Requirements'!G8="","",'Technical Requirements'!G8)
A24: =IF('Technical Requirements'!A9="","",'Technical Requirements'!A9) | B24: =IF('Technical Requirements'!B9="","",'Technical Requirements'!B9) | C24: =IF('Technical Requirements'!C9="","",'Technical Requirements'!C9) | D24: =IF('Technical Requirements'!D9="","",'Technical Requirements'!D9) | E24: =IF('Technical Requirements'!E9="","",'Technical Requirements'!E9) | F24: =IF('Technical Requirements'!F9="","",'Technical Requirements'!F9) | G24: =IF('Technical Requirements'!G9="","",'Technical Requirements'!G9)
A25: =IF('Technical Requirements'!A10="","",'Technical Requirements'!A10) | B25: =IF('Technical Requirements'!B10="","",'Technical Requirements'!B10) | C25: =IF('Technical Requirements'!C10="","",'Technical Requirements'!C10) | D25: =IF('Technical Requirements'!D10="","",'Technical Requirements'!D10) | E25: =IF('Technical Requirements'!E10="","",'Technical Requirements'!E10) | F25: =IF('Technical Requirements'!F10="","",'Technical Requirements'!F10) | G25: =IF('Technical Requirements'!G10="","",'Technical Requirements'!G10)
A26: =IF('Technical Requirements'!A11="","",'Technical Requirements'!A11) | B26: =IF('Technical Requirements'!B11="","",'Technical Requirements'!B11) | C26: =IF('Technical Requirements'!C11="","",'Technical Requirements'!C11) | D26: =IF('Technical Requirements'!D11="","",'Technical Requirements'!D11) | E26: =IF('Technical Requirements'!E11="","",'Technical Requirements'!E11) | F26: =IF('Technical Requirements'!F11="","",'Technical Requirements'!F11) | G26: =IF('Technical Requirements'!G11="","",'Technical Requirements'!G11)
A27: =IF('Technical Requirements'!A12="","",'Technical Requirements'!A12) | B27: =IF('Technical Requirements'!B12="","",'Technical Requirements'!B12) | C27: =IF('Technical Requirements'!C12="","",'Technical Requirements'!C12) | D27: =IF('Technical Requirements'!D12="","",'Technical Requirements'!D12) | E27: =IF('Technical Requirements'!E12="","",'Technical Requirements'!E12) | F27: =IF('Technical Requirements'!F12="","",'Technical Requirements'!F12) | G27: =IF('Technical Requirements'!G12="","",'Technical Requirements'!G12)
A28: =IF('Technical Requirements'!A13="","",'Technical Requirements'!A13) | B28: =IF('Technical Requirements'!B13="","",'Technical Requirements'!B13) | C28: =IF('Technical Requirements'!C13="","",'Technical Requirements'!C13) | D28: =IF('Technical Requirements'!D13="","",'Technical Requirements'!D13) | E28: =IF('Technical Requirements'!E13="","",'Technical Requirements'!E13) | F28: =IF('Technical Requirements'!F13="","",'Technical Requirements'!F13) | G28: =IF('Technical Requirements'!G13="","",'Technical Requirements'!G13)
... A36: =IF('Technical Requirements'!A21="","",'Technical Requirements'!A21) | B36: =IF('Technical Requirements'!B21="","",'Technical Requirements'!B21) | C36: =IF('Technical Requirements'!C21="","",'Technical Requirements'!C21) | D36: =IF('Technical Requirements'!D21="","",'Technical Requirements'!D21) | E36: =IF('Technical Requirements'!E21="","",'Technical Requirements'!E21) | F36: =IF('Technical Requirements'!F21="","",'Technical Requirements'!F21) | G36: =IF('Technical Requirements'!G21="","",'Technical Requirements'!G21)
A37: =IF('Security & Compliance'!A2="","",'Security & Compliance'!A2) | B37: =IF('Security & Compliance'!B2="","",'Security & Compliance'!B2) | C37: =IF('Security & Compliance'!C2="","",'Security & Compliance'!C2) | D37: =IF('Security & Compliance'!D2="","",'Security & Compliance'!D2) | E37: =IF('Security & Compliance'!E2="","",'Security & Compliance'!E2) | F37: =IF('Security & Compliance'!F2="","",'Security & Compliance'!F2) | G37: =IF('Security & Compliance'!G2="","",'Security & Compliance'!G2)
A38: =IF('Security & Compliance'!A3="","",'Security & Compliance'!A3) | B38: =IF('Security & Compliance'!B3="","",'Security & Compliance'!B3) | C38: =IF('Security & Compliance'!C3="","",'Security & Compliance'!C3) | D38: =IF('Security & Compliance'!D3="","",'Security & Compliance'!D3) | E38: =IF('Security & Compliance'!E3="","",'Security & Compliance'!E3) | F38: =IF('Security & Compliance'!F3="","",'Security & Compliance'!F3) | G38: =IF('Security & Compliance'!G3="","",'Security & Compliance'!G3)
A39: =IF('Security & Compliance'!A4="","",'Security & Compliance'!A4) | B39: =IF('Security & Compliance'!B4="","",'Security & Compliance'!B4) | C39: =IF('Security & Compliance'!C4="","",'Security & Compliance'!C4) | D39: =IF('Security & Compliance'!D4="","",'Security & Compliance'!D4) | E39: =IF('Security & Compliance'!E4="","",'Security & Compliance'!E4) | F39: =IF('Security & Compliance'!F4="","",'Security & Compliance'!F4) | G39: =IF('Security & Compliance'!G4="","",'Security & Compliance'!G4)
A40: =IF('Security & Compliance'!A5="","",'Security & Compliance'!A5) | B40: =IF('Security & Compliance'!B5="","",'Security & Compliance'!B5) | C40: =IF('Security & Compliance'!C5="","",'Security & Compliance'!C5) | D40: =IF('Security & Compliance'!D5="","",'Security & Compliance'!D5) | E40: =IF('Security & Compliance'!E5="","",'Security & Compliance'!E5) | F40: =IF('Security & Compliance'!F5="","",'Security & Compliance'!F5) | G40: =IF('Security & Compliance'!G5="","",'Security & Compliance'!G5)
A41: =IF('Security & Compliance'!A6="","",'Security & Compliance'!A6) | B41: =IF('Security & Compliance'!B6="","",'Security & Compliance'!B6) | C41: =IF('Security & Compliance'!C6="","",'Security & Compliance'!C6) | D41: =IF('Security & Compliance'!D6="","",'Security & Compliance'!D6) | E41: =IF('Security & Compliance'!E6="","",'Security & Compliance'!E6) | F41: =IF('Security & Compliance'!F6="","",'Security & Compliance'!F6) | G41: =IF('Security & Compliance'!G6="","",'Security & Compliance'!G6)
A42: =IF('Security & Compliance'!A7="","",'Security & Compliance'!A7) | B42: =IF('Security & Compliance'!B7="","",'Security & Compliance'!B7) | C42: =IF('Security & Compliance'!C7="","",'Security & Compliance'!C7) | D42: =IF('Security & Compliance'!D7="","",'Security & Compliance'!D7) | E42: =IF('Security & Compliance'!E7="","",'Security & Compliance'!E7) | F42: =IF('Security & Compliance'!F7="","",'Security & Compliance'!F7) | G42: =IF('Security & Compliance'!G7="","",'Security & Compliance'!G7)
A43: =IF('Security & Compliance'!A8="","",'Security & Compliance'!A8) | B43: =IF('Security & Compliance'!B8="","",'Security & Compliance'!B8) | C43: =IF('Security & Compliance'!C8="","",'Security & Compliance'!C8) | D43: =IF('Security & Compliance'!D8="","",'Security & Compliance'!D8) | E43: =IF('Security & Compliance'!E8="","",'Security & Compliance'!E8) | F43: =IF('Security & Compliance'!F8="","",'Security & Compliance'!F8) | G43: =IF('Security & Compliance'!G8="","",'Security & Compliance'!G8)
A44: =IF('Security & Compliance'!A9="","",'Security & Compliance'!A9) | B44: =IF('Security & Compliance'!B9="","",'Security & Compliance'!B9) | C44: =IF('Security & Compliance'!C9="","",'Security & Compliance'!C9) | D44: =IF('Security & Compliance'!D9="","",'Security & Compliance'!D9) | E44: =IF('Security & Compliance'!E9="","",'Security & Compliance'!E9) | F44: =IF('Security & Compliance'!F9="","",'Security & Compliance'!F9) | G44: =IF('Security & Compliance'!G9="","",'Security & Compliance'!G9)
A45: =IF('Security & Compliance'!A10="","",'Security & Compliance'!A10) | B45: =IF('Security & Compliance'!B10="","",'Security & Compliance'!B10) | C45: =IF('Security & Compliance'!C10="","",'Security & Compliance'!C10) | D45: =IF('Security & Compliance'!D10="","",'Security & Compliance'!D10) | E45: =IF('Security & Compliance'!E10="","",'Security & Compliance'!E10) | F45: =IF('Security & Compliance'!F10="","",'Security & Compliance'!F10) | G45: =IF('Security & Compliance'!G10="","",'Security & Compliance'!G10)
A46: =IF('Security & Compliance'!A11="","",'Security & Compliance'!A11) | B46: =IF('Security & Compliance'!B11="","",'Security & Compliance'!B11) | C46: =IF('Security & Compliance'!C11="","",'Security & Compliance'!C11) | D46: =IF('Security & Compliance'!D11="","",'Security & Compliance'!D11) | E46: =IF('Security & Compliance'!E11="","",'Security & Compliance'!E11) | F46: =IF('Security & Compliance'!F11="","",'Security & Compliance'!F11) | G46: =IF('Security & Compliance'!G11="","",'Security & Compliance'!G11)
A47: =IF('Operations & Support'!A2="","",'Operations & Support'!A2) | B47: =IF('Operations & Support'!B2="","",'Operations & Support'!B2) | C47: =IF('Operations & Support'!C2="","",'Operations & Support'!C2) | D47: =IF('Operations & Support'!D2="","",'Operations & Support'!D2) | E47: =IF('Operations & Support'!E2="","",'Operations & Support'!E2) | F47: =IF('Operations & Support'!F2="","",'Operations & Support'!F2) | G47: =IF('Operations & Support'!G2="","",'Operations & Support'!G2)
A48: =IF('Operations & Support'!A3="","",'Operations & Support'!A3) | B48: =IF('Operations & Support'!B3="","",'Operations & Support'!B3) | C48: =IF('Operations & Support'!C3="","",'Operations & Support'!C3) | D48: =IF('Operations & Support'!D3="","",'Operations & Support'!D3) | E48: =IF('Operations & Support'!E3="","",'Operations & Support'!E3) | F48: =IF('Operations & Support'!F3="","",'Operations & Support'!F3) | G48: =IF('Operations & Support'!G3="","",'Operations & Support'!G3)
...

Sheet Business Requirements
A1: Question ID | B1: Category | C1: Sub-Category | D1: Question | E1: Guidance | F1: Customer Response | G1: Notes
A2: BUS-001 | B2: Business Requirements | C2: Project Information | D2: What is the name of your OpenShift Container Platform project? | E2: Provide internal project reference name | G2: Internal project reference for tracking
A3: BUS-002 | B3: Business Requirements | C3: Project Information | D3: Who is the primary stakeholder for this OpenShift project? | E3: Name, role, and decision-making authority | G3: Main point of contact and decision authority
A4: BUS-003 | B4: Business Requirements | C4: Business Drivers | D4: What application modernization challenges are you trying to solve? | E4: Common challenges: Slow deployment cycles, Inconsistent environments, Infrastructure bottlenecks, Cloud vendor lock-in, Lack of developer self-service, High operational costs | G4: Primary business driver for OpenShift investment
A5: BUS-004 | B5: Business Requirements | C5: Current State | D5: What is your current application deployment workflow? | E5: Describe manual steps, systems involved, and pain points | G5: Current state baseline assessment
A6: BUS-005 | B6: Business Requirements | C6: Application Portfolio | D6: How many applications do you plan to containerize? | E6: Typical ranges: 1-10, 11-50, 51-100, 100+ | G6: Application scope and migration planning
A7: BUS-006 | B7: Business Requirements | C7: Deployment Frequency | D7: How often do you currently deploy applications to production? | E7: Typical frequencies: Daily, Weekly, Monthly, Quarterly, Ad-hoc | G7: Deployment velocity drives CI/CD requirements
A8: BUS-007 | B8: Business Requirements | C8: Objectives | D8: What are your primary goals for implementing OpenShift? | E8: Common goals: Accelerate deployment cycles, Enable developer self-service, Improve resource utilization, Support hybrid cloud, Modernize legacy apps, Reduce infrastructure costs | G8: Business objectives and expected outcomes
A9: BUS-008 | B9: Business Requirements | C9: Success Criteria | D9: How will you measure OpenShift success? | E9: Define KPIs: deployment frequency increase, time-to-market reduction, infrastructure cost savings, developer productivity gains | G9: Success metrics for project evaluation
A10: BUS-009 | B10: Business Requirements | C10: Timeline | D10: What is your expected timeline for OpenShift implementation? | E10: Typical ranges: 0-3 months, 3-6 months, 6-12 months, 12+ months | G10: Project timeline expectations and constraints
A11: BUS-010 | B11: Business Requirements | C11: Budget | D11: What is your approved budget range for this OpenShift solution? | E11: Common ranges: $100K-500K, $500K-1M, $1M-3M, $3M+. Include both infrastructure and services | G11: Budget constraints for solution sizing
A12: BUS-011 | B12: Business Requirements | C12: Future Vision | D12: What is your long-term vision for container platform adoption? | E12: Consider expansion to additional teams, applications, and environments | G12: Future roadmap and scalability planning
A13: BUS-012 | B13: Business Requirements | C13: Growth Projections | D13: How do you expect containerized workload growth over 3 years? | E13: Provide current container count and projected annual growth rate | G13: Scalability requirements and capacity planning

Sheet Technical Requirements
A1: Question ID | B1: Category | C1: Sub-Category | D1: Question | E1: Guidance | F1: Customer Response | G1: Notes
A2: TECH-001 | B2: Technical Requirements | C2: Development Team | D2: How many developers will use the OpenShift platform? | E2: Typical ranges: 1-25, 26-100, 101-500, 500+ | G2: Developer seat count for RBAC and resource quotas
A3: TECH-002 | B3: Technical Requirements | C3: Development Team | D3: What is your team's experience level with Kubernetes and containers? | E3: Experience levels: None - new to containers, Basic - using Docker, Intermediate - some Kubernetes, Advanced - production Kubernetes | G3: Training requirements assessment
A4: TECH-003 | B4: Technical Requirements | C4: Application Specifications | D4: What types of applications will run on OpenShift? | E4: Common types: Web apps, APIs/microservices, Batch jobs, Databases, Message queues, AI/ML workloads, Legacy apps | G4: Workload classification and requirements
A5: TECH-004 | B5: Technical Requirements | C5: Application Architecture | D5: Are your applications monolithic or microservices-based? | E5: Architecture types: Monolithic, Microservices, Mixed, Planning to modernize | G5: Architecture pattern affects cluster design
A6: TECH-005 | B6: Technical Requirements | C6: Technology Stack | D6: What programming languages and frameworks do you use? | E6: Common stacks: Java/Spring, .NET, Node.js, Python, Go, Ruby, PHP | G6: Runtime and build strategy requirements
A7: TECH-006 | B7: Technical Requirements | C7: Database Requirements | D7: What databases will you run on or connect to from OpenShift? | E7: Database types: PostgreSQL, MySQL, MongoDB, Oracle, SQL Server, Redis, Elasticsearch | G7: Stateful workload and storage requirements
A8: TECH-007 | B8: Technical Requirements | C8: Container Registry | D8: Do you need a private container registry? | E8: Options: Use OpenShift integrated registry, External registry (Quay Harbor DockerHub), Hybrid approach | G8: Container image storage and management
A9: TECH-008 | B9: Technical Requirements | C9: Deployment Platform | D9: What is your target deployment platform for OpenShift? | E9: Platform options: Bare metal servers, VMware vSphere, AWS (ROSA), Azure (ARO), Google Cloud, IBM Cloud, Multi-cloud | G9: Infrastructure provider and deployment model
A10: TECH-009 | B10: Technical Requirements | C10: Cluster Sizing | D10: What is your expected OpenShift cluster size? | E10: Sizing categories: Small (3 control + 3 worker nodes), Medium (3 control + 6-12 workers), Large (3 control + 12+ workers), Multi-cluster | G10: Cluster capacity and node count
A11: TECH-010 | B11: Technical Requirements | C11: Compute Requirements | D11: What are your total compute resource requirements? | E11: Specify total vCPUs and RAM needed across all nodes | G11: Infrastructure sizing for workload capacity
A12: TECH-011 | B12: Technical Requirements | C12: Storage Requirements | D12: What are your persistent storage requirements? | E12: Storage types needed: Block storage (RWO), File storage (RWX), Object storage (S3), No persistent storage | G12: Storage class and volume requirements
A13: TECH-012 | B13: Technical Requirements | C13: Storage Volume | D13: What is your estimated total persistent storage capacity? | E13: Typical ranges: 1-10 TB, 10-50 TB, 50-100 TB, 100+ TB | G13: Storage capacity planning and costs
... A21: TECH-020 | B21: Technical Requirements | C21: GitOps | D21: Are you interested in GitOps deployment model? | E21: GitOps tools: ArgoCD (included), Flux, Manual deployment | G21: Application deployment methodology

Sheet Security & Compliance
A1: Question ID | B1: Category | C1: Sub-Category | D1: Question | E1: Guidance | F1: Customer Response | G1: Notes
A2: SEC-001 | B2: Security & Compliance | C2: Security Standards | D2: What security and compliance standards must you meet? | E2: Common standards: SOC 2, ISO 27001, PCI DSS, HIPAA, GDPR, NIST 800-53, FedRAMP, STIGs | G2: Compliance controls and audit requirements
A3: SEC-002 | B3: Security & Compliance | C3: Data Classification | D3: What is the highest data classification level in your applications? | E3: Levels: Public, Internal use, Confidential, Restricted/Regulated | G3: Determines security controls and encryption
A4: SEC-003 | B4: Security & Compliance | C4: Identity Provider | D4: What identity provider do you use for authentication? | E4: Identity providers: Active Directory, LDAP, Okta, Azure AD, Google Workspace, AWS IAM, OAuth/OIDC | G4: SSO and RBAC integration
A5: SEC-004 | B5: Security & Compliance | C5: Access Control | D5: What role-based access control (RBAC) requirements do you have? | E5: RBAC needs: Developer roles, Admin roles, Read-only roles, Custom roles, External user access | G5: Authorization model design
A6: SEC-005 | B6: Security & Compliance | C6: Container Security | D6: What container security scanning do you require? | E6: Security scanning: Image vulnerability scanning, Compliance scanning, Runtime security, Admission control | G6: Security tooling and policies
A7: SEC-006 | B7: Security & Compliance | C7: Network Security | D7: What network security policies are required? | E7: Network policies: Namespace isolation, Ingress/egress rules, Zero-trust networking, Encryption in transit | G7: Network segmentation and controls
A8: SEC-007 | B8: Security & Compliance | C8: Secrets Management | D8: How do you currently manage application secrets and credentials? | E8: Secret management: Kubernetes secrets, HashiCorp Vault, AWS Secrets Manager, Azure Key Vault, CyberArk | G8: Secrets storage and rotation strategy
A9: SEC-008 | B9: Security & Compliance | C9: Certificate Management | D9: What SSL/TLS certificate management requirements do you have? | E9: Certificate needs: Wildcard certs, Per-route certs, Let's Encrypt integration, Corporate CA | G9: Certificate provisioning and renewal
A10: SEC-009 | B10: Security & Compliance | C10: Encryption | D10: What encryption requirements apply? | E10: Encryption needs: Encryption at rest (LUKS), Encryption in transit (TLS), Key management (KMIP) | G10: Data protection and key management
A11: SEC-010 | B11: Security & Compliance | C11: Audit Logging | D11: What audit and logging requirements do you have? | E11: Logging needs: API audit logs, Application logs, Security events, Compliance reporting | G11: Audit trail and compliance reporting

Sheet Operations & Support
A1: Question ID | B1: Category | C1: Sub-Category | D1: Question | E1: Guidance | F1: Customer Response | G1: Notes
A2: OPS-001 | B2: Operations & Support | C2: Monitoring | D2: What monitoring and observability tools do you use? | E2: Monitoring tools: Prometheus/Grafana (included), Datadog, New Relic, Dynatrace, Splunk, ELK Stack | G2: Platform and application monitoring
A3: OPS-002 | B3: Operations & Support | C3: Logging | D3: What centralized logging solution do you require? | E3: Logging platforms: OpenShift Logging (EFK), Splunk, Elastic, Datadog, CloudWatch | G3: Log aggregation and retention
A4: OPS-003 | B4: Operations & Support | C4: Alerting | D4: What alerting and incident management tools do you use? | E4: Alert systems: Alertmanager (included), PagerDuty, OpsGenie, VictorOps, Email/Slack | G4: Incident response and on-call
A5: OPS-004 | B5: Operations & Support | C5: Backup & Recovery | D5: What backup and recovery procedures are required? | E5: Backup scope: etcd cluster data, Persistent volumes, Application configs, Disaster recovery testing | G5: Data protection and recovery strategy
A6: OPS-005 | B6: Operations & Support | C6: Upgrade Strategy | D6: How do you plan to handle OpenShift version upgrades? | E6: Upgrade approaches: Automated rolling upgrades, Scheduled maintenance windows, Blue-green cluster strategy | G6: Platform lifecycle management
A7: OPS-006 | B7: Operations & Support | C7: Support Coverage | D7: What support coverage do you require? | E7: Support levels: Business hours (8x5), Extended (24x5), Full (24x7), Self-support | G7: Support staffing and SLA requirements
A8: OPS-007 | B8: Operations & Support | C8: Day 2 Operations | D8: Who will manage day-to-day OpenShift operations? | E8: Operations model: Internal platform team, Managed services, Hybrid approach, Vendor support | G8: Operational responsibility and staffing
A9: OPS-008 | B9: Operations & Support | C9: Training Needs | D9: What training do your teams need for OpenShift? | E9: Training types: Developer training, Administrator training, Security training, Architecture training | G9: Skills development and enablement

Sheet Integration Requirements
A1: Question ID | B1: Category | C1: Sub-Category | D1: Question | E1: Guidance | F1: Customer Response | G1: Notes
A2: INT-001 | B2: Integration Requirements | C2: External Systems | D2: What external systems need to integrate with applications on OpenShift? | E2: Integration types: Databases, APIs, Message queues, Legacy systems, SaaS applications | G2: Integration scope and complexity
A3: INT-002 | B3: Integration Requirements | C3: Service Dependencies | D3: What shared services do applications require? | E3: Shared services: LDAP/AD, DNS, SMTP, Proxy servers, NTP, Syslog | G3: Infrastructure dependency mapping
A4: INT-003 | B4: Integration Requirements | C4: API Management | D4: Do you need API management capabilities? | E4: API management: 3scale API Management (Red Hat), Kong, Apigee, AWS API Gateway, None | G4: API gateway and developer portal needs
A5: INT-004 | B5: Integration Requirements | C5: Message Queues | D5: What messaging systems do you use? | E5: Message systems: Kafka, RabbitMQ, ActiveMQ, AWS SQS/SNS, Azure Service Bus | G5: Async messaging and event streaming
A6: INT-005 | B6: Integration Requirements | C6: Observability Integration | D6: How should OpenShift integrate with existing monitoring/logging? | E6: Integration methods: Forward logs to existing SIEM, Export metrics to enterprise monitoring, Standalone monitoring | G6: Enterprise observability platform integration

Sheet Cost & Licensing
A1: Question ID | B1: Category | C1: Sub-Category | D1: Question | E1: Guidance | F1: Customer Response | G1: Notes
A2: COST-001 | B2: Cost & Licensing | C2: Licensing Model | D2: What OpenShift licensing model do you prefer? | E2: License types: OpenShift Platform (base), OpenShift Platform Plus (includes ACM ODF ACS), Core-based, Cluster-based | G2: Licensing structure and features
A3: COST-002 | B3: Cost & Licensing | C3: Subscription Term | D3: What subscription term do you prefer? | E3: Terms: Annual subscription, 3-year commitment, Enterprise Agreement | G3: Contract term and pricing
A4: COST-003 | B4: Cost & Licensing | C4: Infrastructure Costs | D4: Do you have existing infrastructure or need new hardware/VMs? | E4: Infrastructure: Existing capacity available, Need new servers/VMs, Cloud infrastructure (IaaS), Managed service (ROSA/ARO) | G4: Infrastructure investment requirements
A5: COST-004 | B5: Cost & Licensing | C5: Professional Services | D5: What professional services do you need? | E5: Services: Architecture design, Implementation, Migration assistance, Training, Ongoing support | G5: Services scope and budget allocation
A6: COST-005 | B6: Cost & Licensing | C6: Cost Optimization | D6: What are your priorities for cost optimization? | E6: Cost priorities: Right-sizing workloads, Autoscaling, Spot/preemptible instances, Reserved capacity, Multi-tenancy | G6: Cost management strategy
