Workbook

Sheet Cover
B3: Configuration Parameters
B5: Generated: | C5: November 28, 2025
B6: Solution: | C6: Enterprise Platform
B7: Customer: | C7: [Customer Name]
B8: Version: | C8: 1.0
B9: Status: | C9: Draft
C12: eoframework.org

Sheet All Parameters (Read Only)
A1: Total Parameters | B1: Categories | C1: Required | D1: Confidential/Secret
A2: 38 | B2: 7 | C2: 32 | D2: 12
A4: Parameter Name | B4: Category | C4: Environment | D4: Default Value | E4: Description | F4: Required | G4: Data Type | H4: Validation Rules | I4: Security Level | J4: Owner Team | K4: Dependencies | L4: Notes | M4: Last Updated
A5: =IF('Application'!A3="","",'Application'!A3) | B5: Application | C5: =IF('Application'!B3="","",'Application'!B3) | D5: =IF('Application'!C3="","",'Application'!C3) | E5: =IF('Application'!D3="","",'Application'!D3) | F5: =IF('Application'!E3="","",'Application'!E3) | G5: =IF('Application'!F3="","",'Application'!F3) | H5: =IF('Application'!G3="","",'Application'!G3) | I5: =IF('Application'!H3="","",'Application'!H3) | J5: =IF('Application'!I3="","",'Application'!I3) | ... M5: =IF('Application'!L3="","",'Application'!L3)
A6: =IF('Application'!A4="","",'Application'!A4) | B6: Application | C6: =IF('Application'!B4="","",'Application'!B4) | D6: =IF('Application'!C4="","",'Application'!C4) | E6: =IF('Application'!D4="","",'Application'!D4) | F6: =IF('Application'!E4="","",'Application'!E4) | G6: =IF('Application'!F4="","",'Application'!F4) | H6: =IF('Application'!G4="","",'Application'!G4) | I6: =IF('Application'!H4="","",'Application'!H4) | J6: =IF('Application'!I4="","",'Application'!I4) | ... M6: =IF('Application'!L4="","",'Application'!L4)
A7: =IF('Application'!A5="","",'Application'!A5) | B7: Application | C7: =IF('Application'!B5="","",'Application'!B5) | D7: =IF('Application'!C5="","",'Application'!C5) | E7: =IF('Application'!D5="","",'Application'!D5) | F7: =IF('Application'!E5="","",'Application'!E5) | G7: =IF('Application'!F5="","",'Application'!F5) | H7: =IF('Application'!G5="","",'Application'!G5) | I7: =IF('Application'!H5="","",'Application'!H5) | J7: =IF('Application'!I5="","",'Application'!I5) | ... M7: =IF('Application'!L5="","",'Application'!L5)
A8: =IF('Application'!A6="","",'Application'!A6) | B8: Application | C8: =IF('Application'!B6="","",'Application'!B6) | D8: =IF('Application'!C6="","",'Application'!C6) | E8: =IF('Application'!D6="","",'Application'!D6) | F8: =IF('Application'!E6="","",'Application'!E6) | G8: =IF('Application'!F6="","",'Application'!F6) | H8: =IF('Application'!G6="","",'Application'!G6) | I8: =IF('Application'!H6="","",'Application'!H6) | J8: =IF('Application'!I6="","",'Application'!I6) | ... M8: =IF('Application'!L6="","",'Application'!L6)
A9: =IF('Application'!A7="","",'Application'!A7) | B9: Application | C9: =IF('Application'!B7="","",'Application'!B7) | D9: =IF('Application'!C7="","",'Application'!C7) | E9: =IF('Application'!D7="","",'Application'!D7) | F9: =IF('Application'!E7="","",'Application'!E7) | G9: =IF('Application'!F7="","",'Application'!F7) | H9: =IF('Application'!G7="","",'Application'!G7) | I9: =IF('Application'!H7="","",'Application'!H7) | J9: =IF('Application'!I7="","",'Application'!I7) | ... M9: =IF('Application'!L7="","",'Application'!L7)
A10: =IF('Platform'!A3="","",'Platform'!A3) | B10: Platform | C10: =IF('Platform'!B3="","",'Platform'!B3) | D10: =IF('Platform'!C3="","",'Platform'!C3) | E10: =IF('Platform'!D3="","",'Platform'!D3) | F10: =IF('Platform'!E3="","",'Platform'!E3) | G10: =IF('Platform'!F3="","",'Platform'!F3) | H10: =IF('Platform'!G3="","",'Platform'!G3) | I10: =IF('Platform'!H3="","",'Platform'!H3) | J10: =IF('Platform'!I3="","",'Platform'!I3) | ... M10: =IF('Platform'!L3="","",'Platform'!L3)
A11: =IF('Platform'!A4="","",'Platform'!A4) | B11: Platform | C11: =IF('Platform'!B4="","",'Platform'!B4) | D11: =IF('Platform'!C4="","",'Platform'!C4) | E11: =IF('Platform'!D4="","",'Platform'!D4) | F11: =IF('Platform'!E4="","",'Platform'!E4) | G11: =IF('Platform'!F4="","",'Platform'!F4) | H11: =IF('Platform'!G4="","",'Platform'!G4) | I11: =IF('Platform'!H4="","",'Platform'!H4) | J11: =IF('Platform'!I4="","",'Platform'!I4) | ... M11: =IF('Platform'!L4="","",'Platform'!L4)
A12: =IF('Platform'!A5="","",'Platform'!A5) | B12: Platform | C12: =IF('Platform'!B5="","",'Platform'!B5) | D12: =IF('Platform'!C5="","",'Platform'!C5) | E12: =IF('Platform'!D5="","",'Platform'!D5) | F12: =IF('Platform'!E5="","",'Platform'!E5) | G12: =IF('Platform'!F5="","",'Platform'!F5) | H12: =IF('Platform'!G5="","",'Platform'!G5) | I12: =IF('Platform'!H5="","",'Platform'!H5) | J12: =IF('Platform'!I5="","",'Platform'!I5) | ... M12: =IF('Platform'!L5="","",'Platform'!L5)
A13: =IF('Platform'!A6="","",'Platform'!A6) | B13: Platform | C13: =IF('Platform'!B6="","",'Platform'!B6) | D13: =IF('Platform'!C6="","",'Platform'!C6) | E13: =IF('Platform'!D6="","",'Platform'!D6) | F13: =IF('Platform'!E6="","",'Platform'!E6) | G13: =IF('Platform'!F6="","",'Platform'!F6) | H13: =IF('Platform'!G6="","",'Platform'!G6) | I13: =IF('Platform'!H6="","",'Platform'!H6) | J13: =IF('Platform'!I6="","",'Platform'!I6) | ... M13: =IF('Platform'!L6="","",'Platform'!L6)
A14: =IF('Platform'!A7="","",'Platform'!A7) | B14: Platform | C14: =IF('Platform'!B7="","",'Platform'!B7) | D14: =IF('Platform'!C7="","",'Platform'!C7) | E14: =IF('Platform'!D7="","",'Platform'!D7) | F14: =IF('Platform'!E7="","",'Platform'!E7) | G14: =IF('Platform'!F7="","",'Platform'!F7) | H14: =IF('Platform'!G7="","",'Platform'!G7) | I14: =IF('Platform'!H7="","",'Platform'!H7) | J14: =IF('Platform'!I7="","",'Platform'!I7) | ... M14: =IF('Platform'!L7="","",'Platform'!L7)
A15: =IF('Platform'!A8="","",'Platform'!A8) | B15: Platform | C15: =IF('Platform'!B8="","",'Platform'!B8) | D15: =IF('Platform'!C8="","",'Platform'!C8) | E15: =IF('Platform'!D8="","",'Platform'!D8) | F15: =IF('Platform'!E8="","",'Platform'!E8) | G15: =IF('Platform'!F8="","",'Platform'!F8) | H15: =IF('Platform'!G8="","",'Platform'!G8) | I15: =IF('Platform'!H8="","",'Platform'!H8) | J15: =IF('Platform'!I8="","",'Platform'!I8) | ... M15: =IF('Platform'!L8="","",'Platform'!L8)
A16: =IF('Platform'!A9="","",'Platform'!A9) | B16: Platform | C16: =IF('Platform'!B9="","",'Platform'!B9) | D16: =IF('Platform'!C9="","",'Platform'!C9) | E16: =IF('Platform'!D9="","",'Platform'!D9) | F16: =IF('Platform'!E9="","",'Platform'!E9) | G16: =IF('Platform'!F9="","",'Platform'!F9) | H16: =IF('Platform'!G9="","",'Platform'!G9) | I16: =IF('Platform'!H9="","",'Platform'!H9) | J16: =IF('Platform'!I9="","",'Platform'!I9) | ... M16: =IF('Platform'!L9="","",'Platform'!L9)
A17: =IF('Platform'!A10="","",'Platform'!A10) | B17: Platform | C17: =IF('Platform'!B10="","",'Platform'!B10) | D17: =IF('Platform'!C10="","",'Platform'!C10) | E17: =IF('Platform'!D10="","",'Platform'!D10) | F17: =IF('Platform'!E10="","",'Platform'!E10) | G17: =IF('Platform'!F10="","",'Platform'!F10) | H17: =IF('Platform'!G10="","",'Platform'!G10) | I17: =IF('Platform'!H10="","",'Platform'!H10) | J17: =IF('Platform'!I10="","",'Platform'!I10) | ... M17: =IF('Platform'!L10="","",'Platform'!L10)
A18: =IF('Platform'!A11="","",'Platform'!A11) | B18: Platform | C18: =IF('Platform'!B11="","",'Platform'!B11) | D18: =IF('Platform'!C11="","",'Platform'!C11) | E18: =IF('Platform'!D11="","",'Platform'!D11) | F18: =IF('Platform'!E11="","",'Platform'!E11) | G18: =IF('Platform'!F11="","",'Platform'!F11) | H18: =IF('Platform'!G11="","",'Platform'!G11) | I18: =IF('Platform'!H11="","",'Platform'!H11) | J18: =IF('Platform'!I11="","",'Platform'!I11) | ... M18: =IF('Platform'!L11="","",'Platform'!L11)
A19: =IF('Platform'!A12="","",'Platform'!A12) | B19: Platform | C19: =IF('Platform'!B12="","",'Platform'!B12) | D19: =IF('Platform'!C12="","",'Platform'!C12) | E19: =IF('Platform'!D12="","",'Platform'!D12) | F19: =IF('Platform'!E12="","",'Platform'!E12) | G19: =IF('Platform'!F12="","",'Platform'!F12) | H19: =IF('Platform'!G12="","",'Platform'!G12) | I19: =IF('Platform'!H12="","",'Platform'!H12) | J19: =IF('Platform'!I12="","",'Platform'!I12) | ... M19: =IF('Platform'!L12="","",'Platform'!L12)
A20: =IF('Platform'!A13="","",'Platform'!A13) | B20: Platform | C20: =IF('Platform'!B13="","",'Platform'!B13) | D20: =IF('Platform'!C13="","",'Platform'!C13) | E20: =IF('Platform'!D13="","",'Platform'!D13) | F20: =IF('Platform'!E13="","",'Platform'!E13) | G20: =IF('Platform'!F13="","",'Platform'!F13) | H20: =IF('Platform'!G13="","",'Platform'!G13) | I20: =IF('Platform'!H13="","",'Platform'!H13) | J20: =IF('Platform'!I13="","",'Platform'!I13) | ... M20: =IF('Platform'!L13="","",'Platform'!L13)
A21: =IF('Platform'!A14="","",'Platform'!A14) | B21: Platform | C21: =IF('Platform'!B14="","",'Platform'!B14) | D21: =IF('Platform'!C14="","",'Platform'!C14) | E21: =IF('Platform'!D14="","",'Platform'!D14) | F21: =IF('Platform'!E14="","",'Platform'!E14) | G21: =IF('Platform'!F14="","",'Platform'!F14) | H21: =IF('Platform'!G14="","",'Platform'!G14) | I21: =IF('Platform'!H14="","",'Platform'!H14) | J21: =IF('Platform'!I14="","",'Platform'!I14) | ... M21: =IF('Platform'!L14="","",'Platform'!L14)
A22: =IF('Platform'!A15="","",'Platform'!A15) | B22: Platform | C22: =IF('Platform'!B15="","",'Platform'!B15) | D22: =IF('Platform'!C15="","",'Platform'!C15) | E22: =IF('Platform'!D15="","",'Platform'!D15) | F22: =IF('Platform'!E15="","",'Platform'!E15) | G22: =IF('Platform'!F15="","",'Platform'!F15) | H22: =IF('Platform'!G15="","",'Platform'!G15) | I22: =IF('Platform'!H15="","",'Platform'!H15) | J22: =IF('Platform'!I15="","",'Platform'!I15) | ... M22: =IF('Platform'!L15="","",'Platform'!L15)
A23: =IF('Security'!A3="","",'Security'!A3) | B23: Security | C23: =IF('Security'!B3="","",'Security'!B3) | D23: =IF('Security'!C3="","",'Security'!C3) | E23: =IF('Security'!D3="","",'Security'!D3) | F23: =IF('Security'!E3="","",'Security'!E3) | G23: =IF('Security'!F3="","",'Security'!F3) | H23: =IF('Security'!G3="","",'Security'!G3) | I23: =IF('Security'!H3="","",'Security'!H3) | J23: =IF('Security'!I3="","",'Security'!I3) | ... M23: =IF('Security'!L3="","",'Security'!L3)
A24: =IF('Security'!A4="","",'Security'!A4) | B24: Security | C24: =IF('Security'!B4="","",'Security'!B4) | D24: =IF('Security'!C4="","",'Security'!C4) | E24: =IF('Security'!D4="","",'Security'!D4) | F24: =IF('Security'!E4="","",'Security'!E4) | G24: =IF('Security'!F4="","",'Security'!F4) | H24: =IF('Security'!G4="","",'Security'!G4) | I24: =IF('Security'!H4="","",'Security'!H4) | J24: =IF('Security'!I4="","",'Security'!I4) | ... M24: =IF('Security'!L4="","",'Security'!L4)
A25: =IF('Security'!A5="","",'Security'!A5) | B25: Security | C25: =IF('Security'!B5="","",'Security'!B5) | D25: =IF('Security'!C5="","",'Security'!C5) | E25: =IF('Security'!D5="","",'Security'!D5) | F25: =IF('Security'!E5="","",'Security'!E5) | G25: =IF('Security'!F5="","",'Security'!F5) | H25: =IF('Security'!G5="","",'Security'!G5) | I25: =IF('Security'!H5="","",'Security'!H5) | J25: =IF('Security'!I5="","",'Security'!I5) | ... M25: =IF('Security'!L5="","",'Security'!L5)
A26: =IF('Security'!A6="","",'Security'!A6) | B26: Security | C26: =IF('Security'!B6="","",'Security'!B6) | D26: =IF('Security'!C6="","",'Security'!C6) | E26: =IF('Security'!D6="","",'Security'!D6) | F26: =IF('Security'!E6="","",'Security'!E6) | G26: =IF('Security'!F6="","",'Security'!F6) | H26: =IF('Security'!G6="","",'Security'!G6) | I26: =IF('Security'!H6="","",'Security'!H6) | J26: =IF('Security'!I6="","",'Security'!I6) | ... M26: =IF('Security'!L6="","",'Security'!L6)
A27: =IF('Security'!A7="","",'Security'!A7) | B27: Security | C27: =IF('Security'!B7="","",'Security'!B7) | D27: =IF('Security'!C7="","",'Security'!C7) | E27: =IF('Security'!D7="","",'Security'!D7) | F27: =IF('Security'!E7="","",'Security'!E7) | G27: =IF('Security'!F7="","",'Security'!F7) | H27: =IF('Security'!G7="","",'Security'!G7) | I27: =IF('Security'!H7="","",'Security'!H7) | J27: =IF('Security'!I7="","",'Security'!I7) | ... M27: =IF('Security'!L7="","",'Security'!L7)
A28: =IF('Monitoring'!A3="","",'Monitoring'!A3) | B28: Monitoring | C28: =IF('Monitoring'!B3="","",'Monitoring'!B3) | D28: =IF('Monitoring'!C3="","",'Monitoring'!C3) | E28: =IF('Monitoring'!D3="","",'Monitoring'!D3) | F28: =IF('Monitoring'!E3="","",'Monitoring'!E3) | G28: =IF('Monitoring'!F3="","",'Monitoring'!F3) | H28: =IF('Monitoring'!G3="","",'Monitoring'!G3) | I28: =IF('Monitoring'!H3="","",'Monitoring'!H3) | J28: =IF('Monitoring'!I3="","",'Monitoring'!I3) | ... M28: =IF('Monitoring'!L3="","",'Monitoring'!L3)
A29: =IF('Monitoring'!A4="","",'Monitoring'!A4) | B29: Monitoring | C29: =IF('Monitoring'!B4="","",'Monitoring'!B4) | D29: =IF('Monitoring'!C4="","",'Monitoring'!C4) | E29: =IF('Monitoring'!D4="","",'Monitoring'!D4) | F29: =IF('Monitoring'!E4="","",'Monitoring'!E4) | G29: =IF('Monitoring'!F4="","",'Monitoring'!F4) | H29: =IF('Monitoring'!G4="","",'Monitoring'!G4) | I29: =IF('Monitoring'!H4="","",'Monitoring'!H4) | J29: =IF('Monitoring'!I4="","",'Monitoring'!I4) | ... M29: =IF('Monitoring'!L4="","",'Monitoring'!L4)
A30: =IF('Monitoring'!A5="","",'Monitoring'!A5) | B30: Monitoring | C30: =IF('Monitoring'!B5="","",'Monitoring'!B5) | D30: =IF('Monitoring'!C5="","",'Monitoring'!C5) | E30: =IF('Monitoring'!D5="","",'Monitoring'!D5) | F30: =IF('Monitoring'!E5="","",'Monitoring'!E5) | G30: =IF('Monitoring'!F5="","",'Monitoring'!F5) | H30: =IF('Monitoring'!G5="","",'Monitoring'!G5) | I30: =IF('Monitoring'!H5="","",'Monitoring'!H5) | J30: =IF('Monitoring'!I5="","",'Monitoring'!I5) | ... M30: =IF('Monitoring'!L5="","",'Monitoring'!L5)
A31: =IF('Monitoring'!A6="","",'Monitoring'!A6) | B31: Monitoring | C31: =IF('Monitoring'!B6="","",'Monitoring'!B6) | D31: =IF('Monitoring'!C6="","",'Monitoring'!C6) | E31: =IF('Monitoring'!D6="","",'Monitoring'!D6) | F31: =IF('Monitoring'!E6="","",'Monitoring'!E6) | G31: =IF('Monitoring'!F6="","",'Monitoring'!F6) | H31: =IF('Monitoring'!G6="","",'Monitoring'!G6) | I31: =IF('Monitoring'!H6="","",'Monitoring'!H6) | J31: =IF('Monitoring'!I6="","",'Monitoring'!I6) | ... M31: =IF('Monitoring'!L6="","",'Monitoring'!L6)
A32: =IF('Network'!A3="","",'Network'!A3) | B32: Network | C32: =IF('Network'!B3="","",'Network'!B3) | D32: =IF('Network'!C3="","",'Network'!C3) | E32: =IF('Network'!D3="","",'Network'!D3) | F32: =IF('Network'!E3="","",'Network'!E3) | G32: =IF('Network'!F3="","",'Network'!F3) | H32: =IF('Network'!G3="","",'Network'!G3) | I32: =IF('Network'!H3="","",'Network'!H3) | J32: =IF('Network'!I3="","",'Network'!I3) | ... M32: =IF('Network'!L3="","",'Network'!L3)
A33: =IF('Network'!A4="","",'Network'!A4) | B33: Network | C33: =IF('Network'!B4="","",'Network'!B4) | D33: =IF('Network'!C4="","",'Network'!C4) | E33: =IF('Network'!D4="","",'Network'!D4) | F33: =IF('Network'!E4="","",'Network'!E4) | G33: =IF('Network'!F4="","",'Network'!F4) | H33: =IF('Network'!G4="","",'Network'!G4) | I33: =IF('Network'!H4="","",'Network'!H4) | J33: =IF('Network'!I4="","",'Network'!I4) | ... M33: =IF('Network'!L4="","",'Network'!L4)
A34: =IF('Network'!A5="","",'Network'!A5) | B34: Network | C34: =IF('Network'!B5="","",'Network'!B5) | D34: =IF('Network'!C5="","",'Network'!C5) | E34: =IF('Network'!D5="","",'Network'!D5) | F34: =IF('Network'!E5="","",'Network'!E5) | G34: =IF('Network'!F5="","",'Network'!F5) | H34: =IF('Network'!G5="","",'Network'!G5) | I34: =IF('Network'!H5="","",'Network'!H5) | J34: =IF('Network'!I5="","",'Network'!I5) | ... M34: =IF('Network'!L5="","",'Network'!L5)
A35: =IF('Network'!A6="","",'Network'!A6) | B35: Network | C35: =IF('Network'!B6="","",'Network'!B6) | D35: =IF('Network'!C6="","",'Network'!C6) | E35: =IF('Network'!D6="","",'Network'!D6) | F35: =IF('Network'!E6="","",'Network'!E6) | G35: =IF('Network'!F6="","",'Network'!F6) | H35: =IF('Network'!G6="","",'Network'!G6) | I35: =IF('Network'!H6="","",'Network'!H6) | J35: =IF('Network'!I6="","",'Network'!I6) | ... M35: =IF('Network'!L6="","",'Network'!L6)
A36: =IF('Integration'!A3="","",'Integration'!A3) | B36: Integration | C36: =IF('Integration'!B3="","",'Integration'!B3) | D36: =IF('Integration'!C3="","",'Integration'!C3) | E36: =IF('Integration'!D3="","",'Integration'!D3) | F36: =IF('Integration'!E3="","",'Integration'!E3) | G36: =IF('Integration'!F3="","",'Integration'!F3) | H36: =IF('Integration'!G3="","",'Integration'!G3) | I36: =IF('Integration'!H3="","",'Integration'!H3) | J36: =IF('Integration'!I3="","",'Integration'!I3) | ... M36: =IF('Integration'!L3="","",'Integration'!L3)
A37: =IF('Integration'!A4="","",'Integration'!A4) | B37: Integration | C37: =IF('Integration'!B4="","",'Integration'!B4) | D37: =IF('Integration'!C4="","",'Integration'!C4) | E37: =IF('Integration'!D4="","",'Integration'!D4) | F37: =IF('Integration'!E4="","",'Integration'!E4) | G37: =IF('Integration'!F4="","",'Integration'!F4) | H37: =IF('Integration'!G4="","",'Integration'!G4) | I37: =IF('Integration'!H4="","",'Integration'!H4) | J37: =IF('Integration'!I4="","",'Integration'!I4) | ... M37: =IF('Integration'!L4="","",'Integration'!L4)
A38: =IF('Integration'!A5="","",'Integration'!A5) | B38: Integration | C38: =IF('Integration'!B5="","",'Integration'!B5) | D38: =IF('Integration'!C5="","",'Integration'!C5) | E38: =IF('Integration'!D5="","",'Integration'!D5) | F38: =IF('Integration'!E5="","",'Integration'!E5) | G38: =IF('Integration'!F5="","",'Integration'!F5) | H38: =IF('Integration'!G5="","",'Integration'!G5) | I38: =IF('Integration'!H5="","",'Integration'!H5) | J38: =IF('Integration'!I5="","",'Integration'!I5) | ... M38: =IF('Integration'!L5="","",'Integration'!L5)
A39: =IF('Integration'!A6="","",'Integration'!A6) | B39: Integration | C39: =IF('Integration'!B6="","",'Integration'!B6) | D39: =IF('Integration'!C6="","",'Integration'!C6) | E39: =IF('Integration'!D6="","",'Integration'!D6) | F39: =IF('Integration'!E6="","",'Integration'!E6) | G39: =IF('Integration'!F6="","",'Integration'!F6) | H39: =IF('Integration'!G6="","",'Integration'!G6) | I39: =IF('Integration'!H6="","",'Integration'!H6) | J39: =IF('Integration'!I6="","",'Integration'!I6) | ... M39: =IF('Integration'!L6="","",'Integration'!L6)
A40: =IF('Integration'!A7="","",'Integration'!A7) | B40: Integration | C40: =IF('Integration'!B7="","",'Integration'!B7) | D40: =IF('Integration'!C7="","",'Integration'!C7) | E40: =IF('Integration'!D7="","",'Integration'!D7) | F40: =IF('Integration'!E7="","",'Integration'!E7) | G40: =IF('Integration'!F7="","",'Integration'!F7) | H40: =IF('Integration'!G7="","",'Integration'!G7) | I40: =IF('Integration'!H7="","",'Integration'!H7) | J40: =IF('Integration'!I7="","",'Integration'!I7) | ... M40: =IF('Integration'!L7="","",'Integration'!L7)
A41: =IF('Integration'!A8="","",'Integration'!A8) | B41: Integration | C41: =IF('Integration'!B8="","",'Integration'!B8) | D41: =IF('Integration'!C8="","",'Integration'!C8) | E41: =IF('Integration'!D8="","",'Integration'!D8) | F41: =IF('Integration'!E8="","",'Integration'!E8) | G41: =IF('Integration'!F8="","",'Integration'!F8) | H41: =IF('Integration'!G8="","",'Integration'!G8) | I41: =IF('Integration'!H8="","",'Integration'!H8) | J41: =IF('Integration'!I8="","",'Integration'!I8) | ... M41: =IF('Integration'!L8="","",'Integration'!L8)
...

Sheet Application
A1: Application Parameters
A2: Parameter Name | B2: Environment | C2: Default Value | D2: Description | E2: Required | F2: Data Type | G2: Validation Rules | H2: Security Level | I2: Owner Team | J2: Dependencies | K2: Notes | L2: Last Updated
A3: AZURE_SUBSCRIPTION_ID | B3: All | C3: [********] | D3: Azure subscription identifier for DevOps resources | E3: Yes | F3: String | G3: GUID format | H3: Confidential | I3: Infrastructure | J3: None | K3: Required for all Azure deployments | L3: [DATE]
A4: AZURE_TENANT_ID | B4: All | C4: [********] | D4: Azure AD tenant identifier for authentication | E4: Yes | F4: String | G4: GUID format | H4: Confidential | I4: Infrastructure | J4: Azure AD | K4: Required for SSO integration | L4: [DATE]
A5: AZURE_REGION | B5: All | C5: eastus | D5: Primary Azure region for resource deployment | E5: Yes | F5: String | G5: Valid Azure region | H5: Public | I5: Infrastructure | J5: None | K5: Must support all required services | L5: [DATE]
A6: SOLUTION_PREFIX | B6: All | C6: devops | D6: Prefix for all Azure resource naming | E6: Yes | F6: String | G6: 3-8 lowercase alphanumeric | H6: Public | I6: Infrastructure | J6: None | K6: Used in resource naming convention | L6: [DATE]
A7: RESOURCE_GROUP_NAME | B7: All | C7: rg-devops-[env]-001 | D7: Resource group for DevOps platform resources | E7: Yes | F7: String | G7: Azure naming rules | H7: Public | I7: Infrastructure | J7: Subscription | K7: Contains all platform components | L7: [DATE]

Sheet Platform
A1: Platform Parameters
A2: Parameter Name | B2: Environment | C2: Default Value | D2: Description | E2: Required | F2: Data Type | G2: Validation Rules | H2: Security Level | I2: Owner Team | J2: Dependencies | K2: Notes | L2: Last Updated
A3: DEVOPS_ORG_NAME | B3: All | C3: contoso-enterprise-devops | D3: Azure DevOps organization name | E3: Yes | F3: String | G3: Valid org name format | H3: Public | I3: DevOps | J3: Azure AD | K3: Primary DevOps organization | L3: [DATE]
A4: DEVOPS_ORG_URL | B4: All | C4: https://dev.azure.com/[ORG] | D4: Azure DevOps organization URL | E4: Yes | F4: String | G4: Valid HTTPS URL | H4: Public | I4: DevOps | J4: DEVOPS_ORG_NAME | K4: Organization access URL | L4: [DATE]
A5: DEVOPS_PROCESS_TEMPLATE | B5: All | C5: Agile | D5: Azure DevOps process template | E5: Yes | F5: String | G5: Agile|Scrum|CMMI|Basic | H5: Public | I5: DevOps | J5: None | K5: Default process for new projects | L5: [DATE]
A6: DEVOPS_PARALLEL_JOBS_HOSTED | B6: All | C6: 10 | D6: Microsoft-hosted parallel job count | E6: Yes | F6: Integer | G6: 1-100 | H6: Public | I6: DevOps | J6: None | K6: Concurrent build capacity | L6: [DATE]
A7: DEVOPS_PARALLEL_JOBS_SELF | B7: All | C7: 5 | D7: Self-hosted parallel job count | E7: Yes | F7: Integer | G7: 1-50 | H7: Public | I7: DevOps | J7: None | K7: Custom agent capacity | L7: [DATE]
A8: ACR_NAME | B8: All | C8: acrdevops[env]001 | D8: Azure Container Registry name | E8: Yes | F8: String | G8: Azure naming rules | H8: Public | I8: DevOps | J8: Resource Group | K8: Container image storage | L8: [DATE]
A9: ACR_SKU | B9: All | C9: Premium | D9: Container Registry pricing tier | E9: Yes | F9: String | G9: Basic|Standard|Premium | H9: Public | I9: DevOps | J9: None | K9: Premium for geo-replication | L9: [DATE]
A10: AKS_CLUSTER_NAME | B10: All | C10: aks-devops-[env]-001 | D10: Azure Kubernetes Service cluster name | E10: Yes | F10: String | G10: Azure naming rules | H10: Public | I10: DevOps | J10: Resource Group | K10: Container orchestration platform | L10: [DATE]
A11: AKS_NODE_COUNT | B11: Development | C11: 3 | D11: Initial AKS node count for development | E11: Yes | F11: Integer | G11: 1-10 | H11: Public | I11: DevOps | J11: None | K11: Minimum nodes for dev workloads | L11: [DATE]
A12: AKS_NODE_COUNT | B12: Production | C12: 5 | D12: Initial AKS node count for production | E12: Yes | F12: Integer | G12: 3-20 | H12: Public | I12: DevOps | J12: None | K12: Production node baseline | L12: [DATE]
A13: AKS_NODE_SIZE | B13: All | C13: Standard_D4s_v3 | D13: AKS node VM size | E13: Yes | F13: String | G13: Valid VM size | H13: Public | I13: DevOps | J13: None | K13: 4 vCPU 16GB RAM nodes | L13: [DATE]
... A15: AKS_AUTOSCALE_MAX | B15: Production | C15: 10 | D15: Maximum nodes for autoscaling | E15: Yes | F15: Integer | G15: 5-50 | H15: Public | I15: DevOps | J15: AKS_CLUSTER_NAME | K15: Autoscaler maximum | L15: [DATE]

Sheet Security
A1: Security Parameters
A2: Parameter Name | B2: Environment | C2: Default Value | D2: Description | E2: Required | F2: Data Type | G2: Validation Rules | H2: Security Level | I2: Owner Team | J2: Dependencies | K2: Notes | L2: Last Updated
A3: ACR_VULNERABILITY_SCAN | B3: All | C3: true | D3: Enable container vulnerability scanning | E3: Yes | F3: Boolean | G3: true|false | H3: Public | I3: Security | J3: ACR_NAME | K3: Security scanning for images | L3: [DATE]
A4: KEYVAULT_NAME | B4: All | C4: [********] | D4: Key Vault for secrets management | E4: Yes | F4: String | G4: Azure naming rules | H4: Confidential | I4: Security | J4: Resource Group | K4: Secrets and certificates | L4: [DATE]
A5: KEYVAULT_SKU | B5: All | C5: standard | D5: Key Vault pricing tier | E5: Yes | F5: String | G5: standard|premium | H5: Public | I5: Security | J5: None | K5: Standard for most scenarios | L5: [DATE]
A6: DEVOPS_ADMIN_GROUP | B6: All | C6: [********] | D6: Azure AD group for DevOps admins | E6: Yes | F6: String | G6: GUID format | H6: Confidential | I6: Security | J6: Azure AD | K6: Project Collection Admin role | L6: [DATE]
A7: DEVOPS_USER_GROUP | B7: All | C7: [********] | D7: Azure AD group for DevOps users | E7: Yes | F7: String | G7: GUID format | H7: Confidential | I7: Security | J7: Azure AD | K7: Basic access level | L7: [DATE]

Sheet Monitoring
A1: Monitoring Parameters
A2: Parameter Name | B2: Environment | C2: Default Value | D2: Description | E2: Required | F2: Data Type | G2: Validation Rules | H2: Security Level | I2: Owner Team | J2: Dependencies | K2: Notes | L2: Last Updated
A3: LOG_ANALYTICS_WORKSPACE | B3: All | C3: law-devops-[env]-001 | D3: Log Analytics workspace name | E3: Yes | F3: String | G3: Azure naming rules | H3: Public | I3: Monitoring | J3: Resource Group | K3: Centralized logging | L3: [DATE]
A4: LOG_ANALYTICS_RETENTION | B4: Development | C4: 30 | D4: Log retention in days for development | E4: Yes | F4: Integer | G4: 30-730 | H4: Public | I4: Monitoring | J4: None | K4: Cost optimization for dev | L4: [DATE]
A5: LOG_ANALYTICS_RETENTION | B5: Production | C5: 90 | D5: Log retention in days for production | E5: Yes | F5: Integer | G5: 30-730 | H5: Public | I5: Monitoring | J5: None | K5: Production retention policy | L5: [DATE]
A6: APP_INSIGHTS_NAME | B6: All | C6: appi-devops-[env]-001 | D6: Application Insights resource name | E6: Yes | F6: String | G6: Azure naming rules | H6: Public | I6: Monitoring | J6: Resource Group | K6: APM for applications | L6: [DATE]

Sheet Network
A1: Network Parameters
A2: Parameter Name | B2: Environment | C2: Default Value | D2: Description | E2: Required | F2: Data Type | G2: Validation Rules | H2: Security Level | I2: Owner Team | J2: Dependencies | K2: Notes | L2: Last Updated
A3: VNET_NAME | B3: All | C3: vnet-devops-[env]-001 | D3: Virtual network name | E3: Yes | F3: String | G3: Azure naming rules | H3: Public | I3: Network | J3: Resource Group | K3: Network isolation | L3: [DATE]
A4: VNET_ADDRESS_SPACE | B4: All | C4: 10.0.0.0/16 | D4: Virtual network address space | E4: Yes | F4: String | G4: Valid CIDR | H4: Public | I4: Network | J4: None | K4: Network address range | L4: [DATE]
A5: SUBNET_AKS | B5: All | C5: 10.0.1.0/23 | D5: AKS subnet address range | E5: Yes | F5: String | G5: Valid CIDR | H5: Public | I5: Network | J5: VNET_NAME | K5: Kubernetes cluster subnet | L5: [DATE]
A6: SUBNET_AGENTS | B6: All | C6: 10.0.3.0/24 | D6: Build agent subnet address range | E6: Yes | F6: String | G6: Valid CIDR | H6: Public | I6: Network | J6: VNET_NAME | K6: Self-hosted agent subnet | L6: [DATE]

Sheet Integration
A1: Integration Parameters
A2: Parameter Name | B2: Environment | C2: Default Value | D2: Description | E2: Required | F2: Data Type | G2: Validation Rules | H2: Security Level | I2: Owner Team | J2: Dependencies | K2: Notes | L2: Last Updated
A3: SONARCLOUD_ORG | B3: All | C3: [********] | D3: SonarCloud organization key | E3: No | F3: String | G3: Valid org key | H3: Confidential | I3: Security | J3: None | K3: Code quality scanning | L3: [DATE]
A4: SONARCLOUD_TOKEN | B4: All | C4: [********] | D4: SonarCloud authentication token | E4: No | F4: String | G4: Valid token | H4: Secret | I4: Security | J4: SONARCLOUD_ORG | K4: Stored in Key Vault | L4: [DATE]
A5: WHITESOURCE_ORG | B5: All | C5: [********] | D5: WhiteSource organization key | E5: No | F5: String | G5: Valid org key | H5: Confidential | I5: Security | J5: None | K5: Dependency scanning | L5: [DATE]
A6: WHITESOURCE_TOKEN | B6: All | C6: [********] | D6: WhiteSource authentication token | E6: No | F6: String | G6: Valid token | H6: Secret | I6: Security | J6: WHITESOURCE_ORG | K6: Stored in Key Vault | L6: [DATE]
A7: TEAMS_WEBHOOK_URL | B7: All | C7: [********] | D7: Microsoft Teams webhook for notifications | E7: No | F7: String | G7: Valid HTTPS URL | H7: Confidential | I7: Integration | J7: None | K7: Pipeline notifications | L7: [DATE]
A8: SERVICENOW_ENDPOINT | B8: All | C8: [********] | D8: ServiceNow instance URL for ticketing | E8: No | F8: String | G8: Valid HTTPS URL | H8: Confidential | I8: Integration | J8: None | K8: ITSM integration | L8: [DATE]

Sheet Operations
A1: Operations Parameters
A2: Parameter Name | B2: Environment | C2: Default Value | D2: Description | E2: Required | F2: Data Type | G2: Validation Rules | H2: Security Level | I2: Owner Team | J2: Dependencies | K2: Notes | L2: Last Updated
A3: ALERT_EMAIL | B3: All | C3: [********] | D3: Email for platform alerts | E3: Yes | F3: String | G3: Valid email format | H3: Confidential | I3: Operations | J3: None | K3: Operations team distribution list | L3: [DATE]
