Workbook

Sheet Cover
B3: Configuration Parameters
B5: Generated: | C5: November 27, 2025
B6: Solution: | C6: Network Analytics
B7: Customer: | C7: [Customer Name]
B8: Version: | C8: 1.0
B9: Status: | C9: Draft
C12: eoframework.org

Sheet All Parameters (Read Only)
A1: Total Parameters | B1: Categories | C1: Required | D1: Confidential/Secret
A2: 63 | B2: 16 | C2: 60 | D2: 29
A4: Parameter Name | B4: Category | C4: Environment | D4: Default Value | E4: Description | F4: Required | G4: Data Type | H4: Validation Rules | I4: Security Level | J4: Owner Team | K4: Dependencies | L4: Notes | M4: Last Updated
A5: =IF('DNA Center'!A3="","",'DNA Center'!A3) | B5: DNA Center | C5: =IF('DNA Center'!B3="","",'DNA Center'!B3) | D5: =IF('DNA Center'!C3="","",'DNA Center'!C3) | E5: =IF('DNA Center'!D3="","",'DNA Center'!D3) | F5: =IF('DNA Center'!E3="","",'DNA Center'!E3) | G5: =IF('DNA Center'!F3="","",'DNA Center'!F3) | H5: =IF('DNA Center'!G3="","",'DNA Center'!G3) | I5: =IF('DNA Center'!H3="","",'DNA Center'!H3) | J5: =IF('DNA Center'!I3="","",'DNA Center'!I3) | ... M5: =IF('DNA Center'!L3="","",'DNA Center'!L3)
A6: =IF('DNA Center'!A4="","",'DNA Center'!A4) | B6: DNA Center | C6: =IF('DNA Center'!B4="","",'DNA Center'!B4) | D6: =IF('DNA Center'!C4="","",'DNA Center'!C4) | E6: =IF('DNA Center'!D4="","",'DNA Center'!D4) | F6: =IF('DNA Center'!E4="","",'DNA Center'!E4) | G6: =IF('DNA Center'!F4="","",'DNA Center'!F4) | H6: =IF('DNA Center'!G4="","",'DNA Center'!G4) | I6: =IF('DNA Center'!H4="","",'DNA Center'!H4) | J6: =IF('DNA Center'!I4="","",'DNA Center'!I4) | ... M6: =IF('DNA Center'!L4="","",'DNA Center'!L4)
A7: =IF('DNA Center'!A5="","",'DNA Center'!A5) | B7: DNA Center | C7: =IF('DNA Center'!B5="","",'DNA Center'!B5) | D7: =IF('DNA Center'!C5="","",'DNA Center'!C5) | E7: =IF('DNA Center'!D5="","",'DNA Center'!D5) | F7: =IF('DNA Center'!E5="","",'DNA Center'!E5) | G7: =IF('DNA Center'!F5="","",'DNA Center'!F5) | H7: =IF('DNA Center'!G5="","",'DNA Center'!G5) | I7: =IF('DNA Center'!H5="","",'DNA Center'!H5) | J7: =IF('DNA Center'!I5="","",'DNA Center'!I5) | ... M7: =IF('DNA Center'!L5="","",'DNA Center'!L5)
A8: =IF('DNA Center'!A6="","",'DNA Center'!A6) | B8: DNA Center | C8: =IF('DNA Center'!B6="","",'DNA Center'!B6) | D8: =IF('DNA Center'!C6="","",'DNA Center'!C6) | E8: =IF('DNA Center'!D6="","",'DNA Center'!D6) | F8: =IF('DNA Center'!E6="","",'DNA Center'!E6) | G8: =IF('DNA Center'!F6="","",'DNA Center'!F6) | H8: =IF('DNA Center'!G6="","",'DNA Center'!G6) | I8: =IF('DNA Center'!H6="","",'DNA Center'!H6) | J8: =IF('DNA Center'!I6="","",'DNA Center'!I6) | ... M8: =IF('DNA Center'!L6="","",'DNA Center'!L6)
A9: =IF('DNA Center'!A7="","",'DNA Center'!A7) | B9: DNA Center | C9: =IF('DNA Center'!B7="","",'DNA Center'!B7) | D9: =IF('DNA Center'!C7="","",'DNA Center'!C7) | E9: =IF('DNA Center'!D7="","",'DNA Center'!D7) | F9: =IF('DNA Center'!E7="","",'DNA Center'!E7) | G9: =IF('DNA Center'!F7="","",'DNA Center'!F7) | H9: =IF('DNA Center'!G7="","",'DNA Center'!G7) | I9: =IF('DNA Center'!H7="","",'DNA Center'!H7) | J9: =IF('DNA Center'!I7="","",'DNA Center'!I7) | ... M9: =IF('DNA Center'!L7="","",'DNA Center'!L7)
A10: =IF('DNA Center'!A8="","",'DNA Center'!A8) | B10: DNA Center | C10: =IF('DNA Center'!B8="","",'DNA Center'!B8) | D10: =IF('DNA Center'!C8="","",'DNA Center'!C8) | E10: =IF('DNA Center'!D8="","",'DNA Center'!D8) | F10: =IF('DNA Center'!E8="","",'DNA Center'!E8) | G10: =IF('DNA Center'!F8="","",'DNA Center'!F8) | H10: =IF('DNA Center'!G8="","",'DNA Center'!G8) | I10: =IF('DNA Center'!H8="","",'DNA Center'!H8) | J10: =IF('DNA Center'!I8="","",'DNA Center'!I8) | ... M10: =IF('DNA Center'!L8="","",'DNA Center'!L8)
A11: =IF('DNA Center'!A9="","",'DNA Center'!A9) | B11: DNA Center | C11: =IF('DNA Center'!B9="","",'DNA Center'!B9) | D11: =IF('DNA Center'!C9="","",'DNA Center'!C9) | E11: =IF('DNA Center'!D9="","",'DNA Center'!D9) | F11: =IF('DNA Center'!E9="","",'DNA Center'!E9) | G11: =IF('DNA Center'!F9="","",'DNA Center'!F9) | H11: =IF('DNA Center'!G9="","",'DNA Center'!G9) | I11: =IF('DNA Center'!H9="","",'DNA Center'!H9) | J11: =IF('DNA Center'!I9="","",'DNA Center'!I9) | ... M11: =IF('DNA Center'!L9="","",'DNA Center'!L9)
A12: =IF('Licensing'!A3="","",'Licensing'!A3) | B12: Licensing | C12: =IF('Licensing'!B3="","",'Licensing'!B3) | D12: =IF('Licensing'!C3="","",'Licensing'!C3) | E12: =IF('Licensing'!D3="","",'Licensing'!D3) | F12: =IF('Licensing'!E3="","",'Licensing'!E3) | G12: =IF('Licensing'!F3="","",'Licensing'!F3) | H12: =IF('Licensing'!G3="","",'Licensing'!G3) | I12: =IF('Licensing'!H3="","",'Licensing'!H3) | J12: =IF('Licensing'!I3="","",'Licensing'!I3) | ... M12: =IF('Licensing'!L3="","",'Licensing'!L3)
A13: =IF('Licensing'!A4="","",'Licensing'!A4) | B13: Licensing | C13: =IF('Licensing'!B4="","",'Licensing'!B4) | D13: =IF('Licensing'!C4="","",'Licensing'!C4) | E13: =IF('Licensing'!D4="","",'Licensing'!D4) | F13: =IF('Licensing'!E4="","",'Licensing'!E4) | G13: =IF('Licensing'!F4="","",'Licensing'!F4) | H13: =IF('Licensing'!G4="","",'Licensing'!G4) | I13: =IF('Licensing'!H4="","",'Licensing'!H4) | J13: =IF('Licensing'!I4="","",'Licensing'!I4) | ... M13: =IF('Licensing'!L4="","",'Licensing'!L4)
A14: =IF('Licensing'!A5="","",'Licensing'!A5) | B14: Licensing | C14: =IF('Licensing'!B5="","",'Licensing'!B5) | D14: =IF('Licensing'!C5="","",'Licensing'!C5) | E14: =IF('Licensing'!D5="","",'Licensing'!D5) | F14: =IF('Licensing'!E5="","",'Licensing'!E5) | G14: =IF('Licensing'!F5="","",'Licensing'!F5) | H14: =IF('Licensing'!G5="","",'Licensing'!G5) | I14: =IF('Licensing'!H5="","",'Licensing'!H5) | J14: =IF('Licensing'!I5="","",'Licensing'!I5) | ... M14: =IF('Licensing'!L5="","",'Licensing'!L5)
A15: =IF('Active Directory'!A3="","",'Active Directory'!A3) | B15: Active Directory | C15: =IF('Active Directory'!B3="","",'Active Directory'!B3) | D15: =IF('Active Directory'!C3="","",'Active Directory'!C3) | E15: =IF('Active Directory'!D3="","",'Active Directory'!D3) | F15: =IF('Active Directory'!E3="","",'Active Directory'!E3) | G15: =IF('Active Directory'!F3="","",'Active Directory'!F3) | H15: =IF('Active Directory'!G3="","",'Active Directory'!G3) | I15: =IF('Active Directory'!H3="","",'Active Directory'!H3) | J15: =IF('Active Directory'!I3="","",'Active Directory'!I3) | ... M15: =IF('Active Directory'!L3="","",'Active Directory'!L3)
A16: =IF('Active Directory'!A4="","",'Active Directory'!A4) | B16: Active Directory | C16: =IF('Active Directory'!B4="","",'Active Directory'!B4) | D16: =IF('Active Directory'!C4="","",'Active Directory'!C4) | E16: =IF('Active Directory'!D4="","",'Active Directory'!D4) | F16: =IF('Active Directory'!E4="","",'Active Directory'!E4) | G16: =IF('Active Directory'!F4="","",'Active Directory'!F4) | H16: =IF('Active Directory'!G4="","",'Active Directory'!G4) | I16: =IF('Active Directory'!H4="","",'Active Directory'!H4) | J16: =IF('Active Directory'!I4="","",'Active Directory'!I4) | ... M16: =IF('Active Directory'!L4="","",'Active Directory'!L4)
A17: =IF('Active Directory'!A5="","",'Active Directory'!A5) | B17: Active Directory | C17: =IF('Active Directory'!B5="","",'Active Directory'!B5) | D17: =IF('Active Directory'!C5="","",'Active Directory'!C5) | E17: =IF('Active Directory'!D5="","",'Active Directory'!D5) | F17: =IF('Active Directory'!E5="","",'Active Directory'!E5) | G17: =IF('Active Directory'!F5="","",'Active Directory'!F5) | H17: =IF('Active Directory'!G5="","",'Active Directory'!G5) | I17: =IF('Active Directory'!H5="","",'Active Directory'!H5) | J17: =IF('Active Directory'!I5="","",'Active Directory'!I5) | ... M17: =IF('Active Directory'!L5="","",'Active Directory'!L5)
A18: =IF('Active Directory'!A6="","",'Active Directory'!A6) | B18: Active Directory | C18: =IF('Active Directory'!B6="","",'Active Directory'!B6) | D18: =IF('Active Directory'!C6="","",'Active Directory'!C6) | E18: =IF('Active Directory'!D6="","",'Active Directory'!D6) | F18: =IF('Active Directory'!E6="","",'Active Directory'!E6) | G18: =IF('Active Directory'!F6="","",'Active Directory'!F6) | H18: =IF('Active Directory'!G6="","",'Active Directory'!G6) | I18: =IF('Active Directory'!H6="","",'Active Directory'!H6) | J18: =IF('Active Directory'!I6="","",'Active Directory'!I6) | ... M18: =IF('Active Directory'!L6="","",'Active Directory'!L6)
A19: =IF('Active Directory'!A7="","",'Active Directory'!A7) | B19: Active Directory | C19: =IF('Active Directory'!B7="","",'Active Directory'!B7) | D19: =IF('Active Directory'!C7="","",'Active Directory'!C7) | E19: =IF('Active Directory'!D7="","",'Active Directory'!D7) | F19: =IF('Active Directory'!E7="","",'Active Directory'!E7) | G19: =IF('Active Directory'!F7="","",'Active Directory'!F7) | H19: =IF('Active Directory'!G7="","",'Active Directory'!G7) | I19: =IF('Active Directory'!H7="","",'Active Directory'!H7) | J19: =IF('Active Directory'!I7="","",'Active Directory'!I7) | ... M19: =IF('Active Directory'!L7="","",'Active Directory'!L7)
A20: =IF('Active Directory'!A8="","",'Active Directory'!A8) | B20: Active Directory | C20: =IF('Active Directory'!B8="","",'Active Directory'!B8) | D20: =IF('Active Directory'!C8="","",'Active Directory'!C8) | E20: =IF('Active Directory'!D8="","",'Active Directory'!D8) | F20: =IF('Active Directory'!E8="","",'Active Directory'!E8) | G20: =IF('Active Directory'!F8="","",'Active Directory'!F8) | H20: =IF('Active Directory'!G8="","",'Active Directory'!G8) | I20: =IF('Active Directory'!H8="","",'Active Directory'!H8) | J20: =IF('Active Directory'!I8="","",'Active Directory'!I8) | ... M20: =IF('Active Directory'!L8="","",'Active Directory'!L8)
A21: =IF('Active Directory'!A9="","",'Active Directory'!A9) | B21: Active Directory | C21: =IF('Active Directory'!B9="","",'Active Directory'!B9) | D21: =IF('Active Directory'!C9="","",'Active Directory'!C9) | E21: =IF('Active Directory'!D9="","",'Active Directory'!D9) | F21: =IF('Active Directory'!E9="","",'Active Directory'!E9) | G21: =IF('Active Directory'!F9="","",'Active Directory'!F9) | H21: =IF('Active Directory'!G9="","",'Active Directory'!G9) | I21: =IF('Active Directory'!H9="","",'Active Directory'!H9) | J21: =IF('Active Directory'!I9="","",'Active Directory'!I9) | ... M21: =IF('Active Directory'!L9="","",'Active Directory'!L9)
A22: =IF('ServiceNow'!A3="","",'ServiceNow'!A3) | B22: ServiceNow | C22: =IF('ServiceNow'!B3="","",'ServiceNow'!B3) | D22: =IF('ServiceNow'!C3="","",'ServiceNow'!C3) | E22: =IF('ServiceNow'!D3="","",'ServiceNow'!D3) | F22: =IF('ServiceNow'!E3="","",'ServiceNow'!E3) | G22: =IF('ServiceNow'!F3="","",'ServiceNow'!F3) | H22: =IF('ServiceNow'!G3="","",'ServiceNow'!G3) | I22: =IF('ServiceNow'!H3="","",'ServiceNow'!H3) | J22: =IF('ServiceNow'!I3="","",'ServiceNow'!I3) | ... M22: =IF('ServiceNow'!L3="","",'ServiceNow'!L3)
A23: =IF('ServiceNow'!A4="","",'ServiceNow'!A4) | B23: ServiceNow | C23: =IF('ServiceNow'!B4="","",'ServiceNow'!B4) | D23: =IF('ServiceNow'!C4="","",'ServiceNow'!C4) | E23: =IF('ServiceNow'!D4="","",'ServiceNow'!D4) | F23: =IF('ServiceNow'!E4="","",'ServiceNow'!E4) | G23: =IF('ServiceNow'!F4="","",'ServiceNow'!F4) | H23: =IF('ServiceNow'!G4="","",'ServiceNow'!G4) | I23: =IF('ServiceNow'!H4="","",'ServiceNow'!H4) | J23: =IF('ServiceNow'!I4="","",'ServiceNow'!I4) | ... M23: =IF('ServiceNow'!L4="","",'ServiceNow'!L4)
A24: =IF('ServiceNow'!A5="","",'ServiceNow'!A5) | B24: ServiceNow | C24: =IF('ServiceNow'!B5="","",'ServiceNow'!B5) | D24: =IF('ServiceNow'!C5="","",'ServiceNow'!C5) | E24: =IF('ServiceNow'!D5="","",'ServiceNow'!D5) | F24: =IF('ServiceNow'!E5="","",'ServiceNow'!E5) | G24: =IF('ServiceNow'!F5="","",'ServiceNow'!F5) | H24: =IF('ServiceNow'!G5="","",'ServiceNow'!G5) | I24: =IF('ServiceNow'!H5="","",'ServiceNow'!H5) | J24: =IF('ServiceNow'!I5="","",'ServiceNow'!I5) | ... M24: =IF('ServiceNow'!L5="","",'ServiceNow'!L5)
A25: =IF('ServiceNow'!A6="","",'ServiceNow'!A6) | B25: ServiceNow | C25: =IF('ServiceNow'!B6="","",'ServiceNow'!B6) | D25: =IF('ServiceNow'!C6="","",'ServiceNow'!C6) | E25: =IF('ServiceNow'!D6="","",'ServiceNow'!D6) | F25: =IF('ServiceNow'!E6="","",'ServiceNow'!E6) | G25: =IF('ServiceNow'!F6="","",'ServiceNow'!F6) | H25: =IF('ServiceNow'!G6="","",'ServiceNow'!G6) | I25: =IF('ServiceNow'!H6="","",'ServiceNow'!H6) | J25: =IF('ServiceNow'!I6="","",'ServiceNow'!I6) | ... M25: =IF('ServiceNow'!L6="","",'ServiceNow'!L6)
A26: =IF('NetBox'!A3="","",'NetBox'!A3) | B26: NetBox | C26: =IF('NetBox'!B3="","",'NetBox'!B3) | D26: =IF('NetBox'!C3="","",'NetBox'!C3) | E26: =IF('NetBox'!D3="","",'NetBox'!D3) | F26: =IF('NetBox'!E3="","",'NetBox'!E3) | G26: =IF('NetBox'!F3="","",'NetBox'!F3) | H26: =IF('NetBox'!G3="","",'NetBox'!G3) | I26: =IF('NetBox'!H3="","",'NetBox'!H3) | J26: =IF('NetBox'!I3="","",'NetBox'!I3) | ... M26: =IF('NetBox'!L3="","",'NetBox'!L3)
A27: =IF('NetBox'!A4="","",'NetBox'!A4) | B27: NetBox | C27: =IF('NetBox'!B4="","",'NetBox'!B4) | D27: =IF('NetBox'!C4="","",'NetBox'!C4) | E27: =IF('NetBox'!D4="","",'NetBox'!D4) | F27: =IF('NetBox'!E4="","",'NetBox'!E4) | G27: =IF('NetBox'!F4="","",'NetBox'!F4) | H27: =IF('NetBox'!G4="","",'NetBox'!G4) | I27: =IF('NetBox'!H4="","",'NetBox'!H4) | J27: =IF('NetBox'!I4="","",'NetBox'!I4) | ... M27: =IF('NetBox'!L4="","",'NetBox'!L4)
A28: =IF('NetBox'!A5="","",'NetBox'!A5) | B28: NetBox | C28: =IF('NetBox'!B5="","",'NetBox'!B5) | D28: =IF('NetBox'!C5="","",'NetBox'!C5) | E28: =IF('NetBox'!D5="","",'NetBox'!D5) | F28: =IF('NetBox'!E5="","",'NetBox'!E5) | G28: =IF('NetBox'!F5="","",'NetBox'!F5) | H28: =IF('NetBox'!G5="","",'NetBox'!G5) | I28: =IF('NetBox'!H5="","",'NetBox'!H5) | J28: =IF('NetBox'!I5="","",'NetBox'!I5) | ... M28: =IF('NetBox'!L5="","",'NetBox'!L5)
A29: =IF('Monitoring'!A3="","",'Monitoring'!A3) | B29: Monitoring | C29: =IF('Monitoring'!B3="","",'Monitoring'!B3) | D29: =IF('Monitoring'!C3="","",'Monitoring'!C3) | E29: =IF('Monitoring'!D3="","",'Monitoring'!D3) | F29: =IF('Monitoring'!E3="","",'Monitoring'!E3) | G29: =IF('Monitoring'!F3="","",'Monitoring'!F3) | H29: =IF('Monitoring'!G3="","",'Monitoring'!G3) | I29: =IF('Monitoring'!H3="","",'Monitoring'!H3) | J29: =IF('Monitoring'!I3="","",'Monitoring'!I3) | ... M29: =IF('Monitoring'!L3="","",'Monitoring'!L3)
A30: =IF('Monitoring'!A4="","",'Monitoring'!A4) | B30: Monitoring | C30: =IF('Monitoring'!B4="","",'Monitoring'!B4) | D30: =IF('Monitoring'!C4="","",'Monitoring'!C4) | E30: =IF('Monitoring'!D4="","",'Monitoring'!D4) | F30: =IF('Monitoring'!E4="","",'Monitoring'!E4) | G30: =IF('Monitoring'!F4="","",'Monitoring'!F4) | H30: =IF('Monitoring'!G4="","",'Monitoring'!G4) | I30: =IF('Monitoring'!H4="","",'Monitoring'!H4) | J30: =IF('Monitoring'!I4="","",'Monitoring'!I4) | ... M30: =IF('Monitoring'!L4="","",'Monitoring'!L4)
A31: =IF('Monitoring'!A5="","",'Monitoring'!A5) | B31: Monitoring | C31: =IF('Monitoring'!B5="","",'Monitoring'!B5) | D31: =IF('Monitoring'!C5="","",'Monitoring'!C5) | E31: =IF('Monitoring'!D5="","",'Monitoring'!D5) | F31: =IF('Monitoring'!E5="","",'Monitoring'!E5) | G31: =IF('Monitoring'!F5="","",'Monitoring'!F5) | H31: =IF('Monitoring'!G5="","",'Monitoring'!G5) | I31: =IF('Monitoring'!H5="","",'Monitoring'!H5) | J31: =IF('Monitoring'!I5="","",'Monitoring'!I5) | ... M31: =IF('Monitoring'!L5="","",'Monitoring'!L5)
A32: =IF('Infrastructure'!A3="","",'Infrastructure'!A3) | B32: Infrastructure | C32: =IF('Infrastructure'!B3="","",'Infrastructure'!B3) | D32: =IF('Infrastructure'!C3="","",'Infrastructure'!C3) | E32: =IF('Infrastructure'!D3="","",'Infrastructure'!D3) | F32: =IF('Infrastructure'!E3="","",'Infrastructure'!E3) | G32: =IF('Infrastructure'!F3="","",'Infrastructure'!F3) | H32: =IF('Infrastructure'!G3="","",'Infrastructure'!G3) | I32: =IF('Infrastructure'!H3="","",'Infrastructure'!H3) | J32: =IF('Infrastructure'!I3="","",'Infrastructure'!I3) | ... M32: =IF('Infrastructure'!L3="","",'Infrastructure'!L3)
A33: =IF('Infrastructure'!A4="","",'Infrastructure'!A4) | B33: Infrastructure | C33: =IF('Infrastructure'!B4="","",'Infrastructure'!B4) | D33: =IF('Infrastructure'!C4="","",'Infrastructure'!C4) | E33: =IF('Infrastructure'!D4="","",'Infrastructure'!D4) | F33: =IF('Infrastructure'!E4="","",'Infrastructure'!E4) | G33: =IF('Infrastructure'!F4="","",'Infrastructure'!F4) | H33: =IF('Infrastructure'!G4="","",'Infrastructure'!G4) | I33: =IF('Infrastructure'!H4="","",'Infrastructure'!H4) | J33: =IF('Infrastructure'!I4="","",'Infrastructure'!I4) | ... M33: =IF('Infrastructure'!L4="","",'Infrastructure'!L4)
A34: =IF('Infrastructure'!A5="","",'Infrastructure'!A5) | B34: Infrastructure | C34: =IF('Infrastructure'!B5="","",'Infrastructure'!B5) | D34: =IF('Infrastructure'!C5="","",'Infrastructure'!C5) | E34: =IF('Infrastructure'!D5="","",'Infrastructure'!D5) | F34: =IF('Infrastructure'!E5="","",'Infrastructure'!E5) | G34: =IF('Infrastructure'!F5="","",'Infrastructure'!F5) | H34: =IF('Infrastructure'!G5="","",'Infrastructure'!G5) | I34: =IF('Infrastructure'!H5="","",'Infrastructure'!H5) | J34: =IF('Infrastructure'!I5="","",'Infrastructure'!I5) | ... M34: =IF('Infrastructure'!L5="","",'Infrastructure'!L5)
A35: =IF('Infrastructure'!A6="","",'Infrastructure'!A6) | B35: Infrastructure | C35: =IF('Infrastructure'!B6="","",'Infrastructure'!B6) | D35: =IF('Infrastructure'!C6="","",'Infrastructure'!C6) | E35: =IF('Infrastructure'!D6="","",'Infrastructure'!D6) | F35: =IF('Infrastructure'!E6="","",'Infrastructure'!E6) | G35: =IF('Infrastructure'!F6="","",'Infrastructure'!F6) | H35: =IF('Infrastructure'!G6="","",'Infrastructure'!G6) | I35: =IF('Infrastructure'!H6="","",'Infrastructure'!H6) | J35: =IF('Infrastructure'!I6="","",'Infrastructure'!I6) | ... M35: =IF('Infrastructure'!L6="","",'Infrastructure'!L6)
A36: =IF('Alerts'!A3="","",'Alerts'!A3) | B36: Notifications | C36: =IF('Alerts'!B3="","",'Alerts'!B3) | D36: =IF('Alerts'!C3="","",'Alerts'!C3) | E36: =IF('Alerts'!D3="","",'Alerts'!D3) | F36: =IF('Alerts'!E3="","",'Alerts'!E3) | G36: =IF('Alerts'!F3="","",'Alerts'!F3) | H36: =IF('Alerts'!G3="","",'Alerts'!G3) | I36: =IF('Alerts'!H3="","",'Alerts'!H3) | J36: =IF('Alerts'!I3="","",'Alerts'!I3) | ... M36: =IF('Alerts'!L3="","",'Alerts'!L3)
A37: =IF('Alerts'!A4="","",'Alerts'!A4) | B37: Notifications | C37: =IF('Alerts'!B4="","",'Alerts'!B4) | D37: =IF('Alerts'!C4="","",'Alerts'!C4) | E37: =IF('Alerts'!D4="","",'Alerts'!D4) | F37: =IF('Alerts'!E4="","",'Alerts'!E4) | G37: =IF('Alerts'!F4="","",'Alerts'!F4) | H37: =IF('Alerts'!G4="","",'Alerts'!G4) | I37: =IF('Alerts'!H4="","",'Alerts'!H4) | J37: =IF('Alerts'!I4="","",'Alerts'!I4) | ... M37: =IF('Alerts'!L4="","",'Alerts'!L4)
A38: =IF('Alerts'!A5="","",'Alerts'!A5) | B38: Notifications | C38: =IF('Alerts'!B5="","",'Alerts'!B5) | D38: =IF('Alerts'!C5="","",'Alerts'!C5) | E38: =IF('Alerts'!D5="","",'Alerts'!D5) | F38: =IF('Alerts'!E5="","",'Alerts'!E5) | G38: =IF('Alerts'!F5="","",'Alerts'!F5) | H38: =IF('Alerts'!G5="","",'Alerts'!G5) | I38: =IF('Alerts'!H5="","",'Alerts'!H5) | J38: =IF('Alerts'!I5="","",'Alerts'!I5) | ... M38: =IF('Alerts'!L5="","",'Alerts'!L5)
A39: =IF('Alerts'!A6="","",'Alerts'!A6) | B39: Notifications | C39: =IF('Alerts'!B6="","",'Alerts'!B6) | D39: =IF('Alerts'!C6="","",'Alerts'!C6) | E39: =IF('Alerts'!D6="","",'Alerts'!D6) | F39: =IF('Alerts'!E6="","",'Alerts'!E6) | G39: =IF('Alerts'!F6="","",'Alerts'!F6) | H39: =IF('Alerts'!G6="","",'Alerts'!G6) | I39: =IF('Alerts'!H6="","",'Alerts'!H6) | J39: =IF('Alerts'!I6="","",'Alerts'!I6) | ... M39: =IF('Alerts'!L6="","",'Alerts'!L6)
A40: =IF('Device Access'!A3="","",'Device Access'!A3) | B40: Device Access | C40: =IF('Device Access'!B3="","",'Device Access'!B3) | D40: =IF('Device Access'!C3="","",'Device Access'!C3) | E40: =IF('Device Access'!D3="","",'Device Access'!D3) | F40: =IF('Device Access'!E3="","",'Device Access'!E3) | G40: =IF('Device Access'!F3="","",'Device Access'!F3) | H40: =IF('Device Access'!G3="","",'Device Access'!G3) | I40: =IF('Device Access'!H3="","",'Device Access'!H3) | J40: =IF('Device Access'!I3="","",'Device Access'!I3) | ... M40: =IF('Device Access'!L3="","",'Device Access'!L3)
A41: =IF('Device Access'!A4="","",'Device Access'!A4) | B41: Device Access | C41: =IF('Device Access'!B4="","",'Device Access'!B4) | D41: =IF('Device Access'!C4="","",'Device Access'!C4) | E41: =IF('Device Access'!D4="","",'Device Access'!D4) | F41: =IF('Device Access'!E4="","",'Device Access'!E4) | G41: =IF('Device Access'!F4="","",'Device Access'!F4) | H41: =IF('Device Access'!G4="","",'Device Access'!G4) | I41: =IF('Device Access'!H4="","",'Device Access'!H4) | J41: =IF('Device Access'!I4="","",'Device Access'!I4) | ... M41: =IF('Device Access'!L4="","",'Device Access'!L4)
...

Sheet DNA Center
A1: DNA Center Parameters
A2: Parameter Name | B2: Environment | C2: Default Value | D2: Description | E2: Required | F2: Data Type | G2: Validation Rules | H2: Security Level | I2: Owner Team | J2: Dependencies | K2: Notes | L2: Last Updated
A3: DNAC_PRIMARY_IP | B3: All | C3: [********] | D3: Primary DNA Center appliance management IP | E3: Yes | F3: String | G3: Valid IPv4 address | H3: Confidential | I3: Network Team | J3: Network connectivity | K3: Management VLAN access required | L3: [DATE]
A4: DNAC_SECONDARY_IP | B4: All | C4: [********] | D4: Secondary DNA Center appliance management IP (HA) | E4: Yes | F4: String | G4: Valid IPv4 address | H4: Confidential | I4: Network Team | J4: Network connectivity | K4: HA pair for redundancy | L4: [DATE]
A5: DNAC_VIP | B5: All | C5: [********] | D5: DNA Center Virtual IP for HA failover | E5: Yes | F5: String | G5: Valid IPv4 address | H5: Confidential | I5: Network Team | J5: HA Configuration | K5: Clients connect to VIP | L5: [DATE]
A6: DNAC_CLUSTER_NAME | B6: All | C6: dnac-cluster-prod | D6: DNA Center cluster identifier | E6: Yes | F6: String | G6: Alphanumeric max 32 chars | H6: Public | I6: Network Team | J6: None | K6: Used in logging and alerts | L6: [DATE]
A7: DNAC_ADMIN_USER | B7: All | C7: [********] | D7: DNA Center administrative username | E7: Yes | F7: String | G7: Valid username format | H7: Confidential | I7: Security Team | J7: AD Integration | K7: Local admin for initial setup | L7: [DATE]
A8: DNAC_FQDN | B8: All | C8: dnac.client.local | D8: DNA Center fully qualified domain name | E8: Yes | F8: String | G8: Valid FQDN format | H8: Public | I8: Network Team | J8: DNS Configuration | K8: Used for SSL certificate | L8: [DATE]
A9: DNAC_VERSION | B9: All | C9: 2.3.5.x | D9: DNA Center software version | E9: Yes | F9: String | G9: Semantic versioning | H9: Public | I9: Network Team | J9: Cisco support | K9: Minimum for AI Analytics features | L9: [DATE]

Sheet Licensing
A1: Licensing Parameters
A2: Parameter Name | B2: Environment | C2: Default Value | D2: Description | E2: Required | F2: Data Type | G2: Validation Rules | H2: Security Level | I2: Owner Team | J2: Dependencies | K2: Notes | L2: Last Updated
A3: DNAC_LICENSE_TIER | B3: All | C3: DNA Advantage | D3: DNA Center license tier | E3: Yes | F3: String | G3: Essentials|Advantage|Premier | H3: Public | I3: Network Team | J3: Cisco Smart License | K3: Required for AI Analytics | L3: [DATE]
A4: DNAC_DEVICE_COUNT | B4: All | C4: 200 | D4: Number of licensed network devices | E4: Yes | F4: Integer | G4: 1-500 for medium appliance | H4: Public | I4: Network Team | J4: Appliance capacity | K4: Scope per SOW | L4: [DATE]
A5: DNAC_AI_ANALYTICS_ENABLED | B5: All | C5: true | D5: Enable AI Network Analytics subscription | E5: Yes | F5: Boolean | G5: true|false | H5: Public | I5: Network Team | J5: DNA Advantage license | K5: Required for predictive insights | L5: [DATE]

Sheet Active Directory
A1: Active Directory Parameters
A2: Parameter Name | B2: Environment | C2: Default Value | D2: Description | E2: Required | F2: Data Type | G2: Validation Rules | H2: Security Level | I2: Owner Team | J2: Dependencies | K2: Notes | L2: Last Updated
A3: AD_SERVER_PRIMARY | B3: All | C3: [********] | D3: Primary Active Directory server IP | E3: Yes | F3: String | G3: Valid IPv4 address | H3: Confidential | I3: Security Team | J3: Network connectivity | K3: LDAP authentication | L3: [DATE]
A4: AD_SERVER_SECONDARY | B4: All | C4: [********] | D4: Secondary Active Directory server IP | E4: No | F4: String | G4: Valid IPv4 address | H4: Confidential | I4: Security Team | J4: Network connectivity | K4: LDAP failover | L4: [DATE]
A5: AD_DOMAIN | B5: All | C5: [********] | D5: Active Directory domain name | E5: Yes | F5: String | G5: Valid domain format | H5: Confidential | I5: Security Team | J5: None | K5: For user authentication | L5: [DATE]
A6: AD_BASE_DN | B6: All | C6: [********] | D6: LDAP Base Distinguished Name | E6: Yes | F6: String | G6: Valid DN format | H6: Confidential | I6: Security Team | J6: AD_DOMAIN | K6: User search base | L6: [DATE]
A7: AD_BIND_USER | B7: All | C7: [********] | D7: LDAP service account username | E7: Yes | F7: String | G7: Valid username | H7: Secret | I7: Security Team | J7: AD account created | K7: Read-only access to AD | L7: [DATE]
A8: AD_GROUP_ADMIN | B8: All | C8: [********] | D8: AD group for DNA Center administrators | E8: Yes | F8: String | G8: Valid AD group name | H8: Confidential | I8: Security Team | J8: AD group created | K8: Full admin access | L8: [DATE]
A9: AD_GROUP_VIEWER | B9: All | C9: [********] | D9: AD group for DNA Center read-only users | E9: Yes | F9: String | G9: Valid AD group name | H9: Confidential | I9: Security Team | J9: AD group created | K9: Dashboard view only | L9: [DATE]

Sheet ServiceNow
A1: ServiceNow Parameters
A2: Parameter Name | B2: Environment | C2: Default Value | D2: Description | E2: Required | F2: Data Type | G2: Validation Rules | H2: Security Level | I2: Owner Team | J2: Dependencies | K2: Notes | L2: Last Updated
A3: SERVICENOW_INSTANCE | B3: All | C3: [********] | D3: ServiceNow instance URL | E3: Yes | F3: String | G3: Valid ServiceNow URL | H3: Confidential | I3: Integration Team | J3: ServiceNow license | K3: ITSM integration target | L3: [DATE]
A4: SERVICENOW_USER | B4: All | C4: [********] | D4: ServiceNow integration service account | E4: Yes | F4: String | G4: Valid username | H4: Confidential | I4: Integration Team | J4: ServiceNow account | K4: API access required | L4: [DATE]
A5: SERVICENOW_TABLE | B5: All | C5: incident | D5: ServiceNow table for incident creation | E5: Yes | F5: String | G5: Valid table name | H5: Public | I5: Integration Team | J5: None | K5: Auto ticket creation | L5: [DATE]
A6: SERVICENOW_PRIORITY_MAPPING | B6: All | C6: Critical:1 High:2 Medium:3 Low:4 | D6: DNA Center to ServiceNow priority mapping | E6: Yes | F6: String | G6: Colon-separated mapping | H6: Public | I6: Integration Team | J6: None | K6: Severity translation | L6: [DATE]

Sheet NetBox
A1: NetBox Parameters
A2: Parameter Name | B2: Environment | C2: Default Value | D2: Description | E2: Required | F2: Data Type | G2: Validation Rules | H2: Security Level | I2: Owner Team | J2: Dependencies | K2: Notes | L2: Last Updated
A3: NETBOX_URL | B3: All | C3: [********] | D3: NetBox IPAM instance URL | E3: Yes | F3: String | G3: Valid HTTPS URL | H3: Confidential | I3: Integration Team | J3: NetBox instance | K3: IPAM integration target | L3: [DATE]
A4: NETBOX_API_TOKEN | B4: All | C4: [********] | D4: NetBox API authentication token | E4: Yes | F4: String | G4: Valid API token | H4: Secret | I4: Integration Team | J4: NetBox account | K4: Read/write access | L4: [DATE]
A5: NETBOX_SYNC_INTERVAL | B5: All | C5: 15 | D5: NetBox sync interval in minutes | E5: Yes | F5: Integer | G5: 5-60 | H5: Public | I5: Integration Team | J5: None | K5: Inventory synchronization | L5: [DATE]

Sheet Monitoring
A1: Monitoring Parameters
A2: Parameter Name | B2: Environment | C2: Default Value | D2: Description | E2: Required | F2: Data Type | G2: Validation Rules | H2: Security Level | I2: Owner Team | J2: Dependencies | K2: Notes | L2: Last Updated
A3: SYSLOG_SERVER | B3: All | C3: [********] | D3: Centralized syslog server IP | E3: Yes | F3: String | G3: Valid IPv4 address | H3: Confidential | I3: Operations Team | J3: Network connectivity | K3: Log aggregation | L3: [DATE]
A4: SYSLOG_PORT | B4: All | C4: 514 | D4: Syslog UDP port | E4: Yes | F4: Integer | G4: 1-65535 | H4: Public | I4: Operations Team | J4: Firewall rules | K4: Standard syslog port | L4: [DATE]
A5: SYSLOG_FACILITY | B5: All | C5: local7 | D5: Syslog facility for DNA Center logs | E5: Yes | F5: String | G5: Valid syslog facility | H5: Public | I5: Operations Team | J5: None | K5: Log categorization | L5: [DATE]

Sheet Infrastructure
A1: Infrastructure Parameters
A2: Parameter Name | B2: Environment | C2: Default Value | D2: Description | E2: Required | F2: Data Type | G2: Validation Rules | H2: Security Level | I2: Owner Team | J2: Dependencies | K2: Notes | L2: Last Updated
A3: NTP_SERVER_PRIMARY | B3: All | C3: [********] | D3: Primary NTP server IP | E3: Yes | F3: String | G3: Valid IPv4 address | H3: Confidential | I3: Infrastructure Team | J3: Network connectivity | K3: Time synchronization critical | L3: [DATE]
A4: NTP_SERVER_SECONDARY | B4: All | C4: [********] | D4: Secondary NTP server IP | E4: No | F4: String | G4: Valid IPv4 address | H4: Confidential | I4: Infrastructure Team | J4: Network connectivity | K4: NTP failover | L4: [DATE]
A5: DNS_SERVER_PRIMARY | B5: All | C5: [********] | D5: Primary DNS server IP | E5: Yes | F5: String | G5: Valid IPv4 address | H5: Confidential | I5: Infrastructure Team | J5: Network connectivity | K5: Name resolution required | L5: [DATE]
A6: DNS_SERVER_SECONDARY | B6: All | C6: [********] | D6: Secondary DNS server IP | E6: No | F6: String | G6: Valid IPv4 address | H6: Confidential | I6: Infrastructure Team | J6: Network connectivity | K6: DNS failover | L6: [DATE]

Sheet Alerts
A1: Notifications Parameters
A2: Parameter Name | B2: Environment | C2: Default Value | D2: Description | E2: Required | F2: Data Type | G2: Validation Rules | H2: Security Level | I2: Owner Team | J2: Dependencies | K2: Notes | L2: Last Updated
A3: SMTP_SERVER | B3: All | C3: [********] | D3: SMTP server for email notifications | E3: Yes | F3: String | G3: Valid hostname or IP | H3: Confidential | I3: Infrastructure Team | J3: SMTP relay | K3: Alert notifications | L3: [DATE]
A4: SMTP_PORT | B4: All | C4: 587 | D4: SMTP server port | E4: Yes | F4: Integer | G4: 25|587|465 | H4: Public | I4: Infrastructure Team | J4: None | K4: TLS recommended | L4: [DATE]
A5: SMTP_FROM_ADDRESS | B5: All | C5: dnac-alerts@client.local | D5: Email sender address for alerts | E5: Yes | F5: String | G5: Valid email format | H5: Public | I5: Operations Team | J5: None | K5: Alert source identification | L5: [DATE]
A6: ALERT_EMAIL_RECIPIENTS | B6: All | C6: [********] | D6: Email recipients for critical alerts | E6: Yes | F6: String | G6: Comma-separated emails | H6: Confidential | I6: Operations Team | J6: None | K6: NOC distribution list | L6: [DATE]

Sheet Device Access
A1: Device Access Parameters
A2: Parameter Name | B2: Environment | C2: Default Value | D2: Description | E2: Required | F2: Data Type | G2: Validation Rules | H2: Security Level | I2: Owner Team | J2: Dependencies | K2: Notes | L2: Last Updated
A3: DEVICE_CREDENTIAL_CLI | B3: All | C3: [********] | D3: CLI username for device access | E3: Yes | F3: String | G3: Valid username | H3: Secret | I3: Network Team | J3: Device accounts | K3: NETCONF/SSH access | L3: [DATE]
A4: DEVICE_CREDENTIAL_SNMP_RO | B4: All | C4: [********] | D4: SNMP read-only community string | E4: Yes | F4: String | G4: Min 8 characters | H4: Secret | I4: Network Team | J4: Device SNMP config | K4: Telemetry collection | L4: [DATE]
A5: DEVICE_CREDENTIAL_SNMP_RW | B5: All | C5: [********] | D5: SNMP read-write community string | E5: Yes | F5: String | G5: Min 12 characters | H5: Secret | I5: Network Team | J5: Device SNMP config | K5: Device management | L5: [DATE]
A6: DEVICE_ENABLE_SECRET | B6: All | C6: [********] | D6: Device enable/privilege password | E6: Yes | F6: String | G6: Min 12 characters | H6: Secret | I6: Network Team | J6: Device config | K6: Privileged mode access | L6: [DATE]

Sheet AI Analytics
A1: AI Analytics Parameters
A2: Parameter Name | B2: Environment | C2: Default Value | D2: Description | E2: Required | F2: Data Type | G2: Validation Rules | H2: Security Level | I2: Owner Team | J2: Dependencies | K2: Notes | L2: Last Updated
A3: AI_CONFIDENCE_THRESHOLD | B3: All | C3: 0.85 | D3: Minimum confidence score for AI predictions | E3: Yes | F3: Float | G3: 0.0-1.0 | H3: Public | I3: Network Team | J3: AI Analytics enabled | K3: Below triggers human review | L3: [DATE]
A4: AI_ANOMALY_SENSITIVITY | B4: All | C4: Medium | D4: Anomaly detection sensitivity level | E4: Yes | F4: String | G4: Low|Medium|High | H4: Public | I4: Network Team | J4: AI Analytics enabled | K4: Balance accuracy vs alerts | L4: [DATE]
A5: AI_BASELINE_LEARNING_DAYS | B5: All | C5: 14 | D5: Days to establish AI performance baseline | E5: Yes | F5: Integer | G5: 7-30 | H5: Public | I5: Network Team | J5: AI Analytics enabled | K5: Initial learning period | L5: [DATE]
A6: AI_PREDICTIVE_HORIZON_DAYS | B6: All | C6: 14 | D6: Days ahead for failure prediction | E6: Yes | F6: Integer | G6: 7-30 | H6: Public | I6: Network Team | J6: AI Analytics enabled | K6: Per SOW specification | L6: [DATE]

Sheet Automation
A1: Automation Parameters
A2: Parameter Name | B2: Environment | C2: Default Value | D2: Description | E2: Required | F2: Data Type | G2: Validation Rules | H2: Security Level | I2: Owner Team | J2: Dependencies | K2: Notes | L2: Last Updated
A3: POLICY_VLAN_RANGE | B3: All | C3: 100-999 | D3: Valid VLAN ID range for automation | E3: Yes | F3: String | G3: VLAN range format | H3: Public | I3: Network Team | J3: None | K3: Policy template parameter | L3: [DATE]
A4: POLICY_DEPLOYMENT_MODE | B4: All | C4: Staged | D4: Policy deployment strategy | E4: Yes | F4: String | G4: Immediate|Staged|Manual | H4: Public | I4: Network Team | J4: None | K4: Risk mitigation approach | L4: [DATE]
A5: POLICY_COMPLIANCE_CHECK_INTERVAL | B5: All | C5: 60 | D5: Compliance check interval in minutes | E5: Yes | F5: Integer | G5: 15-1440 | H5: Public | I5: Network Team | J5: None | K5: Drift detection frequency | L5: [DATE]

Sheet Operations
A1: Operations Parameters
A2: Parameter Name | B2: Environment | C2: Default Value | D2: Description | E2: Required | F2: Data Type | G2: Validation Rules | H2: Security Level | I2: Owner Team | J2: Dependencies | K2: Notes | L2: Last Updated
A3: BACKUP_RETENTION_DAYS | B3: All | C3: 30 | D3: DNA Center backup retention period | E3: Yes | F3: Integer | G3: 7-365 | H3: Public | I3: Operations Team | J3: Storage capacity | K3: Compliance requirement | L3: [DATE]
A4: BACKUP_SCHEDULE | B4: All | C4: 02:00 | D4: Daily backup time (24-hour format) | E4: Yes | F4: String | G4: HH:MM format | H4: Public | I4: Operations Team | J4: None | K4: Off-hours execution | L4: [DATE]
A5: BACKUP_LOCATION | B5: All | C5: [********] | D5: Backup storage path | E5: Yes | F5: String | G5: Valid path | H5: Confidential | I5: Operations Team | J5: Storage availability | K5: Local or NFS mount | L5: [DATE]

Sheet High Availability
A1: High Availability Parameters
A2: Parameter Name | B2: Environment | C2: Default Value | D2: Description | E2: Required | F2: Data Type | G2: Validation Rules | H2: Security Level | I2: Owner Team | J2: Dependencies | K2: Notes | L2: Last Updated
A3: HA_FAILOVER_THRESHOLD | B3: All | C3: 60 | D3: Seconds before HA failover triggered | E3: Yes | F3: Integer | G3: 30-300 | H3: Public | I3: Network Team | J3: HA Configuration | K3: Balance stability vs speed | L3: [DATE]
A4: HA_HEARTBEAT_INTERVAL | B4: All | C4: 5 | D4: HA heartbeat interval in seconds | E4: Yes | F4: Integer | G4: 1-30 | H4: Public | I4: Network Team | J4: HA Configuration | K4: Health monitoring | L4: [DATE]

Sheet Security
A1: Security Parameters
A2: Parameter Name | B2: Environment | C2: Default Value | D2: Description | E2: Required | F2: Data Type | G2: Validation Rules | H2: Security Level | I2: Owner Team | J2: Dependencies | K2: Notes | L2: Last Updated
A3: SSL_CERTIFICATE_PATH | B3: All | C3: [********] | D3: SSL certificate file path | E3: Yes | F3: String | G3: Valid file path | H3: Confidential | I3: Security Team | J3: SSL certificate | K3: HTTPS encryption | L3: [DATE]
A4: SSL_KEY_PATH | B4: All | C4: [********] | D4: SSL private key file path | E4: Yes | F4: String | G4: Valid file path | H4: Secret | I4: Security Team | J4: SSL certificate | K4: Keep secure | L4: [DATE]
A5: SSL_EXPIRY_WARNING_DAYS | B5: All | C5: 30 | D5: Days before SSL expiry to alert | E5: Yes | F5: Integer | G5: 14-90 | H5: Public | I5: Security Team | J5: None | K5: Certificate renewal reminder | L5: [DATE]
A6: SESSION_TIMEOUT_MINUTES | B6: All | C6: 30 | D6: Web session timeout in minutes | E6: Yes | F6: Integer | G6: 5-480 | H6: Public | I6: Security Team | J6: None | K6: Security policy compliance | L6: [DATE]
A7: MAX_LOGIN_ATTEMPTS | B7: All | C7: 5 | D7: Maximum failed login attempts before lockout | E7: Yes | F7: Integer | G7: 3-10 | H7: Public | I7: Security Team | J7: None | K7: Brute force protection | L7: [DATE]

Sheet Compliance
A1: Compliance Parameters
A2: Parameter Name | B2: Environment | C2: Default Value | D2: Description | E2: Required | F2: Data Type | G2: Validation Rules | H2: Security Level | I2: Owner Team | J2: Dependencies | K2: Notes | L2: Last Updated
A3: AUDIT_LOG_RETENTION_DAYS | B3: All | C3: 365 | D3: Audit log retention period in days | E3: Yes | F3: Integer | G3: 90-730 | H3: Public | I3: Compliance Team | J3: Storage capacity | K3: Regulatory requirement | L3: [DATE]

Sheet Application
A1: Application Parameters
A2: Parameter Name | B2: Environment | C2: Default Value | D2: Description | E2: Required | F2: Data Type | G2: Validation Rules | H2: Security Level | I2: Owner Team | J2: Dependencies | K2: Notes | L2: Last Updated
A3: APP_MONITORING_O365 | B3: All | C3: true | D3: Enable Office 365 application monitoring | E3: Yes | F3: Boolean | G3: true|false | H3: Public | I3: Network Team | J3: O365 API access | K3: Per SOW scope | L3: [DATE]
A4: APP_MONITORING_WEBEX | B4: All | C4: true | D4: Enable Webex application monitoring | E4: Yes | F4: Boolean | G4: true|false | H4: Public | I4: Network Team | J4: Webex API access | K4: Per SOW scope | L4: [DATE]
A5: APP_MONITORING_SAP | B5: All | C5: true | D5: Enable SAP application monitoring | E5: Yes | F5: Boolean | G5: true|false | H5: Public | I5: Network Team | J5: SAP endpoint access | K5: Per SOW scope | L5: [DATE]
A6: APP_SLA_LATENCY_MS | B6: All | C6: 100 | D6: Application latency SLA threshold in ms | E6: Yes | F6: Integer | G6: 10-1000 | H6: Public | I6: Network Team | J6: None | K6: Performance alerting | L6: [DATE]
A7: APP_SLA_JITTER_MS | B7: All | C7: 30 | D7: Application jitter SLA threshold in ms | E7: Yes | F7: Integer | G7: 5-100 | H7: Public | I7: Network Team | J7: None | K7: Voice/video quality | L7: [DATE]
A8: APP_SLA_PACKET_LOSS_PCT | B8: All | C8: 1.0 | D8: Application packet loss SLA threshold % | E8: Yes | F8: Float | G8: 0.1-5.0 | H8: Public | I8: Network Team | J8: None | K8: Quality threshold | L8: [DATE]
