Workbook

Sheet Cover
B3: Configuration Parameters
B5: Generated: | C5: November 28, 2025
B6: Solution: | C6: Gpu Compute Cluster
B7: Customer: | C7: [Customer Name]
B8: Version: | C8: 1.0
B9: Status: | C9: Draft
C12: eoframework.org

Sheet All Parameters (Read Only)
A1: Total Parameters | B1: Categories | C1: Required | D1: Confidential/Secret
A2: 48 | B2: 11 | C2: 48 | D2: 2
A4: Parameter Name | B4: Category | C4: Environment | D4: Default Value | E4: Description | F4: Required | G4: Data Type | H4: Validation Rules | I4: Security Level | J4: Owner Team | K4: Dependencies | L4: Notes | M4: Last Updated
A5: =IF('Application'!A3="","",'Application'!A3) | B5: Application | C5: =IF('Application'!B3="","",'Application'!B3) | D5: =IF('Application'!C3="","",'Application'!C3) | E5: =IF('Application'!D3="","",'Application'!D3) | F5: =IF('Application'!E3="","",'Application'!E3) | G5: =IF('Application'!F3="","",'Application'!F3) | H5: =IF('Application'!G3="","",'Application'!G3) | I5: =IF('Application'!H3="","",'Application'!H3) | J5: =IF('Application'!I3="","",'Application'!I3) | ... M5: =IF('Application'!L3="","",'Application'!L3)
A6: =IF('Hardware'!A3="","",'Hardware'!A3) | B6: Hardware | C6: =IF('Hardware'!B3="","",'Hardware'!B3) | D6: =IF('Hardware'!C3="","",'Hardware'!C3) | E6: =IF('Hardware'!D3="","",'Hardware'!D3) | F6: =IF('Hardware'!E3="","",'Hardware'!E3) | G6: =IF('Hardware'!F3="","",'Hardware'!F3) | H6: =IF('Hardware'!G3="","",'Hardware'!G3) | I6: =IF('Hardware'!H3="","",'Hardware'!H3) | J6: =IF('Hardware'!I3="","",'Hardware'!I3) | ... M6: =IF('Hardware'!L3="","",'Hardware'!L3)
A7: =IF('Hardware'!A4="","",'Hardware'!A4) | B7: Hardware | C7: =IF('Hardware'!B4="","",'Hardware'!B4) | D7: =IF('Hardware'!C4="","",'Hardware'!C4) | E7: =IF('Hardware'!D4="","",'Hardware'!D4) | F7: =IF('Hardware'!E4="","",'Hardware'!E4) | G7: =IF('Hardware'!F4="","",'Hardware'!F4) | H7: =IF('Hardware'!G4="","",'Hardware'!G4) | I7: =IF('Hardware'!H4="","",'Hardware'!H4) | J7: =IF('Hardware'!I4="","",'Hardware'!I4) | ... M7: =IF('Hardware'!L4="","",'Hardware'!L4)
A8: =IF('Hardware'!A5="","",'Hardware'!A5) | B8: Hardware | C8: =IF('Hardware'!B5="","",'Hardware'!B5) | D8: =IF('Hardware'!C5="","",'Hardware'!C5) | E8: =IF('Hardware'!D5="","",'Hardware'!D5) | F8: =IF('Hardware'!E5="","",'Hardware'!E5) | G8: =IF('Hardware'!F5="","",'Hardware'!F5) | H8: =IF('Hardware'!G5="","",'Hardware'!G5) | I8: =IF('Hardware'!H5="","",'Hardware'!H5) | J8: =IF('Hardware'!I5="","",'Hardware'!I5) | ... M8: =IF('Hardware'!L5="","",'Hardware'!L5)
A9: =IF('Hardware'!A6="","",'Hardware'!A6) | B9: Hardware | C9: =IF('Hardware'!B6="","",'Hardware'!B6) | D9: =IF('Hardware'!C6="","",'Hardware'!C6) | E9: =IF('Hardware'!D6="","",'Hardware'!D6) | F9: =IF('Hardware'!E6="","",'Hardware'!E6) | G9: =IF('Hardware'!F6="","",'Hardware'!F6) | H9: =IF('Hardware'!G6="","",'Hardware'!G6) | I9: =IF('Hardware'!H6="","",'Hardware'!H6) | J9: =IF('Hardware'!I6="","",'Hardware'!I6) | ... M9: =IF('Hardware'!L6="","",'Hardware'!L6)
A10: =IF('Hardware'!A7="","",'Hardware'!A7) | B10: Hardware | C10: =IF('Hardware'!B7="","",'Hardware'!B7) | D10: =IF('Hardware'!C7="","",'Hardware'!C7) | E10: =IF('Hardware'!D7="","",'Hardware'!D7) | F10: =IF('Hardware'!E7="","",'Hardware'!E7) | G10: =IF('Hardware'!F7="","",'Hardware'!F7) | H10: =IF('Hardware'!G7="","",'Hardware'!G7) | I10: =IF('Hardware'!H7="","",'Hardware'!H7) | J10: =IF('Hardware'!I7="","",'Hardware'!I7) | ... M10: =IF('Hardware'!L7="","",'Hardware'!L7)
A11: =IF('Hardware'!A8="","",'Hardware'!A8) | B11: Hardware | C11: =IF('Hardware'!B8="","",'Hardware'!B8) | D11: =IF('Hardware'!C8="","",'Hardware'!C8) | E11: =IF('Hardware'!D8="","",'Hardware'!D8) | F11: =IF('Hardware'!E8="","",'Hardware'!E8) | G11: =IF('Hardware'!F8="","",'Hardware'!F8) | H11: =IF('Hardware'!G8="","",'Hardware'!G8) | I11: =IF('Hardware'!H8="","",'Hardware'!H8) | J11: =IF('Hardware'!I8="","",'Hardware'!I8) | ... M11: =IF('Hardware'!L8="","",'Hardware'!L8)
A12: =IF('Hardware'!A9="","",'Hardware'!A9) | B12: Hardware | C12: =IF('Hardware'!B9="","",'Hardware'!B9) | D12: =IF('Hardware'!C9="","",'Hardware'!C9) | E12: =IF('Hardware'!D9="","",'Hardware'!D9) | F12: =IF('Hardware'!E9="","",'Hardware'!E9) | G12: =IF('Hardware'!F9="","",'Hardware'!F9) | H12: =IF('Hardware'!G9="","",'Hardware'!G9) | I12: =IF('Hardware'!H9="","",'Hardware'!H9) | J12: =IF('Hardware'!I9="","",'Hardware'!I9) | ... M12: =IF('Hardware'!L9="","",'Hardware'!L9)
A13: =IF('Network'!A3="","",'Network'!A3) | B13: Network | C13: =IF('Network'!B3="","",'Network'!B3) | D13: =IF('Network'!C3="","",'Network'!C3) | E13: =IF('Network'!D3="","",'Network'!D3) | F13: =IF('Network'!E3="","",'Network'!E3) | G13: =IF('Network'!F3="","",'Network'!F3) | H13: =IF('Network'!G3="","",'Network'!G3) | I13: =IF('Network'!H3="","",'Network'!H3) | J13: =IF('Network'!I3="","",'Network'!I3) | ... M13: =IF('Network'!L3="","",'Network'!L3)
A14: =IF('Network'!A4="","",'Network'!A4) | B14: Network | C14: =IF('Network'!B4="","",'Network'!B4) | D14: =IF('Network'!C4="","",'Network'!C4) | E14: =IF('Network'!D4="","",'Network'!D4) | F14: =IF('Network'!E4="","",'Network'!E4) | G14: =IF('Network'!F4="","",'Network'!F4) | H14: =IF('Network'!G4="","",'Network'!G4) | I14: =IF('Network'!H4="","",'Network'!H4) | J14: =IF('Network'!I4="","",'Network'!I4) | ... M14: =IF('Network'!L4="","",'Network'!L4)
A15: =IF('Network'!A5="","",'Network'!A5) | B15: Network | C15: =IF('Network'!B5="","",'Network'!B5) | D15: =IF('Network'!C5="","",'Network'!C5) | E15: =IF('Network'!D5="","",'Network'!D5) | F15: =IF('Network'!E5="","",'Network'!E5) | G15: =IF('Network'!F5="","",'Network'!F5) | H15: =IF('Network'!G5="","",'Network'!G5) | I15: =IF('Network'!H5="","",'Network'!H5) | J15: =IF('Network'!I5="","",'Network'!I5) | ... M15: =IF('Network'!L5="","",'Network'!L5)
A16: =IF('Storage'!A3="","",'Storage'!A3) | B16: Storage | C16: =IF('Storage'!B3="","",'Storage'!B3) | D16: =IF('Storage'!C3="","",'Storage'!C3) | E16: =IF('Storage'!D3="","",'Storage'!D3) | F16: =IF('Storage'!E3="","",'Storage'!E3) | G16: =IF('Storage'!F3="","",'Storage'!F3) | H16: =IF('Storage'!G3="","",'Storage'!G3) | I16: =IF('Storage'!H3="","",'Storage'!H3) | J16: =IF('Storage'!I3="","",'Storage'!I3) | ... M16: =IF('Storage'!L3="","",'Storage'!L3)
A17: =IF('Storage'!A4="","",'Storage'!A4) | B17: Storage | C17: =IF('Storage'!B4="","",'Storage'!B4) | D17: =IF('Storage'!C4="","",'Storage'!C4) | E17: =IF('Storage'!D4="","",'Storage'!D4) | F17: =IF('Storage'!E4="","",'Storage'!E4) | G17: =IF('Storage'!F4="","",'Storage'!F4) | H17: =IF('Storage'!G4="","",'Storage'!G4) | I17: =IF('Storage'!H4="","",'Storage'!H4) | J17: =IF('Storage'!I4="","",'Storage'!I4) | ... M17: =IF('Storage'!L4="","",'Storage'!L4)
A18: =IF('Storage'!A5="","",'Storage'!A5) | B18: Storage | C18: =IF('Storage'!B5="","",'Storage'!B5) | D18: =IF('Storage'!C5="","",'Storage'!C5) | E18: =IF('Storage'!D5="","",'Storage'!D5) | F18: =IF('Storage'!E5="","",'Storage'!E5) | G18: =IF('Storage'!F5="","",'Storage'!F5) | H18: =IF('Storage'!G5="","",'Storage'!G5) | I18: =IF('Storage'!H5="","",'Storage'!H5) | J18: =IF('Storage'!I5="","",'Storage'!I5) | ... M18: =IF('Storage'!L5="","",'Storage'!L5)
A19: =IF('Storage'!A6="","",'Storage'!A6) | B19: Storage | C19: =IF('Storage'!B6="","",'Storage'!B6) | D19: =IF('Storage'!C6="","",'Storage'!C6) | E19: =IF('Storage'!D6="","",'Storage'!D6) | F19: =IF('Storage'!E6="","",'Storage'!E6) | G19: =IF('Storage'!F6="","",'Storage'!F6) | H19: =IF('Storage'!G6="","",'Storage'!G6) | I19: =IF('Storage'!H6="","",'Storage'!H6) | J19: =IF('Storage'!I6="","",'Storage'!I6) | ... M19: =IF('Storage'!L6="","",'Storage'!L6)
A20: =IF('Platform'!A3="","",'Platform'!A3) | B20: Platform | C20: =IF('Platform'!B3="","",'Platform'!B3) | D20: =IF('Platform'!C3="","",'Platform'!C3) | E20: =IF('Platform'!D3="","",'Platform'!D3) | F20: =IF('Platform'!E3="","",'Platform'!E3) | G20: =IF('Platform'!F3="","",'Platform'!F3) | H20: =IF('Platform'!G3="","",'Platform'!G3) | I20: =IF('Platform'!H3="","",'Platform'!H3) | J20: =IF('Platform'!I3="","",'Platform'!I3) | ... M20: =IF('Platform'!L3="","",'Platform'!L3)
A21: =IF('Platform'!A4="","",'Platform'!A4) | B21: Platform | C21: =IF('Platform'!B4="","",'Platform'!B4) | D21: =IF('Platform'!C4="","",'Platform'!C4) | E21: =IF('Platform'!D4="","",'Platform'!D4) | F21: =IF('Platform'!E4="","",'Platform'!E4) | G21: =IF('Platform'!F4="","",'Platform'!F4) | H21: =IF('Platform'!G4="","",'Platform'!G4) | I21: =IF('Platform'!H4="","",'Platform'!H4) | J21: =IF('Platform'!I4="","",'Platform'!I4) | ... M21: =IF('Platform'!L4="","",'Platform'!L4)
A22: =IF('Platform'!A5="","",'Platform'!A5) | B22: Platform | C22: =IF('Platform'!B5="","",'Platform'!B5) | D22: =IF('Platform'!C5="","",'Platform'!C5) | E22: =IF('Platform'!D5="","",'Platform'!D5) | F22: =IF('Platform'!E5="","",'Platform'!E5) | G22: =IF('Platform'!F5="","",'Platform'!F5) | H22: =IF('Platform'!G5="","",'Platform'!G5) | I22: =IF('Platform'!H5="","",'Platform'!H5) | J22: =IF('Platform'!I5="","",'Platform'!I5) | ... M22: =IF('Platform'!L5="","",'Platform'!L5)
A23: =IF('Platform'!A6="","",'Platform'!A6) | B23: Platform | C23: =IF('Platform'!B6="","",'Platform'!B6) | D23: =IF('Platform'!C6="","",'Platform'!C6) | E23: =IF('Platform'!D6="","",'Platform'!D6) | F23: =IF('Platform'!E6="","",'Platform'!E6) | G23: =IF('Platform'!F6="","",'Platform'!F6) | H23: =IF('Platform'!G6="","",'Platform'!G6) | I23: =IF('Platform'!H6="","",'Platform'!H6) | J23: =IF('Platform'!I6="","",'Platform'!I6) | ... M23: =IF('Platform'!L6="","",'Platform'!L6)
A24: =IF('Platform'!A7="","",'Platform'!A7) | B24: Platform | C24: =IF('Platform'!B7="","",'Platform'!B7) | D24: =IF('Platform'!C7="","",'Platform'!C7) | E24: =IF('Platform'!D7="","",'Platform'!D7) | F24: =IF('Platform'!E7="","",'Platform'!E7) | G24: =IF('Platform'!F7="","",'Platform'!F7) | H24: =IF('Platform'!G7="","",'Platform'!G7) | I24: =IF('Platform'!H7="","",'Platform'!H7) | J24: =IF('Platform'!I7="","",'Platform'!I7) | ... M24: =IF('Platform'!L7="","",'Platform'!L7)
A25: =IF('Platform'!A8="","",'Platform'!A8) | B25: Platform | C25: =IF('Platform'!B8="","",'Platform'!B8) | D25: =IF('Platform'!C8="","",'Platform'!C8) | E25: =IF('Platform'!D8="","",'Platform'!D8) | F25: =IF('Platform'!E8="","",'Platform'!E8) | G25: =IF('Platform'!F8="","",'Platform'!F8) | H25: =IF('Platform'!G8="","",'Platform'!G8) | I25: =IF('Platform'!H8="","",'Platform'!H8) | J25: =IF('Platform'!I8="","",'Platform'!I8) | ... M25: =IF('Platform'!L8="","",'Platform'!L8)
A26: =IF('Platform'!A9="","",'Platform'!A9) | B26: Platform | C26: =IF('Platform'!B9="","",'Platform'!B9) | D26: =IF('Platform'!C9="","",'Platform'!C9) | E26: =IF('Platform'!D9="","",'Platform'!D9) | F26: =IF('Platform'!E9="","",'Platform'!E9) | G26: =IF('Platform'!F9="","",'Platform'!F9) | H26: =IF('Platform'!G9="","",'Platform'!G9) | I26: =IF('Platform'!H9="","",'Platform'!H9) | J26: =IF('Platform'!I9="","",'Platform'!I9) | ... M26: =IF('Platform'!L9="","",'Platform'!L9)
A27: =IF('Platform'!A10="","",'Platform'!A10) | B27: Platform | C27: =IF('Platform'!B10="","",'Platform'!B10) | D27: =IF('Platform'!C10="","",'Platform'!C10) | E27: =IF('Platform'!D10="","",'Platform'!D10) | F27: =IF('Platform'!E10="","",'Platform'!E10) | G27: =IF('Platform'!F10="","",'Platform'!F10) | H27: =IF('Platform'!G10="","",'Platform'!G10) | I27: =IF('Platform'!H10="","",'Platform'!H10) | J27: =IF('Platform'!I10="","",'Platform'!I10) | ... M27: =IF('Platform'!L10="","",'Platform'!L10)
A28: =IF('Platform'!A11="","",'Platform'!A11) | B28: Platform | C28: =IF('Platform'!B11="","",'Platform'!B11) | D28: =IF('Platform'!C11="","",'Platform'!C11) | E28: =IF('Platform'!D11="","",'Platform'!D11) | F28: =IF('Platform'!E11="","",'Platform'!E11) | G28: =IF('Platform'!F11="","",'Platform'!F11) | H28: =IF('Platform'!G11="","",'Platform'!G11) | I28: =IF('Platform'!H11="","",'Platform'!H11) | J28: =IF('Platform'!I11="","",'Platform'!I11) | ... M28: =IF('Platform'!L11="","",'Platform'!L11)
A29: =IF('Platform'!A12="","",'Platform'!A12) | B29: Platform | C29: =IF('Platform'!B12="","",'Platform'!B12) | D29: =IF('Platform'!C12="","",'Platform'!C12) | E29: =IF('Platform'!D12="","",'Platform'!D12) | F29: =IF('Platform'!E12="","",'Platform'!E12) | G29: =IF('Platform'!F12="","",'Platform'!F12) | H29: =IF('Platform'!G12="","",'Platform'!G12) | I29: =IF('Platform'!H12="","",'Platform'!H12) | J29: =IF('Platform'!I12="","",'Platform'!I12) | ... M29: =IF('Platform'!L12="","",'Platform'!L12)
A30: =IF('Platform'!A13="","",'Platform'!A13) | B30: Platform | C30: =IF('Platform'!B13="","",'Platform'!B13) | D30: =IF('Platform'!C13="","",'Platform'!C13) | E30: =IF('Platform'!D13="","",'Platform'!D13) | F30: =IF('Platform'!E13="","",'Platform'!E13) | G30: =IF('Platform'!F13="","",'Platform'!F13) | H30: =IF('Platform'!G13="","",'Platform'!G13) | I30: =IF('Platform'!H13="","",'Platform'!H13) | J30: =IF('Platform'!I13="","",'Platform'!I13) | ... M30: =IF('Platform'!L13="","",'Platform'!L13)
A31: =IF('Platform'!A14="","",'Platform'!A14) | B31: Platform | C31: =IF('Platform'!B14="","",'Platform'!B14) | D31: =IF('Platform'!C14="","",'Platform'!C14) | E31: =IF('Platform'!D14="","",'Platform'!D14) | F31: =IF('Platform'!E14="","",'Platform'!E14) | G31: =IF('Platform'!F14="","",'Platform'!F14) | H31: =IF('Platform'!G14="","",'Platform'!G14) | I31: =IF('Platform'!H14="","",'Platform'!H14) | J31: =IF('Platform'!I14="","",'Platform'!I14) | ... M31: =IF('Platform'!L14="","",'Platform'!L14)
A32: =IF('Software'!A3="","",'Software'!A3) | B32: Software | C32: =IF('Software'!B3="","",'Software'!B3) | D32: =IF('Software'!C3="","",'Software'!C3) | E32: =IF('Software'!D3="","",'Software'!D3) | F32: =IF('Software'!E3="","",'Software'!E3) | G32: =IF('Software'!F3="","",'Software'!F3) | H32: =IF('Software'!G3="","",'Software'!G3) | I32: =IF('Software'!H3="","",'Software'!H3) | J32: =IF('Software'!I3="","",'Software'!I3) | ... M32: =IF('Software'!L3="","",'Software'!L3)
A33: =IF('Software'!A4="","",'Software'!A4) | B33: Software | C33: =IF('Software'!B4="","",'Software'!B4) | D33: =IF('Software'!C4="","",'Software'!C4) | E33: =IF('Software'!D4="","",'Software'!D4) | F33: =IF('Software'!E4="","",'Software'!E4) | G33: =IF('Software'!F4="","",'Software'!F4) | H33: =IF('Software'!G4="","",'Software'!G4) | I33: =IF('Software'!H4="","",'Software'!H4) | J33: =IF('Software'!I4="","",'Software'!I4) | ... M33: =IF('Software'!L4="","",'Software'!L4)
A34: =IF('MLOps'!A3="","",'MLOps'!A3) | B34: MLOps | C34: =IF('MLOps'!B3="","",'MLOps'!B3) | D34: =IF('MLOps'!C3="","",'MLOps'!C3) | E34: =IF('MLOps'!D3="","",'MLOps'!D3) | F34: =IF('MLOps'!E3="","",'MLOps'!E3) | G34: =IF('MLOps'!F3="","",'MLOps'!F3) | H34: =IF('MLOps'!G3="","",'MLOps'!G3) | I34: =IF('MLOps'!H3="","",'MLOps'!H3) | J34: =IF('MLOps'!I3="","",'MLOps'!I3) | ... M34: =IF('MLOps'!L3="","",'MLOps'!L3)
A35: =IF('MLOps'!A4="","",'MLOps'!A4) | B35: MLOps | C35: =IF('MLOps'!B4="","",'MLOps'!B4) | D35: =IF('MLOps'!C4="","",'MLOps'!C4) | E35: =IF('MLOps'!D4="","",'MLOps'!D4) | F35: =IF('MLOps'!E4="","",'MLOps'!E4) | G35: =IF('MLOps'!F4="","",'MLOps'!F4) | H35: =IF('MLOps'!G4="","",'MLOps'!G4) | I35: =IF('MLOps'!H4="","",'MLOps'!H4) | J35: =IF('MLOps'!I4="","",'MLOps'!I4) | ... M35: =IF('MLOps'!L4="","",'MLOps'!L4)
A36: =IF('MLOps'!A5="","",'MLOps'!A5) | B36: MLOps | C36: =IF('MLOps'!B5="","",'MLOps'!B5) | D36: =IF('MLOps'!C5="","",'MLOps'!C5) | E36: =IF('MLOps'!D5="","",'MLOps'!D5) | F36: =IF('MLOps'!E5="","",'MLOps'!E5) | G36: =IF('MLOps'!F5="","",'MLOps'!F5) | H36: =IF('MLOps'!G5="","",'MLOps'!G5) | I36: =IF('MLOps'!H5="","",'MLOps'!H5) | J36: =IF('MLOps'!I5="","",'MLOps'!I5) | ... M36: =IF('MLOps'!L5="","",'MLOps'!L5)
A37: =IF('MLOps'!A6="","",'MLOps'!A6) | B37: MLOps | C37: =IF('MLOps'!B6="","",'MLOps'!B6) | D37: =IF('MLOps'!C6="","",'MLOps'!C6) | E37: =IF('MLOps'!D6="","",'MLOps'!D6) | F37: =IF('MLOps'!E6="","",'MLOps'!E6) | G37: =IF('MLOps'!F6="","",'MLOps'!F6) | H37: =IF('MLOps'!G6="","",'MLOps'!G6) | I37: =IF('MLOps'!H6="","",'MLOps'!H6) | J37: =IF('MLOps'!I6="","",'MLOps'!I6) | ... M37: =IF('MLOps'!L6="","",'MLOps'!L6)
A38: =IF('MLOps'!A7="","",'MLOps'!A7) | B38: MLOps | C38: =IF('MLOps'!B7="","",'MLOps'!B7) | D38: =IF('MLOps'!C7="","",'MLOps'!C7) | E38: =IF('MLOps'!D7="","",'MLOps'!D7) | F38: =IF('MLOps'!E7="","",'MLOps'!E7) | G38: =IF('MLOps'!F7="","",'MLOps'!F7) | H38: =IF('MLOps'!G7="","",'MLOps'!G7) | I38: =IF('MLOps'!H7="","",'MLOps'!H7) | J38: =IF('MLOps'!I7="","",'MLOps'!I7) | ... M38: =IF('MLOps'!L7="","",'MLOps'!L7)
A39: =IF('MLOps'!A8="","",'MLOps'!A8) | B39: MLOps | C39: =IF('MLOps'!B8="","",'MLOps'!B8) | D39: =IF('MLOps'!C8="","",'MLOps'!C8) | E39: =IF('MLOps'!D8="","",'MLOps'!D8) | F39: =IF('MLOps'!E8="","",'MLOps'!E8) | G39: =IF('MLOps'!F8="","",'MLOps'!F8) | H39: =IF('MLOps'!G8="","",'MLOps'!G8) | I39: =IF('MLOps'!H8="","",'MLOps'!H8) | J39: =IF('MLOps'!I8="","",'MLOps'!I8) | ... M39: =IF('MLOps'!L8="","",'MLOps'!L8)
A40: =IF('MLOps'!A9="","",'MLOps'!A9) | B40: MLOps | C40: =IF('MLOps'!B9="","",'MLOps'!B9) | D40: =IF('MLOps'!C9="","",'MLOps'!C9) | E40: =IF('MLOps'!D9="","",'MLOps'!D9) | F40: =IF('MLOps'!E9="","",'MLOps'!E9) | G40: =IF('MLOps'!F9="","",'MLOps'!F9) | H40: =IF('MLOps'!G9="","",'MLOps'!G9) | I40: =IF('MLOps'!H9="","",'MLOps'!H9) | J40: =IF('MLOps'!I9="","",'MLOps'!I9) | ... M40: =IF('MLOps'!L9="","",'MLOps'!L9)
A41: =IF('Development'!A3="","",'Development'!A3) | B41: Development | C41: =IF('Development'!B3="","",'Development'!B3) | D41: =IF('Development'!C3="","",'Development'!C3) | E41: =IF('Development'!D3="","",'Development'!D3) | F41: =IF('Development'!E3="","",'Development'!E3) | G41: =IF('Development'!F3="","",'Development'!F3) | H41: =IF('Development'!G3="","",'Development'!G3) | I41: =IF('Development'!H3="","",'Development'!H3) | J41: =IF('Development'!I3="","",'Development'!I3) | ... M41: =IF('Development'!L3="","",'Development'!L3)
...

Sheet Application
A1: Application Parameters
A2: Parameter Name | B2: Environment | C2: Default Value | D2: Description | E2: Required | F2: Data Type | G2: Validation Rules | H2: Security Level | I2: Owner Team | J2: Dependencies | K2: Notes | L2: Last Updated
A3: CLUSTER_NAME | B3: All | C3: gpu-cluster-prod | D3: Kubernetes cluster identifier | E3: Yes | F3: String | G3: Max 30 alphanumeric chars | H3: Public | I3: Platform Team | J3: None | K3: Used in kubectl context | L3: [DATE]

Sheet Hardware
A1: Hardware Parameters
A2: Parameter Name | B2: Environment | C2: Default Value | D2: Description | E2: Required | F2: Data Type | G2: Validation Rules | H2: Security Level | I2: Owner Team | J2: Dependencies | K2: Notes | L2: Last Updated
A3: GPU_SERVER_COUNT | B3: All | C3: 8 | D3: Number of GPU servers in cluster | E3: Yes | F3: Integer | G3: 1-32 | H3: Public | I3: Hardware Team | J3: Rack capacity | K3: Dell R750xa servers | L3: [DATE]
A4: GPU_MODEL | B4: All | C4: A100 40GB | D4: NVIDIA GPU model specification | E4: Yes | F4: String | G4: Valid NVIDIA GPU model | H4: Public | I4: Hardware Team | J4: Performance requirements | K4: PCIe form factor | L4: [DATE]
A5: GPU_COUNT_PER_SERVER | B5: All | C5: 4 | D5: Number of A100 GPUs per server | E5: Yes | F5: Integer | G5: 1-8 | H5: Public | I5: Hardware Team | J5: Server model | K5: Fixed for R750xa | L5: [DATE]
A6: TOTAL_GPU_COUNT | B6: All | C6: 32 | D6: Total GPUs across all servers | E6: Yes | F6: Integer | G6: Calculated | H6: Public | I6: GPU Team | J6: GPU_COUNT_PER_SERVER | K6: 8 servers x 4 GPUs | L6: [DATE]
A7: GPU_MEMORY_GB | B7: All | C7: 40 | D7: GPU memory in GB per GPU | E7: Yes | F7: Integer | G7: 40 | H7: Public | I7: GPU Team | J7: Model size support | K7: 1.28 TB total cluster | L7: [DATE]
A8: SERVER_RAM_GB | B8: All | C8: 1024 | D8: System RAM per server in GB | E8: Yes | F8: Integer | G8: 512-2048 | H8: Public | I8: Hardware Team | J8: Data preprocessing | K8: 1 TB per server | L8: [DATE]
A9: SERVER_CPU_CORES | B9: All | C9: 128 | D9: CPU cores per server | E9: Yes | F9: Integer | G9: 64-256 | H9: Public | I9: Hardware Team | J9: Dual Xeon Platinum | K9: Multi-processing | L9: [DATE]

Sheet Network
A1: Network Parameters
A2: Parameter Name | B2: Environment | C2: Default Value | D2: Description | E2: Required | F2: Data Type | G2: Validation Rules | H2: Security Level | I2: Owner Team | J2: Dependencies | K2: Notes | L2: Last Updated
A3: NETWORK_SPEED_GBE | B3: All | C3: 100 | D3: Network port speed in Gbps | E3: Yes | F3: Integer | G3: 25-100 | H3: Public | I3: Network Team | J3: Distributed training | K3: RoCE enabled | L3: [DATE]
A4: NETWORK_MTU | B4: All | C4: 9000 | D4: Network MTU for jumbo frames | E4: Yes | F4: Integer | G4: 1500-9216 | H4: Public | I4: Network Team | J4: RoCE performance | K4: Required for RDMA | L4: [DATE]
A5: ROCE_ENABLED | B5: All | C5: true | D5: Enable RDMA over Converged Ethernet | E5: Yes | F5: Boolean | G5: true|false | H5: Public | I5: Network Team | J5: NCCL performance | K5: GPU communication | L5: [DATE]

Sheet Storage
A1: Storage Parameters
A2: Parameter Name | B2: Environment | C2: Default Value | D2: Description | E2: Required | F2: Data Type | G2: Validation Rules | H2: Security Level | I2: Owner Team | J2: Dependencies | K2: Notes | L2: Last Updated
A3: STORAGE_SYSTEM | B3: All | C3: NetApp AFF | D3: Shared storage platform | E3: Yes | F3: String | G3: Valid storage platform | H3: Public | I3: Storage Team | J3: Dataset storage | K3: NVMe all-flash | L3: [DATE]
A4: STORAGE_CAPACITY_TB | B4: All | C4: 200 | D4: Shared storage capacity in TB | E4: Yes | F4: Integer | G4: 100-1000 | H4: Public | I4: Storage Team | J4: Dataset requirements | K4: Expandable | L4: [DATE]
A5: STORAGE_THROUGHPUT_GBS | B5: All | C5: 10 | D5: Target storage throughput GB/s | E5: Yes | F5: Integer | G5: 5-50 | H5: Public | I5: Storage Team | J5: Training I/O | K5: Sustained read/write | L5: [DATE]
A6: STORAGE_MOUNT_PATH | B6: All | C6: /shared | D6: NFS mount point for shared storage | E6: Yes | F6: String | G6: Valid Unix path | H6: Public | I6: Storage Team | J6: All nodes | K6: Dataset and model storage | L6: [DATE]

Sheet Platform
A1: Platform Parameters
A2: Parameter Name | B2: Environment | C2: Default Value | D2: Description | E2: Required | F2: Data Type | G2: Validation Rules | H2: Security Level | I2: Owner Team | J2: Dependencies | K2: Notes | L2: Last Updated
A3: K8S_VERSION | B3: All | C3: 1.28.4 | D3: Kubernetes version | E3: Yes | F3: String | G3: Valid K8s version | H3: Public | I3: Platform Team | J3: GPU Operator compatibility | K3: Latest stable | L3: [DATE]
A4: K8S_CONTROL_PLANE_COUNT | B4: All | C4: 3 | D4: Number of control plane nodes | E4: Yes | F4: Integer | G4: 1-5 | H4: Public | I4: Platform Team | J4: HA requirement | K4: Odd number for quorum | L4: [DATE]
A5: K8S_WORKER_NODE_COUNT | B5: All | C5: 8 | D5: Number of GPU worker nodes | E5: Yes | F5: Integer | G5: Matches GPU servers | H5: Public | I5: Platform Team | J5: GPU_SERVER_COUNT | K5: All servers as workers | L5: [DATE]
A6: K8S_CNI_PLUGIN | B6: All | C6: Calico | D6: Container network plugin | E6: Yes | F6: String | G6: Calico|Cilium|Flannel | H6: Public | I6: Network Team | J6: Network policy | K6: Enterprise networking | L6: [DATE]
A7: GPU_OPERATOR_VERSION | B7: All | C7: v23.9.0 | D7: NVIDIA GPU Operator version | E7: Yes | F7: String | G7: Valid operator version | H7: Public | I7: GPU Team | J7: Driver management | K7: Latest stable | L7: [DATE]
A8: GPU_DRIVER_VERSION | B8: All | C8: 535.129.03 | D8: NVIDIA GPU driver version | E8: Yes | F8: String | G8: Valid driver version | H8: Public | I8: GPU Team | J8: CUDA compatibility | K8: Production driver | L8: [DATE]
A9: DEVICE_PLUGIN_ENABLED | B9: All | C9: true | D9: Enable GPU device plugin | E9: Yes | F9: Boolean | G9: true|false | H9: Public | I9: GPU Team | J9: GPU scheduling | K9: Managed by Operator | L9: [DATE]
A10: TIME_SLICING_ENABLED | B10: All | C10: true | D10: Enable GPU time-slicing | E10: Yes | F10: Boolean | G10: true|false | H10: Public | I10: GPU Team | J10: Resource sharing | K10: Multi-tenant support | L10: [DATE]
A11: TIME_SLICING_REPLICAS | B11: All | C11: 4 | D11: Virtual GPUs per physical GPU | E11: Yes | F11: Integer | G11: 2-10 | H11: Public | I11: GPU Team | J11: User density | K11: 4 users per GPU | L11: [DATE]
A12: CONTAINER_RUNTIME | B12: All | C12: containerd | D12: Container runtime | E12: Yes | F12: String | G12: containerd|docker|cri-o | H12: Public | I12: Platform Team | J12: GPU Operator | K12: NVIDIA Container Toolkit | L12: [DATE]
A13: DEFAULT_GPU_LIMIT | B13: All | C13: 1 | D13: Default GPU limit per pod | E13: Yes | F13: Integer | G13: 1-4 | H13: Public | I13: Platform Team | J13: Resource management | K13: Prevent monopolization | L13: [DATE]
A14: MAX_GPU_PER_USER | B14: All | C14: 8 | D14: Maximum GPUs per user | E14: Yes | F14: Integer | G14: 4-32 | H14: Public | I14: Platform Team | J14: Fair sharing | K14: Team allocation | L14: [DATE]

Sheet Software
A1: Software Parameters
A2: Parameter Name | B2: Environment | C2: Default Value | D2: Description | E2: Required | F2: Data Type | G2: Validation Rules | H2: Security Level | I2: Owner Team | J2: Dependencies | K2: Notes | L2: Last Updated
A3: CUDA_VERSION | B3: All | C3: 12.2 | D3: CUDA toolkit version | E3: Yes | F3: String | G3: Valid CUDA version | H3: Public | I3: Software Team | J3: GPU_DRIVER_VERSION | K3: Framework compatibility | L3: [DATE]
A4: NGC_REGISTRY_URL | B4: All | C4: nvcr.io | D4: NVIDIA NGC container registry | E4: Yes | F4: String | G4: Valid registry URL | H4: Public | I4: AI Team | J4: Container images | K4: Official containers | L4: [DATE]

Sheet MLOps
A1: MLOps Parameters
A2: Parameter Name | B2: Environment | C2: Default Value | D2: Description | E2: Required | F2: Data Type | G2: Validation Rules | H2: Security Level | I2: Owner Team | J2: Dependencies | K2: Notes | L2: Last Updated
A3: KUBEFLOW_VERSION | B3: All | C3: 1.8.0 | D3: Kubeflow version | E3: Yes | F3: String | G3: Valid Kubeflow version | H3: Public | I3: MLOps Team | J3: ML pipelines | K3: Latest stable | L3: [DATE]
A4: KUBEFLOW_NAMESPACE | B4: All | C4: kubeflow | D4: Kubeflow installation namespace | E4: Yes | F4: String | G4: Valid namespace | H4: Public | I4: MLOps Team | J4: Isolation | K4: System namespace | L4: [DATE]
A5: MLFLOW_VERSION | B5: All | C5: 2.9.0 | D5: MLflow version | E5: Yes | F5: String | G5: Valid MLflow version | H5: Public | I5: MLOps Team | J5: Experiment tracking | K5: Latest stable | L5: [DATE]
A6: MLFLOW_TRACKING_URI | B6: All | C6: http://mlflow:5000 | D6: MLflow tracking server URI | E6: Yes | F6: String | G6: Valid URI | H6: Public | I6: MLOps Team | J6: Experiment logging | K6: Internal service | L6: [DATE]
A7: MLFLOW_ARTIFACT_PATH | B7: All | C7: /shared/mlflow/artifacts | D7: MLflow artifact storage path | E7: Yes | F7: String | G7: Valid path | H7: Public | I7: MLOps Team | J7: Model storage | K7: On shared storage | L7: [DATE]
A8: TRITON_VERSION | B8: All | C8: 24.01 | D8: Triton Inference Server version | E8: Yes | F8: String | G8: Valid Triton version | H8: Public | I8: AI Team | J8: Model serving | K8: NGC container | L8: [DATE]
A9: TRITON_MODEL_REPOSITORY | B9: All | C9: /shared/models/triton | D9: Triton model repository path | E9: Yes | F9: String | G9: Valid path | H9: Public | I9: AI Team | J9: Model deployment | K9: On shared storage | L9: [DATE]

Sheet Development
A1: Development Parameters
A2: Parameter Name | B2: Environment | C2: Default Value | D2: Description | E2: Required | F2: Data Type | G2: Validation Rules | H2: Security Level | I2: Owner Team | J2: Dependencies | K2: Notes | L2: Last Updated
A3: JUPYTERHUB_ENABLED | B3: All | C3: true | D3: Enable JupyterHub for data science | E3: Yes | F3: Boolean | G3: true|false | H3: Public | I3: AI Team | J3: Interactive development | K3: GPU notebooks | L3: [DATE]
A4: JUPYTERHUB_NAMESPACE | B4: All | C4: jupyterhub | D4: JupyterHub namespace | E4: Yes | F4: String | G4: Valid namespace | H4: Public | I4: AI Team | J4: User isolation | K4: Per-user pods | L4: [DATE]

Sheet Security
A1: Security Parameters
A2: Parameter Name | B2: Environment | C2: Default Value | D2: Description | E2: Required | F2: Data Type | G2: Validation Rules | H2: Security Level | I2: Owner Team | J2: Dependencies | K2: Notes | L2: Last Updated
A3: LDAP_ENABLED | B3: All | C3: [********] | D3: Enable LDAP authentication | E3: Yes | F3: Boolean | G3: true|false | H3: Confidential | I3: Security Team | J3: User management | K3: Central auth | L3: [DATE]
A4: LDAP_SERVER_URL | B4: All | C4: [********] | D4: LDAP server endpoint | E4: Yes | F4: String | G4: Valid LDAP URL | H4: Secret | I4: Security Team | J4: Directory service | K4: AD integration | L4: [DATE]
A5: RBAC_ENABLED | B5: All | C5: true | D5: Enable Kubernetes RBAC | E5: Yes | F5: Boolean | G5: true|false | H5: Public | I5: Security Team | J5: Access control | K5: Required | L5: [DATE]
A6: NETWORK_POLICY_ENABLED | B6: All | C6: true | D6: Enable Kubernetes network policies | E6: Yes | F6: Boolean | G6: true|false | H6: Public | I6: Security Team | J6: Namespace isolation | K6: Calico policies | L6: [DATE]

Sheet Monitoring
A1: Monitoring Parameters
A2: Parameter Name | B2: Environment | C2: Default Value | D2: Description | E2: Required | F2: Data Type | G2: Validation Rules | H2: Security Level | I2: Owner Team | J2: Dependencies | K2: Notes | L2: Last Updated
A3: PROMETHEUS_ENABLED | B3: All | C3: true | D3: Enable Prometheus monitoring | E3: Yes | F3: Boolean | G3: true|false | H3: Public | I3: Operations | J3: Metrics collection | K3: GPU metrics | L3: [DATE]
A4: GRAFANA_ENABLED | B4: All | C4: true | D4: Enable Grafana dashboards | E4: Yes | F4: Boolean | G4: true|false | H4: Public | I4: Operations | J4: Visualization | K4: Pre-built dashboards | L4: [DATE]
A5: DCGM_EXPORTER_ENABLED | B5: All | C5: true | D5: Enable NVIDIA DCGM exporter | E5: Yes | F5: Boolean | G5: true|false | H5: Public | I5: GPU Team | J5: GPU monitoring | K5: GPU Operator managed | L5: [DATE]
A6: GPU_UTIL_ALERT_THRESHOLD | B6: All | C6: 90 | D6: GPU utilization alert threshold % | E6: Yes | F6: Integer | G6: 80-99 | H6: Public | I6: Operations | J6: Resource management | K6: High util alert | L6: [DATE]

Sheet Operations
A1: Operations Parameters
A2: Parameter Name | B2: Environment | C2: Default Value | D2: Description | E2: Required | F2: Data Type | G2: Validation Rules | H2: Security Level | I2: Owner Team | J2: Dependencies | K2: Notes | L2: Last Updated
A3: BACKUP_ENABLED | B3: All | C3: true | D3: Enable automated backups | E3: Yes | F3: Boolean | G3: true|false | H3: Public | I3: Operations | J3: Data protection | K3: etcd and PV | L3: [DATE]
A4: MAINTENANCE_WINDOW | B4: All | C4: Sunday 02:00-06:00 UTC | D4: Weekly maintenance window | E4: Yes | F4: String | G4: Valid time range | H4: Public | I4: Operations | J4: Updates | K4: Low-usage period | L4: [DATE]
